Workbook

Sheet 說明_ReadMe
A1: VMH-EcoMap-22 聯盟體檢儀表板｜使用說明
A2: P2 評估決策工具・資料快照抽取自 1 號主工具（2026-08）・與 9 號導覽器同源
B4: ■ 這個工具在回答什麼
B5: 導覽器告訴你「缺什麼」（9 項零覆蓋缺口），但沒告訴你另一個同樣危險的事實： 目前 60 項能力裡，每一項都只有「一家」候選夥伴，而且其中 45 家還停留在「目標邀請」——還沒談、沒盡調、沒簽。 這張表把「名單上有人」和「真的靠得住」區分開來，這就是體檢的意義。
B7: ■ 有效冗餘分怎麼算
B8: 不是數「名單上有幾家」，而是按夥伴的實際狀態加權： 群晶主導＝1.0（自己的能力最可靠）｜已通過資格 Qualified＝1.0｜盡職調查中＝0.7｜已接觸 Engaged＝0.5｜目標邀請 Target＝0.25｜缺口＝0 一項能力的有效冗餘分低於 1.0，代表這項能力「還不能承諾給客戶」。
B10: ■ 燈號規則
B11: 🔴 零覆蓋（分數 0）：連候選人都沒有，優先補位 🟠 高風險（0＜分數≤0.35）：只有還沒談的目標對象，等於紙上名單 🟡 待補強（0.35＜分數＜1.0）：有進展但還不能承諾 🟢 可承諾（分數≥1.0）：至少一家可靠來源
B13: ■ 每月體檢例行
B14: ① 每月初把 1 號主工具的能力矩陣異動更新到「能力覆蓋表」（夥伴狀態變了就改狀態欄）。 ② 看儀表板總分有沒有進步——體檢分數是聯盟建設的 KPI，適合放進月報。 ③ 零覆蓋與高風險清單，逐項指定補位負責人與期限，填進「補位行動」頁。
B16: ■ 與其他工具的銜接
B17: 補位人選從 18 號情報站的 115 家名冊找；洽談中的補位對象開進 20 號漏斗當案件追蹤； 夥伴通過資格審查後，回 1 號主工具改狀態，下次快照更新時體檢分數自動反映。

Sheet 00_體檢儀表板_Dashboard
A1: 體檢儀表板｜Dashboard（全自動）
A2: ❓這頁在回答：聯盟現在撐得住幾門生意？最脆的地方在哪？
B4: 總體
B5: 體檢總分（0–100） | C5: =ROUND(AVERAGE(01_能力覆蓋表_Coverage!$J$5:$J$64)*100,0) -> 37 | D5: 平均有效冗餘分×100。目標：逐月上升
B6: 🔴 零覆蓋能力數 | C6: =COUNTIF(01_能力覆蓋表_Coverage!$J$5:$J$64,0) -> 9 | D6: 連候選人都沒有
B7: 🟠 高風險能力數 | C7: =COUNTIFS(01_能力覆蓋表_Coverage!$J$5:$J$64,">0",01_能力覆蓋表_Coverage!$J$5:$J$64,"<=0.35") -> 37 | D7: 只有未接觸的目標對象
B8: 🟢 可承諾能力數 | C8: =COUNTIF(01_能力覆蓋表_Coverage!$J$5:$J$64,">=1") -> 12 | D8: 至少一家可靠來源
B9: 單一來源能力數 | C9: =COUNTIF(01_能力覆蓋表_Coverage!$F$5:$F$64,"P-*") -> 60 | D9: 候選只有一家（目前＝全部）——第二來源是中期目標
B11: 依領域
B12: 領域 | C12: 能力數 | D12: 🔴 零覆蓋 | E12: 平均冗餘分 | F12: 最弱狀態
B13: D01 治理與投資 | C13: =COUNTIF(01_能力覆蓋表_Coverage!$C$5:$C$64,$B13) -> 6 | D13: =COUNTIFS(01_能力覆蓋表_Coverage!$C$5:$C$64,$B13,01_能力覆蓋表_Coverage!$J$5:$J$64,0) -> 0 | E13: =ROUND(AVERAGEIF(01_能力覆蓋表_Coverage!$C$5:$C$64,$B13,01_能力覆蓋表_Coverage!$J$5:$J$64),2) -> 0.42 | F13: =IF($D13>0,"🔴 有零覆蓋",IF($E13<=0.35,"🟠 整體單薄","🟡 持續補強")) -> 🟡 持續補強
B14: D02 臨床服務模式 | C14: =COUNTIF(01_能力覆蓋表_Coverage!$C$5:$C$64,$B14) -> 6 | D14: =COUNTIFS(01_能力覆蓋表_Coverage!$C$5:$C$64,$B14,01_能力覆蓋表_Coverage!$J$5:$J$64,0) -> 0 | E14: =ROUND(AVERAGEIF(01_能力覆蓋表_Coverage!$C$5:$C$64,$B14,01_能力覆蓋表_Coverage!$J$5:$J$64),2) -> 0.25 | F14: =IF($D14>0,"🔴 有零覆蓋",IF($E14<=0.35,"🟠 整體單薄","🟡 持續補強")) -> 🟠 整體單薄
B15: D03 醫院設施與機電 | C15: =COUNTIF(01_能力覆蓋表_Coverage!$C$5:$C$64,$B15) -> 7 | D15: =COUNTIFS(01_能力覆蓋表_Coverage!$C$5:$C$64,$B15,01_能力覆蓋表_Coverage!$J$5:$J$64,0) -> 0 | E15: =ROUND(AVERAGEIF(01_能力覆蓋表_Coverage!$C$5:$C$64,$B15,01_能力覆蓋表_Coverage!$J$5:$J$64),2) -> 0.36 | F15: =IF($D15>0,"🔴 有零覆蓋",IF($E15<=0.35,"🟠 整體單薄","🟡 持續補強")) -> 🟡 持續補強
B16: D04 數位基建與物聯網 | C16: =COUNTIF(01_能力覆蓋表_Coverage!$C$5:$C$64,$B16) -> 7 | D16: =COUNTIFS(01_能力覆蓋表_Coverage!$C$5:$C$64,$B16,01_能力覆蓋表_Coverage!$J$5:$J$64,0) -> 0 | E16: =ROUND(AVERAGEIF(01_能力覆蓋表_Coverage!$C$5:$C$64,$B16,01_能力覆蓋表_Coverage!$J$5:$J$64),2) -> 0.89 | F16: =IF($D16>0,"🔴 有零覆蓋",IF($E16<=0.35,"🟠 整體單薄","🟡 持續補強")) -> 🟡 持續補強
B17: D05 醫材與診斷 | C17: =COUNTIF(01_能力覆蓋表_Coverage!$C$5:$C$64,$B17) -> 6 | D17: =COUNTIFS(01_能力覆蓋表_Coverage!$C$5:$C$64,$B17,01_能力覆蓋表_Coverage!$J$5:$J$64,0) -> 3 | E17: =ROUND(AVERAGEIF(01_能力覆蓋表_Coverage!$C$5:$C$64,$B17,01_能力覆蓋表_Coverage!$J$5:$J$64),2) -> 0.13 | F17: =IF($D17>0,"🔴 有零覆蓋",IF($E17<=0.35,"🟠 整體單薄","🟡 持續補強")) -> 🔴 有零覆蓋
B18: D06 醫療資訊與資料 | C18: =COUNTIF(01_能力覆蓋表_Coverage!$C$5:$C$64,$B18) -> 7 | D18: =COUNTIFS(01_能力覆蓋表_Coverage!$C$5:$C$64,$B18,01_能力覆蓋表_Coverage!$J$5:$J$64,0) -> 2 | E18: =ROUND(AVERAGEIF(01_能力覆蓋表_Coverage!$C$5:$C$64,$B18,01_能力覆蓋表_Coverage!$J$5:$J$64),2) -> 0.24 | F18: =IF($D18>0,"🔴 有零覆蓋",IF($E18<=0.35,"🟠 整體單薄","🟡 持續補強")) -> 🔴 有零覆蓋
B19: D07 品質與病安 | C19: =COUNTIF(01_能力覆蓋表_Coverage!$C$5:$C$64,$B19) -> 5 | D19: =COUNTIFS(01_能力覆蓋表_Coverage!$C$5:$C$64,$B19,01_能力覆蓋表_Coverage!$J$5:$J$64,0) -> 0 | E19: =ROUND(AVERAGEIF(01_能力覆蓋表_Coverage!$C$5:$C$64,$B19,01_能力覆蓋表_Coverage!$J$5:$J$64),2) -> 0.25 | F19: =IF($D19>0,"🔴 有零覆蓋",IF($E19<=0.35,"🟠 整體單薄","🟡 持續補強")) -> 🟠 整體單薄
B20: D08 人才與技轉 | C20: =COUNTIF(01_能力覆蓋表_Coverage!$C$5:$C$64,$B20) -> 5 | D20: =COUNTIFS(01_能力覆蓋表_Coverage!$C$5:$C$64,$B20,01_能力覆蓋表_Coverage!$J$5:$J$64,0) -> 1 | E20: =ROUND(AVERAGEIF(01_能力覆蓋表_Coverage!$C$5:$C$64,$B20,01_能力覆蓋表_Coverage!$J$5:$J$64),2) -> 0.35 | F20: =IF($D20>0,"🔴 有零覆蓋",IF($E20<=0.35,"🟠 整體單薄","🟡 持續補強")) -> 🔴 有零覆蓋
B21: D09 供應鏈與維運 | C21: =COUNTIF(01_能力覆蓋表_Coverage!$C$5:$C$64,$B21) -> 5 | D21: =COUNTIFS(01_能力覆蓋表_Coverage!$C$5:$C$64,$B21,01_能力覆蓋表_Coverage!$J$5:$J$64,0) -> 0 | E21: =ROUND(AVERAGEIF(01_能力覆蓋表_Coverage!$C$5:$C$64,$B21,01_能力覆蓋表_Coverage!$J$5:$J$64),2) -> 0.55 | F21: =IF($D21>0,"🔴 有零覆蓋",IF($E21<=0.35,"🟠 整體單薄","🟡 持續補強")) -> 🟡 持續補強
B22: D10 商模與病人生態 | C22: =COUNTIF(01_能力覆蓋表_Coverage!$C$5:$C$64,$B22) -> 6 | D22: =COUNTIFS(01_能力覆蓋表_Coverage!$C$5:$C$64,$B22,01_能力覆蓋表_Coverage!$J$5:$J$64,0) -> 3 | E22: =ROUND(AVERAGEIF(01_能力覆蓋表_Coverage!$C$5:$C$64,$B22,01_能力覆蓋表_Coverage!$J$5:$J$64),2) -> 0.25 | F22: =IF($D22>0,"🔴 有零覆蓋",IF($E22<=0.35,"🟠 整體單薄","🟡 持續補強")) -> 🔴 有零覆蓋
B24: 讀法：體檢總分是聯盟建設的月度 KPI。目前的結構性事實：60 項能力全部只有單一候選來源，所以短期 KPI 是把「目標邀請」推進成「已通過資格」，中期 KPI 才是替關鍵能力找第二來源。

Sheet 01_能力覆蓋表_Coverage
A1: 能力覆蓋表｜Coverage（自 1 號主工具抽取，狀態變了就改這裡）
A2: ❓這頁在回答：每項能力靠誰？那個「誰」現在可靠到什麼程度？
A3: 圖例： | B3: 要填 | C3: 自動
A4: 能力ID | B4: 能力名稱 | C4: 領域 | D4: 能力狀態 | E4: 主責 | F4: 候選夥伴ID | G4: 候選夥伴 | H4: 夥伴狀態 | I4: 狀態權重 | J4: 有效冗餘分 | K4: 燈號 | L4: 補位優先
A5: CAP-001 | B5: 政府授權與計畫章程 | C5: D01 治理與投資 | D5: 夥伴洽談中 | E5: PI Office | F5: P-002 | G5: 越南政府贊助單位 | H5: Engaged | I5: =IFERROR(INDEX(_選單_Lists!$B$2:$B$8,MATCH($H5,_選單_Lists!$A$2:$A$8,0)),0) -> 0.5 | J5: =IF($D5="群晶主導",1,IF($D5="缺口-待尋找",0,$I5)) -> 0.5 | K5: =IF($J5=0,"🔴 零覆蓋",IF($J5<=0.35,"🟠 高風險",IF($J5<1,"🟡 待補強","🟢 可承諾"))) -> 🟡 待補強 | L5: =IF($J5=0,"P1 最優先",IF($J5<=0.35,"P2","—")) -> —
A6: CAP-002 | B6: 利害關係人與權力地圖 | C6: D01 治理與投資 | D6: 夥伴洽談中 | E6: PI Office | F6: P-017 | G6: 越南公共事務顧問 | H6: Target | I6: =IFERROR(INDEX(_選單_Lists!$B$2:$B$8,MATCH($H6,_選單_Lists!$A$2:$A$8,0)),0) -> 0.25 | J6: =IF($D6="群晶主導",1,IF($D6="缺口-待尋找",0,$I6)) -> 0.25 | K6: =IF($J6=0,"🔴 零覆蓋",IF($J6<=0.35,"🟠 高風險",IF($J6<1,"🟡 待補強","🟢 可承諾"))) -> 🟠 高風險 | L6: =IF($J6=0,"P1 最優先",IF($J6<=0.35,"P2","—")) -> P2
A7: CAP-003 | B7: 交易模式選擇 | C7: D01 治理與投資 | D7: 夥伴洽談中 | E7: PPP Advisor | F7: P-011 | G7: 財務與PPP顧問 | H7: Target | I7: =IFERROR(INDEX(_選單_Lists!$B$2:$B$8,MATCH($H7,_選單_Lists!$A$2:$A$8,0)),0) -> 0.25 | J7: =IF($D7="群晶主導",1,IF($D7="缺口-待尋找",0,$I7)) -> 0.25 | K7: =IF($J7=0,"🔴 零覆蓋",IF($J7<=0.35,"🟠 高風險",IF($J7<1,"🟡 待補強","🟢 可承諾"))) -> 🟠 高風險 | L7: =IF($J7=0,"P1 最優先",IF($J7<=0.35,"P2","—")) -> P2
A8: CAP-004 | B8: 法規與執照路徑 | C8: D01 治理與投資 | D8: 夥伴洽談中 | E8: Regulatory Lead | F8: P-012 | G8: 越南法律與法規顧問 | H8: Target | I8: =IFERROR(INDEX(_選單_Lists!$B$2:$B$8,MATCH($H8,_選單_Lists!$A$2:$A$8,0)),0) -> 0.25 | J8: =IF($D8="群晶主導",1,IF($D8="缺口-待尋找",0,$I8)) -> 0.25 | K8: =IF($J8=0,"🔴 零覆蓋",IF($J8<=0.35,"🟠 高風險",IF($J8<1,"🟡 待補強","🟢 可承諾"))) -> 🟠 高風險 | L8: =IF($J8=0,"P1 最優先",IF($J8<=0.35,"P2","—")) -> P2
A9: CAP-005 | B9: 聯盟治理與利益衝突 | C9: D01 治理與投資 | D9: 夥伴洽談中 | E9: PI Office | F9: P-016 | G9: PI 計畫辦公室 | H9: Qualified | I9: =IFERROR(INDEX(_選單_Lists!$B$2:$B$8,MATCH($H9,_選單_Lists!$A$2:$A$8,0)),0) -> 1 | J9: =IF($D9="群晶主導",1,IF($D9="缺口-待尋找",0,$I9)) -> 1 | K9: =IF($J9=0,"🔴 零覆蓋",IF($J9<=0.35,"🟠 高風險",IF($J9<1,"🟡 待補強","🟢 可承諾"))) -> 🟢 可承諾 | L9: =IF($J9=0,"P1 最優先",IF($J9<=0.35,"P2","—")) -> —
A10: CAP-006 | B10: 績效契約與變更控制 | C10: D01 治理與投資 | D10: 夥伴洽談中 | E10: Commercial Lead | F10: P-003 | G10: 越南在地醫院營運者 | H10: Target | I10: =IFERROR(INDEX(_選單_Lists!$B$2:$B$8,MATCH($H10,_選單_Lists!$A$2:$A$8,0)),0) -> 0.25 | J10: =IF($D10="群晶主導",1,IF($D10="缺口-待尋找",0,$I10)) -> 0.25 | K10: =IF($J10=0,"🔴 零覆蓋",IF($J10<=0.35,"🟠 高風險",IF($J10<1,"🟡 待補強","🟢 可承諾"))) -> 🟠 高風險 | L10: =IF($J10=0,"P1 最優先",IF($J10<=0.35,"P2","—")) -> P2
A11: CAP-007 | B11: 人口需求與病例量預測 | C11: D02 臨床服務模式 | D11: 夥伴洽談中 | E11: Clinical Planner | F11: P-004 | G11: 台灣參考醫院 | H11: Target | I11: =IFERROR(INDEX(_選單_Lists!$B$2:$B$8,MATCH($H11,_選單_Lists!$A$2:$A$8,0)),0) -> 0.25 | J11: =IF($D11="群晶主導",1,IF($D11="缺口-待尋找",0,$I11)) -> 0.25 | K11: =IF($J11=0,"🔴 零覆蓋",IF($J11<=0.35,"🟠 高風險",IF($J11<1,"🟡 待補強","🟢 可承諾"))) -> 🟠 高風險 | L11: =IF($J11=0,"P1 最優先",IF($J11<=0.35,"P2","—")) -> P2
A12: CAP-008 | B12: 醫院定位與服務組合 | C12: D02 臨床服務模式 | D12: 夥伴洽談中 | E12: Clinical Planner | F12: P-003 | G12: 越南在地醫院營運者 | H12: Target | I12: =IFERROR(INDEX(_選單_Lists!$B$2:$B$8,MATCH($H12,_選單_Lists!$A$2:$A$8,0)),0) -> 0.25 | J12: =IF($D12="群晶主導",1,IF($D12="缺口-待尋找",0,$I12)) -> 0.25 | K12: =IF($J12=0,"🔴 零覆蓋",IF($J12<=0.35,"🟠 高風險",IF($J12<1,"🟡 待補強","🟢 可承諾"))) -> 🟠 高風險 | L12: =IF($J12=0,"P1 最優先",IF($J12<=0.35,"P2","—")) -> P2
A13: CAP-009 | B13: 重點專科優先化 | C13: D02 臨床服務模式 | D13: 夥伴洽談中 | E13: Clinical Operator | F13: P-004 | G13: 台灣參考醫院 | H13: Target | I13: =IFERROR(INDEX(_選單_Lists!$B$2:$B$8,MATCH($H13,_選單_Lists!$A$2:$A$8,0)),0) -> 0.25 | J13: =IF($D13="群晶主導",1,IF($D13="缺口-待尋找",0,$I13)) -> 0.25 | K13: =IF($J13=0,"🔴 零覆蓋",IF($J13<=0.35,"🟠 高風險",IF($J13<1,"🟡 待補強","🟢 可承諾"))) -> 🟠 高風險 | L13: =IF($J13=0,"P1 最優先",IF($J13<=0.35,"P2","—")) -> P2
A14: CAP-010 | B14: 病人流程與容量設計 | C14: D02 臨床服務模式 | D14: 夥伴洽談中 | E14: Clinical Planner | F14: P-013 | G14: 品質與JCI顧問 | H14: Target | I14: =IFERROR(INDEX(_選單_Lists!$B$2:$B$8,MATCH($H14,_選單_Lists!$A$2:$A$8,0)),0) -> 0.25 | J14: =IF($D14="群晶主導",1,IF($D14="缺口-待尋找",0,$I14)) -> 0.25 | K14: =IF($J14=0,"🔴 零覆蓋",IF($J14<=0.35,"🟠 高風險",IF($J14<1,"🟡 待補強","🟢 可承諾"))) -> 🟠 高風險 | L14: =IF($J14=0,"P1 最優先",IF($J14<=0.35,"P2","—")) -> P2
A15: CAP-011 | B15: 轉診與區域照護網絡 | C15: D02 臨床服務模式 | D15: 夥伴洽談中 | E15: Clinical Operator | F15: P-003 | G15: 越南在地醫院營運者 | H15: Target | I15: =IFERROR(INDEX(_選單_Lists!$B$2:$B$8,MATCH($H15,_選單_Lists!$A$2:$A$8,0)),0) -> 0.25 | J15: =IF($D15="群晶主導",1,IF($D15="缺口-待尋找",0,$I15)) -> 0.25 | K15: =IF($J15=0,"🔴 零覆蓋",IF($J15<=0.35,"🟠 高風險",IF($J15<1,"🟡 待補強","🟢 可承諾"))) -> 🟠 高風險 | L15: =IF($J15=0,"P1 最優先",IF($J15<=0.35,"P2","—")) -> P2
A16: CAP-012 | B16: 臨床治理與責任架構 | C16: D02 臨床服務模式 | D16: 夥伴洽談中 | E16: Clinical Operator | F16: P-004 | G16: 台灣參考醫院 | H16: Target | I16: =IFERROR(INDEX(_選單_Lists!$B$2:$B$8,MATCH($H16,_選單_Lists!$A$2:$A$8,0)),0) -> 0.25 | J16: =IF($D16="群晶主導",1,IF($D16="缺口-待尋找",0,$I16)) -> 0.25 | K16: =IF($J16=0,"🔴 零覆蓋",IF($J16<=0.35,"🟠 高風險",IF($J16<1,"🟡 待補強","🟢 可承諾"))) -> 🟠 高風險 | L16: =IF($J16=0,"P1 最優先",IF($J16<=0.35,"P2","—")) -> P2
... A64: CAP-060 | B64: 效益實現與複製藍圖 | C64: D10 商模與病人生態 | D64: 夥伴洽談中 | E64: PI Office | F64: P-016 | G64: PI 計畫辦公室 | H64: Qualified | I64: =IFERROR(INDEX(_選單_Lists!$B$2:$B$8,MATCH($H64,_選單_Lists!$A$2:$A$8,0)),0) -> 1 | J64: =IF($D64="群晶主導",1,IF($D64="缺口-待尋找",0,$I64)) -> 1 | K64: =IF($J64=0,"🔴 零覆蓋",IF($J64<=0.35,"🟠 高風險",IF($J64<1,"🟡 待補強","🟢 可承諾"))) -> 🟢 可承諾 | L64: =IF($J64=0,"P1 最優先",IF($J64<=0.35,"P2","—")) -> —

Sheet 02_夥伴依賴表_Dependency
A1: 夥伴依賴表｜Dependency（自動統計，誰倒了我們最痛）
A2: ❓這頁在回答：哪家夥伴承擔最多能力？它現在可靠嗎？
A4: 夥伴ID | B4: 夥伴名稱 | C4: 國別 | D4: 夥伴狀態 | E4: 承擔能力數 | F4: 其中唯一來源 | G4: 依賴風險
A5: P-001 | B5: 群晶科技 | C5: Taiwan | D5: Target | E5: =COUNTIF(01_能力覆蓋表_Coverage!$F$5:$F$64,$A5) -> 8 | F5: =$E5 -> 8 | G5: =IF($E5=0,"—",IF(AND($E5>=3,$D5="Target"),"🔴 高依賴且未洽談",IF($E5>=3,"🟠 高依賴",IF($D5="Target","🟡 未洽談","🟢")))) -> 🔴 高依賴且未洽談
A6: P-002 | B6: 越南政府贊助單位 | C6: Vietnam | D6: Engaged | E6: =COUNTIF(01_能力覆蓋表_Coverage!$F$5:$F$64,$A6) -> 1 | F6: =$E6 -> 1 | G6: =IF($E6=0,"—",IF(AND($E6>=3,$D6="Target"),"🔴 高依賴且未洽談",IF($E6>=3,"🟠 高依賴",IF($D6="Target","🟡 未洽談","🟢")))) -> 🟢
A7: P-003 | B7: 越南在地醫院營運者 | C7: Vietnam | D7: Target | E7: =COUNTIF(01_能力覆蓋表_Coverage!$F$5:$F$64,$A7) -> 6 | F7: =$E7 -> 6 | G7: =IF($E7=0,"—",IF(AND($E7>=3,$D7="Target"),"🔴 高依賴且未洽談",IF($E7>=3,"🟠 高依賴",IF($D7="Target","🟡 未洽談","🟢")))) -> 🔴 高依賴且未洽談
A8: P-004 | B8: 台灣參考醫院 | C8: Taiwan | D8: Target | E8: =COUNTIF(01_能力覆蓋表_Coverage!$F$5:$F$64,$A8) -> 7 | F8: =$E8 -> 7 | G8: =IF($E8=0,"—",IF(AND($E8>=3,$D8="Target"),"🔴 高依賴且未洽談",IF($E8>=3,"🟠 高依賴",IF($D8="Target","🟡 未洽談","🟢")))) -> 🔴 高依賴且未洽談
A9: P-005 | B9: 醫療建築與總體規劃團隊 | C9: TBD | D9: Target | E9: =COUNTIF(01_能力覆蓋表_Coverage!$F$5:$F$64,$A9) -> 2 | F9: =$E9 -> 2 | G9: =IF($E9=0,"—",IF(AND($E9>=3,$D9="Target"),"🔴 高依賴且未洽談",IF($E9>=3,"🟠 高依賴",IF($D9="Target","🟡 未洽談","🟢")))) -> 🟡 未洽談
A10: P-006 | B10: 越南EPC／機電夥伴 | C10: Vietnam | D10: Target | E10: =COUNTIF(01_能力覆蓋表_Coverage!$F$5:$F$64,$A10) -> 3 | F10: =$E10 -> 3 | G10: =IF($E10=0,"—",IF(AND($E10>=3,$D10="Target"),"🔴 高依賴且未洽談",IF($E10>=3,"🟠 高依賴",IF($D10="Target","🟡 未洽談","🟢")))) -> 🔴 高依賴且未洽談
A11: P-007 | B11: 醫療資訊整合商 | C11: TBD | D11: Target | E11: =COUNTIF(01_能力覆蓋表_Coverage!$F$5:$F$64,$A11) -> 4 | F11: =$E11 -> 4 | G11: =IF($E11=0,"—",IF(AND($E11>=3,$D11="Target"),"🔴 高依賴且未洽談",IF($E11>=3,"🟠 高依賴",IF($D11="Target","🟡 未洽談","🟢")))) -> 🔴 高依賴且未洽談
A12: P-008 | B12: 美國雲端服務商 | C12: United States | D12: Due diligence | E12: =COUNTIF(01_能力覆蓋表_Coverage!$F$5:$F$64,$A12) -> 1 | F12: =$E12 -> 1 | G12: =IF($E12=0,"—",IF(AND($E12>=3,$D12="Target"),"🔴 高依賴且未洽談",IF($E12>=3,"🟠 高依賴",IF($D12="Target","🟡 未洽談","🟢")))) -> 🟢
A13: P-009 | B13: 醫材整合商 | C13: TBD | D13: Target | E13: =COUNTIF(01_能力覆蓋表_Coverage!$F$5:$F$64,$A13) -> 1 | F13: =$E13 -> 1 | G13: =IF($E13=0,"—",IF(AND($E13>=3,$D13="Target"),"🔴 高依賴且未洽談",IF($E13>=3,"🟠 高依賴",IF($D13="Target","🟡 未洽談","🟢")))) -> 🟡 未洽談
A14: P-010 | B14: 資安與隱私獨立驗證 | C14: TBD | D14: Target | E14: =COUNTIF(01_能力覆蓋表_Coverage!$F$5:$F$64,$A14) -> 1 | F14: =$E14 -> 1 | G14: =IF($E14=0,"—",IF(AND($E14>=3,$D14="Target"),"🔴 高依賴且未洽談",IF($E14>=3,"🟠 高依賴",IF($D14="Target","🟡 未洽談","🟢")))) -> 🟡 未洽談
A15: P-011 | B15: 財務與PPP顧問 | C15: TBD | D15: Target | E15: =COUNTIF(01_能力覆蓋表_Coverage!$F$5:$F$64,$A15) -> 3 | F15: =$E15 -> 3 | G15: =IF($E15=0,"—",IF(AND($E15>=3,$D15="Target"),"🔴 高依賴且未洽談",IF($E15>=3,"🟠 高依賴",IF($D15="Target","🟡 未洽談","🟢")))) -> 🔴 高依賴且未洽談
A16: P-012 | B16: 越南法律與法規顧問 | C16: Vietnam | D16: Target | E16: =COUNTIF(01_能力覆蓋表_Coverage!$F$5:$F$64,$A16) -> 1 | F16: =$E16 -> 1 | G16: =IF($E16=0,"—",IF(AND($E16>=3,$D16="Target"),"🔴 高依賴且未洽談",IF($E16>=3,"🟠 高依賴",IF($D16="Target","🟡 未洽談","🟢")))) -> 🟡 未洽談
... A34: P-001 群晶科技 | B34: ✓ | C34: ✓ | D34: 未登錄 | E34: =COUNTIF(01_能力覆蓋表_Coverage!$F$5:$F$64,$A34) -> 0 | F34: =$E34 -> 0 | G34: =IF($E34=0,"—",IF(AND($E34>=3,$D34="Target"),"🔴 高依賴且未洽談",IF($E34>=3,"🟠 高依賴",IF($D34="Target","🟡 未洽談","🟢")))) -> —
A35: P-002 越南政府贊助單位 | B35: ✓ | D35: 未登錄 | E35: =COUNTIF(01_能力覆蓋表_Coverage!$F$5:$F$64,$A35) -> 0 | F35: =$E35 -> 0 | G35: =IF($E35=0,"—",IF(AND($E35>=3,$D35="Target"),"🔴 高依賴且未洽談",IF($E35>=3,"🟠 高依賴",IF($D35="Target","🟡 未洽談","🟢")))) -> —
A36: P-003 越南在地醫院營運者 | D36: 未登錄 | E36: =COUNTIF(01_能力覆蓋表_Coverage!$F$5:$F$64,$A36) -> 0 | F36: =$E36 -> 0 | G36: =IF($E36=0,"—",IF(AND($E36>=3,$D36="Target"),"🔴 高依賴且未洽談",IF($E36>=3,"🟠 高依賴",IF($D36="Target","🟡 未洽談","🟢")))) -> —
A37: P-004 台灣參考醫院 | D37: 未登錄 | E37: =COUNTIF(01_能力覆蓋表_Coverage!$F$5:$F$64,$A37) -> 0 | F37: =$E37 -> 0 | G37: =IF($E37=0,"—",IF(AND($E37>=3,$D37="Target"),"🔴 高依賴且未洽談",IF($E37>=3,"🟠 高依賴",IF($D37="Target","🟡 未洽談","🟢")))) -> —
A38: P-005 醫療建築與總體規劃團隊 | D38: 未登錄 | E38: =COUNTIF(01_能力覆蓋表_Coverage!$F$5:$F$64,$A38) -> 0 | F38: =$E38 -> 0 | G38: =IF($E38=0,"—",IF(AND($E38>=3,$D38="Target"),"🔴 高依賴且未洽談",IF($E38>=3,"🟠 高依賴",IF($D38="Target","🟡 未洽談","🟢")))) -> —
A39: P-006 越南EPC／機電夥伴 | C39: ✓ | D39: 未登錄 | E39: =COUNTIF(01_能力覆蓋表_Coverage!$F$5:$F$64,$A39) -> 0 | F39: =$E39 -> 0 | G39: =IF($E39=0,"—",IF(AND($E39>=3,$D39="Target"),"🔴 高依賴且未洽談",IF($E39>=3,"🟠 高依賴",IF($D39="Target","🟡 未洽談","🟢")))) -> —
A40: P-007 醫療資訊整合商 | D40: 未登錄 | E40: =COUNTIF(01_能力覆蓋表_Coverage!$F$5:$F$64,$A40) -> 0 | F40: =$E40 -> 0 | G40: =IF($E40=0,"—",IF(AND($E40>=3,$D40="Target"),"🔴 高依賴且未洽談",IF($E40>=3,"🟠 高依賴",IF($D40="Target","🟡 未洽談","🟢")))) -> —
A41: P-008 美國雲端服務商 | C41: ✓ | D41: 未登錄 | E41: =COUNTIF(01_能力覆蓋表_Coverage!$F$5:$F$64,$A41) -> 0 | F41: =$E41 -> 0 | G41: =IF($E41=0,"—",IF(AND($E41>=3,$D41="Target"),"🔴 高依賴且未洽談",IF($E41>=3,"🟠 高依賴",IF($D41="Target","🟡 未洽談","🟢")))) -> —
A42: P-009 醫材整合商 | D42: 未登錄 | E42: =COUNTIF(01_能力覆蓋表_Coverage!$F$5:$F$64,$A42) -> 0 | F42: =$E42 -> 0 | G42: =IF($E42=0,"—",IF(AND($E42>=3,$D42="Target"),"🔴 高依賴且未洽談",IF($E42>=3,"🟠 高依賴",IF($D42="Target","🟡 未洽談","🟢")))) -> —
A43: P-010 資安與隱私獨立驗證 | B43: ✓ | C43: ✓ | D43: 未登錄 | E43: =COUNTIF(01_能力覆蓋表_Coverage!$F$5:$F$64,$A43) -> 0 | F43: =$E43 -> 0 | G43: =IF($E43=0,"—",IF(AND($E43>=3,$D43="Target"),"🔴 高依賴且未洽談",IF($E43>=3,"🟠 高依賴",IF($D43="Target","🟡 未洽談","🟢")))) -> —
A44: P-011 財務與PPP顧問 | B44: ✓ | D44: 未登錄 | E44: =COUNTIF(01_能力覆蓋表_Coverage!$F$5:$F$64,$A44) -> 0 | F44: =$E44 -> 0 | G44: =IF($E44=0,"—",IF(AND($E44>=3,$D44="Target"),"🔴 高依賴且未洽談",IF($E44>=3,"🟠 高依賴",IF($D44="Target","🟡 未洽談","🟢")))) -> —
A45: P-012 越南法律與法規顧問 | B45: ✓ | D45: 未登錄 | E45: =COUNTIF(01_能力覆蓋表_Coverage!$F$5:$F$64,$A45) -> 0 | F45: =$E45 -> 0 | G45: =IF($E45=0,"—",IF(AND($E45>=3,$D45="Target"),"🔴 高依賴且未洽談",IF($E45>=3,"🟠 高依賴",IF($D45="Target","🟡 未洽談","🟢")))) -> —
A46: P-013 品質與JCI顧問 | D46: 未登錄 | E46: =COUNTIF(01_能力覆蓋表_Coverage!$F$5:$F$64,$A46) -> 0 | F46: =$E46 -> 0 | G46: =IF($E46=0,"—",IF(AND($E46>=3,$D46="Target"),"🔴 高依賴且未洽談",IF($E46>=3,"🟠 高依賴",IF($D46="Target","🟡 未洽談","🟢")))) -> —
A47: P-014 物流／SPD與冷鏈夥伴 | D47: 未登錄 | E47: =COUNTIF(01_能力覆蓋表_Coverage!$F$5:$F$64,$A47) -> 0 | F47: =$E47 -> 0 | G47: =IF($E47=0,"—",IF(AND($E47>=3,$D47="Target"),"🔴 高依賴且未洽談",IF($E47>=3,"🟠 高依賴",IF($D47="Target","🟡 未洽談","🟢")))) -> —
A48: P-015 獨立臨床與成本驗證 | B48: ✓ | D48: 未登錄 | E48: =COUNTIF(01_能力覆蓋表_Coverage!$F$5:$F$64,$A48) -> 0 | F48: =$E48 -> 0 | G48: =IF($E48=0,"—",IF(AND($E48>=3,$D48="Target"),"🔴 高依賴且未洽談",IF($E48>=3,"🟠 高依賴",IF($D48="Target","🟡 未洽談","🟢")))) -> —
A49: P-016 PI 計畫辦公室 | B49: ✓ | D49: 未登錄 | E49: =COUNTIF(01_能力覆蓋表_Coverage!$F$5:$F$64,$A49) -> 0 | F49: =$E49 -> 0 | G49: =IF($E49=0,"—",IF(AND($E49>=3,$D49="Target"),"🔴 高依賴且未洽談",IF($E49>=3,"🟠 高依賴",IF($D49="Target","🟡 未洽談","🟢")))) -> —
A50: P-017 越南公共事務顧問 | B50: ✓ | D50: 未登錄 | E50: =COUNTIF(01_能力覆蓋表_Coverage!$F$5:$F$64,$A50) -> 0 | F50: =$E50 -> 0 | G50: =IF($E50=0,"—",IF(AND($E50>=3,$D50="Target"),"🔴 高依賴且未洽談",IF($E50>=3,"🟠 高依賴",IF($D50="Target","🟡 未洽談","🟢")))) -> —
A51: P-018 越南環保與廢棄物處理商 | D51: 未登錄 | E51: =COUNTIF(01_能力覆蓋表_Coverage!$F$5:$F$64,$A51) -> 0 | F51: =$E51 -> 0 | G51: =IF($E51=0,"—",IF(AND($E51>=3,$D51="Target"),"🔴 高依賴且未洽談",IF($E51>=3,"🟠 高依賴",IF($D51="Target","🟡 未洽談","🟢")))) -> —
A52: P-019 影像設備與PACS整合商 | D52: 未登錄 | E52: =COUNTIF(01_能力覆蓋表_Coverage!$F$5:$F$64,$A52) -> 0 | F52: =$E52 -> 0 | G52: =IF($E52=0,"—",IF(AND($E52>=3,$D52="Target"),"🔴 高依賴且未洽談",IF($E52>=3,"🟠 高依賴",IF($D52="Target","🟡 未洽談","🟢")))) -> —
A53: P-020 檢驗自動化與LIS供應商 | D53: 未登錄 | E53: =COUNTIF(01_能力覆蓋表_Coverage!$F$5:$F$64,$A53) -> 0 | F53: =$E53 -> 0 | G53: =IF($E53=0,"—",IF(AND($E53>=3,$D53="Target"),"🔴 高依賴且未洽談",IF($E53>=3,"🟠 高依賴",IF($D53="Target","🟡 未洽談","🟢")))) -> —
A54: P-021 手術室與重症設備整合商 | D54: 未登錄 | E54: =COUNTIF(01_能力覆蓋表_Coverage!$F$5:$F$64,$A54) -> 0 | F54: =$E54 -> 0 | G54: =IF($E54=0,"—",IF(AND($E54>=3,$D54="Target"),"🔴 高依賴且未洽談",IF($E54>=3,"🟠 高依賴",IF($D54="Target","🟡 未洽談","🟢")))) -> —
A55: P-022 越南數位身分介接夥伴 | D55: 未登錄 | E55: =COUNTIF(01_能力覆蓋表_Coverage!$F$5:$F$64,$A55) -> 0 | F55: =$E55 -> 0 | G55: =IF($E55=0,"—",IF(AND($E55>=3,$D55="Target"),"🔴 高依賴且未洽談",IF($E55>=3,"🟠 高依賴",IF($D55="Target","🟡 未洽談","🟢")))) -> —
A56: P-023 病人App與在地支付夥伴 | D56: 未登錄 | E56: =COUNTIF(01_能力覆蓋表_Coverage!$F$5:$F$64,$A56) -> 0 | F56: =$E56 -> 0 | G56: =IF($E56=0,"—",IF(AND($E56>=3,$D56="Target"),"🔴 高依賴且未洽談",IF($E56>=3,"🟠 高依賴",IF($D56="Target","🟡 未洽談","🟢")))) -> —
A57: P-024 越南醫護大學／人力機構 | D57: 未登錄 | E57: =COUNTIF(01_能力覆蓋表_Coverage!$F$5:$F$64,$A57) -> 0 | F57: =$E57 -> 0 | G57: =IF($E57=0,"—",IF(AND($E57>=3,$D57="Target"),"🔴 高依賴且未洽談",IF($E57>=3,"🟠 高依賴",IF($D57="Target","🟡 未洽談","🟢")))) -> —
A58: P-025 越南健保申報介接夥伴 | D58: 未登錄 | E58: =COUNTIF(01_能力覆蓋表_Coverage!$F$5:$F$64,$A58) -> 0 | F58: =$E58 -> 0 | G58: =IF($E58=0,"—",IF(AND($E58>=3,$D58="Target"),"🔴 高依賴且未洽談",IF($E58>=3,"🟠 高依賴",IF($D58="Target","🟡 未洽談","🟢")))) -> —
...

Sheet 03_補位行動_Actions
A1: 補位行動｜Actions（零覆蓋與高風險能力，逐項指定負責人）
A2: ❓這頁在回答：誰、在什麼期限前、要把哪個缺口補起來？
A3: 圖例： | B3: 要填 | C3: 自動
A4: 能力ID | B4: 缺口描述 | C4: 補位方向 | D4: 候選來源（從 18 號名冊） | E4: 負責人 | F4: 期限 | G4: 狀態 | H4: 進 20 號漏斗案件ID | I4: 備註
A5: CAP-042 | B5: （範例）越南醫材註冊代理 | C5: 找在地法規顧問所 | D5: 情報站名冊：法規類 4 家 | E5: 王 | F5: 2026-10-31 | G5: 洽談中 | H5: P-005 | I5: 已接觸 2 家，等報價

Sheet _選單_Lists
A1: 夥伴狀態 | B1: 權重 | C1: 說明 | D1: 能力狀態
A2: Qualified | B2: 1 | C2: 已通過資格審查 | D2: 夥伴洽談中
A3: Due diligence | B3: 0.7 | C3: 盡職調查中 | D3: 群晶主導
A4: Engaged | B4: 0.5 | C4: 已實際接觸洽談 | D4: 缺口-待尋找
A5: Target | B5: 0.25 | C5: 目標邀請——只是名單
A6: 未登錄 | B6: 0.1 | C6: 夥伴檔案不完整
A7: 缺口-待尋找 | B7: 0 | C7: 無候選
