Workbook

Sheet 說明_ReadMe
A1: VMH-EcoMap-21 投標經濟性試算器｜使用說明
A2: P1 推進管理工具・我方視角・搭配 20 號商機推進漏斗使用
B4: ■ 這個工具跟 2 號試算器差在哪（很重要，不要用錯）
B5: 2 號專案商模試算器算的是「醫院該不該投資這個案子」——站在業主立場，看 NPV、IRR、回收年限。 這一份算的是「我們該不該投標、報多少、底價在哪」——站在我方立場，看成本堆疊、毛利率、資金缺口。 兩份都要算：2 號用來說服客戶，21 號用來保護自己。贏了但賠錢，比沒贏更糟。
B7: ■ 使用順序
B8: ① 專案設定：填匯率、關稅率、在地化要求、最低可接受毛利率（這是走人價的依據，要先跟老闆講好）。 ② 成本堆疊：把每一筆成本填進去，原幣別填原幣別，系統會自動折算。寧可多列，不要漏列。 ③ 付款條件：填里程碑收款比例與月份——這決定資金缺口，很多案子是被現金流拖垮而不是被毛利拖垮。 ④ 報價與毛利：填你打算報的價，看毛利率跟走人價。 ⑤ 敏感度：看哪個變數最傷，那就是談判時要優先鎖住的條款。
B10: ■ 三個最容易被低估的成本
B11: 進口關稅與清關：越南醫療設備關稅級距差異大，同一張報價單裡不同 HS Code 稅率可能差 10 個百分點以上，開標前要確認過。 在地化要求：越南公立醫院標案常有在地供應比例要求，湊不到會直接失格——這在「在地化檢核」頁單獨看。 保固準備：三年保固的備品、工程師出差、故障重工，通常要抓合約額的 2–4%，很多人抓 0。
B13: ■ 走人價是什麼、為什麼要先算
B14: 走人價 ＝ 在最低可接受毛利率下，還能接的最低報價。低於這個數字就該退出，不是「再想想」。 議價現場壓力很大，先算好寫在紙上，才不會在會議室裡自己說服自己。 公式已考慮夥伴分潤與保固準備會隨報價等比變動——所以走人價不是「成本加一點」那麼簡單。
B16: ■ 資金缺口為什麼要看
B17: 越南公立醫院付款慢是常態。如果設備要先付款出海、驗收後才收得到 60%，中間那段是我方墊資。 「付款條件」頁會算出最大資金缺口與發生月份——這個數字要拿去跟財務確認調得動再投標。
B19: ■ 與其他工具的銜接
B20: 案件進到 20 號漏斗的「S4 提案報價」階段前，應該先在這裡算過一輪，把毛利率回填到漏斗的「我方毛利率」欄。 15 號標案雷達的資格要求若含在地化比例，填到本檔「專案設定」的在地化要求欄。 結案後（不論輸贏）回來把實際成本填一次——這是下一案估價唯一可靠的基礎。

Sheet 05_報價與毛利_Pricing
A1: 報價與毛利｜Pricing & Margin（先看走人價，再決定報多少）
A2: ❓這頁在回答：報這個價，我們賺不賺得到？底價在哪？ ★ 走人價請在議價前印出來帶進會議室
A3: 圖例： | B3: 要填 | C3: 自動 | D3: （範例）數字為示意，請換成你這一案的真實成本
B5: 報價決策
B6: 我方報價（千USD） | C6: 3680 | D6: ★ 唯一要你決定的數字。改這格，下面全部跟著動
B8: 成本結構
B9: 直接成本（千USD） | C9: =02_成本堆疊_CostBuildup!$H$45 -> 2440.5827 | D9: 來自成本堆疊頁
B10: 夥伴分潤（千USD） | C10: =$C$6*01_專案設定_Setup!$C$24 -> 220.8 | D10: 隨報價等比變動
B11: 保固準備（千USD） | C11: =$C$6*01_專案設定_Setup!$C$25 -> 110.4 | D11: 隨報價等比變動
B12: 風險準備（千USD） | C12: =02_成本堆疊_CostBuildup!$H$45*01_專案設定_Setup!$C$26 -> 122.02913 | D12: 占直接成本
B13: 總成本（千USD） | C13: =$C$9+$C$10+$C$11+$C$12 -> 2893.8118
B15: 毛利
B16: 毛利額（千USD） | C16: =$C$6-$C$13 -> 786.18819
B17: 毛利率 | C17: =IFERROR($C$16/$C$6,"") -> 0.21363809 | D17: ★ 這個數字要回填到 20 號漏斗
B18: 現金流折現損失（千USD） | C18: =04_付款條件_PaymentTerms!$D$34 -> 98.469898 | D18: 付款條件造成的資金成本
B19: 折現後毛利（千USD） | C19: =$C$16-$C$18 -> 687.71829 | D19: 這才是真正落袋的數字
B20: 折現後毛利率 | C20: =IFERROR($C$19/$C$6,"") -> 0.18687997
B22: 底價與區間
B23: 走人價（千USD） | C23: =IFERROR(($C$9+$C$12)/(1-01_專案設定_Setup!$C$24-01_專案設定_Setup!$C$25-01_專案設定_Setup!$C$32),"") -> 3243.8124 | D23: ★★ 低於此價就退出。已計入分潤與保固會隨報價縮水
B24: 目標價（千USD） | C24: =IFERROR(($C$9+$C$12)/(1-01_專案設定_Setup!$C$24-01_專案設定_Setup!$C$25-01_專案設定_Setup!$C$33),"") -> 3713.9302 | D24: 達成目標毛利率所需的報價
B25: 目前報價 vs 走人價 | C25: =IFERROR($C$6-$C$23,"") -> 436.18758 | D25: 還有多少讓價空間（千USD）
B26: 可讓價幅度 | C26: =IFERROR(($C$6-$C$23)/$C$6,"") -> 0.11852923
B27: 判定 | C27: =IF($C$6="","",IF($C$6<$C$23,"✗ 低於走人價，應退出",IF($C$17<01_專案設定_Setup!$C$33,"△ 可接但低於目標毛利","✓ 達目標毛利"))) -> △ 可接但低於目標毛利
B29: 資金
B30: 最大資金缺口（千USD） | C30: =04_付款條件_PaymentTerms!$D$31 -> 668.29134 | D30: ★ 這筆錢調不動就不要投
B31: 缺口占報價比例 | C31: =IFERROR($C$30/$C$6,"") -> 0.18160091
B33: 走人價公式說明：報價 ×（1 − 分潤率 − 保固率 − 最低毛利率）＝ 直接成本 ＋ 風險準備。 因為分潤與保固準備是「占報價的百分比」，報價一降，這兩項也跟著降——所以走人價不是「成本 ÷（1−最低毛利率）」那麼簡單， 直覺算法會把底價算得太高，議價時反而錯失可以接的案子。

Sheet 01_專案設定_Setup
A1: 專案設定｜Setup（所有參數的唯一來源，其他頁都引用這裡）
A2: ❓這頁在回答：這一案的匯率、稅率、在地化要求、最低可接受毛利是多少？ ★ 最低毛利率要先跟決策者講好，不是算完再回頭喬
A3: 圖例： | B3: 要填 | C3: 自動 | D3: （範例）數字為示意，請換成你這一案的真實成本
B5: 案件基本資料
B6: 案件ID（對應 20 號漏斗） | C6: P-001
B7: 案件名稱 | C7: 中央兒童醫院資料中心機房整建
B8: 客戶／醫院 | C8: 國家兒童醫院
B9: 試算日期 | C9: 2026-08-18
B10: 報價幣別 | C10: USD | D10: 本檔所有折算後金額一律為「千USD」
B12: 匯率（原幣 → 1 USD）
B13: USD | C13: 1 | D13: 基準幣別，固定為 1
B14: VND | C14: 25400 | D14: 越南盾。★ 這是敏感度分析的頭號變數
B15: TWD | C15: 32.5 | D15: 新台幣
B17: 政策與稅務參數
B18: 進口設備平均關稅率 | C18: 0.08 | D18: ★ 不同 HS Code 差異大，開標前務必逐項確認
B19: VAT（可扣抵，不計入成本） | C19: 0.1 | D19: 一般可扣抵，此處僅備查
B20: 在地化要求比例 | C20: 0.3 | D20: 標書若有規定填這裡，沒有就填 0
B22: 財務與風險參數
B23: 年化折現率（資金成本） | C23: 0.09 | D23: 用於付款條件的現金流折現
B24: 夥伴分潤率（占報價） | C24: 0.06 | D24: 在地夥伴抽成，隨報價等比變動
B25: 保固準備率（占報價） | C25: 0.03 | D25: ★ 三年保固建議 2–4%，填 0 是自欺欺人
B26: 風險準備率（占直接成本） | C26: 0.05 | D26: 未知的未知。首次進入的市場建議 5–8%
B27: 履約保證金比例 | C27: 0.1 | D27: 占合約額
B28: 保證金年費率 | C28: 0.025 | D28: 銀行開立保函的年費
B29: 保證金存續年數 | C29: 3 | D29: 通常＝保固期
B31: 決策門檻
B32: 最低可接受毛利率 | C32: 0.12 | D32: ★★ 走人價的依據。低於這個數字就退出——請先跟決策者確認後填入
B33: 目標毛利率 | C33: 0.22 | D33: 正常情況希望達到的水準
B35: 填寫提醒：百分比欄位請直接輸入如 8% 或 0.08，不要輸入 8（會變成 800%）。 匯率請填「1 美元換多少原幣」，例如 VND 填 25400。所有折算後金額全檔統一為「千USD」。

Sheet 02_成本堆疊_CostBuildup
A1: 成本堆疊｜Cost Buildup（我方要花的每一塊錢，寧可多列不要漏列）
A2: ❓這頁在回答：這一案我方的直接成本是多少、其中多少是進口、多少落在越南當地？
A3: 圖例： | B3: 要填 | C3: 自動 | D3: （範例）數字為示意，請換成你這一案的真實成本
A4: 項次 | B4: 成本項目 | C4: 類別 | D4: 來源 | E4: 原幣別 | F4: 原幣金額 | G4: 匯率 | H4: 折算(千USD) | I4: 占直接成本 | J4: 風險等級 | K4: 備註／依據
A5: 1 | B5: 主機櫃、配電盤與匯流排 | C5: 設備 | D5: 進口 | E5: USD | F5: 420000 | G5: =IF($E5="","",IFERROR(INDEX(01_專案設定_Setup!$C$13:$C$15,MATCH($E5,01_專案設定_Setup!$B$13:$B$15,0)),"")) -> 1 | H5: =IF(OR($F5="",$G5="",$G5=0),"",$F5/$G5/1000) -> 420 | I5: =IF($H5="","",IFERROR($H5/$H$45,"")) -> 0.17209005 | J5: 高 | K5: 原廠報價 2026-07，含 3 年零件保固
A6: 2 | B6: UPS 不斷電系統（含電池） | C6: 設備 | D6: 進口 | E6: USD | F6: 380000 | G6: =IF($E6="","",IFERROR(INDEX(01_專案設定_Setup!$C$13:$C$15,MATCH($E6,01_專案設定_Setup!$B$13:$B$15,0)),"")) -> 1 | H6: =IF(OR($F6="",$G6="",$G6=0),"",$F6/$G6/1000) -> 380 | I6: =IF($H6="","",IFERROR($H6/$H$45,"")) -> 0.15570052 | J6: 高 | K6: 電池 5 年更換，已列在保固準備
A7: 3 | B7: 精密空調與冷卻系統 | C7: 設備 | D7: 進口 | E7: USD | F7: 310000 | G7: =IF($E7="","",IFERROR(INDEX(01_專案設定_Setup!$C$13:$C$15,MATCH($E7,01_專案設定_Setup!$B$13:$B$15,0)),"")) -> 1 | H7: =IF(OR($F7="",$G7="",$G7=0),"",$F7/$G7/1000) -> 310 | I7: =IF($H7="","",IFERROR($H7/$H$45,"")) -> 0.12701885 | J7: 高 | K7: 含冷凍水管路，未含土建
A8: 4 | B8: DCIM 監控軟體與授權 | C8: 設備 | D8: 進口 | E8: USD | F8: 95000 | G8: =IF($E8="","",IFERROR(INDEX(01_專案設定_Setup!$C$13:$C$15,MATCH($E8,01_專案設定_Setup!$B$13:$B$15,0)),"")) -> 1 | H8: =IF(OR($F8="",$G8="",$G8=0),"",$F8/$G8/1000) -> 95 | I8: =IF($H8="","",IFERROR($H8/$H$45,"")) -> 0.038925131 | J8: 中 | K8: 3 年授權，續約另計
A9: 5 | B9: 消防、門禁與 CCTV | C9: 設備 | D9: 在地 | E9: VND | F9: 3800000000 | G9: =IF($E9="","",IFERROR(INDEX(01_專案設定_Setup!$C$13:$C$15,MATCH($E9,01_專案設定_Setup!$B$13:$B$15,0)),"")) -> 25400 | H9: =IF(OR($F9="",$G9="",$G9=0),"",$F9/$G9/1000) -> 149.6063 | I9: =IF($H9="","",IFERROR($H9/$H$45,"")) -> 0.061299419 | J9: 低 | K9: 在地夥伴供應，計入在地化比例
A10: 6 | B10: 海運、保險與清關 | C10: 物流關稅 | D10: 進口 | E10: USD | F10: 68000 | G10: =IF($E10="","",IFERROR(INDEX(01_專案設定_Setup!$C$13:$C$15,MATCH($E10,01_專案設定_Setup!$B$13:$B$15,0)),"")) -> 1 | H10: =IF(OR($F10="",$G10="",$G10=0),"",$F10/$G10/1000) -> 68 | I10: =IF($H10="","",IFERROR($H10/$H$45,"")) -> 0.027862199 | J10: 中 | K10: CIF 海防港，含保險
A11: 7 | B11: 進口關稅（自動計算） | C11: 物流關稅 | D11: 進口 | E11: USD | F11: =ROUND(SUMIFS($F$5:$F$44,$D$5:$D$44,"進口",$E$5:$E$44,"USD",$C$5:$C$44,"設備")*01_專案設定_Setup!$C$18,0) -> 96400 | G11: =IF($E11="","",IFERROR(INDEX(01_專案設定_Setup!$C$13:$C$15,MATCH($E11,01_專案設定_Setup!$B$13:$B$15,0)),"")) -> 1 | H11: =IF(OR($F11="",$G11="",$G11=0),"",$F11/$G11/1000) -> 96.4 | I11: =IF($H11="","",IFERROR($H11/$H$45,"")) -> 0.039498764 | J11: 高 | K11: ＝進口設備合計 × 關稅率，逐項 HS Code 需複核
A12: 8 | B12: 內陸運輸與吊裝 | C12: 物流關稅 | D12: 在地 | E12: VND | F12: 1450000000 | G12: =IF($E12="","",IFERROR(INDEX(01_專案設定_Setup!$C$13:$C$15,MATCH($E12,01_專案設定_Setup!$B$13:$B$15,0)),"")) -> 25400 | H12: =IF(OR($F12="",$G12="",$G12=0),"",$F12/$G12/1000) -> 57.086614 | I12: =IF($H12="","",IFERROR($H12/$H$45,"")) -> 0.023390568 | J12: 低
A13: 9 | B13: 機電安裝工程 | C13: 工程安裝 | D13: 在地 | E13: VND | F13: 6200000000 | G13: =IF($E13="","",IFERROR(INDEX(01_專案設定_Setup!$C$13:$C$15,MATCH($E13,01_專案設定_Setup!$B$13:$B$15,0)),"")) -> 25400 | H13: =IF(OR($F13="",$G13="",$G13=0),"",$F13/$G13/1000) -> 244.09449 | I13: =IF($H13="","",IFERROR($H13/$H$45,"")) -> 0.10001484 | J13: 中 | K13: 在地夥伴施工，計入在地化比例
A14: 10 | B14: 土建配合與機房裝修 | C14: 工程安裝 | D14: 在地 | E14: VND | F14: 4100000000 | G14: =IF($E14="","",IFERROR(INDEX(01_專案設定_Setup!$C$13:$C$15,MATCH($E14,01_專案設定_Setup!$B$13:$B$15,0)),"")) -> 25400 | H14: =IF(OR($F14="",$G14="",$G14=0),"",$F14/$G14/1000) -> 161.41732 | I14: =IF($H14="","",IFERROR($H14/$H$45,"")) -> 0.066138846 | J14: 中 | K14: 含防火區劃與架高地板
A15: 11 | B15: 測試、試運轉與整合驗證 | C15: 工程安裝 | D15: 進口 | E15: USD | F15: 72000 | G15: =IF($E15="","",IFERROR(INDEX(01_專案設定_Setup!$C$13:$C$15,MATCH($E15,01_專案設定_Setup!$B$13:$B$15,0)),"")) -> 1 | H15: =IF(OR($F15="",$G15="",$G15=0),"",$F15/$G15/1000) -> 72 | I15: =IF($H15="","",IFERROR($H15/$H$45,"")) -> 0.029501152 | J15: 中 | K15: 台籍工程師 2 人 × 6 週
A16: 12 | B16: 台籍專案經理駐點 | C16: 專案管理 | D16: 進口 | E16: USD | F16: 86000 | G16: =IF($E16="","",IFERROR(INDEX(01_專案設定_Setup!$C$13:$C$15,MATCH($E16,01_專案設定_Setup!$B$13:$B$15,0)),"")) -> 1 | H16: =IF(OR($F16="",$G16="",$G16=0),"",$F16/$G16/1000) -> 86 | I16: =IF($H16="","",IFERROR($H16/$H$45,"")) -> 0.035237487 | J16: 中 | K16: 12 個月，含住宿
A17: 13 | B17: 在地專案管理與協調 | C17: 專案管理 | D17: 在地 | E17: VND | F17: 2300000000 | G17: =IF($E17="","",IFERROR(INDEX(01_專案設定_Setup!$C$13:$C$15,MATCH($E17,01_專案設定_Setup!$B$13:$B$15,0)),"")) -> 25400 | H17: =IF(OR($F17="",$G17="",$G17=0),"",$F17/$G17/1000) -> 90.551181 | I17: =IF($H17="","",IFERROR($H17/$H$45,"")) -> 0.03710228 | J17: 低
A18: 14 | B18: 差旅與往返機票 | C18: 專案管理 | D18: 進口 | E18: USD | F18: 24000 | G18: =IF($E18="","",IFERROR(INDEX(01_專案設定_Setup!$C$13:$C$15,MATCH($E18,01_專案設定_Setup!$B$13:$B$15,0)),"")) -> 1 | H18: =IF(OR($F18="",$G18="",$G18=0),"",$F18/$G18/1000) -> 24 | I18: =IF($H18="","",IFERROR($H18/$H$45,"")) -> 0.0098337173 | J18: 低
A19: 15 | B19: 備品庫存（首年） | C19: 售後保固 | D19: 進口 | E19: USD | F19: 55000 | G19: =IF($E19="","",IFERROR(INDEX(01_專案設定_Setup!$C$13:$C$15,MATCH($E19,01_專案設定_Setup!$B$13:$B$15,0)),"")) -> 1 | H19: =IF(OR($F19="",$G19="",$G19=0),"",$F19/$G19/1000) -> 55 | I19: =IF($H19="","",IFERROR($H19/$H$45,"")) -> 0.022535602 | J19: 中 | K19: 關鍵零件在地備料，縮短停機
A20: 16 | B20: 教育訓練與操作手冊越文化 | C20: 售後保固 | D20: 在地 | E20: VND | F20: 980000000 | G20: =IF($E20="","",IFERROR(INDEX(01_專案設定_Setup!$C$13:$C$15,MATCH($E20,01_專案設定_Setup!$B$13:$B$15,0)),"")) -> 25400 | H20: =IF(OR($F20="",$G20="",$G20=0),"",$F20/$G20/1000) -> 38.582677 | I20: =IF($H20="","",IFERROR($H20/$H$45,"")) -> 0.015808797 | J20: 低 | K20: 含越文技術文件翻譯
A21: 17 | B21: 在地認證、檢驗與測試報告 | C21: 認證合規 | D21: 在地 | E21: VND | F21: 1200000000 | G21: =IF($E21="","",IFERROR(INDEX(01_專案設定_Setup!$C$13:$C$15,MATCH($E21,01_專案設定_Setup!$B$13:$B$15,0)),"")) -> 25400 | H21: =IF(OR($F21="",$G21="",$G21=0),"",$F21/$G21/1000) -> 47.244094 | I21: =IF($H21="","",IFERROR($H21/$H$45,"")) -> 0.019357711 | J21: 中 | K21: ★ 時程風險大於金額風險
A22: 18 | B22: 投標成本（文件、公證、保證金） | C22: 財務成本 | D22: 進口 | E22: USD | F22: 18000 | G22: =IF($E22="","",IFERROR(INDEX(01_專案設定_Setup!$C$13:$C$15,MATCH($E22,01_專案設定_Setup!$B$13:$B$15,0)),"")) -> 1 | H22: =IF(OR($F22="",$G22="",$G22=0),"",$F22/$G22/1000) -> 18 | I22: =IF($H22="","",IFERROR($H22/$H$45,"")) -> 0.0073752879 | J22: 低 | K22: 不論輸贏都會發生
A23: 19 | B23: 履約保證金成本（自動計算） | C23: 財務成本 | D23: 進口 | E23: USD | F23: =ROUND(05_報價與毛利_Pricing!$C$6*1000*01_專案設定_Setup!$C$27*01_專案設定_Setup!$C$28*01_專案設定_Setup!$C$29,0) -> 27600 | G23: =IF($E23="","",IFERROR(INDEX(01_專案設定_Setup!$C$13:$C$15,MATCH($E23,01_專案設定_Setup!$B$13:$B$15,0)),"")) -> 1 | H23: =IF(OR($F23="",$G23="",$G23=0),"",$F23/$G23/1000) -> 27.6 | I23: =IF($H23="","",IFERROR($H23/$H$45,"")) -> 0.011308775 | J23: 低 | K23: ＝報價 × 保證金比例 × 年費率 × 年數
G24: =IF($E24="","",IFERROR(INDEX(01_專案設定_Setup!$C$13:$C$15,MATCH($E24,01_專案設定_Setup!$B$13:$B$15,0)),"")) | H24: =IF(OR($F24="",$G24="",$G24=0),"",$F24/$G24/1000) | I24: =IF($H24="","",IFERROR($H24/$H$45,""))
G25: =IF($E25="","",IFERROR(INDEX(01_專案設定_Setup!$C$13:$C$15,MATCH($E25,01_專案設定_Setup!$B$13:$B$15,0)),"")) | H25: =IF(OR($F25="",$G25="",$G25=0),"",$F25/$G25/1000) | I25: =IF($H25="","",IFERROR($H25/$H$45,""))
G26: =IF($E26="","",IFERROR(INDEX(01_專案設定_Setup!$C$13:$C$15,MATCH($E26,01_專案設定_Setup!$B$13:$B$15,0)),"")) | H26: =IF(OR($F26="",$G26="",$G26=0),"",$F26/$G26/1000) | I26: =IF($H26="","",IFERROR($H26/$H$45,""))
G27: =IF($E27="","",IFERROR(INDEX(01_專案設定_Setup!$C$13:$C$15,MATCH($E27,01_專案設定_Setup!$B$13:$B$15,0)),"")) | H27: =IF(OR($F27="",$G27="",$G27=0),"",$F27/$G27/1000) | I27: =IF($H27="","",IFERROR($H27/$H$45,""))
G28: =IF($E28="","",IFERROR(INDEX(01_專案設定_Setup!$C$13:$C$15,MATCH($E28,01_專案設定_Setup!$B$13:$B$15,0)),"")) | H28: =IF(OR($F28="",$G28="",$G28=0),"",$F28/$G28/1000) | I28: =IF($H28="","",IFERROR($H28/$H$45,""))
G29: =IF($E29="","",IFERROR(INDEX(01_專案設定_Setup!$C$13:$C$15,MATCH($E29,01_專案設定_Setup!$B$13:$B$15,0)),"")) | H29: =IF(OR($F29="",$G29="",$G29=0),"",$F29/$G29/1000) | I29: =IF($H29="","",IFERROR($H29/$H$45,""))
G30: =IF($E30="","",IFERROR(INDEX(01_專案設定_Setup!$C$13:$C$15,MATCH($E30,01_專案設定_Setup!$B$13:$B$15,0)),"")) | H30: =IF(OR($F30="",$G30="",$G30=0),"",$F30/$G30/1000) | I30: =IF($H30="","",IFERROR($H30/$H$45,""))
G31: =IF($E31="","",IFERROR(INDEX(01_專案設定_Setup!$C$13:$C$15,MATCH($E31,01_專案設定_Setup!$B$13:$B$15,0)),"")) | H31: =IF(OR($F31="",$G31="",$G31=0),"",$F31/$G31/1000) | I31: =IF($H31="","",IFERROR($H31/$H$45,""))
G32: =IF($E32="","",IFERROR(INDEX(01_專案設定_Setup!$C$13:$C$15,MATCH($E32,01_專案設定_Setup!$B$13:$B$15,0)),"")) | H32: =IF(OR($F32="",$G32="",$G32=0),"",$F32/$G32/1000) | I32: =IF($H32="","",IFERROR($H32/$H$45,""))
G33: =IF($E33="","",IFERROR(INDEX(01_專案設定_Setup!$C$13:$C$15,MATCH($E33,01_專案設定_Setup!$B$13:$B$15,0)),"")) | H33: =IF(OR($F33="",$G33="",$G33=0),"",$F33/$G33/1000) | I33: =IF($H33="","",IFERROR($H33/$H$45,""))
G34: =IF($E34="","",IFERROR(INDEX(01_專案設定_Setup!$C$13:$C$15,MATCH($E34,01_專案設定_Setup!$B$13:$B$15,0)),"")) | H34: =IF(OR($F34="",$G34="",$G34=0),"",$F34/$G34/1000) | I34: =IF($H34="","",IFERROR($H34/$H$45,""))
G35: =IF($E35="","",IFERROR(INDEX(01_專案設定_Setup!$C$13:$C$15,MATCH($E35,01_專案設定_Setup!$B$13:$B$15,0)),"")) | H35: =IF(OR($F35="",$G35="",$G35=0),"",$F35/$G35/1000) | I35: =IF($H35="","",IFERROR($H35/$H$45,""))
... G44: =IF($E44="","",IFERROR(INDEX(01_專案設定_Setup!$C$13:$C$15,MATCH($E44,01_專案設定_Setup!$B$13:$B$15,0)),"")) | H44: =IF(OR($F44="",$G44="",$G44=0),"",$F44/$G44/1000) | I44: =IF($H44="","",IFERROR($H44/$H$45,""))
B45: 直接成本合計 | H45: =SUM($H$5:$H$44) -> 2440.5827
B46: 其中：進口部分 | H46: =SUMIFS($H$5:$H$44,$D$5:$D$44,"進口") -> 1652
B47: 其中：在地部分 | H47: =SUMIFS($H$5:$H$44,$D$5:$D$44,"在地") -> 788.58268
B49: 依類別彙總
...

Sheet 03_在地化檢核_LocalContent
A1: 在地化檢核｜Local Content（湊不到比例會直接失格，不是扣分）
A2: ❓這頁在回答：我方的在地採購比例達標了嗎？沒達標差多少、怎麼補？
B5: 直接成本合計（千USD） | C5: =02_成本堆疊_CostBuildup!$H$45 -> 2440.5827
B6: 在地採購金額（千USD） | C6: =02_成本堆疊_CostBuildup!$H$47 -> 788.58268
B7: 進口金額（千USD） | C7: =02_成本堆疊_CostBuildup!$H$46 -> 1652
B8: 目前在地化比例 | C8: =IFERROR(02_成本堆疊_CostBuildup!$H$47/02_成本堆疊_CostBuildup!$H$45,"") -> 0.32311246
B9: 標書要求比例 | C9: =01_專案設定_Setup!$C$20 -> 0.3
B10: 達標判定 | C10: =IF(01_專案設定_Setup!$C$20=0,"標書無要求",IF(IFERROR(02_成本堆疊_CostBuildup!$H$47/02_成本堆疊_CostBuildup!$H$45,0)>=01_專案設定_Setup!$C$20,"✓ 達標","✗ 未達標")) -> ✓ 達標
B11: 尚差金額（千USD） | C11: =IF(01_專案設定_Setup!$C$20=0,0,MAX(0,01_專案設定_Setup!$C$20*02_成本堆疊_CostBuildup!$H$45-02_成本堆疊_CostBuildup!$H$47)) -> 0 | D11: 要再把這麼多金額轉為在地採購才達標
B13: 補救方向（依可行性排序）： ① 把可在地化的工程項目（裝修、管路、線槽）從進口打包中拆出來，改由在地夥伴承作——最快、對品質衝擊最小。 ② 教育訓練、技術文件越文化、在地認證測試改由在地單位執行。 ③ 與在地夥伴簽組裝協議，部分機櫃在越南組裝——需確認標書對「在地組裝」是否計入。 ④ 最後才考慮更換設備品牌為在地可供貨者，這會牽動規格與保固，風險最高。 ★ 提醒：多數越南標書認定「在地」的定義寫在資格文件裡，投標前務必確認是以「金額」還是「工項」計算，兩者結果可能差很多。

Sheet 04_付款條件_PaymentTerms
A1: 付款條件與資金缺口｜Payment Terms & Funding Gap
A2: ❓這頁在回答：錢什麼時候進來、什麼時候出去、中間我方要墊多少？ ★ 很多案子是被現金流拖垮，不是被毛利拖垮
A3: 圖例： | B3: 要填 | C3: 自動 | D3: （範例）數字為示意，請換成你這一案的真實成本
A4: 月份 | B4: 里程碑 | C4: 收款比例 | D4: 收款(千USD) | E4: 成本支出比例 | F4: 支出(千USD) | G4: 淨現金流 | H4: 累計現金流 | I4: 折現因子 | J4: 折現淨額
A5: 0 | B5: 合約簽訂預付款 | C5: 0.15 | D5: =IF($C5="","",$C5*05_報價與毛利_Pricing!$C$6) -> 552 | E5: 0.05 | F5: =IF($E5="","",$E5*05_報價與毛利_Pricing!$C$9) -> 122.02913 | G5: =IFERROR(N($D5)-N($F5),"") -> 429.97087 | H5: =$G5 -> 429.97087 | I5: =IF($A5="","",1/(1+01_專案設定_Setup!$C$23)^($A5/12)) -> 1 | J5: =IFERROR($G5*$I5,"") -> 429.97087
A6: 1 | C6: 0 | D6: =IF($C6="","",$C6*05_報價與毛利_Pricing!$C$6) -> 0 | E6: 0.05 | F6: =IF($E6="","",$E6*05_報價與毛利_Pricing!$C$9) -> 122.02913 | G6: =IFERROR(N($D6)-N($F6),"") -> -122.02913 | H6: =IFERROR($H5+$G6,"") -> 307.94173 | I6: =IF($A6="","",1/(1+01_專案設定_Setup!$C$23)^($A6/12)) -> 0.99284425 | J6: =IFERROR($G6*$I6,"") -> -121.15592
A7: 2 | B7: 設備開始製造 | C7: 0 | D7: =IF($C7="","",$C7*05_報價與毛利_Pricing!$C$6) -> 0 | E7: 0.25 | F7: =IF($E7="","",$E7*05_報價與毛利_Pricing!$C$9) -> 610.14567 | G7: =IFERROR(N($D7)-N($F7),"") -> -610.14567 | H7: =IFERROR($H6+$G7,"") -> -302.20394 | I7: =IF($A7="","",1/(1+01_專案設定_Setup!$C$23)^($A7/12)) -> 0.98573971 | J7: =IFERROR($G7*$I7,"") -> -601.44481
A8: 3 | C8: 0 | D8: =IF($C8="","",$C8*05_報價與毛利_Pricing!$C$6) -> 0 | E8: 0.15 | F8: =IF($E8="","",$E8*05_報價與毛利_Pricing!$C$9) -> 366.0874 | G8: =IFERROR(N($D8)-N($F8),"") -> -366.0874 | H8: =IFERROR($H7+$G8,"") -> -668.29134 | I8: =IF($A8="","",1/(1+01_專案設定_Setup!$C$23)^($A8/12)) -> 0.978686 | J8: =IFERROR($G8*$I8,"") -> -358.28461
A9: 4 | B9: 設備到港／驗貨 | C9: 0.25 | D9: =IF($C9="","",$C9*05_報價與毛利_Pricing!$C$6) -> 920 | E9: 0.1 | F9: =IF($E9="","",$E9*05_報價與毛利_Pricing!$C$9) -> 244.05827 | G9: =IFERROR(N($D9)-N($F9),"") -> 675.94173 | H9: =IFERROR($H8+$G9,"") -> 7.6503937 | I9: =IF($A9="","",1/(1+01_專案設定_Setup!$C$23)^($A9/12)) -> 0.97168277 | J9: =IFERROR($G9*$I9,"") -> 656.80093
A10: 5 | C10: 0 | D10: =IF($C10="","",$C10*05_報價與毛利_Pricing!$C$6) -> 0 | E10: 0.08 | F10: =IF($E10="","",$E10*05_報價與毛利_Pricing!$C$9) -> 195.24661 | G10: =IFERROR(N($D10)-N($F10),"") -> -195.24661 | H10: =IFERROR($H9+$G10,"") -> -187.59622 | I10: =IF($A10="","",1/(1+01_專案設定_Setup!$C$23)^($A10/12)) -> 0.96472965 | J10: =IFERROR($G10*$I10,"") -> -188.3602
A11: 6 | B11: 安裝進度 50% | C11: 0.2 | D11: =IF($C11="","",$C11*05_報價與毛利_Pricing!$C$6) -> 736 | E11: 0.1 | F11: =IF($E11="","",$E11*05_報價與毛利_Pricing!$C$9) -> 244.05827 | G11: =IFERROR(N($D11)-N($F11),"") -> 491.94173 | H11: =IFERROR($H10+$G11,"") -> 304.34551 | I11: =IF($A11="","",1/(1+01_專案設定_Setup!$C$23)^($A11/12)) -> 0.95782629 | J11: =IFERROR($G11*$I11,"") -> 471.19472
A12: 7 | C12: 0 | D12: =IF($C12="","",$C12*05_報價與毛利_Pricing!$C$6) -> 0 | E12: 0.08 | F12: =IF($E12="","",$E12*05_報價與毛利_Pricing!$C$9) -> 195.24661 | G12: =IFERROR(N($D12)-N($F12),"") -> -195.24661 | H12: =IFERROR($H11+$G12,"") -> 109.0989 | I12: =IF($A12="","",1/(1+01_專案設定_Setup!$C$23)^($A12/12)) -> 0.95097232 | J12: =IFERROR($G12*$I12,"") -> -185.67413
A13: 8 | B13: 安裝完成 | C13: 0 | D13: =IF($C13="","",$C13*05_報價與毛利_Pricing!$C$6) -> 0 | E13: 0.06 | F13: =IF($E13="","",$E13*05_報價與毛利_Pricing!$C$9) -> 146.43496 | G13: =IFERROR(N($D13)-N($F13),"") -> -146.43496 | H13: =IFERROR($H12+$G13,"") -> -37.336063 | I13: =IF($A13="","",1/(1+01_專案設定_Setup!$C$23)^($A13/12)) -> 0.9441674 | J13: =IFERROR($G13*$I13,"") -> -138.25912
A14: 9 | B14: 測試與試運轉完成 | C14: 0.2 | D14: =IF($C14="","",$C14*05_報價與毛利_Pricing!$C$6) -> 736 | E14: 0.04 | F14: =IF($E14="","",$E14*05_報價與毛利_Pricing!$C$9) -> 97.623307 | G14: =IFERROR(N($D14)-N($F14),"") -> 638.37669 | H14: =IFERROR($H13+$G14,"") -> 601.04063 | I14: =IF($A14="","",1/(1+01_專案設定_Setup!$C$23)^($A14/12)) -> 0.93741118 | J14: =IFERROR($G14*$I14,"") -> 598.42145
A15: 10 | C15: 0 | D15: =IF($C15="","",$C15*05_報價與毛利_Pricing!$C$6) -> 0 | E15: 0.02 | F15: =IF($E15="","",$E15*05_報價與毛利_Pricing!$C$9) -> 48.811654 | G15: =IFERROR(N($D15)-N($F15),"") -> -48.811654 | H15: =IFERROR($H14+$G15,"") -> 552.22898 | I15: =IF($A15="","",1/(1+01_專案設定_Setup!$C$23)^($A15/12)) -> 0.9307033 | J15: =IFERROR($G15*$I15,"") -> -45.429167
A16: 11 | C16: 0 | D16: =IF($C16="","",$C16*05_報價與毛利_Pricing!$C$6) -> 0 | E16: 0.01 | F16: =IF($E16="","",$E16*05_報價與毛利_Pricing!$C$9) -> 24.405827 | G16: =IFERROR(N($D16)-N($F16),"") -> -24.405827 | H16: =IFERROR($H15+$G16,"") -> 527.82315 | I16: =IF($A16="","",1/(1+01_專案設定_Setup!$C$23)^($A16/12)) -> 0.92404342 | J16: =IFERROR($G16*$I16,"") -> -22.552044
A17: 12 | B17: 正式驗收 | C17: 0.15 | D17: =IF($C17="","",$C17*05_報價與毛利_Pricing!$C$6) -> 552 | E17: 0.01 | F17: =IF($E17="","",$E17*05_報價與毛利_Pricing!$C$9) -> 24.405827 | G17: =IFERROR(N($D17)-N($F17),"") -> 527.59417 | H17: =IFERROR($H16+$G17,"") -> 1055.4173 | I17: =IF($A17="","",1/(1+01_專案設定_Setup!$C$23)^($A17/12)) -> 0.91743119 | J17: =IFERROR($G17*$I17,"") -> 484.03135
A18: 13 | C18: 0 | D18: =IF($C18="","",$C18*05_報價與毛利_Pricing!$C$6) -> 0 | E18: 0 | F18: =IF($E18="","",$E18*05_報價與毛利_Pricing!$C$9) -> 0 | G18: =IFERROR(N($D18)-N($F18),"") -> 0 | H18: =IFERROR($H17+$G18,"") -> 1055.4173 | I18: =IF($A18="","",1/(1+01_專案設定_Setup!$C$23)^($A18/12)) -> 0.91086628 | J18: =IFERROR($G18*$I18,"") -> 0
A19: 14 | C19: 0 | D19: =IF($C19="","",$C19*05_報價與毛利_Pricing!$C$6) -> 0 | E19: 0 | F19: =IF($E19="","",$E19*05_報價與毛利_Pricing!$C$9) -> 0 | G19: =IFERROR(N($D19)-N($F19),"") -> 0 | H19: =IFERROR($H18+$G19,"") -> 1055.4173 | I19: =IF($A19="","",1/(1+01_專案設定_Setup!$C$23)^($A19/12)) -> 0.90434835 | J19: =IFERROR($G19*$I19,"") -> 0
A20: 15 | C20: 0 | D20: =IF($C20="","",$C20*05_報價與毛利_Pricing!$C$6) -> 0 | E20: 0 | F20: =IF($E20="","",$E20*05_報價與毛利_Pricing!$C$9) -> 0 | G20: =IFERROR(N($D20)-N($F20),"") -> 0 | H20: =IFERROR($H19+$G20,"") -> 1055.4173 | I20: =IF($A20="","",1/(1+01_專案設定_Setup!$C$23)^($A20/12)) -> 0.89787706 | J20: =IFERROR($G20*$I20,"") -> 0
A21: 16 | C21: 0 | D21: =IF($C21="","",$C21*05_報價與毛利_Pricing!$C$6) -> 0 | E21: 0 | F21: =IF($E21="","",$E21*05_報價與毛利_Pricing!$C$9) -> 0 | G21: =IFERROR(N($D21)-N($F21),"") -> 0 | H21: =IFERROR($H20+$G21,"") -> 1055.4173 | I21: =IF($A21="","",1/(1+01_專案設定_Setup!$C$23)^($A21/12)) -> 0.89145208 | J21: =IFERROR($G21*$I21,"") -> 0
A22: 17 | C22: 0 | D22: =IF($C22="","",$C22*05_報價與毛利_Pricing!$C$6) -> 0 | E22: 0 | F22: =IF($E22="","",$E22*05_報價與毛利_Pricing!$C$9) -> 0 | G22: =IFERROR(N($D22)-N($F22),"") -> 0 | H22: =IFERROR($H21+$G22,"") -> 1055.4173 | I22: =IF($A22="","",1/(1+01_專案設定_Setup!$C$23)^($A22/12)) -> 0.88507307 | J22: =IFERROR($G22*$I22,"") -> 0
A23: 18 | B23: 保固期滿尾款 | C23: 0.05 | D23: =IF($C23="","",$C23*05_報價與毛利_Pricing!$C$6) -> 184 | E23: 0 | F23: =IF($E23="","",$E23*05_報價與毛利_Pricing!$C$9) -> 0 | G23: =IFERROR(N($D23)-N($F23),"") -> 184 | H23: =IFERROR($H22+$G23,"") -> 1239.4173 | I23: =IF($A23="","",1/(1+01_專案設定_Setup!$C$23)^($A23/12)) -> 0.87873971 | J23: =IFERROR($G23*$I23,"") -> 161.68811
D24: =IF($C24="","",$C24*05_報價與毛利_Pricing!$C$6) | F24: =IF($E24="","",$E24*05_報價與毛利_Pricing!$C$9) | G24: =IFERROR(N($D24)-N($F24),"") -> 0 | H24: =IFERROR($H23+$G24,"") -> 1239.4173 | I24: =IF($A24="","",1/(1+01_專案設定_Setup!$C$23)^($A24/12)) | J24: =IFERROR($G24*$I24,"")
D25: =IF($C25="","",$C25*05_報價與毛利_Pricing!$C$6) | F25: =IF($E25="","",$E25*05_報價與毛利_Pricing!$C$9) | G25: =IFERROR(N($D25)-N($F25),"") -> 0 | H25: =IFERROR($H24+$G25,"") -> 1239.4173 | I25: =IF($A25="","",1/(1+01_專案設定_Setup!$C$23)^($A25/12)) | J25: =IFERROR($G25*$I25,"")
D26: =IF($C26="","",$C26*05_報價與毛利_Pricing!$C$6) | F26: =IF($E26="","",$E26*05_報價與毛利_Pricing!$C$9) | G26: =IFERROR(N($D26)-N($F26),"") -> 0 | H26: =IFERROR($H25+$G26,"") -> 1239.4173 | I26: =IF($A26="","",1/(1+01_專案設定_Setup!$C$23)^($A26/12)) | J26: =IFERROR($G26*$I26,"")
D27: =IF($C27="","",$C27*05_報價與毛利_Pricing!$C$6) | F27: =IF($E27="","",$E27*05_報價與毛利_Pricing!$C$9) | G27: =IFERROR(N($D27)-N($F27),"") -> 0 | H27: =IFERROR($H26+$G27,"") -> 1239.4173 | I27: =IF($A27="","",1/(1+01_專案設定_Setup!$C$23)^($A27/12)) | J27: =IFERROR($G27*$I27,"")
D28: =IF($C28="","",$C28*05_報價與毛利_Pricing!$C$6) | F28: =IF($E28="","",$E28*05_報價與毛利_Pricing!$C$9) | G28: =IFERROR(N($D28)-N($F28),"") -> 0 | H28: =IFERROR($H27+$G28,"") -> 1239.4173 | I28: =IF($A28="","",1/(1+01_專案設定_Setup!$C$23)^($A28/12)) | J28: =IFERROR($G28*$I28,"")
B29: 合計 | C29: =SUM($C$5:$C$28) -> 1 | D29: =SUM($D$5:$D$28) -> 3680 | E29: =SUM($E$5:$E$28) -> 1 | F29: =SUM($F$5:$F$28) -> 2440.5827 | J29: =SUM($J$5:$J$28) -> 1140.9474
B31: 最大資金缺口（千USD） | D31: =-MIN($H$5:$H$28,0) -> 668.29134 | E31: ★ 累計現金流的最低點。要先確認財務調得動這筆錢再投標
B32: 缺口發生月份 | D32: =IFERROR(INDEX($A$5:$A$28,MATCH(MIN($H$5:$H$28),$H$5:$H$28,0)),"") -> 3 | E32: 從簽約起算第幾個月
B33: 收款加權平均月數 | D33: =IFERROR(SUMPRODUCT($A$5:$A$28,$C$5:$C$28)/SUM($C$5:$C$28),"") -> 6.7 | E33: 平均要等幾個月才收到錢
B34: 現金流折現損失（千USD） | D34: =IFERROR(SUM($G$5:$G$28)-SUM($J$5:$J$28),"") -> 98.469898 | E34: 名目毛利與折現後毛利的差額——這是付款條件的隱形代價

Sheet 06_敏感度_Sensitivity
A1: 敏感度｜Tornado（哪個變數最傷？那就是談判要優先鎖住的條款）
A2: ❓這頁在回答：如果事情不如預期，毛利率會掉到哪？ ★ 影響幅度最大的前三項，就是合約裡最該寫清楚的三件事
A4: 變數 | B4: 不利情境 | C4: 有利情境 | D4: 不利時毛利率 | E4: 有利時毛利率 | F4: 影響幅度(百分點) | G4: 應對方向
A5: VND 匯率 ±10% | B5: 越南盾貶值 10%（在地成本以USD計變貴） | C5: 越南盾升值 10% | D5: =IFERROR((05_報價與毛利_Pricing!$C$6-(02_成本堆疊_CostBuildup!$H$45+02_成本堆疊_CostBuildup!$H$47*0.1111)-05_報價與毛利_Pricing!$C$6*01_專案設定_Setup!$C$24-05_報價與毛利_Pricing!$C$6*01_專案設定_Setup!$C$25-(02_成本堆疊_CostBuildup!$H$45+02_成本堆疊_CostBuildup!$H$47*0.1111)*01_專案設定_Setup!$C$26)/05_報價與毛利_Pricing!$C$6,"") -> 0.18864024 | E5: =IFERROR((05_報價與毛利_Pricing!$C$6-(02_成本堆疊_CostBuildup!$H$45-02_成本堆疊_CostBuildup!$H$47*0.0909)-05_報價與毛利_Pricing!$C$6*01_專案設定_Setup!$C$24-05_報價與毛利_Pricing!$C$6*01_專案設定_Setup!$C$25-(02_成本堆疊_CostBuildup!$H$45-02_成本堆疊_CostBuildup!$H$47*0.0909)*01_專案設定_Setup!$C$26)/05_報價與毛利_Pricing!$C$6,"") -> 0.23409089 | F5: =IFERROR(($E5-$D5)*100,"") -> 4.5450648 | G5: 在地採購合約盡量以 VND 計價並鎖定總價，把匯率風險留在對方
A6: 進口設備成本 ±15% | B6: 原廠漲價或規格加嚴 +15% | C6: 議價成功 −15% | D6: =IFERROR((05_報價與毛利_Pricing!$C$6-(02_成本堆疊_CostBuildup!$H$45+02_成本堆疊_CostBuildup!$H$46*0.15)-05_報價與毛利_Pricing!$C$6*01_專案設定_Setup!$C$24-05_報價與毛利_Pricing!$C$6*01_專案設定_Setup!$C$25-(02_成本堆疊_CostBuildup!$H$45+02_成本堆疊_CostBuildup!$H$46*0.15)*01_專案設定_Setup!$C$26)/05_報價與毛利_Pricing!$C$6,"") -> 0.14293429 | E6: =IFERROR((05_報價與毛利_Pricing!$C$6-(02_成本堆疊_CostBuildup!$H$45-02_成本堆疊_CostBuildup!$H$46*0.15)-05_報價與毛利_Pricing!$C$6*01_專案設定_Setup!$C$24-05_報價與毛利_Pricing!$C$6*01_專案設定_Setup!$C$25-(02_成本堆疊_CostBuildup!$H$45-02_成本堆疊_CostBuildup!$H$46*0.15)*01_專案設定_Setup!$C$26)/05_報價與毛利_Pricing!$C$6,"") -> 0.2843419 | F6: =IFERROR(($E6-$D6)*100,"") -> 14.140761 | G6: 投標前取得原廠有效期涵蓋決標日的報價，並約定漲價分攤條款
A7: 進口關稅 ±5 個百分點 | B7: HS Code 認定不利 +5pp | C7: 認定有利 −5pp | D7: =IFERROR((05_報價與毛利_Pricing!$C$6-(02_成本堆疊_CostBuildup!$H$45+02_成本堆疊_CostBuildup!$H$46*0.05)-05_報價與毛利_Pricing!$C$6*01_專案設定_Setup!$C$24-05_報價與毛利_Pricing!$C$6*01_專案設定_Setup!$C$25-(02_成本堆疊_CostBuildup!$H$45+02_成本堆疊_CostBuildup!$H$46*0.05)*01_專案設定_Setup!$C$26)/05_報價與毛利_Pricing!$C$6,"") -> 0.19007016 | E7: =IFERROR((05_報價與毛利_Pricing!$C$6-(02_成本堆疊_CostBuildup!$H$45-02_成本堆疊_CostBuildup!$H$46*0.05)-05_報價與毛利_Pricing!$C$6*01_專案設定_Setup!$C$24-05_報價與毛利_Pricing!$C$6*01_專案設定_Setup!$C$25-(02_成本堆疊_CostBuildup!$H$45-02_成本堆疊_CostBuildup!$H$46*0.05)*01_專案設定_Setup!$C$26)/05_報價與毛利_Pricing!$C$6,"") -> 0.23720603 | F7: =IFERROR(($E7-$D7)*100,"") -> 4.713587 | G7: ★ 開標前向海關取得預先歸類（advance ruling），不要用猜的
A8: 工程延誤 6 個月 | B8: 工地交付延遲，PM 與駐點成本增加 | C8: 如期完工 | D8: =IFERROR((05_報價與毛利_Pricing!$C$6-(02_成本堆疊_CostBuildup!$H$45*1.06)-05_報價與毛利_Pricing!$C$6*01_專案設定_Setup!$C$24-05_報價與毛利_Pricing!$C$6*01_專案設定_Setup!$C$25-(02_成本堆疊_CostBuildup!$H$45*1.06)*01_專案設定_Setup!$C$26)/05_報價與毛利_Pricing!$C$6,"") -> 0.17185638 | E8: =IFERROR((05_報價與毛利_Pricing!$C$6-(02_成本堆疊_CostBuildup!$H$45)-05_報價與毛利_Pricing!$C$6*01_專案設定_Setup!$C$24-05_報價與毛利_Pricing!$C$6*01_專案設定_Setup!$C$25-(02_成本堆疊_CostBuildup!$H$45)*01_專案設定_Setup!$C$26)/05_報價與毛利_Pricing!$C$6,"") -> 0.21363809 | F8: =IFERROR(($E8-$D8)*100,"") -> 4.1781714 | G8: 合約中明訂工地交付前置條件與延誤責任歸屬，逾期由對方吸收
A9: 保固索賠超支 | B9: 保固期實際支出達合約額 6%（預估 3%） | C9: 保固支出僅 1.5% | D9: =IFERROR((05_報價與毛利_Pricing!$C$6-(02_成本堆疊_CostBuildup!$H$45+05_報價與毛利_Pricing!$C$6*0.03)-05_報價與毛利_Pricing!$C$6*01_專案設定_Setup!$C$24-05_報價與毛利_Pricing!$C$6*01_專案設定_Setup!$C$25-(02_成本堆疊_CostBuildup!$H$45+05_報價與毛利_Pricing!$C$6*0.03)*01_專案設定_Setup!$C$26)/05_報價與毛利_Pricing!$C$6,"") -> 0.18213809 | E9: =IFERROR((05_報價與毛利_Pricing!$C$6-(02_成本堆疊_CostBuildup!$H$45-05_報價與毛利_Pricing!$C$6*0.015)-05_報價與毛利_Pricing!$C$6*01_專案設定_Setup!$C$24-05_報價與毛利_Pricing!$C$6*01_專案設定_Setup!$C$25-(02_成本堆疊_CostBuildup!$H$45-05_報價與毛利_Pricing!$C$6*0.015)*01_專案設定_Setup!$C$26)/05_報價與毛利_Pricing!$C$6,"") -> 0.22938809 | F9: =IFERROR(($E9-$D9)*100,"") -> 4.725 | G9: 備品在地化、遠端診斷、明確排除人為損壞與電網品質問題
A10: 夥伴分潤上調 3pp | B10: 在地夥伴議價力提高 | C10: 維持原分潤 | D10: =IFERROR((05_報價與毛利_Pricing!$C$6-(02_成本堆疊_CostBuildup!$H$45+05_報價與毛利_Pricing!$C$6*0.03)-05_報價與毛利_Pricing!$C$6*01_專案設定_Setup!$C$24-05_報價與毛利_Pricing!$C$6*01_專案設定_Setup!$C$25-(02_成本堆疊_CostBuildup!$H$45+05_報價與毛利_Pricing!$C$6*0.03)*01_專案設定_Setup!$C$26)/05_報價與毛利_Pricing!$C$6,"") -> 0.18213809 | E10: =IFERROR((05_報價與毛利_Pricing!$C$6-(02_成本堆疊_CostBuildup!$H$45)-05_報價與毛利_Pricing!$C$6*01_專案設定_Setup!$C$24-05_報價與毛利_Pricing!$C$6*01_專案設定_Setup!$C$25-(02_成本堆疊_CostBuildup!$H$45)*01_專案設定_Setup!$C$26)/05_報價與毛利_Pricing!$C$6,"") -> 0.21363809 | F10: =IFERROR(($E10-$D10)*100,"") -> 3.15 | G10: 提早簽定分潤上限條款，避免決標後被回頭加碼
A12: 基準毛利率 | D12: =05_報價與毛利_Pricing!$C$17 -> 0.21363809 | E12: ← 全部變數維持預設時的毛利率，上表所有情境都跟這個比
A14: 讀法：「影響幅度」欄由大到小排，就是你的風險排序。前三名請逐條對應到合約條款或投標前的查核動作—— 敏感度分析的價值不在算出數字，而在把「該去確認什麼」變成一張具體的待辦清單。 注意：各變數獨立計算，未考慮同時發生。真要看最壞情況，請到「情境比較」頁看保守情境。

Sheet 07_情境比較_Scenarios
A1: 情境比較｜Scenarios（同時出錯的時候，還撐得住嗎）
A2: ❓這頁在回答：保守情境下毛利率剩多少？還在走人價之上嗎？
A4: 項目 | B4: 保守情境 | C4: 基準情境 | D4: 樂觀情境 | E4: 說明
A5: 進口設備成本變動 | B5: 0.1 | C5: 0 | D5: -0.08 | E5: 原廠報價與規格變更的幅度
A6: 在地成本變動（含匯率） | B6: 0.05 | C6: 0 | D6: -0.03 | E6: 越南盾貶值會推高以USD計的在地成本
A7: 額外保固／延誤成本（占報價） | B7: 0.06 | C7: 0 | D7: 0 | E7: 工期延誤與保固索賠的合計衝擊
A9: 調整後直接成本（千USD） | B9: =(02_成本堆疊_CostBuildup!$H$45+02_成本堆疊_CostBuildup!$H$46*$B$5+02_成本堆疊_CostBuildup!$H$47*$B$6+05_報價與毛利_Pricing!$C$6*$B$7) -> 2866.0118 | C9: =(02_成本堆疊_CostBuildup!$H$45+02_成本堆疊_CostBuildup!$H$46*$C$5+02_成本堆疊_CostBuildup!$H$47*$C$6+05_報價與毛利_Pricing!$C$6*$C$7) -> 2440.5827 | D9: =(02_成本堆疊_CostBuildup!$H$45+02_成本堆疊_CostBuildup!$H$46*$D$5+02_成本堆疊_CostBuildup!$H$47*$D$6+05_報價與毛利_Pricing!$C$6*$D$7) -> 2284.7652
A10: 毛利額（千USD） | B10: =IFERROR((05_報價與毛利_Pricing!$C$6-(02_成本堆疊_CostBuildup!$H$45+02_成本堆疊_CostBuildup!$H$46*$B$5+02_成本堆疊_CostBuildup!$H$47*$B$6+05_報價與毛利_Pricing!$C$6*$B$7)-05_報價與毛利_Pricing!$C$6*01_專案設定_Setup!$C$24-05_報價與毛利_Pricing!$C$6*01_專案設定_Setup!$C$25-(02_成本堆疊_CostBuildup!$H$45+02_成本堆疊_CostBuildup!$H$46*$B$5+02_成本堆疊_CostBuildup!$H$47*$B$6+05_報價與毛利_Pricing!$C$6*$B$7)*01_專案設定_Setup!$C$26),"") -> 339.4876 | C10: =IFERROR((05_報價與毛利_Pricing!$C$6-(02_成本堆疊_CostBuildup!$H$45+02_成本堆疊_CostBuildup!$H$46*$C$5+02_成本堆疊_CostBuildup!$H$47*$C$6+05_報價與毛利_Pricing!$C$6*$C$7)-05_報價與毛利_Pricing!$C$6*01_專案設定_Setup!$C$24-05_報價與毛利_Pricing!$C$6*01_專案設定_Setup!$C$25-(02_成本堆疊_CostBuildup!$H$45+02_成本堆疊_CostBuildup!$H$46*$C$5+02_成本堆疊_CostBuildup!$H$47*$C$6+05_報價與毛利_Pricing!$C$6*$C$7)*01_專案設定_Setup!$C$26),"") -> 786.18819 | D10: =IFERROR((05_報價與毛利_Pricing!$C$6-(02_成本堆疊_CostBuildup!$H$45+02_成本堆疊_CostBuildup!$H$46*$D$5+02_成本堆疊_CostBuildup!$H$47*$D$6+05_報價與毛利_Pricing!$C$6*$D$7)-05_報價與毛利_Pricing!$C$6*01_專案設定_Setup!$C$24-05_報價與毛利_Pricing!$C$6*01_專案設定_Setup!$C$25-(02_成本堆疊_CostBuildup!$H$45+02_成本堆疊_CostBuildup!$H$46*$D$5+02_成本堆疊_CostBuildup!$H$47*$D$6+05_報價與毛利_Pricing!$C$6*$D$7)*01_專案設定_Setup!$C$26),"") -> 949.79654
A11: 毛利率 | B11: =IFERROR($B$10/05_報價與毛利_Pricing!$C$6,"") -> 0.092252065 | C11: =IFERROR($C$10/05_報價與毛利_Pricing!$C$6,"") -> 0.21363809 | D11: =IFERROR($D$10/05_報價與毛利_Pricing!$C$6,"") -> 0.25809689
A12: 該情境下的走人價（千USD） | B12: =IFERROR((02_成本堆疊_CostBuildup!$H$45+02_成本堆疊_CostBuildup!$H$46*$B$5+02_成本堆疊_CostBuildup!$H$47*$B$6+05_報價與毛利_Pricing!$C$6*$B$7+(02_成本堆疊_CostBuildup!$H$45+02_成本堆疊_CostBuildup!$H$46*$B$5+02_成本堆疊_CostBuildup!$H$47*$B$6+05_報價與毛利_Pricing!$C$6*$B$7)*01_專案設定_Setup!$C$26)/(1-01_專案設定_Setup!$C$24-01_專案設定_Setup!$C$25-01_專案設定_Setup!$C$32),"") -> 3809.2562 | C12: =IFERROR((02_成本堆疊_CostBuildup!$H$45+02_成本堆疊_CostBuildup!$H$46*$C$5+02_成本堆疊_CostBuildup!$H$47*$C$6+05_報價與毛利_Pricing!$C$6*$C$7+(02_成本堆疊_CostBuildup!$H$45+02_成本堆疊_CostBuildup!$H$46*$C$5+02_成本堆疊_CostBuildup!$H$47*$C$6+05_報價與毛利_Pricing!$C$6*$C$7)*01_專案設定_Setup!$C$26)/(1-01_專案設定_Setup!$C$24-01_專案設定_Setup!$C$25-01_專案設定_Setup!$C$32),"") -> 3243.8124 | D12: =IFERROR((02_成本堆疊_CostBuildup!$H$45+02_成本堆疊_CostBuildup!$H$46*$D$5+02_成本堆疊_CostBuildup!$H$47*$D$6+05_報價與毛利_Pricing!$C$6*$D$7+(02_成本堆疊_CostBuildup!$H$45+02_成本堆疊_CostBuildup!$H$46*$D$5+02_成本堆疊_CostBuildup!$H$47*$D$6+05_報價與毛利_Pricing!$C$6*$D$7)*01_專案設定_Setup!$C$26)/(1-01_專案設定_Setup!$C$24-01_專案設定_Setup!$C$25-01_專案設定_Setup!$C$32),"") -> 3036.7132
A13: 判定 | B13: =IF($B$11="","",IF(05_報價與毛利_Pricing!$C$6<$B$12,"✗ 應退出",IF($B$11<01_專案設定_Setup!$C$33,"△ 低於目標","✓ 可接"))) -> ✗ 應退出 | C13: =IF($C$11="","",IF(05_報價與毛利_Pricing!$C$6<$C$12,"✗ 應退出",IF($C$11<01_專案設定_Setup!$C$33,"△ 低於目標","✓ 可接"))) -> △ 低於目標 | D13: =IF($D$11="","",IF(05_報價與毛利_Pricing!$C$6<$D$12,"✗ 應退出",IF($D$11<01_專案設定_Setup!$C$33,"△ 低於目標","✓ 可接"))) -> ✓ 可接
A15: 怎麼用：先看「保守情境」那一欄的判定。如果保守情境就已經是「✗ 應退出」，代表這個報價沒有容錯空間—— 要嘛提高報價，要嘛把風險透過合約條款移轉出去，要嘛就不要投。 保守情境的假設不是悲觀，是「合理會發生的壞事都發生」：原廠漲價 10%、越南盾貶 5%、工程延誤加保固超支 6%。 首次進入越南市場的案子，建議直接用保守情境當決策依據，基準情境當內部目標。

Sheet 08_假設來源_Assumptions
A1: 假設來源｜Assumptions（每個數字從哪來、誰說的、什麼時候會過期）
A2: ❓這頁在回答：這份試算可信嗎？哪些數字已經該重新確認了？ ★ 情報有半衰期，過期的假設比沒有假設更危險
A3: 圖例： | B3: 要填 | C3: 自動 | D3: （範例）數字為示意，請換成你這一案的真實成本
A4: 項目 | B4: 採用值 | C4: 來源／依據 | D4: 取得日 | E4: 有效期限 | F4: 信心 | G4: 複核負責人 | H4: 備註
A5: 進口關稅率 | B5: 8% | C5: 越南海關稅則 2026 版，同類設備級距 | D5: 2026-07-20 | E5: 2026-12-31 | F5: B | G5: — | H5: ★ 需逐項 HS Code 取得預先歸類確認
A6: VND/USD 匯率 | B6: 25,400 | C6: 越南國家銀行中心匯率 | D6: 2026-08-15 | E6: 2026-09-15 | F6: A | G6: — | H6: 匯率頁面每日更新，投標前重取
A7: 原廠設備報價 | B7: 見成本堆疊 | C7: 原廠正式報價單 | D7: 2026-07-15 | E7: 2026-10-15 | F7: A | G7: — | H7: ★ 報價有效期須涵蓋決標日，否則要求展延
A8: 在地工程單價 | B8: 見成本堆疊 | C8: 在地夥伴 P-07 口頭估算 | D8: 2026-08-01 | E8: 2026-10-01 | F8: C | G8: — | H8: ★ 信心低——需取得書面報價後更新
A9: 保固準備率 | B9: 3% | C9: 過往東南亞專案經驗值 | D9: 2026-08-18 | E9: — | F9: B | G9: — | H9: 越南電網品質較差，建議偏保守
A10: 在地化要求比例 | B10: 30% | C10: 標書資格文件 | D10: 2026-08-10 | E10: 依標書 | F10: A | G10: — | H10: 須確認以金額或工項計算
A11: 付款條件 | B11: 見付款條件頁 | C11: 標書草案付款辦法 | D11: 2026-08-10 | E11: 依標書 | F11: B | G11: — | H11: 正式標書可能調整，決標前複核
A32: 信心等級：A＝有書面正式來源 B＝有依據但需複核 C＝估算值，尚未證實（C 級項目若金額占比高，投標前必須升級為 A 或 B）

Sheet _選單_Lists
A1: 成本類別 | B1: 來源 | C1: 幣別 | D1: 風險等級
A2: 設備 | B2: 進口 | C2: USD | D2: 高
A3: 物流關稅 | B3: 在地 | C3: VND | D3: 中
A4: 工程安裝 | C4: TWD | D4: 低
A5: 專案管理
A6: 售後保固
A7: 認證合規
A8: 財務成本
