Workbook

Sheet 說明
A1: 單元2A 量表發展八關｜模擬資料練習檔
A2: 情境：發展「臨床護理人員工作意義感量表」（模擬），三個構面：V 工作價值、G 專業成長、C 團隊連結。
A3: 全部資料皆為教學用模擬資料，不代表真實調查結果。
A5: 工作表對照
A6: 3_專家評分：第③關，6 位專家 × 18 題的相關性評分，算 I-CVI 與 S-CVI/Ave（全部公式）
A7: 5_樣本A：第⑤⑥關原始資料，有效樣本 240 人 × 16 題（④修正後題庫），含總分、高低組、刪題後總分輔助欄
A8: 5_項目分析：第⑤關四把尺，全部公式；改動樣本A任何一格，結果會自動重算
A9: 6_EFA結果：第⑥關以統計軟體跑出的結果（Excel 無法做 EFA），請用 JASP 開啟「樣本A_EFA用_13題.csv」自行重跑對照
A10: 7_樣本B：第⑦⑧關原始資料，有效樣本 280 人 × 12 題（與樣本 A 不重複）
A11: 7_CFA結果：第⑦關軟體結果；CFI、TLI、RMSEA 由卡方值以公式自行算出
A12: 8_信效度：AVE、CR、√AVE、相關矩陣與 HTMT（全部公式）
A13: 8_再測：樣本 B 前 60 人於 2 週後再填 12 題，以二因子變異數分析算 ICC（全部公式）
... A21: HTMT < .85、ICC ≥ .75 為一般參考值

Sheet 3_專家評分
A1: 第③關 內容效度：6 位專家評「與構面的相關性」（1 不相關、2 有點相關、3 相關、4 非常相關）
A3: 題號 | B3: 題目（②題庫原稿） | C3: 專家1 | D3: 專家2 | E3: 專家3 | F3: 專家4 | G3: 專家5 | H3: 專家6 | I3: 給3或4分人數 | J3: I-CVI | K3: 決策
A4: V1 | B4: 我覺得我的護理工作對病人很重要 | C4: 4 | D4: 4 | E4: 4 | F4: 4 | G4: 4 | H4: 4 | I4: =COUNTIF(C4:H4,">=3") -> 6 | J4: =I4/COUNT(C4:H4) -> 1 | K4: =IF(J4>=0.78,"保留","刪除或改寫") -> 保留
A5: V2 | B5: 我的工作讓病人和家屬都受益 | C5: 4 | D5: 3 | E5: 4 | F5: 4 | G5: 3 | H5: 4 | I5: =COUNTIF(C5:H5,">=3") -> 6 | J5: =I5/COUNT(C5:H5) -> 1 | K5: =IF(J5>=0.78,"保留","刪除或改寫") -> 保留
A6: V3 | B6: 我能從工作中看到自己的價值 | C6: 4 | D6: 3 | E6: 4 | F6: 2 | G6: 4 | H6: 3 | I6: =COUNTIF(C6:H6,">=3") -> 5 | J6: =I6/COUNT(C6:H6) -> 0.83333333 | K6: =IF(J6>=0.78,"保留","刪除或改寫") -> 保留
A7: V4 | B7: 照顧病人讓我覺得這份工作值得 | C7: 4 | D7: 4 | E7: 3 | F7: 4 | G7: 4 | H7: 4 | I7: =COUNTIF(C7:H7,">=3") -> 6 | J7: =I7/COUNT(C7:H7) -> 1 | K7: =IF(J7>=0.78,"保留","刪除或改寫") -> 保留
A8: V5 | B8: 護理是一份受社會尊敬的職業 | C8: 2 | D8: 3 | E8: 1 | F8: 2 | G8: 3 | H8: 4 | I8: =COUNTIF(C8:H8,">=3") -> 3 | J8: =I8/COUNT(C8:H8) -> 0.5 | K8: =IF(J8>=0.78,"保留","刪除或改寫") -> 刪除或改寫
A9: V6 | B9: 和同事一起幫助病人，讓我覺得工作有價值 | C9: 3 | D9: 4 | E9: 4 | F9: 3 | G9: 4 | H9: 3 | I9: =COUNTIF(C9:H9,">=3") -> 6 | J9: =I9/COUNT(C9:H9) -> 1 | K9: =IF(J9>=0.78,"保留","刪除或改寫") -> 保留
A10: G1 | B10: 我在工作中持續學到新的專業知識 | C10: 4 | D10: 4 | E10: 3 | F10: 4 | G10: 4 | H10: 4 | I10: =COUNTIF(C10:H10,">=3") -> 6 | J10: =I10/COUNT(C10:H10) -> 1 | K10: =IF(J10>=0.78,"保留","刪除或改寫") -> 保留
A11: G2 | B11: 我的臨床判斷能力越來越好 | C11: 3 | D11: 4 | E11: 4 | F11: 4 | G11: 2 | H11: 4 | I11: =COUNTIF(C11:H11,">=3") -> 5 | J11: =I11/COUNT(C11:H11) -> 0.83333333 | K11: =IF(J11>=0.78,"保留","刪除或改寫") -> 保留
A12: G3 | B12: 工作中的挑戰讓我成長 | C12: 3 | D12: 4 | E12: 4 | F12: 3 | G12: 4 | H12: 4 | I12: =COUNTIF(C12:H12,">=3") -> 6 | J12: =I12/COUNT(C12:H12) -> 1 | K12: =IF(J12>=0.78,"保留","刪除或改寫") -> 保留
A13: G4 | B13: 我會主動參加院內外的進修課程 | C13: 3 | D13: 3 | E13: 4 | F13: 3 | G13: 3 | H13: 4 | I13: =COUNTIF(C13:H13,">=3") -> 6 | J13: =I13/COUNT(C13:H13) -> 1 | K13: =IF(J13>=0.78,"保留","刪除或改寫") -> 保留
A14: G5 | B14: 我覺得自己比剛入職時更有能力 | C14: 4 | D14: 3 | E14: 4 | F14: 4 | G14: 4 | H14: 3 | I14: =COUNTIF(C14:H14,">=3") -> 6 | J14: =I14/COUNT(C14:H14) -> 1 | K14: =IF(J14>=0.78,"保留","刪除或改寫") -> 保留
A15: G6 | B15: 醫院提供足夠的教育訓練資源 | C15: 3 | D15: 2 | E15: 4 | F15: 1 | G15: 3 | H15: 4 | I15: =COUNTIF(C15:H15,">=3") -> 4 | J15: =I15/COUNT(C15:H15) -> 0.66666667 | K15: =IF(J15>=0.78,"保留","刪除或改寫") -> 刪除或改寫
... A21: C6 | B21: 我認識單位裡的每一位同事 | C21: 3 | D21: 2 | E21: 3 | F21: 4 | G21: 3 | H21: 4 | I21: =COUNTIF(C21:H21,">=3") -> 5 | J21: =I21/COUNT(C21:H21) -> 0.83333333 | K21: =IF(J21>=0.78,"保留","刪除或改寫") -> 保留
B23: S-CVI/Ave（全部 18 題） | J23: =AVERAGE(J4:J21) -> 0.91666667
B24: S-CVI/Ave（刪除 I-CVI < .78 後） | J24: =AVERAGEIF(J4:J21,">=0.78") -> 0.95833333
B25: 保留題數 | J25: =COUNTIF(J4:J21,">=0.78") -> 16

Sheet 5_樣本A
A1: ID | B1: V1 | C1: V2 | D1: V3 | E1: V4 | F1: V6 | G1: G1 | H1: G2 | I1: G3 | J1: G4 | K1: G5 | L1: C1 | M1: C2 | N1: C3 | O1: C4 | P1: C5 | Q1: C6 | R1: 總分 | S1: 組別 | T1: 總分−V1 | U1: 總分−V2 | V1: 總分−V3 | W1: 總分−V4 | X1: 總分−V6 | Y1: 總分−G1 | Z1: 總分−G2 | AA1: 總分−G3 | AB1: 總分−G4 | AC1: 總分−G5 | AD1: 總分−C1 | AE1: 總分−C2 | AF1: 總分−C3 | AG1: 總分−C4 | AH1: 總分−C5 | AI1: 總分−C6
A2: A001 | B2: 3 | C2: 4 | D2: 3 | E2: 4 | F2: 5 | G2: 4 | H2: 4 | I2: 4 | J2: 4 | K2: 4 | L2: 5 | M2: 4 | N2: 4 | O2: 5 | P2: 3 | Q2: 4 | R2: =SUM(B2:Q2) -> 64 | S2: =IF(R2>=5_項目分析!$B$6,"高",IF(R2<=5_項目分析!$B$5,"低","")) | T2: =R2-B2 -> 61 | U2: =R2-C2 -> 60 | V2: =R2-D2 -> 61 | W2: =R2-E2 -> 60 | X2: =R2-F2 -> 59 | Y2: =R2-G2 -> 60 | Z2: =R2-H2 -> 60 | AA2: =R2-I2 -> 60 | AB2: =R2-J2 -> 60 | AC2: =R2-K2 -> 60 | AD2: =R2-L2 -> 59 | AE2: =R2-M2 -> 60 | AF2: =R2-N2 -> 60 | AG2: =R2-O2 -> 59 | AH2: =R2-P2 -> 61 | AI2: =R2-Q2 -> 60
A3: A002 | B3: 3 | C3: 2 | D3: 4 | E3: 3 | F3: 4 | G3: 4 | H3: 3 | I3: 3 | J3: 2 | K3: 3 | L3: 3 | M3: 3 | N3: 4 | O3: 4 | P3: 3 | Q3: 5 | R3: =SUM(B3:Q3) -> 53 | S3: =IF(R3>=5_項目分析!$B$6,"高",IF(R3<=5_項目分析!$B$5,"低","")) -> 低 | T3: =R3-B3 -> 50 | U3: =R3-C3 -> 51 | V3: =R3-D3 -> 49 | W3: =R3-E3 -> 50 | X3: =R3-F3 -> 49 | Y3: =R3-G3 -> 49 | Z3: =R3-H3 -> 50 | AA3: =R3-I3 -> 50 | AB3: =R3-J3 -> 51 | AC3: =R3-K3 -> 50 | AD3: =R3-L3 -> 50 | AE3: =R3-M3 -> 50 | AF3: =R3-N3 -> 49 | AG3: =R3-O3 -> 49 | AH3: =R3-P3 -> 50 | AI3: =R3-Q3 -> 48
A4: A003 | B4: 3 | C4: 4 | D4: 4 | E4: 4 | F4: 4 | G4: 4 | H4: 2 | I4: 3 | J4: 3 | K4: 4 | L4: 2 | M4: 3 | N4: 4 | O4: 2 | P4: 4 | Q4: 5 | R4: =SUM(B4:Q4) -> 55 | S4: =IF(R4>=5_項目分析!$B$6,"高",IF(R4<=5_項目分析!$B$5,"低","")) -> 低 | T4: =R4-B4 -> 52 | U4: =R4-C4 -> 51 | V4: =R4-D4 -> 51 | W4: =R4-E4 -> 51 | X4: =R4-F4 -> 51 | Y4: =R4-G4 -> 51 | Z4: =R4-H4 -> 53 | AA4: =R4-I4 -> 52 | AB4: =R4-J4 -> 52 | AC4: =R4-K4 -> 51 | AD4: =R4-L4 -> 53 | AE4: =R4-M4 -> 52 | AF4: =R4-N4 -> 51 | AG4: =R4-O4 -> 53 | AH4: =R4-P4 -> 51 | AI4: =R4-Q4 -> 50
A5: A004 | B5: 4 | C5: 4 | D5: 4 | E5: 3 | F5: 4 | G5: 4 | H5: 4 | I5: 4 | J5: 4 | K5: 4 | L5: 5 | M5: 5 | N5: 5 | O5: 3 | P5: 4 | Q5: 5 | R5: =SUM(B5:Q5) -> 66 | S5: =IF(R5>=5_項目分析!$B$6,"高",IF(R5<=5_項目分析!$B$5,"低","")) -> 高 | T5: =R5-B5 -> 62 | U5: =R5-C5 -> 62 | V5: =R5-D5 -> 62 | W5: =R5-E5 -> 63 | X5: =R5-F5 -> 62 | Y5: =R5-G5 -> 62 | Z5: =R5-H5 -> 62 | AA5: =R5-I5 -> 62 | AB5: =R5-J5 -> 62 | AC5: =R5-K5 -> 62 | AD5: =R5-L5 -> 61 | AE5: =R5-M5 -> 61 | AF5: =R5-N5 -> 61 | AG5: =R5-O5 -> 63 | AH5: =R5-P5 -> 62 | AI5: =R5-Q5 -> 61
A6: A005 | B6: 3 | C6: 4 | D6: 4 | E6: 3 | F6: 5 | G6: 4 | H6: 4 | I6: 4 | J6: 4 | K6: 5 | L6: 4 | M6: 4 | N6: 5 | O6: 5 | P6: 5 | Q6: 5 | R6: =SUM(B6:Q6) -> 68 | S6: =IF(R6>=5_項目分析!$B$6,"高",IF(R6<=5_項目分析!$B$5,"低","")) -> 高 | T6: =R6-B6 -> 65 | U6: =R6-C6 -> 64 | V6: =R6-D6 -> 64 | W6: =R6-E6 -> 65 | X6: =R6-F6 -> 63 | Y6: =R6-G6 -> 64 | Z6: =R6-H6 -> 64 | AA6: =R6-I6 -> 64 | AB6: =R6-J6 -> 64 | AC6: =R6-K6 -> 63 | AD6: =R6-L6 -> 64 | AE6: =R6-M6 -> 64 | AF6: =R6-N6 -> 63 | AG6: =R6-O6 -> 63 | AH6: =R6-P6 -> 63 | AI6: =R6-Q6 -> 63
A7: A006 | B7: 5 | C7: 4 | D7: 3 | E7: 4 | F7: 4 | G7: 5 | H7: 5 | I7: 5 | J7: 3 | K7: 4 | L7: 4 | M7: 4 | N7: 4 | O7: 5 | P7: 5 | Q7: 5 | R7: =SUM(B7:Q7) -> 69 | S7: =IF(R7>=5_項目分析!$B$6,"高",IF(R7<=5_項目分析!$B$5,"低","")) -> 高 | T7: =R7-B7 -> 64 | U7: =R7-C7 -> 65 | V7: =R7-D7 -> 66 | W7: =R7-E7 -> 65 | X7: =R7-F7 -> 65 | Y7: =R7-G7 -> 64 | Z7: =R7-H7 -> 64 | AA7: =R7-I7 -> 64 | AB7: =R7-J7 -> 66 | AC7: =R7-K7 -> 65 | AD7: =R7-L7 -> 65 | AE7: =R7-M7 -> 65 | AF7: =R7-N7 -> 65 | AG7: =R7-O7 -> 64 | AH7: =R7-P7 -> 64 | AI7: =R7-Q7 -> 64
A8: A007 | B8: 3 | C8: 3 | D8: 4 | E8: 4 | F8: 4 | G8: 4 | H8: 4 | I8: 4 | J8: 5 | K8: 5 | L8: 4 | M8: 4 | N8: 3 | O8: 4 | P8: 2 | Q8: 4 | R8: =SUM(B8:Q8) -> 61 | S8: =IF(R8>=5_項目分析!$B$6,"高",IF(R8<=5_項目分析!$B$5,"低","")) | T8: =R8-B8 -> 58 | U8: =R8-C8 -> 58 | V8: =R8-D8 -> 57 | W8: =R8-E8 -> 57 | X8: =R8-F8 -> 57 | Y8: =R8-G8 -> 57 | Z8: =R8-H8 -> 57 | AA8: =R8-I8 -> 57 | AB8: =R8-J8 -> 56 | AC8: =R8-K8 -> 56 | AD8: =R8-L8 -> 57 | AE8: =R8-M8 -> 57 | AF8: =R8-N8 -> 58 | AG8: =R8-O8 -> 57 | AH8: =R8-P8 -> 59 | AI8: =R8-Q8 -> 57
A9: A008 | B9: 3 | C9: 4 | D9: 5 | E9: 5 | F9: 5 | G9: 4 | H9: 4 | I9: 4 | J9: 2 | K9: 4 | L9: 4 | M9: 4 | N9: 5 | O9: 5 | P9: 5 | Q9: 5 | R9: =SUM(B9:Q9) -> 68 | S9: =IF(R9>=5_項目分析!$B$6,"高",IF(R9<=5_項目分析!$B$5,"低","")) -> 高 | T9: =R9-B9 -> 65 | U9: =R9-C9 -> 64 | V9: =R9-D9 -> 63 | W9: =R9-E9 -> 63 | X9: =R9-F9 -> 63 | Y9: =R9-G9 -> 64 | Z9: =R9-H9 -> 64 | AA9: =R9-I9 -> 64 | AB9: =R9-J9 -> 66 | AC9: =R9-K9 -> 64 | AD9: =R9-L9 -> 64 | AE9: =R9-M9 -> 64 | AF9: =R9-N9 -> 63 | AG9: =R9-O9 -> 63 | AH9: =R9-P9 -> 63 | AI9: =R9-Q9 -> 63
A10: A009 | B10: 4 | C10: 3 | D10: 3 | E10: 3 | F10: 4 | G10: 3 | H10: 2 | I10: 2 | J10: 2 | K10: 3 | L10: 4 | M10: 5 | N10: 4 | O10: 5 | P10: 5 | Q10: 5 | R10: =SUM(B10:Q10) -> 57 | S10: =IF(R10>=5_項目分析!$B$6,"高",IF(R10<=5_項目分析!$B$5,"低","")) | T10: =R10-B10 -> 53 | U10: =R10-C10 -> 54 | V10: =R10-D10 -> 54 | W10: =R10-E10 -> 54 | X10: =R10-F10 -> 53 | Y10: =R10-G10 -> 54 | Z10: =R10-H10 -> 55 | AA10: =R10-I10 -> 55 | AB10: =R10-J10 -> 55 | AC10: =R10-K10 -> 54 | AD10: =R10-L10 -> 53 | AE10: =R10-M10 -> 52 | AF10: =R10-N10 -> 53 | AG10: =R10-O10 -> 52 | AH10: =R10-P10 -> 52 | AI10: =R10-Q10 -> 52
A11: A010 | B11: 3 | C11: 4 | D11: 3 | E11: 4 | F11: 3 | G11: 4 | H11: 3 | I11: 3 | J11: 5 | K11: 2 | L11: 3 | M11: 3 | N11: 3 | O11: 3 | P11: 4 | Q11: 5 | R11: =SUM(B11:Q11) -> 55 | S11: =IF(R11>=5_項目分析!$B$6,"高",IF(R11<=5_項目分析!$B$5,"低","")) -> 低 | T11: =R11-B11 -> 52 | U11: =R11-C11 -> 51 | V11: =R11-D11 -> 52 | W11: =R11-E11 -> 51 | X11: =R11-F11 -> 52 | Y11: =R11-G11 -> 51 | Z11: =R11-H11 -> 52 | AA11: =R11-I11 -> 52 | AB11: =R11-J11 -> 50 | AC11: =R11-K11 -> 53 | AD11: =R11-L11 -> 52 | AE11: =R11-M11 -> 52 | AF11: =R11-N11 -> 52 | AG11: =R11-O11 -> 52 | AH11: =R11-P11 -> 51 | AI11: =R11-Q11 -> 50
A12: A011 | B12: 4 | C12: 4 | D12: 4 | E12: 4 | F12: 5 | G12: 3 | H12: 3 | I12: 3 | J12: 3 | K12: 2 | L12: 5 | M12: 5 | N12: 5 | O12: 4 | P12: 5 | Q12: 4 | R12: =SUM(B12:Q12) -> 63 | S12: =IF(R12>=5_項目分析!$B$6,"高",IF(R12<=5_項目分析!$B$5,"低","")) | T12: =R12-B12 -> 59 | U12: =R12-C12 -> 59 | V12: =R12-D12 -> 59 | W12: =R12-E12 -> 59 | X12: =R12-F12 -> 58 | Y12: =R12-G12 -> 60 | Z12: =R12-H12 -> 60 | AA12: =R12-I12 -> 60 | AB12: =R12-J12 -> 60 | AC12: =R12-K12 -> 61 | AD12: =R12-L12 -> 58 | AE12: =R12-M12 -> 58 | AF12: =R12-N12 -> 58 | AG12: =R12-O12 -> 59 | AH12: =R12-P12 -> 58 | AI12: =R12-Q12 -> 59
A13: A012 | B13: 4 | C13: 5 | D13: 5 | E13: 5 | F13: 4 | G13: 3 | H13: 3 | I13: 3 | J13: 4 | K13: 3 | L13: 5 | M13: 3 | N13: 5 | O13: 3 | P13: 5 | Q13: 5 | R13: =SUM(B13:Q13) -> 65 | S13: =IF(R13>=5_項目分析!$B$6,"高",IF(R13<=5_項目分析!$B$5,"低","")) -> 高 | T13: =R13-B13 -> 61 | U13: =R13-C13 -> 60 | V13: =R13-D13 -> 60 | W13: =R13-E13 -> 60 | X13: =R13-F13 -> 61 | Y13: =R13-G13 -> 62 | Z13: =R13-H13 -> 62 | AA13: =R13-I13 -> 62 | AB13: =R13-J13 -> 61 | AC13: =R13-K13 -> 62 | AD13: =R13-L13 -> 60 | AE13: =R13-M13 -> 62 | AF13: =R13-N13 -> 60 | AG13: =R13-O13 -> 62 | AH13: =R13-P13 -> 60 | AI13: =R13-Q13 -> 60
... A241: A240 | B241: 3 | C241: 3 | D241: 4 | E241: 3 | F241: 3 | G241: 3 | H241: 4 | I241: 3 | J241: 4 | K241: 3 | L241: 4 | M241: 5 | N241: 4 | O241: 5 | P241: 3 | Q241: 5 | R241: =SUM(B241:Q241) -> 59 | S241: =IF(R241>=5_項目分析!$B$6,"高",IF(R241<=5_項目分析!$B$5,"低","")) | T241: =R241-B241 -> 56 | U241: =R241-C241 -> 56 | V241: =R241-D241 -> 55 | W241: =R241-E241 -> 56 | X241: =R241-F241 -> 56 | Y241: =R241-G241 -> 56 | Z241: =R241-H241 -> 55 | AA241: =R241-I241 -> 56 | AB241: =R241-J241 -> 55 | AC241: =R241-K241 -> 56 | AD241: =R241-L241 -> 55 | AE241: =R241-M241 -> 54 | AF241: =R241-N241 -> 55 | AG241: =R241-O241 -> 54 | AH241: =R241-P241 -> 56 | AI241: =R241-Q241 -> 54

Sheet 5_項目分析
A1: 第⑤關 項目分析：四把尺（全部公式，資料來自「5_樣本A」）
A3: 有效樣本數 n | B3: =COUNT(5_樣本A!$R$2:$R$241) -> 240
A4: 每組人數 = n × 27%（四捨五入） | B4: =ROUND(B3*0.27,0) -> 65
A5: 低分組切點（第 g 低的總分，含同分者） | B5: =SMALL(5_樣本A!$R$2:$R$241,B4) -> 56
A6: 高分組切點（第 g 高的總分，含同分者） | B6: =LARGE(5_樣本A!$R$2:$R$241,B4) -> 65
A7: 題數 k | B7: 16
A8: 整體 Cronbach’s α | B8: =B7/(B7-1)*(1-SUM(E13:E28)/VAR(5_樣本A!$R$2:$R$241)) -> 0.82716028
A12: 題號 | B12: 題目 | C12: 平均數 | D12: 標準差 | E12: 變異數 | F12: 高組人數 | G12: 低組人數 | H12: 高組平均 | I12: 低組平均 | J12: 高組變異數 | K12: 低組變異數 | L12: 決斷值 t | M12: 校正題總相關 | N12: 刪題後 α | O12: 尺1 描述 | P12: 尺2 決斷值 | Q12: 尺3 題總相關 | R12: 尺4 刪題後α | S12: 不合格數 | T12: 決策
A13: V1 | B13: 我覺得我的護理工作對病人很重要 | C13: =AVERAGE(5_樣本A!B$2:B$241) -> 3.6708333 | D13: =STDEV(5_樣本A!B$2:B$241) -> 0.98735909 | E13: =VAR(5_樣本A!B$2:B$241) -> 0.97487796 | F13: =COUNTIF(5_樣本A!$S$2:$S$241,"高") -> 67 | G13: =COUNTIF(5_樣本A!$S$2:$S$241,"低") -> 72 | H13: =AVERAGEIF(5_樣本A!$S$2:$S$241,"高",5_樣本A!B$2:B$241) -> 4.3283582 | I13: =AVERAGEIF(5_樣本A!$S$2:$S$241,"低",5_樣本A!B$2:B$241) -> 3 | J13: =SUMPRODUCT((5_樣本A!$S$2:$S$241="高")*(5_樣本A!B$2:B$241-H13)^2)/(F13-1) -> 0.46630484 | K13: =SUMPRODUCT((5_樣本A!$S$2:$S$241="低")*(5_樣本A!B$2:B$241-I13)^2)/(G13-1) -> 0.81690141 | L13: =(H13-I13)/SQRT(J13/F13+K13/G13) -> 9.8179972 | M13: =CORREL(5_樣本A!B$2:B$241,5_樣本A!T$2:T$241) -> 0.50241856 | N13: =($B$7-1)/($B$7-2)*(1-(SUM($E$13:$E$28)-E13)/VAR(5_樣本A!T$2:T$241)) -> 0.81332941 | O13: =IF(OR(C13>=4.5,C13<=1.5,D13<0.7),1,0) -> 0 | P13: =IF(L13<3,1,0) -> 0 | Q13: =IF(M13<0.3,1,0) -> 0 | R13: =IF(N13>$B$8,1,0) -> 0 | S13: =SUM(O13:R13) -> 0 | T13: =IF(S13>=2,"刪除","保留") -> 保留
A14: V2 | B14: 我的照護能讓病人的狀況變好 | C14: =AVERAGE(5_樣本A!C$2:C$241) -> 3.6208333 | D14: =STDEV(5_樣本A!C$2:C$241) -> 1.0155606 | E14: =VAR(5_樣本A!C$2:C$241) -> 1.0313633 | F14: =COUNTIF(5_樣本A!$S$2:$S$241,"高") -> 67 | G14: =COUNTIF(5_樣本A!$S$2:$S$241,"低") -> 72 | H14: =AVERAGEIF(5_樣本A!$S$2:$S$241,"高",5_樣本A!C$2:C$241) -> 4.358209 | I14: =AVERAGEIF(5_樣本A!$S$2:$S$241,"低",5_樣本A!C$2:C$241) -> 2.875 | J14: =SUMPRODUCT((5_樣本A!$S$2:$S$241="高")*(5_樣本A!C$2:C$241-H14)^2)/(F14-1) -> 0.41519674 | K14: =SUMPRODUCT((5_樣本A!$S$2:$S$241="低")*(5_樣本A!C$2:C$241-I14)^2)/(G14-1) -> 0.75880282 | L14: =(H14-I14)/SQRT(J14/F14+K14/G14) -> 11.465101 | M14: =CORREL(5_樣本A!C$2:C$241,5_樣本A!U$2:U$241) -> 0.53523528 | N14: =($B$7-1)/($B$7-2)*(1-(SUM($E$13:$E$28)-E14)/VAR(5_樣本A!U$2:U$241)) -> 0.81104098 | O14: =IF(OR(C14>=4.5,C14<=1.5,D14<0.7),1,0) -> 0 | P14: =IF(L14<3,1,0) -> 0 | Q14: =IF(M14<0.3,1,0) -> 0 | R14: =IF(N14>$B$8,1,0) -> 0 | S14: =SUM(O14:R14) -> 0 | T14: =IF(S14>=2,"刪除","保留") -> 保留
A15: V3 | B15: 我能從工作中看到自己的價值 | C15: =AVERAGE(5_樣本A!D$2:D$241) -> 3.7125 | D15: =STDEV(5_樣本A!D$2:D$241) -> 0.92198281 | E15: =VAR(5_樣本A!D$2:D$241) -> 0.8500523 | F15: =COUNTIF(5_樣本A!$S$2:$S$241,"高") -> 67 | G15: =COUNTIF(5_樣本A!$S$2:$S$241,"低") -> 72 | H15: =AVERAGEIF(5_樣本A!$S$2:$S$241,"高",5_樣本A!D$2:D$241) -> 4.3432836 | I15: =AVERAGEIF(5_樣本A!$S$2:$S$241,"低",5_樣本A!D$2:D$241) -> 3.1666667 | J15: =SUMPRODUCT((5_樣本A!$S$2:$S$241="高")*(5_樣本A!D$2:D$241-H15)^2)/(F15-1) -> 0.47127996 | K15: =SUMPRODUCT((5_樣本A!$S$2:$S$241="低")*(5_樣本A!D$2:D$241-I15)^2)/(G15-1) -> 0.81690141 | L15: =(H15-I15)/SQRT(J15/F15+K15/G15) -> 8.6788808 | M15: =CORREL(5_樣本A!D$2:D$241,5_樣本A!V$2:V$241) -> 0.49511939 | N15: =($B$7-1)/($B$7-2)*(1-(SUM($E$13:$E$28)-E15)/VAR(5_樣本A!V$2:V$241)) -> 0.81399617 | O15: =IF(OR(C15>=4.5,C15<=1.5,D15<0.7),1,0) -> 0 | P15: =IF(L15<3,1,0) -> 0 | Q15: =IF(M15<0.3,1,0) -> 0 | R15: =IF(N15>$B$8,1,0) -> 0 | S15: =SUM(O15:R15) -> 0 | T15: =IF(S15>=2,"刪除","保留") -> 保留
A16: V4 | B16: 照顧病人讓我覺得這份工作值得 | C16: =AVERAGE(5_樣本A!E$2:E$241) -> 3.6958333 | D16: =STDEV(5_樣本A!E$2:E$241) -> 0.95241563 | E16: =VAR(5_樣本A!E$2:E$241) -> 0.90709554 | F16: =COUNTIF(5_樣本A!$S$2:$S$241,"高") -> 67 | G16: =COUNTIF(5_樣本A!$S$2:$S$241,"低") -> 72 | H16: =AVERAGEIF(5_樣本A!$S$2:$S$241,"高",5_樣本A!E$2:E$241) -> 4.2985075 | I16: =AVERAGEIF(5_樣本A!$S$2:$S$241,"低",5_樣本A!E$2:E$241) -> 3 | J16: =SUMPRODUCT((5_樣本A!$S$2:$S$241="高")*(5_樣本A!E$2:E$241-H16)^2)/(F16-1) -> 0.54590683 | K16: =SUMPRODUCT((5_樣本A!$S$2:$S$241="低")*(5_樣本A!E$2:E$241-I16)^2)/(G16-1) -> 0.81690141 | L16: =(H16-I16)/SQRT(J16/F16+K16/G16) -> 9.3003037 | M16: =CORREL(5_樣本A!E$2:E$241,5_樣本A!W$2:W$241) -> 0.5043714 | N16: =($B$7-1)/($B$7-2)*(1-(SUM($E$13:$E$28)-E16)/VAR(5_樣本A!W$2:W$241)) -> 0.81330151 | O16: =IF(OR(C16>=4.5,C16<=1.5,D16<0.7),1,0) -> 0 | P16: =IF(L16<3,1,0) -> 0 | Q16: =IF(M16<0.3,1,0) -> 0 | R16: =IF(N16>$B$8,1,0) -> 0 | S16: =SUM(O16:R16) -> 0 | T16: =IF(S16>=2,"刪除","保留") -> 保留
A17: V6 | B17: 和同事一起幫助病人，讓我覺得工作有價值 | C17: =AVERAGE(5_樣本A!F$2:F$241) -> 3.7333333 | D17: =STDEV(5_樣本A!F$2:F$241) -> 0.87487796 | E17: =VAR(5_樣本A!F$2:F$241) -> 0.76541144 | F17: =COUNTIF(5_樣本A!$S$2:$S$241,"高") -> 67 | G17: =COUNTIF(5_樣本A!$S$2:$S$241,"低") -> 72 | H17: =AVERAGEIF(5_樣本A!$S$2:$S$241,"高",5_樣本A!F$2:F$241) -> 4.4179104 | I17: =AVERAGEIF(5_樣本A!$S$2:$S$241,"低",5_樣本A!F$2:F$241) -> 3.0972222 | J17: =SUMPRODUCT((5_樣本A!$S$2:$S$241="高")*(5_樣本A!F$2:F$241-H17)^2)/(F17-1) -> 0.3681592 | K17: =SUMPRODUCT((5_樣本A!$S$2:$S$241="低")*(5_樣本A!F$2:F$241-I17)^2)/(G17-1) -> 0.70872457 | L17: =(H17-I17)/SQRT(J17/F17+K17/G17) -> 10.663789 | M17: =CORREL(5_樣本A!F$2:F$241,5_樣本A!X$2:X$241) -> 0.60563332 | N17: =($B$7-1)/($B$7-2)*(1-(SUM($E$13:$E$28)-E17)/VAR(5_樣本A!X$2:X$241)) -> 0.807698 | O17: =IF(OR(C17>=4.5,C17<=1.5,D17<0.7),1,0) -> 0 | P17: =IF(L17<3,1,0) -> 0 | Q17: =IF(M17<0.3,1,0) -> 0 | R17: =IF(N17>$B$8,1,0) -> 0 | S17: =SUM(O17:R17) -> 0 | T17: =IF(S17>=2,"刪除","保留") -> 保留
A18: G1 | B18: 我在工作中持續學到新的專業知識 | C18: =AVERAGE(5_樣本A!G$2:G$241) -> 3.6958333 | D18: =STDEV(5_樣本A!G$2:G$241) -> 0.96550512 | E18: =VAR(5_樣本A!G$2:G$241) -> 0.93220014 | F18: =COUNTIF(5_樣本A!$S$2:$S$241,"高") -> 67 | G18: =COUNTIF(5_樣本A!$S$2:$S$241,"低") -> 72 | H18: =AVERAGEIF(5_樣本A!$S$2:$S$241,"高",5_樣本A!G$2:G$241) -> 4.2089552 | I18: =AVERAGEIF(5_樣本A!$S$2:$S$241,"低",5_樣本A!G$2:G$241) -> 3.1111111 | J18: =SUMPRODUCT((5_樣本A!$S$2:$S$241="高")*(5_樣本A!G$2:G$241-H18)^2)/(F18-1) -> 0.5920398 | K18: =SUMPRODUCT((5_樣本A!$S$2:$S$241="低")*(5_樣本A!G$2:G$241-I18)^2)/(G18-1) -> 1.0015649 | L18: =(H18-I18)/SQRT(J18/F18+K18/G18) -> 7.2791093 | M18: =CORREL(5_樣本A!G$2:G$241,5_樣本A!Y$2:Y$241) -> 0.44366551 | N18: =($B$7-1)/($B$7-2)*(1-(SUM($E$13:$E$28)-E18)/VAR(5_樣本A!Y$2:Y$241)) -> 0.8171563 | O18: =IF(OR(C18>=4.5,C18<=1.5,D18<0.7),1,0) -> 0 | P18: =IF(L18<3,1,0) -> 0 | Q18: =IF(M18<0.3,1,0) -> 0 | R18: =IF(N18>$B$8,1,0) -> 0 | S18: =SUM(O18:R18) -> 0 | T18: =IF(S18>=2,"刪除","保留") -> 保留
A19: G2 | B19: 我的臨床判斷能力越來越好 | C19: =AVERAGE(5_樣本A!H$2:H$241) -> 3.65 | D19: =STDEV(5_樣本A!H$2:H$241) -> 0.88832502 | E19: =VAR(5_樣本A!H$2:H$241) -> 0.78912134 | F19: =COUNTIF(5_樣本A!$S$2:$S$241,"高") -> 67 | G19: =COUNTIF(5_樣本A!$S$2:$S$241,"低") -> 72 | H19: =AVERAGEIF(5_樣本A!$S$2:$S$241,"高",5_樣本A!H$2:H$241) -> 4.1492537 | I19: =AVERAGEIF(5_樣本A!$S$2:$S$241,"低",5_樣本A!H$2:H$241) -> 3.125 | J19: =SUMPRODUCT((5_樣本A!$S$2:$S$241="高")*(5_樣本A!H$2:H$241-H19)^2)/(F19-1) -> 0.49253731 | K19: =SUMPRODUCT((5_樣本A!$S$2:$S$241="低")*(5_樣本A!H$2:H$241-I19)^2)/(G19-1) -> 0.70246479 | L19: =(H19-I19)/SQRT(J19/F19+K19/G19) -> 7.8308877 | M19: =CORREL(5_樣本A!H$2:H$241,5_樣本A!Z$2:Z$241) -> 0.44698991 | N19: =($B$7-1)/($B$7-2)*(1-(SUM($E$13:$E$28)-E19)/VAR(5_樣本A!Z$2:Z$241)) -> 0.81698784 | O19: =IF(OR(C19>=4.5,C19<=1.5,D19<0.7),1,0) -> 0 | P19: =IF(L19<3,1,0) -> 0 | Q19: =IF(M19<0.3,1,0) -> 0 | R19: =IF(N19>$B$8,1,0) -> 0 | S19: =SUM(O19:R19) -> 0 | T19: =IF(S19>=2,"刪除","保留") -> 保留
A20: G3 | B20: 工作中的挑戰讓我成長 | C20: =AVERAGE(5_樣本A!I$2:I$241) -> 3.6666667 | D20: =STDEV(5_樣本A!I$2:I$241) -> 0.94919771 | E20: =VAR(5_樣本A!I$2:I$241) -> 0.90097629 | F20: =COUNTIF(5_樣本A!$S$2:$S$241,"高") -> 67 | G20: =COUNTIF(5_樣本A!$S$2:$S$241,"低") -> 72 | H20: =AVERAGEIF(5_樣本A!$S$2:$S$241,"高",5_樣本A!I$2:I$241) -> 4.238806 | I20: =AVERAGEIF(5_樣本A!$S$2:$S$241,"低",5_樣本A!I$2:I$241) -> 2.9583333 | J20: =SUMPRODUCT((5_樣本A!$S$2:$S$241="高")*(5_樣本A!I$2:I$241-H20)^2)/(F20-1) -> 0.45725916 | K20: =SUMPRODUCT((5_樣本A!$S$2:$S$241="低")*(5_樣本A!I$2:I$241-I20)^2)/(G20-1) -> 0.80105634 | L20: =(H20-I20)/SQRT(J20/F20+K20/G20) -> 9.5572175 | M20: =CORREL(5_樣本A!I$2:I$241,5_樣本A!AA$2:AA$241) -> 0.46433823 | N20: =($B$7-1)/($B$7-2)*(1-(SUM($E$13:$E$28)-E20)/VAR(5_樣本A!AA$2:AA$241)) -> 0.81584575 | O20: =IF(OR(C20>=4.5,C20<=1.5,D20<0.7),1,0) -> 0 | P20: =IF(L20<3,1,0) -> 0 | Q20: =IF(M20<0.3,1,0) -> 0 | R20: =IF(N20>$B$8,1,0) -> 0 | S20: =SUM(O20:R20) -> 0 | T20: =IF(S20>=2,"刪除","保留") -> 保留
A21: G4 | B21: 我會主動參加院內外的進修課程 | C21: =AVERAGE(5_樣本A!J$2:J$241) -> 3.3791667 | D21: =STDEV(5_樣本A!J$2:J$241) -> 1.0155606 | E21: =VAR(5_樣本A!J$2:J$241) -> 1.0313633 | F21: =COUNTIF(5_樣本A!$S$2:$S$241,"高") -> 67 | G21: =COUNTIF(5_樣本A!$S$2:$S$241,"低") -> 72 | H21: =AVERAGEIF(5_樣本A!$S$2:$S$241,"高",5_樣本A!J$2:J$241) -> 3.641791 | I21: =AVERAGEIF(5_樣本A!$S$2:$S$241,"低",5_樣本A!J$2:J$241) -> 2.9861111 | J21: =SUMPRODUCT((5_樣本A!$S$2:$S$241="高")*(5_樣本A!J$2:J$241-H21)^2)/(F21-1) -> 0.90004523 | K21: =SUMPRODUCT((5_樣本A!$S$2:$S$241="低")*(5_樣本A!J$2:J$241-I21)^2)/(G21-1) -> 0.91529734 | L21: =(H21-I21)/SQRT(J21/F21+K21/G21) -> 4.0549871 | M21: =CORREL(5_樣本A!J$2:J$241,5_樣本A!AB$2:AB$241) -> 0.073483695 | N21: =($B$7-1)/($B$7-2)*(1-(SUM($E$13:$E$28)-E21)/VAR(5_樣本A!AB$2:AB$241)) -> 0.84092863 | O21: =IF(OR(C21>=4.5,C21<=1.5,D21<0.7),1,0) -> 0 | P21: =IF(L21<3,1,0) -> 0 | Q21: =IF(M21<0.3,1,0) -> 1 | R21: =IF(N21>$B$8,1,0) -> 1 | S21: =SUM(O21:R21) -> 2 | T21: =IF(S21>=2,"刪除","保留") -> 刪除
A22: G5 | B22: 我覺得自己比剛入職時更有能力 | C22: =AVERAGE(5_樣本A!K$2:K$241) -> 3.6333333 | D22: =STDEV(5_樣本A!K$2:K$241) -> 0.96320015 | E22: =VAR(5_樣本A!K$2:K$241) -> 0.92775453 | F22: =COUNTIF(5_樣本A!$S$2:$S$241,"高") -> 67 | G22: =COUNTIF(5_樣本A!$S$2:$S$241,"低") -> 72 | H22: =AVERAGEIF(5_樣本A!$S$2:$S$241,"高",5_樣本A!K$2:K$241) -> 4.2238806 | I22: =AVERAGEIF(5_樣本A!$S$2:$S$241,"低",5_樣本A!K$2:K$241) -> 2.9583333 | J22: =SUMPRODUCT((5_樣本A!$S$2:$S$241="高")*(5_樣本A!K$2:K$241-H22)^2)/(F22-1) -> 0.50972411 | K22: =SUMPRODUCT((5_樣本A!$S$2:$S$241="低")*(5_樣本A!K$2:K$241-I22)^2)/(G22-1) -> 0.88556338 | L22: =(H22-I22)/SQRT(J22/F22+K22/G22) -> 8.9695785 | M22: =CORREL(5_樣本A!K$2:K$241,5_樣本A!AC$2:AC$241) -> 0.50214993 | N22: =($B$7-1)/($B$7-2)*(1-(SUM($E$13:$E$28)-E22)/VAR(5_樣本A!AC$2:AC$241)) -> 0.81340877 | O22: =IF(OR(C22>=4.5,C22<=1.5,D22<0.7),1,0) -> 0 | P22: =IF(L22<3,1,0) -> 0 | Q22: =IF(M22<0.3,1,0) -> 0 | R22: =IF(N22>$B$8,1,0) -> 0 | S22: =SUM(O22:R22) -> 0 | T22: =IF(S22>=2,"刪除","保留") -> 保留
A23: C1 | B23: 我和同事之間互相支持 | C23: =AVERAGE(5_樣本A!L$2:L$241) -> 3.7916667 | D23: =STDEV(5_樣本A!L$2:L$241) -> 0.94974855 | E23: =VAR(5_樣本A!L$2:L$241) -> 0.90202232 | F23: =COUNTIF(5_樣本A!$S$2:$S$241,"高") -> 67 | G23: =COUNTIF(5_樣本A!$S$2:$S$241,"低") -> 72 | H23: =AVERAGEIF(5_樣本A!$S$2:$S$241,"高",5_樣本A!L$2:L$241) -> 4.5522388 | I23: =AVERAGEIF(5_樣本A!$S$2:$S$241,"低",5_樣本A!L$2:L$241) -> 3.0277778 | J23: =SUMPRODUCT((5_樣本A!$S$2:$S$241="高")*(5_樣本A!L$2:L$241-H23)^2)/(F23-1) -> 0.3116237 | K23: =SUMPRODUCT((5_樣本A!$S$2:$S$241="低")*(5_樣本A!L$2:L$241-I23)^2)/(G23-1) -> 0.81611894 | L23: =(H23-I23)/SQRT(J23/F23+K23/G23) -> 12.057167 | M23: =CORREL(5_樣本A!L$2:L$241,5_樣本A!AD$2:AD$241) -> 0.58389768 | N23: =($B$7-1)/($B$7-2)*(1-(SUM($E$13:$E$28)-E23)/VAR(5_樣本A!AD$2:AD$241)) -> 0.80820456 | O23: =IF(OR(C23>=4.5,C23<=1.5,D23<0.7),1,0) -> 0 | P23: =IF(L23<3,1,0) -> 0 | Q23: =IF(M23<0.3,1,0) -> 0 | R23: =IF(N23>$B$8,1,0) -> 0 | S23: =SUM(O23:R23) -> 0 | T23: =IF(S23>=2,"刪除","保留") -> 保留
A24: C2 | B24: 遇到困難時，我知道可以找誰幫忙 | C24: =AVERAGE(5_樣本A!M$2:M$241) -> 3.75 | D24: =STDEV(5_樣本A!M$2:M$241) -> 0.87980599 | E24: =VAR(5_樣本A!M$2:M$241) -> 0.77405858 | F24: =COUNTIF(5_樣本A!$S$2:$S$241,"高") -> 67 | G24: =COUNTIF(5_樣本A!$S$2:$S$241,"低") -> 72 | H24: =AVERAGEIF(5_樣本A!$S$2:$S$241,"高",5_樣本A!M$2:M$241) -> 4.4029851 | I24: =AVERAGEIF(5_樣本A!$S$2:$S$241,"低",5_樣本A!M$2:M$241) -> 3.1388889 | J24: =SUMPRODUCT((5_樣本A!$S$2:$S$241="高")*(5_樣本A!M$2:M$241-H24)^2)/(F24-1) -> 0.3654455 | K24: =SUMPRODUCT((5_樣本A!$S$2:$S$241="低")*(5_樣本A!M$2:M$241-I24)^2)/(G24-1) -> 0.76917058 | L24: =(H24-I24)/SQRT(J24/F24+K24/G24) -> 9.9509424 | M24: =CORREL(5_樣本A!M$2:M$241,5_樣本A!AE$2:AE$241) -> 0.48455809 | N24: =($B$7-1)/($B$7-2)*(1-(SUM($E$13:$E$28)-E24)/VAR(5_樣本A!AE$2:AE$241)) -> 0.81481552 | O24: =IF(OR(C24>=4.5,C24<=1.5,D24<0.7),1,0) -> 0 | P24: =IF(L24<3,1,0) -> 0 | Q24: =IF(M24<0.3,1,0) -> 0 | R24: =IF(N24>$B$8,1,0) -> 0 | S24: =SUM(O24:R24) -> 0 | T24: =IF(S24>=2,"刪除","保留") -> 保留
A25: C3 | B25: 單位同仁會主動關心我 | C25: =AVERAGE(5_樣本A!N$2:N$241) -> 3.775 | D25: =STDEV(5_樣本A!N$2:N$241) -> 0.86747361 | E25: =VAR(5_樣本A!N$2:N$241) -> 0.75251046 | F25: =COUNTIF(5_樣本A!$S$2:$S$241,"高") -> 67 | G25: =COUNTIF(5_樣本A!$S$2:$S$241,"低") -> 72 | H25: =AVERAGEIF(5_樣本A!$S$2:$S$241,"高",5_樣本A!N$2:N$241) -> 4.3880597 | I25: =AVERAGEIF(5_樣本A!$S$2:$S$241,"低",5_樣本A!N$2:N$241) -> 3.1111111 | J25: =SUMPRODUCT((5_樣本A!$S$2:$S$241="高")*(5_樣本A!N$2:N$241-H25)^2)/(F25-1) -> 0.57440072 | K25: =SUMPRODUCT((5_樣本A!$S$2:$S$241="低")*(5_樣本A!N$2:N$241-I25)^2)/(G25-1) -> 0.46635368 | L25: =(H25-I25)/SQRT(J25/F25+K25/G25) -> 10.408811 | M25: =CORREL(5_樣本A!N$2:N$241,5_樣本A!AF$2:AF$241) -> 0.46557755 | N25: =($B$7-1)/($B$7-2)*(1-(SUM($E$13:$E$28)-E25)/VAR(5_樣本A!AF$2:AF$241)) -> 0.81596984 | O25: =IF(OR(C25>=4.5,C25<=1.5,D25<0.7),1,0) -> 0 | P25: =IF(L25<3,1,0) -> 0 | Q25: =IF(M25<0.3,1,0) -> 0 | R25: =IF(N25>$B$8,1,0) -> 0 | S25: =SUM(O25:R25) -> 0 | T25: =IF(S25>=2,"刪除","保留") -> 保留
A26: C4 | B26: 我是這個護理團隊的一份子 | C26: =AVERAGE(5_樣本A!O$2:O$241) -> 3.7791667 | D26: =STDEV(5_樣本A!O$2:O$241) -> 0.90395651 | E26: =VAR(5_樣本A!O$2:O$241) -> 0.81713738 | F26: =COUNTIF(5_樣本A!$S$2:$S$241,"高") -> 67 | G26: =COUNTIF(5_樣本A!$S$2:$S$241,"低") -> 72 | H26: =AVERAGEIF(5_樣本A!$S$2:$S$241,"高",5_樣本A!O$2:O$241) -> 4.4925373 | I26: =AVERAGEIF(5_樣本A!$S$2:$S$241,"低",5_樣本A!O$2:O$241) -> 3.1388889 | J26: =SUMPRODUCT((5_樣本A!$S$2:$S$241="高")*(5_樣本A!O$2:O$241-H26)^2)/(F26-1) -> 0.40524649 | K26: =SUMPRODUCT((5_樣本A!$S$2:$S$241="低")*(5_樣本A!O$2:O$241-I26)^2)/(G26-1) -> 0.76917058 | L26: =(H26-I26)/SQRT(J26/F26+K26/G26) -> 10.465019 | M26: =CORREL(5_樣本A!O$2:O$241,5_樣本A!AG$2:AG$241) -> 0.53186252 | N26: =($B$7-1)/($B$7-2)*(1-(SUM($E$13:$E$28)-E26)/VAR(5_樣本A!AG$2:AG$241)) -> 0.81184807 | O26: =IF(OR(C26>=4.5,C26<=1.5,D26<0.7),1,0) -> 0 | P26: =IF(L26<3,1,0) -> 0 | Q26: =IF(M26<0.3,1,0) -> 0 | R26: =IF(N26>$B$8,1,0) -> 0 | S26: =SUM(O26:R26) -> 0 | T26: =IF(S26>=2,"刪除","保留") -> 保留
A27: C5 | B27: 我和其他職類（醫師、藥師）合作順利 | C27: =AVERAGE(5_樣本A!P$2:P$241) -> 3.6708333 | D27: =STDEV(5_樣本A!P$2:P$241) -> 0.94845356 | E27: =VAR(5_樣本A!P$2:P$241) -> 0.89956416 | F27: =COUNTIF(5_樣本A!$S$2:$S$241,"高") -> 67 | G27: =COUNTIF(5_樣本A!$S$2:$S$241,"低") -> 72 | H27: =AVERAGEIF(5_樣本A!$S$2:$S$241,"高",5_樣本A!P$2:P$241) -> 4.2089552 | I27: =AVERAGEIF(5_樣本A!$S$2:$S$241,"低",5_樣本A!P$2:P$241) -> 3.3055556 | J27: =SUMPRODUCT((5_樣本A!$S$2:$S$241="高")*(5_樣本A!P$2:P$241-H27)^2)/(F27-1) -> 0.50113071 | K27: =SUMPRODUCT((5_樣本A!$S$2:$S$241="低")*(5_樣本A!P$2:P$241-I27)^2)/(G27-1) -> 0.77856025 | L27: =(H27-I27)/SQRT(J27/F27+K27/G27) -> 6.6794184 | M27: =CORREL(5_樣本A!P$2:P$241,5_樣本A!AH$2:AH$241) -> 0.25665122 | N27: =($B$7-1)/($B$7-2)*(1-(SUM($E$13:$E$28)-E27)/VAR(5_樣本A!AH$2:AH$241)) -> 0.82859181 | O27: =IF(OR(C27>=4.5,C27<=1.5,D27<0.7),1,0) -> 0 | P27: =IF(L27<3,1,0) -> 0 | Q27: =IF(M27<0.3,1,0) -> 1 | R27: =IF(N27>$B$8,1,0) -> 1 | S27: =SUM(O27:R27) -> 2 | T27: =IF(S27>=2,"刪除","保留") -> 刪除
A28: C6 | B28: 我認識單位裡的每一位同事 | C28: =AVERAGE(5_樣本A!Q$2:Q$241) -> 4.7833333 | D28: =STDEV(5_樣本A!Q$2:Q$241) -> 0.48721449 | E28: =VAR(5_樣本A!Q$2:Q$241) -> 0.23737796 | F28: =COUNTIF(5_樣本A!$S$2:$S$241,"高") -> 67 | G28: =COUNTIF(5_樣本A!$S$2:$S$241,"低") -> 72 | H28: =AVERAGEIF(5_樣本A!$S$2:$S$241,"高",5_樣本A!Q$2:Q$241) -> 4.8059701 | I28: =AVERAGEIF(5_樣本A!$S$2:$S$241,"低",5_樣本A!Q$2:Q$241) -> 4.7777778 | J28: =SUMPRODUCT((5_樣本A!$S$2:$S$241="高")*(5_樣本A!Q$2:Q$241-H28)^2)/(F28-1) -> 0.18905473 | K28: =SUMPRODUCT((5_樣本A!$S$2:$S$241="低")*(5_樣本A!Q$2:Q$241-I28)^2)/(G28-1) -> 0.25978091 | L28: =(H28-I28)/SQRT(J28/F28+K28/G28) -> 0.35158759 | M28: =CORREL(5_樣本A!Q$2:Q$241,5_樣本A!AI$2:AI$241) -> -0.018072841 | N28: =($B$7-1)/($B$7-2)*(1-(SUM($E$13:$E$28)-E28)/VAR(5_樣本A!AI$2:AI$241)) -> 0.83468756 | O28: =IF(OR(C28>=4.5,C28<=1.5,D28<0.7),1,0) -> 1 | P28: =IF(L28<3,1,0) -> 1 | Q28: =IF(M28<0.3,1,0) -> 1 | R28: =IF(N28>$B$8,1,0) -> 1 | S28: =SUM(O28:R28) -> 4 | T28: =IF(S28>=2,"刪除","保留") -> 刪除
A30: 尺1：平均數 ≥ 4.5 或 ≤ 1.5（天花板／地板），或標準差 < .70，記 1
A31: 尺2：決斷值 t =（高組平均 − 低組平均）÷ √(高組變異數/高組人數 + 低組變異數/低組人數)；t < 3 記 1
A32: 尺3：校正題總相關＝該題與「總分扣掉該題」的相關；< .30 記 1
A33: 尺4：刪題後 α = (k−1)/(k−2) × [1 − (各題變異數總和 − 該題變異數) ÷ 刪題後總分變異數]；高於整體 α 記 1
A34: 高低組含同分者，因此兩組人數可能略多於 n × 27%

Sheet 6_EFA結果
A1: 第⑥關 EFA 結果（主軸因子法＋Promax 斜交轉軸；以樣本 A 刪除 G4、C5、C6 後之 13 題）
A2: 本表為統計軟體輸出值。用 JASP 重跑時小數點第三位可能略有差異，判斷結果相同即可。
A4: KMO | B4: 0.869
A5: Bartlett 卡方 | B5: 1281.61
A6: Bartlett 自由度 = p(p−1)/2 | B6: =13*12/2 -> 78
A7: Bartlett p 值 | B7: < .001
A9: 平行分析 | B9: 實際資料特徵值 | C9: 隨機資料平均 | D9: 隨機資料第95百分位 | E9: 實際 > 隨機95%？
A10: 第 1 個 | B10: 4.744 | C10: 1.404 | D10: 1.5 | E10: =IF(B10>D10,"保留","停止") -> 保留
A11: 第 2 個 | B11: 2.043 | C11: 1.305 | D11: 1.373 | E11: =IF(B11>D11,"保留","停止") -> 保留
A12: 第 3 個 | B12: 1.777 | C12: 1.224 | D12: 1.276 | E12: =IF(B12>D12,"保留","停止") -> 保留
A13: 第 4 個 | B13: 0.606 | C13: 1.157 | D13: 1.206 | E13: =IF(B13>D13,"保留","停止") -> 停止
A14: 第 5 個 | B14: 0.549 | C14: 1.097 | D14: 1.142 | E14: =IF(B14>D14,"保留","停止") -> 停止
A15: 第 6 個 | B15: 0.514 | C15: 1.04 | D15: 1.083 | E15: =IF(B15>D15,"保留","停止") -> 停止
A16: 建議因素數 | B16: =COUNTIF(E10:E15,"保留") -> 3
A18: 第 1 輪（13 題）樣式矩陣
A19: 題號 | B19: 題目 | C19: F1 工作價值 | D19: F2 專業成長 | E19: F3 團隊連結 | F19: 最高 | G19: 次高 | H19: 差距 | I19: 判斷
A20: V1 | B20: 我覺得我的護理工作對病人很重要 | C20: 0.837 | D20: -0.018 | E20: -0.033 | F20: =MAX(ABS(C20),ABS(D20),ABS(E20)) -> 0.837 | G20: =ABS(C20)+ABS(D20)+ABS(E20)-MAX(ABS(C20),ABS(D20),ABS(E20))-MIN(ABS(C20),ABS(D20),ABS(E20)) -> 0.033 | H20: =F20-G20 -> 0.804 | I20: =IF(F20<0.4,"主負荷<.40",IF(AND(G20>=0.3,H20<0.2),"跨負荷","OK")) -> OK
A21: V2 | B21: 我的照護能讓病人的狀況變好 | C21: 0.82 | D21: 0.001 | E21: 0.011 | F21: =MAX(ABS(C21),ABS(D21),ABS(E21)) -> 0.82 | G21: =ABS(C21)+ABS(D21)+ABS(E21)-MAX(ABS(C21),ABS(D21),ABS(E21))-MIN(ABS(C21),ABS(D21),ABS(E21)) -> 0.011 | H21: =F21-G21 -> 0.809 | I21: =IF(F21<0.4,"主負荷<.40",IF(AND(G21>=0.3,H21<0.2),"跨負荷","OK")) -> OK
A22: V3 | B22: 我能從工作中看到自己的價值 | C22: 0.855 | D22: 0.003 | E22: -0.062 | F22: =MAX(ABS(C22),ABS(D22),ABS(E22)) -> 0.855 | G22: =ABS(C22)+ABS(D22)+ABS(E22)-MAX(ABS(C22),ABS(D22),ABS(E22))-MIN(ABS(C22),ABS(D22),ABS(E22)) -> 0.062 | H22: =F22-G22 -> 0.793 | I22: =IF(F22<0.4,"主負荷<.40",IF(AND(G22>=0.3,H22<0.2),"跨負荷","OK")) -> OK
A23: V4 | B23: 照顧病人讓我覺得這份工作值得 | C23: 0.848 | D23: 0.053 | E23: -0.11 | F23: =MAX(ABS(C23),ABS(D23),ABS(E23)) -> 0.848 | G23: =ABS(C23)+ABS(D23)+ABS(E23)-MAX(ABS(C23),ABS(D23),ABS(E23))-MIN(ABS(C23),ABS(D23),ABS(E23)) -> 0.11 | H23: =F23-G23 -> 0.738 | I23: =IF(F23<0.4,"主負荷<.40",IF(AND(G23>=0.3,H23<0.2),"跨負荷","OK")) -> OK
A24: V6 | B24: 和同事一起幫助病人，讓我覺得工作有價值 | C24: 0.544 | D24: -0.062 | E24: 0.434 | F24: =MAX(ABS(C24),ABS(D24),ABS(E24)) -> 0.544 | G24: =ABS(C24)+ABS(D24)+ABS(E24)-MAX(ABS(C24),ABS(D24),ABS(E24))-MIN(ABS(C24),ABS(D24),ABS(E24)) -> 0.434 | H24: =F24-G24 -> 0.11 | I24: =IF(F24<0.4,"主負荷<.40",IF(AND(G24>=0.3,H24<0.2),"跨負荷","OK")) -> 跨負荷
A25: G1 | B25: 我在工作中持續學到新的專業知識 | C25: -0.029 | D25: 0.839 | E25: -0.029 | F25: =MAX(ABS(C25),ABS(D25),ABS(E25)) -> 0.839 | G25: =ABS(C25)+ABS(D25)+ABS(E25)-MAX(ABS(C25),ABS(D25),ABS(E25))-MIN(ABS(C25),ABS(D25),ABS(E25)) -> 0.029 | H25: =F25-G25 -> 0.81 | I25: =IF(F25<0.4,"主負荷<.40",IF(AND(G25>=0.3,H25<0.2),"跨負荷","OK")) -> OK
A26: G2 | B26: 我的臨床判斷能力越來越好 | C26: -0.053 | D26: 0.774 | E26: 0.076 | F26: =MAX(ABS(C26),ABS(D26),ABS(E26)) -> 0.774 | G26: =ABS(C26)+ABS(D26)+ABS(E26)-MAX(ABS(C26),ABS(D26),ABS(E26))-MIN(ABS(C26),ABS(D26),ABS(E26)) -> 0.076 | H26: =F26-G26 -> 0.698 | I26: =IF(F26<0.4,"主負荷<.40",IF(AND(G26>=0.3,H26<0.2),"跨負荷","OK")) -> OK
A27: G3 | B27: 工作中的挑戰讓我成長 | C27: 0.066 | D27: 0.833 | E27: -0.065 | F27: =MAX(ABS(C27),ABS(D27),ABS(E27)) -> 0.833 | G27: =ABS(C27)+ABS(D27)+ABS(E27)-MAX(ABS(C27),ABS(D27),ABS(E27))-MIN(ABS(C27),ABS(D27),ABS(E27)) -> 0.066 | H27: =F27-G27 -> 0.767 | I27: =IF(F27<0.4,"主負荷<.40",IF(AND(G27>=0.3,H27<0.2),"跨負荷","OK")) -> OK
A28: G5 | B28: 我覺得自己比剛入職時更有能力 | C28: 0.039 | D28: 0.793 | E28: 0.047 | F28: =MAX(ABS(C28),ABS(D28),ABS(E28)) -> 0.793 | G28: =ABS(C28)+ABS(D28)+ABS(E28)-MAX(ABS(C28),ABS(D28),ABS(E28))-MIN(ABS(C28),ABS(D28),ABS(E28)) -> 0.047 | H28: =F28-G28 -> 0.746 | I28: =IF(F28<0.4,"主負荷<.40",IF(AND(G28>=0.3,H28<0.2),"跨負荷","OK")) -> OK
A29: C1 | B29: 我和同事之間互相支持 | C29: 0.048 | D29: 0.061 | E29: 0.769 | F29: =MAX(ABS(C29),ABS(D29),ABS(E29)) -> 0.769 | G29: =ABS(C29)+ABS(D29)+ABS(E29)-MAX(ABS(C29),ABS(D29),ABS(E29))-MIN(ABS(C29),ABS(D29),ABS(E29)) -> 0.061 | H29: =F29-G29 -> 0.708 | I29: =IF(F29<0.4,"主負荷<.40",IF(AND(G29>=0.3,H29<0.2),"跨負荷","OK")) -> OK
A30: C2 | B30: 遇到困難時，我知道可以找誰幫忙 | C30: -0.098 | D30: 0.02 | E30: 0.829 | F30: =MAX(ABS(C30),ABS(D30),ABS(E30)) -> 0.829 | G30: =ABS(C30)+ABS(D30)+ABS(E30)-MAX(ABS(C30),ABS(D30),ABS(E30))-MIN(ABS(C30),ABS(D30),ABS(E30)) -> 0.098 | H30: =F30-G30 -> 0.731 | I30: =IF(F30<0.4,"主負荷<.40",IF(AND(G30>=0.3,H30<0.2),"跨負荷","OK")) -> OK
A31: C3 | B31: 單位同仁會主動關心我 | C31: -0.093 | D31: -0.029 | E31: 0.833 | F31: =MAX(ABS(C31),ABS(D31),ABS(E31)) -> 0.833 | G31: =ABS(C31)+ABS(D31)+ABS(E31)-MAX(ABS(C31),ABS(D31),ABS(E31))-MIN(ABS(C31),ABS(D31),ABS(E31)) -> 0.093 | H31: =F31-G31 -> 0.74 | I31: =IF(F31<0.4,"主負荷<.40",IF(AND(G31>=0.3,H31<0.2),"跨負荷","OK")) -> OK
A32: C4 | B32: 我是這個護理團隊的一份子 | C32: 0.025 | D32: -0.007 | E32: 0.765 | F32: =MAX(ABS(C32),ABS(D32),ABS(E32)) -> 0.765 | G32: =ABS(C32)+ABS(D32)+ABS(E32)-MAX(ABS(C32),ABS(D32),ABS(E32))-MIN(ABS(C32),ABS(D32),ABS(E32)) -> 0.025 | H32: =F32-G32 -> 0.74 | I32: =IF(F32<0.4,"主負荷<.40",IF(AND(G32>=0.3,H32<0.2),"跨負荷","OK")) -> OK
A33: 因素間相關
B34: F1 | C34: 1 | D34: 0.276 | E34: 0.387
B35: F2 | C35: 0.276 | D35: 1 | E35: 0.306
B36: F3 | C36: 0.387 | D36: 0.306 | E36: 1
A39: 第 2 輪（12 題）樣式矩陣
A40: 題號 | B40: 題目 | C40: F1 工作價值 | D40: F2 專業成長 | E40: F3 團隊連結 | F40: 最高 | G40: 次高 | H40: 差距 | I40: 判斷
A41: V1 | B41: 我覺得我的護理工作對病人很重要 | C41: 0.834 | D41: -0.034 | E41: 0.02 | F41: =MAX(ABS(C41),ABS(D41),ABS(E41)) -> 0.834 | G41: =ABS(C41)+ABS(D41)+ABS(E41)-MAX(ABS(C41),ABS(D41),ABS(E41))-MIN(ABS(C41),ABS(D41),ABS(E41)) -> 0.034 | H41: =F41-G41 -> 0.8 | I41: =IF(F41<0.4,"主負荷<.40",IF(AND(G41>=0.3,H41<0.2),"跨負荷","OK")) -> OK
A42: V2 | B42: 我的照護能讓病人的狀況變好 | C42: 0.812 | D42: -0.008 | E42: 0.056 | F42: =MAX(ABS(C42),ABS(D42),ABS(E42)) -> 0.812 | G42: =ABS(C42)+ABS(D42)+ABS(E42)-MAX(ABS(C42),ABS(D42),ABS(E42))-MIN(ABS(C42),ABS(D42),ABS(E42)) -> 0.056 | H42: =F42-G42 -> 0.756 | I42: =IF(F42<0.4,"主負荷<.40",IF(AND(G42>=0.3,H42<0.2),"跨負荷","OK")) -> OK
A43: V3 | B43: 我能從工作中看到自己的價值 | C43: 0.846 | D43: -0.009 | E43: -0.013 | F43: =MAX(ABS(C43),ABS(D43),ABS(E43)) -> 0.846 | G43: =ABS(C43)+ABS(D43)+ABS(E43)-MAX(ABS(C43),ABS(D43),ABS(E43))-MIN(ABS(C43),ABS(D43),ABS(E43)) -> 0.013 | H43: =F43-G43 -> 0.833 | I43: =IF(F43<0.4,"主負荷<.40",IF(AND(G43>=0.3,H43<0.2),"跨負荷","OK")) -> OK
A44: V4 | B44: 照顧病人讓我覺得這份工作值得 | C44: 0.835 | D44: 0.044 | E44: -0.063 | F44: =MAX(ABS(C44),ABS(D44),ABS(E44)) -> 0.835 | G44: =ABS(C44)+ABS(D44)+ABS(E44)-MAX(ABS(C44),ABS(D44),ABS(E44))-MIN(ABS(C44),ABS(D44),ABS(E44)) -> 0.063 | H44: =F44-G44 -> 0.772 | I44: =IF(F44<0.4,"主負荷<.40",IF(AND(G44>=0.3,H44<0.2),"跨負荷","OK")) -> OK
A45: G1 | B45: 我在工作中持續學到新的專業知識 | C45: -0.048 | D45: 0.855 | E45: -0.049 | F45: =MAX(ABS(C45),ABS(D45),ABS(E45)) -> 0.855 | G45: =ABS(C45)+ABS(D45)+ABS(E45)-MAX(ABS(C45),ABS(D45),ABS(E45))-MIN(ABS(C45),ABS(D45),ABS(E45)) -> 0.049 | H45: =F45-G45 -> 0.806 | I45: =IF(F45<0.4,"主負荷<.40",IF(AND(G45>=0.3,H45<0.2),"跨負荷","OK")) -> OK
...

Sheet 7_樣本B
A1: ID | B1: V1 | C1: V2 | D1: V3 | E1: V4 | F1: G1 | G1: G2 | H1: G3 | I1: G5 | J1: C1 | K1: C2 | L1: C3 | M1: C4 | N1: 平均分
A2: B001 | B2: 3 | C2: 4 | D2: 4 | E2: 4 | F2: 3 | G2: 3 | H2: 3 | I2: 3 | J2: 5 | K2: 4 | L2: 5 | M2: 5 | N2: =AVERAGE(B2:M2) -> 3.8333333
A3: B002 | B3: 2 | C3: 2 | D3: 2 | E3: 3 | F3: 3 | G3: 3 | H3: 4 | I3: 2 | J3: 4 | K3: 4 | L3: 3 | M3: 4 | N3: =AVERAGE(B3:M3) -> 3
A4: B003 | B4: 3 | C4: 4 | D4: 3 | E4: 3 | F4: 3 | G4: 3 | H4: 4 | I4: 4 | J4: 3 | K4: 4 | L4: 3 | M4: 3 | N4: =AVERAGE(B4:M4) -> 3.3333333
A5: B004 | B5: 5 | C5: 5 | D5: 5 | E5: 5 | F5: 4 | G5: 4 | H5: 4 | I5: 4 | J5: 4 | K5: 4 | L5: 5 | M5: 4 | N5: =AVERAGE(B5:M5) -> 4.4166667
A6: B005 | B6: 4 | C6: 3 | D6: 3 | E6: 3 | F6: 2 | G6: 4 | H6: 1 | I6: 2 | J6: 4 | K6: 4 | L6: 2 | M6: 4 | N6: =AVERAGE(B6:M6) -> 3
A7: B006 | B7: 5 | C7: 5 | D7: 5 | E7: 5 | F7: 5 | G7: 5 | H7: 5 | I7: 4 | J7: 4 | K7: 5 | L7: 5 | M7: 5 | N7: =AVERAGE(B7:M7) -> 4.8333333
A8: B007 | B8: 2 | C8: 2 | D8: 2 | E8: 3 | F8: 2 | G8: 3 | H8: 2 | I8: 2 | J8: 3 | K8: 3 | L8: 3 | M8: 3 | N8: =AVERAGE(B8:M8) -> 2.5
A9: B008 | B9: 2 | C9: 2 | D9: 2 | E9: 2 | F9: 4 | G9: 4 | H9: 4 | I9: 3 | J9: 3 | K9: 4 | L9: 3 | M9: 2 | N9: =AVERAGE(B9:M9) -> 2.9166667
A10: B009 | B10: 5 | C10: 4 | D10: 4 | E10: 4 | F10: 4 | G10: 4 | H10: 4 | I10: 4 | J10: 4 | K10: 2 | L10: 3 | M10: 2 | N10: =AVERAGE(B10:M10) -> 3.6666667
A11: B010 | B11: 3 | C11: 3 | D11: 2 | E11: 3 | F11: 3 | G11: 3 | H11: 2 | I11: 3 | J11: 2 | K11: 2 | L11: 3 | M11: 2 | N11: =AVERAGE(B11:M11) -> 2.5833333
A12: B011 | B12: 4 | C12: 4 | D12: 4 | E12: 3 | F12: 4 | G12: 4 | H12: 4 | I12: 5 | J12: 5 | K12: 3 | L12: 4 | M12: 4 | N12: =AVERAGE(B12:M12) -> 4
A13: B012 | B13: 2 | C13: 3 | D13: 3 | E13: 3 | F13: 3 | G13: 4 | H13: 4 | I13: 3 | J13: 4 | K13: 4 | L13: 3 | M13: 4 | N13: =AVERAGE(B13:M13) -> 3.3333333
... A281: B280 | B281: 5 | C281: 4 | D281: 5 | E281: 5 | F281: 5 | G281: 4 | H281: 5 | I281: 5 | J281: 5 | K281: 5 | L281: 4 | M281: 4 | N281: =AVERAGE(B281:M281) -> 4.6666667

Sheet 7_CFA結果
A1: 第⑦關 CFA（最大概似法；三因素、每題只負荷一個因素、因素變異數固定為 1）
A3: 觀察變項數 p | B3: 12
A4: 資料提供的資訊量 = p(p+1)/2 | B4: =B3*(B3+1)/2 -> 78
A5: 估計參數 q = 負荷量 12 + 誤差變異 12 + 因素相關 3 | B5: =12+12+3 -> 27
A6: 自由度 df = 資訊量 − q | B6: =B4-B5 -> 51
A7: 樣本數 N | B7: 280
A8: 模型卡方 χ²（軟體輸出） | B8: 81.92
A9: 虛無模型卡方 χ²₀（軟體輸出） | B9: 1753.7
A10: 虛無模型 df₀ = p(p−1)/2 | B10: =B3*(B3-1)/2 -> 66
A11: CFI = 1 − max(χ²−df,0) ÷ max(χ²₀−df₀, χ²−df, 0) | B11: =1-MAX(B8-B6,0)/MAX(B9-B10,B8-B6,0) -> 0.98167921
A12: TLI = [(χ²₀/df₀) − (χ²/df)] ÷ [(χ²₀/df₀) − 1] | B12: =((B9/B10)-(B8/B6))/((B9/B10)-1) -> 0.97629074
A13: RMSEA = √[max(χ²−df,0) ÷ (df × (N−1))] | B13: =SQRT(MAX(B8-B6,0)/(B6*(B7-1))) -> 0.046615737
A14: SRMR（軟體輸出） | B14: 0.045
A15: χ²/df | B15: =B8/B6 -> 1.6062745
A18: 題號 | B18: 題目 | C18: 構面 | D18: 標準化負荷量
A19: V1 | B19: 我覺得我的護理工作對病人很重要 | C19: 工作價值 | D19: 0.786
A20: V2 | B20: 我的照護能讓病人的狀況變好 | C20: 工作價值 | D20: 0.765
A21: V3 | B21: 我能從工作中看到自己的價值 | C21: 工作價值 | D21: 0.844
A22: V4 | B22: 照顧病人讓我覺得這份工作值得 | C22: 工作價值 | D22: 0.803
A23: G1 | B23: 我在工作中持續學到新的專業知識 | C23: 專業成長 | D23: 0.747
A24: G2 | B24: 我的臨床判斷能力越來越好 | C24: 專業成長 | D24: 0.755
A25: G3 | B25: 工作中的挑戰讓我成長 | C25: 專業成長 | D25: 0.834
A26: G5 | B26: 我覺得自己比剛入職時更有能力 | C26: 專業成長 | D26: 0.735
A27: C1 | B27: 我和同事之間互相支持 | C27: 團隊連結 | D27: 0.83
A28: C2 | B28: 遇到困難時，我知道可以找誰幫忙 | C28: 團隊連結 | D28: 0.77
A29: C3 | B29: 單位同仁會主動關心我 | C29: 團隊連結 | D29: 0.717
A30: C4 | B30: 我是這個護理團隊的一份子 | C30: 團隊連結 | D30: 0.82
A32: 因素間相關（軟體輸出）
A33: 工作價值–專業成長 | B33: 0.562
A34: 工作價值–團隊連結 | B34: 0.448
A35: 專業成長–團隊連結 | B35: 0.355

Sheet 8_信效度
A1: 第⑧關 收斂效度 AVE、組合信度 CR、區辨效度（Fornell–Larcker 與 HTMT）
A3: 題號 | B3: 構面 | C3: 標準化負荷 λ | D3: λ² | E3: 誤差 1−λ²
A4: V1 | B4: V | C4: =7_CFA結果!D19 -> 0.786 | D4: =C4^2 -> 0.617796 | E4: =1-D4 -> 0.382204
A5: V2 | B5: V | C5: =7_CFA結果!D20 -> 0.765 | D5: =C5^2 -> 0.585225 | E5: =1-D5 -> 0.414775
A6: V3 | B6: V | C6: =7_CFA結果!D21 -> 0.844 | D6: =C6^2 -> 0.712336 | E6: =1-D6 -> 0.287664
A7: V4 | B7: V | C7: =7_CFA結果!D22 -> 0.803 | D7: =C7^2 -> 0.644809 | E7: =1-D7 -> 0.355191
A8: G1 | B8: G | C8: =7_CFA結果!D23 -> 0.747 | D8: =C8^2 -> 0.558009 | E8: =1-D8 -> 0.441991
A9: G2 | B9: G | C9: =7_CFA結果!D24 -> 0.755 | D9: =C9^2 -> 0.570025 | E9: =1-D9 -> 0.429975
A10: G3 | B10: G | C10: =7_CFA結果!D25 -> 0.834 | D10: =C10^2 -> 0.695556 | E10: =1-D10 -> 0.304444
A11: G5 | B11: G | C11: =7_CFA結果!D26 -> 0.735 | D11: =C11^2 -> 0.540225 | E11: =1-D11 -> 0.459775
A12: C1 | B12: C | C12: =7_CFA結果!D27 -> 0.83 | D12: =C12^2 -> 0.6889 | E12: =1-D12 -> 0.3111
A13: C2 | B13: C | C13: =7_CFA結果!D28 -> 0.77 | D13: =C13^2 -> 0.5929 | E13: =1-D13 -> 0.4071
A14: C3 | B14: C | C14: =7_CFA結果!D29 -> 0.717 | D14: =C14^2 -> 0.514089 | E14: =1-D14 -> 0.485911
A15: C4 | B15: C | C15: =7_CFA結果!D30 -> 0.82 | D15: =C15^2 -> 0.6724 | E15: =1-D15 -> 0.3276
A18: 構面 | B18: Σλ | C18: Σλ² | D18: Σ(1−λ²) | E18: 題數 | F18: AVE = Σλ²/題數 | G18: CR = (Σλ)²/[(Σλ)²+Σ(1−λ²)] | H18: √AVE
A19: V | B19: =SUMIF($B$4:$B$15,"V",$C$4:$C$15) -> 3.198 | C19: =SUMIF($B$4:$B$15,"V",$D$4:$D$15) -> 2.560166 | D19: =SUMIF($B$4:$B$15,"V",$E$4:$E$15) -> 1.439834 | E19: =COUNTIF($B$4:$B$15,"V") -> 4 | F19: =C19/E19 -> 0.6400415 | G19: =B19^2/(B19^2+D19) -> 0.87658959 | H19: =SQRT(F19) -> 0.80002594
A20: G | B20: =SUMIF($B$4:$B$15,"G",$C$4:$C$15) -> 3.071 | C20: =SUMIF($B$4:$B$15,"G",$D$4:$D$15) -> 2.363815 | D20: =SUMIF($B$4:$B$15,"G",$E$4:$E$15) -> 1.636185 | E20: =COUNTIF($B$4:$B$15,"G") -> 4 | F20: =C20/E20 -> 0.59095375 | G20: =B20^2/(B20^2+D20) -> 0.85215943 | H20: =SQRT(F20) -> 0.76873516
A21: C | B21: =SUMIF($B$4:$B$15,"C",$C$4:$C$15) -> 3.137 | C21: =SUMIF($B$4:$B$15,"C",$D$4:$D$15) -> 2.468289 | D21: =SUMIF($B$4:$B$15,"C",$E$4:$E$15) -> 1.531711 | E21: =COUNTIF($B$4:$B$15,"C") -> 4 | F21: =C21/E21 -> 0.61707225 | G21: =B21^2/(B21^2+D21) -> 0.86531425 | H21: =SQRT(F21) -> 0.78553946
A23: Fornell–Larcker：√AVE 要大於該構面與其他構面的相關
A24: 構面對 | B24: 因素相關（CFA） | C24: 較小的 √AVE | D24: 通過？
A25: V–G | B25: =7_CFA結果!B33 -> 0.562 | C25: =MIN(H19,H20) -> 0.76873516 | D25: =IF(C25>B25,"通過","未通過") -> 通過
A26: V–C | B26: =7_CFA結果!B34 -> 0.448 | C26: =MIN(H19,H21) -> 0.78553946 | D26: =IF(C26>B26,"通過","未通過") -> 通過
A27: G–C | B27: =7_CFA結果!B35 -> 0.355 | C27: =MIN(H20,H21) -> 0.76873516 | D27: =IF(C27>B27,"通過","未通過") -> 通過
A29: 題目間相關矩陣（樣本 B，CORREL 公式）
B30: V1 | C30: V2 | D30: V3 | E30: V4 | F30: G1 | G30: G2 | H30: G3 | I30: G5 | J30: C1 | K30: C2 | L30: C3 | M30: C4
A31: V1 | B31: =CORREL(7_樣本B!B$2:B$281,7_樣本B!B$2:B$281) -> 1 | C31: =CORREL(7_樣本B!B$2:B$281,7_樣本B!C$2:C$281) -> 0.59788658 | D31: =CORREL(7_樣本B!B$2:B$281,7_樣本B!D$2:D$281) -> 0.68328932 | E31: =CORREL(7_樣本B!B$2:B$281,7_樣本B!E$2:E$281) -> 0.61133467 | F31: =CORREL(7_樣本B!B$2:B$281,7_樣本B!F$2:F$281) -> 0.33034205 | G31: =CORREL(7_樣本B!B$2:B$281,7_樣本B!G$2:G$281) -> 0.25791878 | H31: =CORREL(7_樣本B!B$2:B$281,7_樣本B!H$2:H$281) -> 0.42993159 | I31: =CORREL(7_樣本B!B$2:B$281,7_樣本B!I$2:I$281) -> 0.33311715 | J31: =CORREL(7_樣本B!B$2:B$281,7_樣本B!J$2:J$281) -> 0.29040159 | K31: =CORREL(7_樣本B!B$2:B$281,7_樣本B!K$2:K$281) -> 0.26806842 | L31: =CORREL(7_樣本B!B$2:B$281,7_樣本B!L$2:L$281) -> 0.16353188 | M31: =CORREL(7_樣本B!B$2:B$281,7_樣本B!M$2:M$281) -> 0.25806195
A32: V2 | B32: =CORREL(7_樣本B!C$2:C$281,7_樣本B!B$2:B$281) -> 0.59788658 | C32: =CORREL(7_樣本B!C$2:C$281,7_樣本B!C$2:C$281) -> 1 | D32: =CORREL(7_樣本B!C$2:C$281,7_樣本B!D$2:D$281) -> 0.65419875 | E32: =CORREL(7_樣本B!C$2:C$281,7_樣本B!E$2:E$281) -> 0.61588115 | F32: =CORREL(7_樣本B!C$2:C$281,7_樣本B!F$2:F$281) -> 0.28064675 | G32: =CORREL(7_樣本B!C$2:C$281,7_樣本B!G$2:G$281) -> 0.32881426 | H32: =CORREL(7_樣本B!C$2:C$281,7_樣本B!H$2:H$281) -> 0.41788032 | I32: =CORREL(7_樣本B!C$2:C$281,7_樣本B!I$2:I$281) -> 0.30967204 | J32: =CORREL(7_樣本B!C$2:C$281,7_樣本B!J$2:J$281) -> 0.22931893 | K32: =CORREL(7_樣本B!C$2:C$281,7_樣本B!K$2:K$281) -> 0.24299187 | L32: =CORREL(7_樣本B!C$2:C$281,7_樣本B!L$2:L$281) -> 0.12644015 | M32: =CORREL(7_樣本B!C$2:C$281,7_樣本B!M$2:M$281) -> 0.22953027
A33: V3 | B33: =CORREL(7_樣本B!D$2:D$281,7_樣本B!B$2:B$281) -> 0.68328932 | C33: =CORREL(7_樣本B!D$2:D$281,7_樣本B!C$2:C$281) -> 0.65419875 | D33: =CORREL(7_樣本B!D$2:D$281,7_樣本B!D$2:D$281) -> 1 | E33: =CORREL(7_樣本B!D$2:D$281,7_樣本B!E$2:E$281) -> 0.66742142 | F33: =CORREL(7_樣本B!D$2:D$281,7_樣本B!F$2:F$281) -> 0.29230303 | G33: =CORREL(7_樣本B!D$2:D$281,7_樣本B!G$2:G$281) -> 0.28807577 | H33: =CORREL(7_樣本B!D$2:D$281,7_樣本B!H$2:H$281) -> 0.42361036 | I33: =CORREL(7_樣本B!D$2:D$281,7_樣本B!I$2:I$281) -> 0.29928377 | J33: =CORREL(7_樣本B!D$2:D$281,7_樣本B!J$2:J$281) -> 0.28220933 | K33: =CORREL(7_樣本B!D$2:D$281,7_樣本B!K$2:K$281) -> 0.27280811 | L33: =CORREL(7_樣本B!D$2:D$281,7_樣本B!L$2:L$281) -> 0.16716746 | M33: =CORREL(7_樣本B!D$2:D$281,7_樣本B!M$2:M$281) -> 0.35240897
A34: V4 | B34: =CORREL(7_樣本B!E$2:E$281,7_樣本B!B$2:B$281) -> 0.61133467 | C34: =CORREL(7_樣本B!E$2:E$281,7_樣本B!C$2:C$281) -> 0.61588115 | D34: =CORREL(7_樣本B!E$2:E$281,7_樣本B!D$2:D$281) -> 0.66742142 | E34: =CORREL(7_樣本B!E$2:E$281,7_樣本B!E$2:E$281) -> 1 | F34: =CORREL(7_樣本B!E$2:E$281,7_樣本B!F$2:F$281) -> 0.33216587 | G34: =CORREL(7_樣本B!E$2:E$281,7_樣本B!G$2:G$281) -> 0.34809845 | H34: =CORREL(7_樣本B!E$2:E$281,7_樣本B!H$2:H$281) -> 0.44969891 | I34: =CORREL(7_樣本B!E$2:E$281,7_樣本B!I$2:I$281) -> 0.320783 | J34: =CORREL(7_樣本B!E$2:E$281,7_樣本B!J$2:J$281) -> 0.38592357 | K34: =CORREL(7_樣本B!E$2:E$281,7_樣本B!K$2:K$281) -> 0.36504062 | L34: =CORREL(7_樣本B!E$2:E$281,7_樣本B!L$2:L$281) -> 0.30035603 | M34: =CORREL(7_樣本B!E$2:E$281,7_樣本B!M$2:M$281) -> 0.43457503
A35: G1 | B35: =CORREL(7_樣本B!F$2:F$281,7_樣本B!B$2:B$281) -> 0.33034205 | C35: =CORREL(7_樣本B!F$2:F$281,7_樣本B!C$2:C$281) -> 0.28064675 | D35: =CORREL(7_樣本B!F$2:F$281,7_樣本B!D$2:D$281) -> 0.29230303 | E35: =CORREL(7_樣本B!F$2:F$281,7_樣本B!E$2:E$281) -> 0.33216587 | F35: =CORREL(7_樣本B!F$2:F$281,7_樣本B!F$2:F$281) -> 1 | G35: =CORREL(7_樣本B!F$2:F$281,7_樣本B!G$2:G$281) -> 0.6267694 | H35: =CORREL(7_樣本B!F$2:F$281,7_樣本B!H$2:H$281) -> 0.60154141 | I35: =CORREL(7_樣本B!F$2:F$281,7_樣本B!I$2:I$281) -> 0.54065349 | J35: =CORREL(7_樣本B!F$2:F$281,7_樣本B!J$2:J$281) -> 0.16135214 | K35: =CORREL(7_樣本B!F$2:F$281,7_樣本B!K$2:K$281) -> 0.16461455 | L35: =CORREL(7_樣本B!F$2:F$281,7_樣本B!L$2:L$281) -> 0.12117403 | M35: =CORREL(7_樣本B!F$2:F$281,7_樣本B!M$2:M$281) -> 0.14720353
A36: G2 | B36: =CORREL(7_樣本B!G$2:G$281,7_樣本B!B$2:B$281) -> 0.25791878 | C36: =CORREL(7_樣本B!G$2:G$281,7_樣本B!C$2:C$281) -> 0.32881426 | D36: =CORREL(7_樣本B!G$2:G$281,7_樣本B!D$2:D$281) -> 0.28807577 | E36: =CORREL(7_樣本B!G$2:G$281,7_樣本B!E$2:E$281) -> 0.34809845 | F36: =CORREL(7_樣本B!G$2:G$281,7_樣本B!F$2:F$281) -> 0.6267694 | G36: =CORREL(7_樣本B!G$2:G$281,7_樣本B!G$2:G$281) -> 1 | H36: =CORREL(7_樣本B!G$2:G$281,7_樣本B!H$2:H$281) -> 0.60773859 | I36: =CORREL(7_樣本B!G$2:G$281,7_樣本B!I$2:I$281) -> 0.54686159 | J36: =CORREL(7_樣本B!G$2:G$281,7_樣本B!J$2:J$281) -> 0.18179821 | K36: =CORREL(7_樣本B!G$2:G$281,7_樣本B!K$2:K$281) -> 0.25296491 | L36: =CORREL(7_樣本B!G$2:G$281,7_樣本B!L$2:L$281) -> 0.14156913 | M36: =CORREL(7_樣本B!G$2:G$281,7_樣本B!M$2:M$281) -> 0.21746986
A37: G3 | B37: =CORREL(7_樣本B!H$2:H$281,7_樣本B!B$2:B$281) -> 0.42993159 | C37: =CORREL(7_樣本B!H$2:H$281,7_樣本B!C$2:C$281) -> 0.41788032 | D37: =CORREL(7_樣本B!H$2:H$281,7_樣本B!D$2:D$281) -> 0.42361036 | E37: =CORREL(7_樣本B!H$2:H$281,7_樣本B!E$2:E$281) -> 0.44969891 | F37: =CORREL(7_樣本B!H$2:H$281,7_樣本B!F$2:F$281) -> 0.60154141 | G37: =CORREL(7_樣本B!H$2:H$281,7_樣本B!G$2:G$281) -> 0.60773859 | H37: =CORREL(7_樣本B!H$2:H$281,7_樣本B!H$2:H$281) -> 1 | I37: =CORREL(7_樣本B!H$2:H$281,7_樣本B!I$2:I$281) -> 0.62829135 | J37: =CORREL(7_樣本B!H$2:H$281,7_樣本B!J$2:J$281) -> 0.23409069 | K37: =CORREL(7_樣本B!H$2:H$281,7_樣本B!K$2:K$281) -> 0.31189095 | L37: =CORREL(7_樣本B!H$2:H$281,7_樣本B!L$2:L$281) -> 0.21739862 | M37: =CORREL(7_樣本B!H$2:H$281,7_樣本B!M$2:M$281) -> 0.31764047
A38: G5 | B38: =CORREL(7_樣本B!I$2:I$281,7_樣本B!B$2:B$281) -> 0.33311715 | C38: =CORREL(7_樣本B!I$2:I$281,7_樣本B!C$2:C$281) -> 0.30967204 | D38: =CORREL(7_樣本B!I$2:I$281,7_樣本B!D$2:D$281) -> 0.29928377 | E38: =CORREL(7_樣本B!I$2:I$281,7_樣本B!E$2:E$281) -> 0.320783 | F38: =CORREL(7_樣本B!I$2:I$281,7_樣本B!F$2:F$281) -> 0.54065349 | G38: =CORREL(7_樣本B!I$2:I$281,7_樣本B!G$2:G$281) -> 0.54686159 | H38: =CORREL(7_樣本B!I$2:I$281,7_樣本B!H$2:H$281) -> 0.62829135 | I38: =CORREL(7_樣本B!I$2:I$281,7_樣本B!I$2:I$281) -> 1 | J38: =CORREL(7_樣本B!I$2:I$281,7_樣本B!J$2:J$281) -> 0.2246962 | K38: =CORREL(7_樣本B!I$2:I$281,7_樣本B!K$2:K$281) -> 0.24714079 | L38: =CORREL(7_樣本B!I$2:I$281,7_樣本B!L$2:L$281) -> 0.17281653 | M38: =CORREL(7_樣本B!I$2:I$281,7_樣本B!M$2:M$281) -> 0.21938256
A39: C1 | B39: =CORREL(7_樣本B!J$2:J$281,7_樣本B!B$2:B$281) -> 0.29040159 | C39: =CORREL(7_樣本B!J$2:J$281,7_樣本B!C$2:C$281) -> 0.22931893 | D39: =CORREL(7_樣本B!J$2:J$281,7_樣本B!D$2:D$281) -> 0.28220933 | E39: =CORREL(7_樣本B!J$2:J$281,7_樣本B!E$2:E$281) -> 0.38592357 | F39: =CORREL(7_樣本B!J$2:J$281,7_樣本B!F$2:F$281) -> 0.16135214 | G39: =CORREL(7_樣本B!J$2:J$281,7_樣本B!G$2:G$281) -> 0.18179821 | H39: =CORREL(7_樣本B!J$2:J$281,7_樣本B!H$2:H$281) -> 0.23409069 | I39: =CORREL(7_樣本B!J$2:J$281,7_樣本B!I$2:I$281) -> 0.2246962 | J39: =CORREL(7_樣本B!J$2:J$281,7_樣本B!J$2:J$281) -> 1 | K39: =CORREL(7_樣本B!J$2:J$281,7_樣本B!K$2:K$281) -> 0.63711771 | L39: =CORREL(7_樣本B!J$2:J$281,7_樣本B!L$2:L$281) -> 0.6074825 | M39: =CORREL(7_樣本B!J$2:J$281,7_樣本B!M$2:M$281) -> 0.67731188
A40: C2 | B40: =CORREL(7_樣本B!K$2:K$281,7_樣本B!B$2:B$281) -> 0.26806842 | C40: =CORREL(7_樣本B!K$2:K$281,7_樣本B!C$2:C$281) -> 0.24299187 | D40: =CORREL(7_樣本B!K$2:K$281,7_樣本B!D$2:D$281) -> 0.27280811 | E40: =CORREL(7_樣本B!K$2:K$281,7_樣本B!E$2:E$281) -> 0.36504062 | F40: =CORREL(7_樣本B!K$2:K$281,7_樣本B!F$2:F$281) -> 0.16461455 | G40: =CORREL(7_樣本B!K$2:K$281,7_樣本B!G$2:G$281) -> 0.25296491 | H40: =CORREL(7_樣本B!K$2:K$281,7_樣本B!H$2:H$281) -> 0.31189095 | I40: =CORREL(7_樣本B!K$2:K$281,7_樣本B!I$2:I$281) -> 0.24714079 | J40: =CORREL(7_樣本B!K$2:K$281,7_樣本B!J$2:J$281) -> 0.63711771 | K40: =CORREL(7_樣本B!K$2:K$281,7_樣本B!K$2:K$281) -> 1 | L40: =CORREL(7_樣本B!K$2:K$281,7_樣本B!L$2:L$281) -> 0.55524804 | M40: =CORREL(7_樣本B!K$2:K$281,7_樣本B!M$2:M$281) -> 0.62503446
A41: C3 | B41: =CORREL(7_樣本B!L$2:L$281,7_樣本B!B$2:B$281) -> 0.16353188 | C41: =CORREL(7_樣本B!L$2:L$281,7_樣本B!C$2:C$281) -> 0.12644015 | D41: =CORREL(7_樣本B!L$2:L$281,7_樣本B!D$2:D$281) -> 0.16716746 | E41: =CORREL(7_樣本B!L$2:L$281,7_樣本B!E$2:E$281) -> 0.30035603 | F41: =CORREL(7_樣本B!L$2:L$281,7_樣本B!F$2:F$281) -> 0.12117403 | G41: =CORREL(7_樣本B!L$2:L$281,7_樣本B!G$2:G$281) -> 0.14156913 | H41: =CORREL(7_樣本B!L$2:L$281,7_樣本B!H$2:H$281) -> 0.21739862 | I41: =CORREL(7_樣本B!L$2:L$281,7_樣本B!I$2:I$281) -> 0.17281653 | J41: =CORREL(7_樣本B!L$2:L$281,7_樣本B!J$2:J$281) -> 0.6074825 | K41: =CORREL(7_樣本B!L$2:L$281,7_樣本B!K$2:K$281) -> 0.55524804 | L41: =CORREL(7_樣本B!L$2:L$281,7_樣本B!L$2:L$281) -> 1 | M41: =CORREL(7_樣本B!L$2:L$281,7_樣本B!M$2:M$281) -> 0.58895514
A42: C4 | B42: =CORREL(7_樣本B!M$2:M$281,7_樣本B!B$2:B$281) -> 0.25806195 | C42: =CORREL(7_樣本B!M$2:M$281,7_樣本B!C$2:C$281) -> 0.22953027 | D42: =CORREL(7_樣本B!M$2:M$281,7_樣本B!D$2:D$281) -> 0.35240897 | E42: =CORREL(7_樣本B!M$2:M$281,7_樣本B!E$2:E$281) -> 0.43457503 | F42: =CORREL(7_樣本B!M$2:M$281,7_樣本B!F$2:F$281) -> 0.14720353 | G42: =CORREL(7_樣本B!M$2:M$281,7_樣本B!G$2:G$281) -> 0.21746986 | H42: =CORREL(7_樣本B!M$2:M$281,7_樣本B!H$2:H$281) -> 0.31764047 | I42: =CORREL(7_樣本B!M$2:M$281,7_樣本B!I$2:I$281) -> 0.21938256 | J42: =CORREL(7_樣本B!M$2:M$281,7_樣本B!J$2:J$281) -> 0.67731188 | K42: =CORREL(7_樣本B!M$2:M$281,7_樣本B!K$2:K$281) -> 0.62503446 | L42: =CORREL(7_樣本B!M$2:M$281,7_樣本B!L$2:L$281) -> 0.58895514 | M42: =CORREL(7_樣本B!M$2:M$281,7_樣本B!M$2:M$281) -> 1
A44: HTMT ＝ 異質相關平均 ÷ √(構面A內部相關平均 × 構面B內部相關平均)
A45: 構面 | B45: 內部相關平均 = (區塊總和 − 4) ÷ 12
A46: V | B46: =(SUM(B31:E34)-4)/12 -> 0.63833531
...

Sheet 8_再測
A1: 第⑧關 再測信度：樣本 B 前 60 人，間隔 2 週再填一次；以 12 題平均分計算 ICC（二因子、絕對一致、單一測量）
A3: ID | B3: V1_T2 | C3: V2_T2 | D3: V3_T2 | E3: V4_T2 | F3: G1_T2 | G3: G2_T2 | H3: G3_T2 | I3: G5_T2 | J3: C1_T2 | K3: C2_T2 | L3: C3_T2 | M3: C4_T2 | N3: T1 平均 | O3: T2 平均 | P3: 個人平均
A4: B001 | B4: 4 | C4: 3 | D4: 3 | E4: 4 | F4: 3 | G4: 3 | H4: 4 | I4: 4 | J4: 5 | K4: 4 | L4: 5 | M4: 4 | N4: =7_樣本B!N2 -> 3.8333333 | O4: =AVERAGE(B4:M4) -> 3.8333333 | P4: =AVERAGE(N4:O4) -> 3.8333333 | R4: 受試者數 n | S4: =COUNT(N4:N63) -> 60
A5: B002 | B5: 4 | C5: 3 | D5: 3 | E5: 3 | F5: 3 | G5: 4 | H5: 4 | I5: 4 | J5: 3 | K5: 4 | L5: 3 | M5: 4 | N5: =7_樣本B!N3 -> 3 | O5: =AVERAGE(B5:M5) -> 3.5 | P5: =AVERAGE(N5:O5) -> 3.25 | R5: 施測次數 k | S5: 2
A6: B003 | B6: 3 | C6: 4 | D6: 3 | E6: 4 | F6: 4 | G6: 4 | H6: 3 | I6: 3 | J6: 3 | K6: 3 | L6: 3 | M6: 3 | N6: =7_樣本B!N4 -> 3.3333333 | O6: =AVERAGE(B6:M6) -> 3.3333333 | P6: =AVERAGE(N6:O6) -> 3.3333333 | R6: 總平均 GM | S6: =AVERAGE(N4:N63,O4:O63) -> 3.6611111
A7: B004 | B7: 4 | C7: 4 | D7: 5 | E7: 5 | F7: 4 | G7: 4 | H7: 3 | I7: 4 | J7: 5 | K7: 5 | L7: 5 | M7: 5 | N7: =7_樣本B!N5 -> 4.4166667 | O7: =AVERAGE(B7:M7) -> 4.4166667 | P7: =AVERAGE(N7:O7) -> 4.4166667 | R7: T1 平均 | S7: =AVERAGE(N4:N63) -> 3.65
A8: B005 | B8: 3 | C8: 3 | D8: 4 | E8: 4 | F8: 3 | G8: 2 | H8: 4 | I8: 2 | J8: 3 | K8: 4 | L8: 3 | M8: 3 | N8: =7_樣本B!N6 -> 3 | O8: =AVERAGE(B8:M8) -> 3.1666667 | P8: =AVERAGE(N8:O8) -> 3.0833333 | R8: T2 平均 | S8: =AVERAGE(O4:O63) -> 3.6722222
A9: B006 | B9: 4 | C9: 4 | D9: 4 | E9: 5 | F9: 4 | G9: 5 | H9: 5 | I9: 5 | J9: 5 | K9: 5 | L9: 5 | M9: 5 | N9: =7_樣本B!N7 -> 4.8333333 | O9: =AVERAGE(B9:M9) -> 4.6666667 | P9: =AVERAGE(N9:O9) -> 4.75 | R9: SS受試者 = k × Σ(個人平均 − GM)² | S9: =S5*SUMPRODUCT((P4:P63-S6)^2) -> 48.468519
A10: B007 | B10: 2 | C10: 2 | D10: 3 | E10: 2 | F10: 2 | G10: 4 | H10: 3 | I10: 3 | J10: 2 | K10: 3 | L10: 3 | M10: 3 | N10: =7_樣本B!N8 -> 2.5 | O10: =AVERAGE(B10:M10) -> 2.6666667 | P10: =AVERAGE(N10:O10) -> 2.5833333 | R10: SS時間 = n × Σ(各次平均 − GM)² | S10: =S4*((S7-S6)^2+(S8-S6)^2) -> 0.014814815
A11: B008 | B11: 3 | C11: 4 | D11: 2 | E11: 3 | F11: 5 | G11: 4 | H11: 4 | I11: 4 | J11: 3 | K11: 4 | L11: 4 | M11: 5 | N11: =7_樣本B!N9 -> 2.9166667 | O11: =AVERAGE(B11:M11) -> 3.75 | P11: =AVERAGE(N11:O11) -> 3.3333333 | R11: SS總 = Σ(每個分數 − GM)² | S11: =SUMPRODUCT((N4:N63-S6)^2)+SUMPRODUCT((O4:O63-S6)^2) -> 51.95463
A12: B009 | B12: 4 | C12: 4 | D12: 5 | E12: 4 | F12: 4 | G12: 4 | H12: 3 | I12: 4 | J12: 2 | K12: 3 | L12: 3 | M12: 3 | N12: =7_樣本B!N10 -> 3.6666667 | O12: =AVERAGE(B12:M12) -> 3.5833333 | P12: =AVERAGE(N12:O12) -> 3.625 | R12: SS誤差 = SS總 − SS受試者 − SS時間 | S12: =S11-S9-S10 -> 3.4712963
A13: B010 | B13: 2 | C13: 2 | D13: 2 | E13: 2 | F13: 3 | G13: 2 | H13: 1 | I13: 1 | J13: 2 | K13: 2 | L13: 2 | M13: 1 | N13: =7_樣本B!N11 -> 2.5833333 | O13: =AVERAGE(B13:M13) -> 1.8333333 | P13: =AVERAGE(N13:O13) -> 2.2083333 | R13: MSR = SS受試者 ÷ (n−1) | S13: =S9/(S4-1) -> 0.82150031
A14: B011 | B14: 5 | C14: 4 | D14: 4 | E14: 4 | F14: 4 | G14: 4 | H14: 3 | I14: 4 | J14: 4 | K14: 5 | L14: 5 | M14: 5 | N14: =7_樣本B!N12 -> 4 | O14: =AVERAGE(B14:M14) -> 4.25 | P14: =AVERAGE(N14:O14) -> 4.125 | R14: MSC = SS時間 ÷ (k−1) | S14: =S10/(S5-1) -> 0.014814815
A15: B012 | B15: 4 | C15: 4 | D15: 4 | E15: 2 | F15: 4 | G15: 3 | H15: 4 | I15: 4 | J15: 2 | K15: 3 | L15: 2 | M15: 3 | N15: =7_樣本B!N13 -> 3.3333333 | O15: =AVERAGE(B15:M15) -> 3.25 | P15: =AVERAGE(N15:O15) -> 3.2916667 | R15: MSE = SS誤差 ÷ [(n−1)(k−1)] | S15: =S12/((S4-1)*(S5-1)) -> 0.05883553
A16: B013 | B16: 3 | C16: 3 | D16: 3 | E16: 3 | F16: 4 | G16: 3 | H16: 4 | I16: 3 | J16: 5 | K16: 5 | L16: 5 | M16: 5 | N16: =7_樣本B!N14 -> 4.1666667 | O16: =AVERAGE(B16:M16) -> 3.8333333 | P16: =AVERAGE(N16:O16) -> 4 | R16: ICC = (MSR−MSE) ÷ [MSR + (k−1)MSE + k(MSC−MSE)/n] | S16: =(S13-S15)/(S13+(S5-1)*S15+S5*(S14-S15)/S4) -> 0.86778033
A17: B014 | B17: 3 | C17: 2 | D17: 2 | E17: 3 | F17: 4 | G17: 4 | H17: 5 | I17: 4 | J17: 4 | K17: 5 | L17: 4 | M17: 3 | N17: =7_樣本B!N15 -> 4.3333333 | O17: =AVERAGE(B17:M17) -> 3.5833333 | P17: =AVERAGE(N17:O17) -> 3.9583333
A18: B015 | B18: 4 | C18: 4 | D18: 5 | E18: 5 | F18: 5 | G18: 5 | H18: 5 | I18: 5 | J18: 5 | K18: 4 | L18: 5 | M18: 5 | N18: =7_樣本B!N16 -> 4.25 | O18: =AVERAGE(B18:M18) -> 4.75 | P18: =AVERAGE(N18:O18) -> 4.5
A19: B016 | B19: 5 | C19: 4 | D19: 4 | E19: 5 | F19: 4 | G19: 4 | H19: 4 | I19: 5 | J19: 5 | K19: 5 | L19: 4 | M19: 5 | N19: =7_樣本B!N17 -> 4.25 | O19: =AVERAGE(B19:M19) -> 4.5 | P19: =AVERAGE(N19:O19) -> 4.375
A20: B017 | B20: 3 | C20: 4 | D20: 3 | E20: 3 | F20: 3 | G20: 4 | H20: 3 | I20: 3 | J20: 3 | K20: 2 | L20: 4 | M20: 3 | N20: =7_樣本B!N18 -> 3.5 | O20: =AVERAGE(B20:M20) -> 3.1666667 | P20: =AVERAGE(N20:O20) -> 3.3333333
A21: B018 | B21: 5 | C21: 5 | D21: 4 | E21: 5 | F21: 4 | G21: 4 | H21: 4 | I21: 5 | J21: 3 | K21: 4 | L21: 3 | M21: 4 | N21: =7_樣本B!N19 -> 4.3333333 | O21: =AVERAGE(B21:M21) -> 4.1666667 | P21: =AVERAGE(N21:O21) -> 4.25
A22: B019 | B22: 3 | C22: 4 | D22: 5 | E22: 4 | F22: 3 | G22: 3 | H22: 3 | I22: 3 | J22: 4 | K22: 4 | L22: 4 | M22: 5 | N22: =7_樣本B!N20 -> 3.5833333 | O22: =AVERAGE(B22:M22) -> 3.75 | P22: =AVERAGE(N22:O22) -> 3.6666667
A23: B020 | B23: 3 | C23: 4 | D23: 2 | E23: 3 | F23: 4 | G23: 4 | H23: 4 | I23: 4 | J23: 5 | K23: 3 | L23: 4 | M23: 4 | N23: =7_樣本B!N21 -> 3.8333333 | O23: =AVERAGE(B23:M23) -> 3.6666667 | P23: =AVERAGE(N23:O23) -> 3.75
A24: B021 | B24: 4 | C24: 5 | D24: 4 | E24: 3 | F24: 2 | G24: 3 | H24: 3 | I24: 3 | J24: 4 | K24: 4 | L24: 4 | M24: 4 | N24: =7_樣本B!N22 -> 3.75 | O24: =AVERAGE(B24:M24) -> 3.5833333 | P24: =AVERAGE(N24:O24) -> 3.6666667
A25: B022 | B25: 2 | C25: 3 | D25: 3 | E25: 4 | F25: 3 | G25: 3 | H25: 4 | I25: 4 | J25: 3 | K25: 2 | L25: 2 | M25: 3 | N25: =7_樣本B!N23 -> 3.5 | O25: =AVERAGE(B25:M25) -> 3 | P25: =AVERAGE(N25:O25) -> 3.25
A26: B023 | B26: 5 | C26: 4 | D26: 5 | E26: 5 | F26: 4 | G26: 4 | H26: 5 | I26: 5 | J26: 4 | K26: 4 | L26: 4 | M26: 4 | N26: =7_樣本B!N24 -> 4.3333333 | O26: =AVERAGE(B26:M26) -> 4.4166667 | P26: =AVERAGE(N26:O26) -> 4.375
A27: B024 | B27: 3 | C27: 4 | D27: 4 | E27: 4 | F27: 4 | G27: 4 | H27: 5 | I27: 4 | J27: 4 | K27: 4 | L27: 3 | M27: 4 | N27: =7_樣本B!N25 -> 3.8333333 | O27: =AVERAGE(B27:M27) -> 3.9166667 | P27: =AVERAGE(N27:O27) -> 3.875
A28: B025 | B28: 3 | C28: 3 | D28: 4 | E28: 3 | F28: 4 | G28: 3 | H28: 3 | I28: 3 | J28: 5 | K28: 4 | L28: 4 | M28: 4 | N28: =7_樣本B!N26 -> 3.0833333 | O28: =AVERAGE(B28:M28) -> 3.5833333 | P28: =AVERAGE(N28:O28) -> 3.3333333
... A63: B060 | B63: 4 | C63: 4 | D63: 4 | E63: 5 | F63: 5 | G63: 4 | H63: 5 | I63: 5 | J63: 3 | K63: 4 | L63: 3 | M63: 3 | N63: =7_樣本B!N61 -> 4.3333333 | O63: =AVERAGE(B63:M63) -> 4.0833333 | P63: =AVERAGE(N63:O63) -> 4.2083333
