Workbook

Sheet 00A_從這裡開始_Start
A1: 00A 從這裡開始｜夥伴版（選一個身分，照著五步走） | P1: key | R1: 去哪頁 | S1: 做什麼 | T1: 改哪些 | U1: 完成的樣子
A2: 這是 VMH-EcoMap 主工具的夥伴版：只留下 7 個分頁，把顧問在用的盤點工作區收起來了（資料與公式完整保留，沒有刪任何東西）。★ 選完下拉，下面五步會自動換成你的路徑。看完這頁就可以動手。 | P2: ① 夥伴｜第一次打開這個檔-1 | R2: 15_商機字典_OppLibrary | S2: 先看這 85 門越南醫院市場可以做的生意，分成 A~J 十個族群。只看「在賣什麼／誰付錢／大概多少錢／越南現況」四欄，找跟你本業有關的。 | T2: 不用改任何格子 | U2: 圈出 3–5 個你做得到的商機
A3: ⌂ 回導引頁 | P3: ① 夥伴｜第一次打開這個檔-2 | R3: 15_商機字典_OppLibrary | S3: 看 L 欄「★白地商機」——越南有這門生意，但聯盟目前沒有能力接。那是最歡迎你補位的位置。 | T3: 不用改任何格子 | U3: 確認裡面有沒有你的位置
A4: 我是誰 | B4: ① 夥伴｜第一次打開這個檔 | D4: ◀ 先選這裡 | P4: ① 夥伴｜第一次打開這個檔-3 | R4: 17_商機作戰卡_OppView | S4: 在最上面的下拉選單挑一個你圈出來的商機，這一頁會自動組出作戰卡：需要哪些能力、誰在做、還缺什麼、對手是誰。 | T4: 只改下拉那一格 | U4: 知道你要補的是哪一塊
P5: ① 夥伴｜第一次打開這個檔-4 | R5: 11_缺口招募_GapRFI | S5: 看紅底的那幾列——那是「牽動 ≥3 個商機」的缺口，補一個能同時解鎖好幾門生意，聯盟最急著找人。 | T5: 不用改任何格子 | U5: 選出你要認領的缺口
A6: 步驟 | B6: 去哪一頁 | C6: 要做什麼 | D6: 你只要改這些 | E6: 完成的樣子 | P6: ① 夥伴｜第一次打開這個檔-5 | R6: （回報給 PI，不用動這個檔） | S6: 把你能做的商機與想認領的缺口，填進 VMH-EcoMap-3 夥伴提案回覆表交回來。這個主檔由 PI 統一維護。 | T6: 不用改任何格子 | U6: 提案回覆表已寄出
A7: 第 1 步 | B7: =IFERROR(INDEX($R$2:$R$200,MATCH($B$4&"-1",$P$2:$P$200,0)),"") -> 15_商機字典_OppLibrary | C7: =IFERROR(INDEX($S$2:$S$200,MATCH($B$4&"-1",$P$2:$P$200,0)),"") -> 先看這 85 門越南醫院市場可以做的生意，分成 A~J 十個族群。只看「在賣什麼／誰付錢／大概多少錢／越南現況」四欄，找跟你本業有關的。 | D7: =IFERROR(INDEX($T$2:$T$200,MATCH($B$4&"-1",$P$2:$P$200,0)),"") -> 不用改任何格子 | E7: =IFERROR(INDEX($U$2:$U$200,MATCH($B$4&"-1",$P$2:$P$200,0)),"") -> 圈出 3–5 個你做得到的商機 | P7: ② 夥伴｜我已經在夥伴名單上-1 | R7: 12_夥伴視角_PartnerView | S7: 在下拉選單選你的代號（顯示「P-016 影像設備與PACS整合商」這種格式），這一頁自動列出你被指名的所有能力項與所屬商機。 | T7: 只改下拉那一格 | U7: 看到自己被指名的完整清單
A8: 第 2 步 | B8: =IFERROR(INDEX($R$2:$R$200,MATCH($B$4&"-2",$P$2:$P$200,0)),"") -> 15_商機字典_OppLibrary | C8: =IFERROR(INDEX($S$2:$S$200,MATCH($B$4&"-2",$P$2:$P$200,0)),"") -> 看 L 欄「★白地商機」——越南有這門生意，但聯盟目前沒有能力接。那是最歡迎你補位的位置。 | D8: =IFERROR(INDEX($T$2:$T$200,MATCH($B$4&"-2",$P$2:$P$200,0)),"") -> 不用改任何格子 | E8: =IFERROR(INDEX($U$2:$U$200,MATCH($B$4&"-2",$P$2:$P$200,0)),"") -> 確認裡面有沒有你的位置 | P8: ② 夥伴｜我已經在夥伴名單上-2 | R8: 17_商機作戰卡_OppView | S8: 挑一個你有份的商機，看這場仗整體怎麼打：還缺哪些能力、對手是誰、憑什麼贏、卡在哪些法規門檻。 | T8: 只改下拉那一格 | U8: 知道自己在這場仗裡的位置
A9: 第 3 步 | B9: =IFERROR(INDEX($R$2:$R$200,MATCH($B$4&"-3",$P$2:$P$200,0)),"") -> 17_商機作戰卡_OppView | C9: =IFERROR(INDEX($S$2:$S$200,MATCH($B$4&"-3",$P$2:$P$200,0)),"") -> 在最上面的下拉選單挑一個你圈出來的商機，這一頁會自動組出作戰卡：需要哪些能力、誰在做、還缺什麼、對手是誰。 | D9: =IFERROR(INDEX($T$2:$T$200,MATCH($B$4&"-3",$P$2:$P$200,0)),"") -> 只改下拉那一格 | E9: =IFERROR(INDEX($U$2:$U$200,MATCH($B$4&"-3",$P$2:$P$200,0)),"") -> 知道你要補的是哪一塊 | P9: ② 夥伴｜我已經在夥伴名單上-3 | R9: 11_缺口招募_GapRFI | S9: 看你負責的能力旁邊還缺什麼。如果是你能一起接的，主動說，比等 PI 來問快。 | T9: 不用改任何格子 | U9: 列出你可以一起接的缺口
A10: 第 4 步 | B10: =IFERROR(INDEX($R$2:$R$200,MATCH($B$4&"-4",$P$2:$P$200,0)),"") -> 11_缺口招募_GapRFI | C10: =IFERROR(INDEX($S$2:$S$200,MATCH($B$4&"-4",$P$2:$P$200,0)),"") -> 看紅底的那幾列——那是「牽動 ≥3 個商機」的缺口，補一個能同時解鎖好幾門生意，聯盟最急著找人。 | D10: =IFERROR(INDEX($T$2:$T$200,MATCH($B$4&"-4",$P$2:$P$200,0)),"") -> 不用改任何格子 | E10: =IFERROR(INDEX($U$2:$U$200,MATCH($B$4&"-4",$P$2:$P$200,0)),"") -> 選出你要認領的缺口 | P10: ② 夥伴｜我已經在夥伴名單上-4 | R10: 15_商機字典_OppLibrary | S10: 查你「沒有被指名、但其實做得到」的生意。被指名的清單是 PI 的判斷，不一定完整。 | T10: 不用改任何格子 | U10: 列出你想爭取的商機
A11: 第 5 步 | B11: =IFERROR(INDEX($R$2:$R$200,MATCH($B$4&"-5",$P$2:$P$200,0)),"") -> （回報給 PI，不用動這個檔） | C11: =IFERROR(INDEX($S$2:$S$200,MATCH($B$4&"-5",$P$2:$P$200,0)),"") -> 把你能做的商機與想認領的缺口，填進 VMH-EcoMap-3 夥伴提案回覆表交回來。這個主檔由 PI 統一維護。 | D11: =IFERROR(INDEX($T$2:$T$200,MATCH($B$4&"-5",$P$2:$P$200,0)),"") -> 不用改任何格子 | E11: =IFERROR(INDEX($U$2:$U$200,MATCH($B$4&"-5",$P$2:$P$200,0)),"") -> 提案回覆表已寄出 | P11: ② 夥伴｜我已經在夥伴名單上-5 | R11: （回報給 PI，不用動這個檔） | S11: 有任何異動請 PI 更新 03 能力總表與 04 夥伴拼圖，不要自己改——那兩頁是全工具的資料源。 | T11: 不用改任何格子 | U11: 異動已回報
P12: ③ 業主／老闆｜我要看整體與該打哪一個-1 | R12: 儀表板_Dashboard | S12: 六個數字卡加四張圖，三十秒看完整體：商機族群分佈、越南現況、各領域缺口、管線階段。開會先投影這頁。 | T12: 不用改任何格子 | U12: 掌握整體盤勢
A13: 三十秒認識這個工具 | P13: ③ 業主／老闆｜我要看整體與該打哪一個-2 | R13: 儀表板_Dashboard | S13: 看 Top 10 攻擊順位表。分數已自動算好＝價值 × 準備度 × 越南現況 − 缺口扣分。 | T13: 不用改任何格子 | U13: 知道前十名是哪些
A14: 它在回答什麼 | B14: 「大家一起去越南做醫院生意」——哪些生意可以做、我們做得到哪些、缺什麼、誰來補、什麼時候做。 | P14: ③ 業主／老闆｜我要看整體與該打哪一個-3 | R14: 14_商機清單_Pipeline | S14: A 欄下拉選一個商機，名稱、族群、越南現況、涵蓋領域、對應能力數、缺口數、建議付費方與金額級距全部自動帶入。你只要填本案實際的商業判斷。 | T14: 改 A 欄下拉＋商業判斷欄 | U14: 管線上有你拍板過的商機
A15: 它不回答什麼 | B15: 不回答「這一案划不划算」。財務試算在另一個檔：VMH-EcoMap-2 專案商模試算器。 | P15: ③ 業主／老闆｜我要看整體與該打哪一個-4 | R15: 17_商機作戰卡_OppView | S15: 對某一個商機要細節時看這頁：需要哪些能力、誰在做誰還缺、對手是誰、卡哪些門檻。 | T15: 只改下拉那一格 | U15: 知道這一案打不打得動
A16: 核心是兩張表 | B16: 03_能力總表（我們會什麼，60 項）與 15_商機字典（市場有什麼，85 門）。中間用 16_能力商機矩陣 打✓連起來，其餘 19 個分頁全部是這三張表自動算出來的。 | P16: ③ 業主／老闆｜我要看整體與該打哪一個-5 | R16: （跳到另一個檔） | S16: 要算錢請開 VMH-EcoMap-2 專案商模試算器。這個主檔回答「做不做、誰做、何時做」，不回答「划不划算」。 | T16: 不用改任何格子 | U16: 財務結論已另案試算
A17: 顏色怎麼看 | B17: 黃底＝可以改；藍字＝公式，改了會壞；綠＝就緒／通過；橘＝洽談中／注意；紅＝缺口／未通過。 | P17: ④ PI／專案經理｜我要跑週會、追進度-1 | R17: 13_待辦看板_Actions | S17: 未確認強制法規、高風險、缺口三張清單合一。週會直接照這頁跑，不用東翻西找。 | T17: 不用改任何格子 | U17: 本週要解的事已列出
A18: 分頁標籤顏色 | B18: 綠＝入口（從這裡開始）；藍綠＝夥伴看的；深藍＝決策與簡報用；中藍＝顧問工作區；灰＝維護區，平常不用打開。 | P18: ④ PI／專案經理｜我要跑週會、追進度-2 | R18: 01_總藍圖_Blueprint | S18: 紅色缺口與門檻警示就是本週要解的事。各夥伴在這張圖上確認自己的定位。 | T18: 不用改任何格子 | U18: 缺口地圖已對過
P19: ④ PI／專案經理｜我要跑週會、追進度-3 | R19: 03_能力總表_Master | S19: 有任何盤點異動只改這裡——階段、拼圖狀態、分數。這是單一資料源，其他 20 個分頁全部自動連動。 | T19: 只改黃色儲存格 | U19: 異動已寫入，全檔連動
A20: 五個身分一覽（投影時用這塊，讓每個人先認領自己的角色） | P20: ④ PI／專案經理｜我要跑週會、追進度-4 | R20: 05_法規門檻_Gates | S20: 本階段的強制法規確認了沒？未確認不得過關。這是 Gate，不是 Task，不能往後排。 | T20: 只改黃色儲存格 | U20: 本階段法規狀態已更新
A21: ① 夥伴｜第一次打開這個檔 | C21: 第一步就去 → 15_商機字典_OppLibrary | P21: ④ PI／專案經理｜我要跑週會、追進度-5 | R21: 10_決策紀錄_Log | S21: 決議、升級事項、擱置理由都寫這裡。這頁不上鎖，自由書寫。三年後要回答「當初為什麼這樣決定」，靠的就是它。 | T21: 整頁自由書寫 | U21: 本週決議已留痕
A22: ② 夥伴｜我已經在夥伴名單上 | C22: 第一步就去 → 12_夥伴視角_PartnerView | P22: ⑤ 顧問／分析師｜我要更新盤點資料-1 | R22: 03_能力總表_Master | S22: 單一資料源。新增能力請到第一個空白列（第 65 列起）填 CAP-061…，只要 A 欄有 ID，分數、判斷、總藍圖矩陣、缺口計數全部自動出現。 | T22: 只改黃色儲存格 | U22: 新能力已納入全檔統計
A23: ③ 業主／老闆｜我要看整體與該打哪一個 | C23: 第一步就去 → 儀表板_Dashboard | P23: ⑤ 顧問／分析師｜我要更新盤點資料-2 | R23: 16_能力商機矩陣_CapOppMap | S23: 用打「✓」建立能力 ↔ 商機的多對多關聯，不用打字。勾完 03 的 AF 欄、15 與 14 全部自動更新。 | T23: 只在格子裡打 ✓ | U23: 關聯已建立
A24: ④ PI／專案經理｜我要跑週會、追進度 | C24: 第一步就去 → 13_待辦看板_Actions | P24: ⑤ 顧問／分析師｜我要更新盤點資料-3 | R24: 04_夥伴拼圖_Partners | S24: 新夥伴只要填名稱，ID 自動編號；右側 U–AD 勾選 D01–D10，涵蓋領域欄自動組成，不用打「D01; D04」這種格式。 | T24: 改黃色格＋勾選欄 | U24: 夥伴名冊與覆蓋矩陣已更新
A25: ⑤ 顧問／分析師｜我要更新盤點資料 | C25: 第一步就去 → 03_能力總表_Master | P25: ⑤ 顧問／分析師｜我要更新盤點資料-4 | R25: 02_情境權重_Scenario | S25: 調整評分權重（合計必須等於 1），60 項能力的價值分與準備分會同步重算。改這裡等於改全檔的排序邏輯。 | T25: 只改黃色儲存格 | U25: 評分邏輯已調整
P26: ⑤ 顧問／分析師｜我要更新盤點資料-5 | R26: 98_選單維護_Lists | S26: 所有下拉選單的唯一維護處。要新增選項只在該欄最下方接著往下填，全工具的下拉自動增加。請勿刪標題列、勿在清單中間留空白。 | T26: 只改黃色儲存格 | U26: 選單已擴充
A27: ★ 這一頁沒有任何數字要你填。夥伴版的 7 個分頁全部是唯讀的參考資料，你只需要在 17 商機作戰卡與 12 夥伴視角上方的下拉選單挑選項目。要回報請用 VMH-EcoMap-3 夥伴提案回覆表，不要改這個檔。

Sheet 儀表板_Dashboard
A1: 儀表板｜Dashboard（開會先投影這一頁：四張圖與六個數字，全部自動更新）
A2: ❓ 這頁在回答：整體盤勢如何？該打的前十名是哪些？ ▸ 本頁全部是公式與圖表，不需要也不可以輸入。數字來源：03 能力總表、14 商機清單、15 商機字典。看完這頁要細節：能力面→01 總藍圖，商機面→15 商機字典／14 商機清單。
A3: ⌂ 回導引頁 | R3: 商機族群分佈 | T3: 越南現況 | V3: 各領域缺口數 | X3: 商機管線階段
B4: 能力總數 | D4: ○缺口（能力） | F4: 立即推進 Go | R4: 規劃投資與交易架構 | S4: =COUNTIF(15_商機字典_OppLibrary!$D$5:$D$94,"A 規劃投資與交易架構") -> 5 | T4: ①已成熟 | U4: =COUNTIF(15_商機字典_OppLibrary!$F$5:$F$94,"①*") -> 3 | V4: D01 治理與投資 | W4: =COUNTIFS(03_能力總表_Master!$B$5:$B$154,"D01*",03_能力總表_Master!$H$5:$H$154,"缺口*") -> 0 | X4: Lead 潛在 | Y4: =COUNTIF(14_商機清單_Pipeline!$P$5:$P$24,"Lead*") -> 4
B5: =COUNTA(03_能力總表_Master!$A$5:$A$154) -> 60 | D5: =COUNTIF(03_能力總表_Master!$H$5:$H$154,"缺口*") -> 9 | F5: =COUNTIF(03_能力總表_Master!$W$5:$W$154,"立即推進*") -> 19 | R5: 建築工程與設施 | S5: =COUNTIF(15_商機字典_OppLibrary!$D$5:$D$94,"B 建築工程與設施") -> 8 | T5: ②起步中 | U5: =COUNTIF(15_商機字典_OppLibrary!$F$5:$F$94,"②*") -> 42 | V5: D02 臨床服務模式 | W5: =COUNTIFS(03_能力總表_Master!$B$5:$B$154,"D02*",03_能力總表_Master!$H$5:$H$154,"缺口*") -> 0 | X5: Qualified 已篩選 | Y5: =COUNTIF(14_商機清單_Pipeline!$P$5:$P$24,"Qualified*") -> 2
R6: 醫材與臨床設備 | S6: =COUNTIF(15_商機字典_OppLibrary!$D$5:$D$94,"C 醫材與臨床設備") -> 10 | T6: ③尚未出現 | U6: =COUNTIF(15_商機字典_OppLibrary!$F$5:$F$94,"③*") -> 40 | V6: D03 醫院設施與機電 | W6: =COUNTIFS(03_能力總表_Master!$B$5:$B$154,"D03*",03_能力總表_Master!$H$5:$H$154,"缺口*") -> 0 | X6: Proposal 已提案 | Y6: =COUNTIF(14_商機清單_Pipeline!$P$5:$P$24,"Proposal*") -> 1
B7: 商機總數 | D7: ③越南尚未出現 | F7: ★白地商機 | R7: 數位基建與資安 | S7: =COUNTIF(15_商機字典_OppLibrary!$D$5:$D$94,"D 數位基建與資安") -> 7 | V7: D04 數位基建與物聯網 | W7: =COUNTIFS(03_能力總表_Master!$B$5:$B$154,"D04*",03_能力總表_Master!$H$5:$H$154,"缺口*") -> 0 | X7: Negotiation 議約中 | Y7: =COUNTIF(14_商機清單_Pipeline!$P$5:$P$24,"Negotiation*") -> 1
B8: =COUNTA(15_商機字典_OppLibrary!$B$5:$B$94) -> 85 | D8: =COUNTIF(15_商機字典_OppLibrary!$F$5:$F$94,"③*") -> 40 | F8: =COUNTIF(15_商機字典_OppLibrary!$L$5:$L$94,"★*") -> 6 | R8: 醫療資訊與資料 | S8: =COUNTIF(15_商機字典_OppLibrary!$D$5:$D$94,"E 醫療資訊與資料") -> 12 | V8: D05 醫材與診斷 | W8: =COUNTIFS(03_能力總表_Master!$B$5:$B$154,"D05*",03_能力總表_Master!$H$5:$H$154,"缺口*") -> 3 | X8: Won 已簽約 | Y8: =COUNTIF(14_商機清單_Pipeline!$P$5:$P$24,"Won*") -> 0
R9: AI與智慧醫療 | S9: =COUNTIF(15_商機字典_OppLibrary!$D$5:$D$94,"F AI與智慧醫療") -> 17 | V9: D06 醫療資訊與資料 | W9: =COUNTIFS(03_能力總表_Master!$B$5:$B$154,"D06*",03_能力總表_Master!$H$5:$H$154,"缺口*") -> 2
R10: 品質認證與人才 | S10: =COUNTIF(15_商機字典_OppLibrary!$D$5:$D$94,"G 品質認證與人才") -> 4 | V10: D07 品質與病安 | W10: =COUNTIFS(03_能力總表_Master!$B$5:$B$154,"D07*",03_能力總表_Master!$H$5:$H$154,"缺口*") -> 0
R11: 供應鏈與維運服務 | S11: =COUNTIF(15_商機字典_OppLibrary!$D$5:$D$94,"H 供應鏈與維運服務") -> 7 | V11: D08 人才與技轉 | W11: =COUNTIFS(03_能力總表_Master!$B$5:$B$154,"D08*",03_能力總表_Master!$H$5:$H$154,"缺口*") -> 1
R12: 照護服務新業態 | S12: =COUNTIF(15_商機字典_OppLibrary!$D$5:$D$94,"I 照護服務新業態") -> 10 | V12: D09 供應鏈與維運 | W12: =COUNTIFS(03_能力總表_Master!$B$5:$B$154,"D09*",03_能力總表_Master!$H$5:$H$154,"缺口*") -> 0
R13: 商模支付與病人生態 | S13: =COUNTIF(15_商機字典_OppLibrary!$D$5:$D$94,"J 商模支付與病人生態") -> 5 | V13: D10 商模與病人生態 | W13: =COUNTIFS(03_能力總表_Master!$B$5:$B$154,"D10*",03_能力總表_Master!$H$5:$H$154,"缺口*") -> 3
B51: Top 10 攻擊順位（0.45×價值＋0.35×準備＋0.2×越南現況－缺口扣分；白地商機另走 13④）
B52: 順位 | C52: 商機 | G52: 優先分 | I52: 越南現況 | J52: ○缺口
B53: 1 | C53: =IFERROR(INDEX(15_商機字典_OppLibrary!$U$5:$U$94,MATCH(1,15_商機字典_OppLibrary!$Z$5:$Z$94,0)),"") -> OPP-78 居家醫療、居家護理與安寧 | G53: =IFERROR(INDEX(15_商機字典_OppLibrary!$Y$5:$Y$94,MATCH(1,15_商機字典_OppLibrary!$Z$5:$Z$94,0)),"") -> 4.20082 | I53: =IFERROR(LEFT(INDEX(15_商機字典_OppLibrary!$F$5:$F$94,MATCH(1,15_商機字典_OppLibrary!$Z$5:$Z$94,0)),7),"") -> ③ 尚未出現： | J53: =IFERROR(INDEX(15_商機字典_OppLibrary!$K$5:$K$94,MATCH(1,15_商機字典_OppLibrary!$Z$5:$Z$94,0)),"") -> 0
B54: 2 | C54: =IFERROR(INDEX(15_商機字典_OppLibrary!$U$5:$U$94,MATCH(2,15_商機字典_OppLibrary!$Z$5:$Z$94,0)),"") -> OPP-79 復健與亞急性照護中心 | G54: =IFERROR(INDEX(15_商機字典_OppLibrary!$Y$5:$Y$94,MATCH(2,15_商機字典_OppLibrary!$Z$5:$Z$94,0)),"") -> 4.15083 | I54: =IFERROR(LEFT(INDEX(15_商機字典_OppLibrary!$F$5:$F$94,MATCH(2,15_商機字典_OppLibrary!$Z$5:$Z$94,0)),7),"") -> ③ 尚未出現： | J54: =IFERROR(INDEX(15_商機字典_OppLibrary!$K$5:$K$94,MATCH(2,15_商機字典_OppLibrary!$Z$5:$Z$94,0)),"") -> 0
B55: 3 | C55: =IFERROR(INDEX(15_商機字典_OppLibrary!$U$5:$U$94,MATCH(3,15_商機字典_OppLibrary!$Z$5:$Z$94,0)),"") -> OPP-42 閉環給藥與條碼用藥安全 | G55: =IFERROR(INDEX(15_商機字典_OppLibrary!$Y$5:$Y$94,MATCH(3,15_商機字典_OppLibrary!$Z$5:$Z$94,0)),"") -> 4.15046 | I55: =IFERROR(LEFT(INDEX(15_商機字典_OppLibrary!$F$5:$F$94,MATCH(3,15_商機字典_OppLibrary!$Z$5:$Z$94,0)),7),"") -> ③ 尚未出現： | J55: =IFERROR(INDEX(15_商機字典_OppLibrary!$K$5:$K$94,MATCH(3,15_商機字典_OppLibrary!$Z$5:$Z$94,0)),"") -> 0
B56: 4 | C56: =IFERROR(INDEX(15_商機字典_OppLibrary!$U$5:$U$94,MATCH(4,15_商機字典_OppLibrary!$Z$5:$Z$94,0)),"") -> OPP-35 臨床術語與編碼服務 | G56: =IFERROR(INDEX(15_商機字典_OppLibrary!$Y$5:$Y$94,MATCH(4,15_商機字典_OppLibrary!$Z$5:$Z$94,0)),"") -> 4.09039 | I56: =IFERROR(LEFT(INDEX(15_商機字典_OppLibrary!$F$5:$F$94,MATCH(4,15_商機字典_OppLibrary!$Z$5:$Z$94,0)),7),"") -> ③ 尚未出現： | J56: =IFERROR(INDEX(15_商機字典_OppLibrary!$K$5:$K$94,MATCH(4,15_商機字典_OppLibrary!$Z$5:$Z$94,0)),"") -> 0
B57: 5 | C57: =IFERROR(INDEX(15_商機字典_OppLibrary!$U$5:$U$94,MATCH(5,15_商機字典_OppLibrary!$Z$5:$Z$94,0)),"") -> OPP-29 災難復原與營運持續(DR/BCM) | G57: =IFERROR(INDEX(15_商機字典_OppLibrary!$Y$5:$Y$94,MATCH(5,15_商機字典_OppLibrary!$Z$5:$Z$94,0)),"") -> 4.04033 | I57: =IFERROR(LEFT(INDEX(15_商機字典_OppLibrary!$F$5:$F$94,MATCH(5,15_商機字典_OppLibrary!$Z$5:$Z$94,0)),7),"") -> ③ 尚未出現： | J57: =IFERROR(INDEX(15_商機字典_OppLibrary!$K$5:$K$94,MATCH(5,15_商機字典_OppLibrary!$Z$5:$Z$94,0)),"") -> 0
B58: 6 | C58: =IFERROR(INDEX(15_商機字典_OppLibrary!$U$5:$U$94,MATCH(6,15_商機字典_OppLibrary!$Z$5:$Z$94,0)),"") -> OPP-63 開院前臨床安全驗證與試營運 | G58: =IFERROR(INDEX(15_商機字典_OppLibrary!$Y$5:$Y$94,MATCH(6,15_商機字典_OppLibrary!$Z$5:$Z$94,0)),"") -> 4.03067 | I58: =IFERROR(LEFT(INDEX(15_商機字典_OppLibrary!$F$5:$F$94,MATCH(6,15_商機字典_OppLibrary!$Z$5:$Z$94,0)),7),"") -> ③ 尚未出現： | J58: =IFERROR(INDEX(15_商機字典_OppLibrary!$K$5:$K$94,MATCH(6,15_商機字典_OppLibrary!$Z$5:$Z$94,0)),"") -> 0
B59: 7 | C59: =IFERROR(INDEX(15_商機字典_OppLibrary!$U$5:$U$94,MATCH(7,15_商機字典_OppLibrary!$Z$5:$Z$94,0)),"") -> OPP-71 洗腎連鎖（衛星洗腎中心） | G59: =IFERROR(INDEX(15_商機字典_OppLibrary!$Y$5:$Y$94,MATCH(7,15_商機字典_OppLibrary!$Z$5:$Z$94,0)),"") -> 3.96075 | I59: =IFERROR(LEFT(INDEX(15_商機字典_OppLibrary!$F$5:$F$94,MATCH(7,15_商機字典_OppLibrary!$Z$5:$Z$94,0)),7),"") -> ③ 尚未出現： | J59: =IFERROR(INDEX(15_商機字典_OppLibrary!$K$5:$K$94,MATCH(7,15_商機字典_OppLibrary!$Z$5:$Z$94,0)),"") -> 0
B60: 8 | C60: =IFERROR(INDEX(15_商機字典_OppLibrary!$U$5:$U$94,MATCH(8,15_商機字典_OppLibrary!$Z$5:$Z$94,0)),"") -> OPP-65 消毒供應外包（區域CSSD服務化） | G60: =IFERROR(INDEX(15_商機字典_OppLibrary!$Y$5:$Y$94,MATCH(8,15_商機字典_OppLibrary!$Z$5:$Z$94,0)),"") -> 3.96069 | I60: =IFERROR(LEFT(INDEX(15_商機字典_OppLibrary!$F$5:$F$94,MATCH(8,15_商機字典_OppLibrary!$Z$5:$Z$94,0)),7),"") -> ③ 尚未出現： | J60: =IFERROR(INDEX(15_商機字典_OppLibrary!$K$5:$K$94,MATCH(8,15_商機字典_OppLibrary!$Z$5:$Z$94,0)),"") -> 0
B61: 9 | C61: =IFERROR(INDEX(15_商機字典_OppLibrary!$U$5:$U$94,MATCH(9,15_商機字典_OppLibrary!$Z$5:$Z$94,0)),"") -> OPP-46 內視鏡AI息肉偵測 | G61: =IFERROR(INDEX(15_商機字典_OppLibrary!$Y$5:$Y$94,MATCH(9,15_商機字典_OppLibrary!$Z$5:$Z$94,0)),"") -> 3.9605 | I61: =IFERROR(LEFT(INDEX(15_商機字典_OppLibrary!$F$5:$F$94,MATCH(9,15_商機字典_OppLibrary!$Z$5:$Z$94,0)),7),"") -> ③ 尚未出現： | J61: =IFERROR(INDEX(15_商機字典_OppLibrary!$K$5:$K$94,MATCH(9,15_商機字典_OppLibrary!$Z$5:$Z$94,0)),"") -> 0
B62: 10 | C62: =IFERROR(INDEX(15_商機字典_OppLibrary!$U$5:$U$94,MATCH(10,15_商機字典_OppLibrary!$Z$5:$Z$94,0)),"") -> OPP-38 醫材資料介接與床邊自動擷取 | G62: =IFERROR(INDEX(15_商機字典_OppLibrary!$Y$5:$Y$94,MATCH(10,15_商機字典_OppLibrary!$Z$5:$Z$94,0)),"") -> 3.96042 | I62: =IFERROR(LEFT(INDEX(15_商機字典_OppLibrary!$F$5:$F$94,MATCH(10,15_商機字典_OppLibrary!$Z$5:$Z$94,0)),7),"") -> ③ 尚未出現： | J62: =IFERROR(INDEX(15_商機字典_OppLibrary!$K$5:$K$94,MATCH(10,15_商機字典_OppLibrary!$Z$5:$Z$94,0)),"") -> 0
B64: ★ 本頁圖表與數字全部自動連動：03/14/15 的資料一改，重新開啟或按 F9 即更新。不要在本頁輸入任何東西。要看單一商機怎麼打 → 17 商機作戰卡。

Sheet 15_商機字典_OppLibrary
A1: 15 商機字典｜Opportunity Library（越南醫院市場有哪些生意可以做）
A2: ❓ 這頁在回答：越南醫院市場有哪 85 門生意可以做？（★不熟醫療產業先看這頁） ▸ 不熟醫療產業的夥伴請先看這頁：85 種可以獨立談的生意，分成 A~J 十個族群，說明它在賣什麼、誰付錢、大概多少錢、通常什麼階段切入，以及「越南現況」——標③尚未出現的，代表越南目前幾乎沒人在做，是主動出擊的空間。藍字欄位（G-L、T）由 16 能力商機矩陣自動算出。14 商機清單的商機下拉就是從本頁 B 欄來的。
A3: ★ 本頁每一列對應 16 能力商機矩陣的一個欄位（第5列↔D欄、第6列↔E欄…），請不要插入或刪除列，要新增請在最下方空白列往下填。 | G3: ="全部 "&COUNTA($B$5:$B$94)&" 個商機 ｜ ③尚未出現（越南幾乎空白）"&COUNTIF($F$5:$F$94,"③*")&" 個 ｜ ★白地商機（聯盟目前無對應能力）"&COUNTIF($L$5:$L$94,"★*")&" 個 ｜ 有缺口可對外招募 "&COUNTIF($L$5:$L$94,"有缺口*")&" 個 ｜ 已列入14商機清單 "&COUNTIF($T$5:$T$94,">0")&" 個" -> 全部 85 個商機 ｜ ③尚未出現（越南幾乎空白）40 個 ｜ ★白地商機（聯盟目前無對應能力）6 個 ｜ 有缺口可對外招募 26 個 ｜ 已列入14商機清單 8 個 | V3: ⌂ 回導引頁
A4: 商機代號 OPP ID | B4: 商機名稱（中） Opportunity | C4: Opportunity (EN) | D4: 商機族群 Family | E4: 這門生意在賣什麼／誰付錢 What we sell & who pays | F4: 越南現況 VN maturity | G4: 涵蓋領域（自動） Domains | H4: 對應能力 CAP數(自動) | I4: 平均價值分 (自動) | J4: 平均準備分 (自動) | K4: ○缺口數 (自動) | L4: ★聯盟能力對應狀態（自動） Our position | M4: 典型切入階段 Stage | N4: 典型付費方 Typical payer | O4: 典型交易模式 Txn mode | P4: 典型金額級距 Amount tier | Q4: 可否獨立成案 Standalone | R4: 建議主責 Lead | S4: 越南在地重點／注意事項 Vietnam notes | T4: 已列入14 商機清單(自動) | U4: 代號＋名稱 (下拉用·勿刪) | V4: 主要競爭者／在地玩家 Competitors & incumbents | W4: 我們的切入角度 Our angle | X4: 群晶主導 CAP數(自動) | Y4: 攻擊優先分 (自動) | Z4: 攻擊順位 (自動) | AA4: ★層級 Layer | AB4: ★深研提示（本項專屬發現） Research finding | AC4: 信心 Conf | AD4: ★越南現況（家族／領域趨勢） VN status now
A5: OPP-01 | B5: 醫院投資規劃與PPP交易架構顧問 | C5: Hospital Investment & PPP Structuring | D5: A 規劃投資與交易架構 | E5: 把「要不要蓋、誰出錢、風險怎麼分」變成可以簽的交易架構；賣可行性報告、財務模型與契約設計 | F5: ② 起步中：剛開始有人做 | G5: =IF($A5="","",IF($H5=0,"（尚無對應能力）",IFERROR(INDEX(16_能力商機矩陣_CapOppMap!$D$160:$CO$160,MATCH($A5,16_能力商機矩陣_CapOppMap!$D$4:$CO$4,0)),""))) -> D01; D10 | H5: =IF($A5="","",IFERROR(INDEX(16_能力商機矩陣_CapOppMap!$D$156:$CO$156,MATCH($A5,16_能力商機矩陣_CapOppMap!$D$4:$CO$4,0)),"")) -> 9 | I5: =IF($A5="","",IFERROR(INDEX(16_能力商機矩陣_CapOppMap!$D$157:$CO$157,MATCH($A5,16_能力商機矩陣_CapOppMap!$D$4:$CO$4,0)),"")) -> 3.7 | J5: =IF($A5="","",IFERROR(INDEX(16_能力商機矩陣_CapOppMap!$D$158:$CO$158,MATCH($A5,16_能力商機矩陣_CapOppMap!$D$4:$CO$4,0)),"")) -> 2 | K5: =IF($A5="","",IFERROR(INDEX(16_能力商機矩陣_CapOppMap!$D$159:$CO$159,MATCH($A5,16_能力商機矩陣_CapOppMap!$D$4:$CO$4,0)),"")) -> 0 | L5: =IF($A5="","",IF($H5=0,"★白地商機：目前無對應能力，需新增能力或找新夥伴",IF($K5>0,"有缺口："&$K5&"項可對外招募","已有能力可承接"))) -> 已有能力可承接 | M5: G0 | N5: 越南政府／衛生部預算 | O5: 顧問服務 | P5: 500K-2M USD | Q5: 是 | R5: PPP Advisor | S5: ⚠Decree 71/2025 已被 Nghị định 243/2025（2025-09-11生效）第81條全部廢止，現行細則為243/2025體系（另含312/2025財務管理、257/2025 BT合約、19/2026重點專案審定）；醫療PPP門檻在新體系下的條文位置待查。案例面：河內2026-08-10核准醫療綜合體PPP-BT案（逾14.2兆越盾、1,600床）——市場已從「僅2案」進入新階段 | T5: =IF($A5="","",COUNTIF(14_商機清單_Pipeline!$A$5:$A$34,$U5)) -> 1 | U5: =IF($B5="","",$A5&" "&$B5) -> OPP-01 醫院投資規劃與PPP交易架構顧問 | V5: 世銀/ADB體系顧問、四大會計師事務所；越南健康PPP全國僅2案、無成熟本土顧問 | W5: 台灣醫院全生命週期實績＋願意當PPP先行者（PPP細則已改為 Nghị định 243/2025 體系） | X5: =IF($A5="","",IFERROR(INDEX(16_能力商機矩陣_CapOppMap!$D$162:$CO$162,MATCH($A5,16_能力商機矩陣_CapOppMap!$D$4:$CO$4,0)),"")) -> 0 | Y5: =IF(OR($A5="",$H5=""),"",IF($H5=0,"",ROUND(0.45*$I5+0.35*$J5+0.2*IF(LEFT($F5,1)="③",5,IF(LEFT($F5,1)="②",3,1))-IF($K5>0,0.3,0),2)+ROW()/100000)) -> 2.97005 | Z5: =IF($Y5="","",RANK($Y5,$Y$5:$Y$94)) -> 73 | AA5: G 治理合規層（跨層） | AB5: 修正note：門檻取消的法源是Law 57/2024修法（2025-01-15生效）；Decree 71/2025（2025-03-28生效）⚠已被 Nghị định 243/2025（2025-09-11生效）第81條全部廢止，引用時務必改用243/2025體系。「全國健康PPP僅2案（安沛、峴港）」為2024-08官方數據、2026年未見官方重申；新增大案：河內市人民議會2026-08-10核准「醫療綜合體－高齡者照護－河內醫科大學」PPP-BT案，總投資逾14.2兆越盾、含1,600床教學醫院。衛生部醫療PPP指引通知自2024-06徵詢至今仍為草案。 | AC5: A | AD5: Law 57/2024（2025-01生效）取消PPP投資門檻、恢復BT模式；Decree 71/2025（2025-03-28生效）刪除細則限制、招標縮至10-60天，⚠但已被Nghị định 243/2025（2025-09-11）全部廢止。健康PPP原僅2案（安沛、峴港），2026-08-10河內核准逾14.2兆越盾醫療綜合體PPP-BT案。外資交易熱：Thomson收購FV醫院3.81億美元（越南史上最大醫療交易）、Raffles收購AIH。外資可100%持有醫院，門檻2,000萬美元。
A6: OPP-02 | B6: 臨床服務定位與營運模式規劃 | C6: Clinical Service Model & Operations Planning | D6: A 規劃投資與交易架構 | E6: 決定這家醫院要看什麼病、開幾床、病人怎麼走；後面所有採購金額都由它決定 | F6: ② 起步中：剛開始有人做 | G6: =IF($A6="","",IF($H6=0,"（尚無對應能力）",IFERROR(INDEX(16_能力商機矩陣_CapOppMap!$D$160:$CO$160,MATCH($A6,16_能力商機矩陣_CapOppMap!$D$4:$CO$4,0)),""))) -> D02 | H6: =IF($A6="","",IFERROR(INDEX(16_能力商機矩陣_CapOppMap!$D$156:$CO$156,MATCH($A6,16_能力商機矩陣_CapOppMap!$D$4:$CO$4,0)),"")) -> 6 | I6: =IF($A6="","",IFERROR(INDEX(16_能力商機矩陣_CapOppMap!$D$157:$CO$157,MATCH($A6,16_能力商機矩陣_CapOppMap!$D$4:$CO$4,0)),"")) -> 4.7 | J6: =IF($A6="","",IFERROR(INDEX(16_能力商機矩陣_CapOppMap!$D$158:$CO$158,MATCH($A6,16_能力商機矩陣_CapOppMap!$D$4:$CO$4,0)),"")) -> 2.7 | K6: =IF($A6="","",IFERROR(INDEX(16_能力商機矩陣_CapOppMap!$D$159:$CO$159,MATCH($A6,16_能力商機矩陣_CapOppMap!$D$4:$CO$4,0)),"")) -> 0 | L6: =IF($A6="","",IF($H6=0,"★白地商機：目前無對應能力，需新增能力或找新夥伴",IF($K6>0,"有缺口："&$K6&"項可對外招募","已有能力可承接"))) -> 已有能力可承接 | M6: G1 | N6: 醫院業主資本支出(CAPEX) | O6: 顧問服務 | P6: 100K-500K USD | Q6: 是 | R6: Clinical Planner | S6: 河內／胡志明市公立醫院使用率超過設計量能200%，服務組合與分流設計是真正的痛點 | T6: =IF($A6="","",COUNTIF(14_商機清單_Pipeline!$A$5:$A$34,$U6)) -> 0 | U6: =IF($B6="","",$A6&" "&$B6) -> OPP-02 臨床服務定位與營運模式規劃 | V6: 國際醫管顧問零星進場；公立醫院多自行規劃 | W6: 台灣參考醫院的真實營運數據在地化，不是紙上模型 | X6: =IF($A6="","",IFERROR(INDEX(16_能力商機矩陣_CapOppMap!$D$162:$CO$162,MATCH($A6,16_能力商機矩陣_CapOppMap!$D$4:$CO$4,0)),"")) -> 0 | Y6: =IF(OR($A6="",$H6=""),"",IF($H6=0,"",ROUND(0.45*$I6+0.35*$J6+0.2*IF(LEFT($F6,1)="③",5,IF(LEFT($F6,1)="②",3,1))-IF($K6>0,0.3,0),2)+ROW()/100000)) -> 3.66006 | Z6: =IF($Y6="","",RANK($Y6,$Y$5:$Y$94)) -> 36 | AA6: G 治理合規層（跨層） | AB6: （本項無專屬發現——見同列右方的家族／領域趨勢，或 19／20 分頁） | AC6: B | AD6: Law 57/2024（2025-01生效）取消PPP投資門檻、恢復BT模式；Decree 71/2025（2025-03-28生效）刪除細則限制、招標縮至10-60天，⚠但已被Nghị định 243/2025（2025-09-11）全部廢止。健康PPP原僅2案（安沛、峴港），2026-08-10河內核准逾14.2兆越盾醫療綜合體PPP-BT案。外資交易熱：Thomson收購FV醫院3.81億美元（越南史上最大醫療交易）、Raffles收購AIH。外資可100%持有醫院，門檻2,000萬美元。
A7: OPP-03 | B7: 外資醫院綠地投資與經營 | C7: Foreign-invested Greenfield Hospital | D7: A 規劃投資與交易架構 | E7: 自己蓋、自己開一家醫院，賺中產階級自費與商業保險；也接回每年赴海外就醫的病人 | F7: ② 起步中：剛開始有人做 | G7: =IF($A7="","",IF($H7=0,"（尚無對應能力）",IFERROR(INDEX(16_能力商機矩陣_CapOppMap!$D$160:$CO$160,MATCH($A7,16_能力商機矩陣_CapOppMap!$D$4:$CO$4,0)),""))) -> D01; D02; D10 | H7: =IF($A7="","",IFERROR(INDEX(16_能力商機矩陣_CapOppMap!$D$156:$CO$156,MATCH($A7,16_能力商機矩陣_CapOppMap!$D$4:$CO$4,0)),"")) -> 4 | I7: =IF($A7="","",IFERROR(INDEX(16_能力商機矩陣_CapOppMap!$D$157:$CO$157,MATCH($A7,16_能力商機矩陣_CapOppMap!$D$4:$CO$4,0)),"")) -> 4.2 | J7: =IF($A7="","",IFERROR(INDEX(16_能力商機矩陣_CapOppMap!$D$158:$CO$158,MATCH($A7,16_能力商機矩陣_CapOppMap!$D$4:$CO$4,0)),"")) -> 2.2 | K7: =IF($A7="","",IFERROR(INDEX(16_能力商機矩陣_CapOppMap!$D$159:$CO$159,MATCH($A7,16_能力商機矩陣_CapOppMap!$D$4:$CO$4,0)),"")) -> 0 | L7: =IF($A7="","",IF($H7=0,"★白地商機：目前無對應能力，需新增能力或找新夥伴",IF($K7>0,"有缺口："&$K7&"項可對外招募","已有能力可承接"))) -> 已有能力可承接 | M7: G0 | N7: 民間投資方／基金 | O7: 民營醫院投資 | P7: >10M USD | Q7: 是 | R7: Commercial Director | S7: 外資醫院最低註冊資本US$20m、每床樓地板50㎡；私立僅占5.8%床數，政策目標2030年15%、2050年25% | T7: =IF($A7="","",COUNTIF(14_商機清單_Pipeline!$A$5:$A$34,$U7)) -> 0 | U7: =IF($B7="","",$A7&" "&$B7) -> OPP-03 外資醫院綠地投資與經營 | V7: Vinmec(9院)/Hoan My/Tam Anh 連鎖擴張；FV 已被 Thomson Medical 以約US$3.8億收購 | W7: 不與連鎖拚規模，聚焦專科旗艦＋台灣醫療品牌接外流病人 | X7: =IF($A7="","",IFERROR(INDEX(16_能力商機矩陣_CapOppMap!$D$162:$CO$162,MATCH($A7,16_能力商機矩陣_CapOppMap!$D$4:$CO$4,0)),"")) -> 0 | Y7: =IF(OR($A7="",$H7=""),"",IF($H7=0,"",ROUND(0.45*$I7+0.35*$J7+0.2*IF(LEFT($F7,1)="③",5,IF(LEFT($F7,1)="②",3,1))-IF($K7>0,0.3,0),2)+ROW()/100000)) -> 3.26007 | Z7: =IF($Y7="","",RANK($Y7,$Y$5:$Y$94)) -> 64 | AA7: L7 商模金流層 | AB7: WTO承諾允許100%外資醫院；醫院最低投資2,000萬美元、綜合門診200萬、專科20萬。Thomson/FV案（3.81億美元、16.8×EBITDA）為估值標竿。 | AC7: A | AD7: Law 57/2024（2025-01生效）取消PPP投資門檻、恢復BT模式；Decree 71/2025（2025-03-28生效）刪除細則限制、招標縮至10-60天，⚠但已被Nghị định 243/2025（2025-09-11）全部廢止。健康PPP原僅2案（安沛、峴港），2026-08-10河內核准逾14.2兆越盾醫療綜合體PPP-BT案。外資交易熱：Thomson收購FV醫院3.81億美元（越南史上最大醫療交易）、Raffles收購AIH。外資可100%持有醫院，門檻2,000萬美元。
A8: OPP-04 | B8: 公立醫院合作經營高端診區 | C8: Public-hospital Premium Wing (BCC/JV) | D8: A 規劃投資與交易架構 | E8: 出資在公立醫院裡蓋一個高階門診／影像／腫瘤診區，跟院方分帳；病人自費與商業保險付錢 | F8: ② 起步中：剛開始有人做 | G8: =IF($A8="","",IF($H8=0,"（尚無對應能力）",IFERROR(INDEX(16_能力商機矩陣_CapOppMap!$D$160:$CO$160,MATCH($A8,16_能力商機矩陣_CapOppMap!$D$4:$CO$4,0)),""))) -> D01; D02; D10 | H8: =IF($A8="","",IFERROR(INDEX(16_能力商機矩陣_CapOppMap!$D$156:$CO$156,MATCH($A8,16_能力商機矩陣_CapOppMap!$D$4:$CO$4,0)),"")) -> 4 | I8: =IF($A8="","",IFERROR(INDEX(16_能力商機矩陣_CapOppMap!$D$157:$CO$157,MATCH($A8,16_能力商機矩陣_CapOppMap!$D$4:$CO$4,0)),"")) -> 4.2 | J8: =IF($A8="","",IFERROR(INDEX(16_能力商機矩陣_CapOppMap!$D$158:$CO$158,MATCH($A8,16_能力商機矩陣_CapOppMap!$D$4:$CO$4,0)),"")) -> 2.2 | K8: =IF($A8="","",IFERROR(INDEX(16_能力商機矩陣_CapOppMap!$D$159:$CO$159,MATCH($A8,16_能力商機矩陣_CapOppMap!$D$4:$CO$4,0)),"")) -> 0 | L8: =IF($A8="","",IF($H8=0,"★白地商機：目前無對應能力，需新增能力或找新夥伴",IF($K8>0,"有缺口："&$K8&"項可對外招募","已有能力可承接"))) -> 已有能力可承接 | M8: G2 | N8: 民間投資方／基金 | O8: 共址合資 | P8: 2M-10M USD | Q8: 需組合 | R8: Commercial Lead | S8: 越南稱「社會化」，是最快取得公立醫院病人量的路徑，但法律灰帶大，合規設計要先做 | T8: =IF($A8="","",COUNTIF(14_商機清單_Pipeline!$A$5:$A$34,$U8)) -> 0 | U8: =IF($B8="","",$A8&" "&$B8) -> OPP-04 公立醫院合作經營高端診區 | V8: （待調查） | X8: =IF($A8="","",IFERROR(INDEX(16_能力商機矩陣_CapOppMap!$D$162:$CO$162,MATCH($A8,16_能力商機矩陣_CapOppMap!$D$4:$CO$4,0)),"")) -> 0 | Y8: =IF(OR($A8="",$H8=""),"",IF($H8=0,"",ROUND(0.45*$I8+0.35*$J8+0.2*IF(LEFT($F8,1)="③",5,IF(LEFT($F8,1)="②",3,1))-IF($K8>0,0.3,0),2)+ROW()/100000)) -> 3.26008 | Z8: =IF($Y8="","",RANK($Y8,$Y$5:$Y$94)) -> 63 | AA8: L7 商模金流層 | AB8: （本項無專屬發現——見同列右方的家族／領域趨勢，或 19／20 分頁） | AC8: B | AD8: Law 57/2024（2025-01生效）取消PPP投資門檻、恢復BT模式；Decree 71/2025（2025-03-28生效）刪除細則限制、招標縮至10-60天，⚠但已被Nghị định 243/2025（2025-09-11）全部廢止。健康PPP原僅2案（安沛、峴港），2026-08-10河內核准逾14.2兆越盾醫療綜合體PPP-BT案。外資交易熱：Thomson收購FV醫院3.81億美元（越南史上最大醫療交易）、Raffles收購AIH。外資可100%持有醫院，門檻2,000萬美元。
A9: OPP-05 | B9: 省級醫院升級改造整案 | C9: Provincial Hospital Upgrade Programme | D9: A 規劃投資與交易架構 | E9: 把老舊的省級醫院手術室、ICU、影像區整區翻新再配設備；省預算＋中央專項計畫付錢 | F9: ① 已成熟：在地已有供應商 | G9: =IF($A9="","",IF($H9=0,"（尚無對應能力）",IFERROR(INDEX(16_能力商機矩陣_CapOppMap!$D$160:$CO$160,MATCH($A9,16_能力商機矩陣_CapOppMap!$D$4:$CO$4,0)),""))) -> D03; D05 | H9: =IF($A9="","",IFERROR(INDEX(16_能力商機矩陣_CapOppMap!$D$156:$CO$156,MATCH($A9,16_能力商機矩陣_CapOppMap!$D$4:$CO$4,0)),"")) -> 4 | I9: =IF($A9="","",IFERROR(INDEX(16_能力商機矩陣_CapOppMap!$D$157:$CO$157,MATCH($A9,16_能力商機矩陣_CapOppMap!$D$4:$CO$4,0)),"")) -> 4.6 | J9: =IF($A9="","",IFERROR(INDEX(16_能力商機矩陣_CapOppMap!$D$158:$CO$158,MATCH($A9,16_能力商機矩陣_CapOppMap!$D$4:$CO$4,0)),"")) -> 2.4 | K9: =IF($A9="","",IFERROR(INDEX(16_能力商機矩陣_CapOppMap!$D$159:$CO$159,MATCH($A9,16_能力商機矩陣_CapOppMap!$D$4:$CO$4,0)),"")) -> 1 | L9: =IF($A9="","",IF($H9=0,"★白地商機：目前無對應能力，需新增能力或找新夥伴",IF($K9>0,"有缺口："&$K9&"項可對外招募","已有能力可承接"))) -> 有缺口：1項可對外招募 | M9: G2 | N9: 省級衛生局預算 | O9: 政府採購 | P9: >10M USD | Q9: 是 | R9: Healthcare Architect | S9: 60多個省、標案流量穩定，但目前多由在地與中韓廠商拿下，價格競爭激烈 | T9: =IF($A9="","",COUNTIF(14_商機清單_Pipeline!$A$5:$A$34,$U9)) -> 0 | U9: =IF($B9="","",$A9&" "&$B9) -> OPP-05 省級醫院升級改造整案 | V9: 省級標案多由在地與中韓 EPC 低價取得 | W9: 不拚土建低價，賣「機電＋驗證確效＋開院」整包品質 | X9: =IF($A9="","",IFERROR(INDEX(16_能力商機矩陣_CapOppMap!$D$162:$CO$162,MATCH($A9,16_能力商機矩陣_CapOppMap!$D$4:$CO$4,0)),"")) -> 0 | Y9: =IF(OR($A9="",$H9=""),"",IF($H9=0,"",ROUND(0.45*$I9+0.35*$J9+0.2*IF(LEFT($F9,1)="③",5,IF(LEFT($F9,1)="②",3,1))-IF($K9>0,0.3,0),2)+ROW()/100000)) -> 2.81009 | Z9: =IF($Y9="","",RANK($Y9,$Y$5:$Y$94)) -> 76 | AA9: L1 實體基礎層 | AB9: 峴港2021-25規劃7醫院項目13.6兆越盾；白梅二院/越德二院各約5,000億越盾（約1.9億美元）、設計各1,000床，2025-12-19落成、2026-06/07分別收治病人；六大醫院升級國際水準列入2021-2030規劃。 | AC9: A | AD9: Law 57/2024（2025-01生效）取消PPP投資門檻、恢復BT模式；Decree 71/2025（2025-03-28生效）刪除細則限制、招標縮至10-60天，⚠但已被Nghị định 243/2025（2025-09-11）全部廢止。健康PPP原僅2案（安沛、峴港），2026-08-10河內核准逾14.2兆越盾醫療綜合體PPP-BT案。外資交易熱：Thomson收購FV醫院3.81億美元（越南史上最大醫療交易）、Raffles收購AIH。外資可100%持有醫院，門檻2,000萬美元。
A10: OPP-06 | B10: 醫院建築與院區總體規劃設計 | C10: Hospital Master Planning & Design | D10: B 建築工程與設施 | E10: 院區配置、醫療功能空間與感染管制動線的規劃設計服務，是工程統包的前置設計費 | F10: ② 起步中：剛開始有人做 | G10: =IF($A10="","",IF($H10=0,"（尚無對應能力）",IFERROR(INDEX(16_能力商機矩陣_CapOppMap!$D$160:$CO$160,MATCH($A10,16_能力商機矩陣_CapOppMap!$D$4:$CO$4,0)),""))) -> D03 | H10: =IF($A10="","",IFERROR(INDEX(16_能力商機矩陣_CapOppMap!$D$156:$CO$156,MATCH($A10,16_能力商機矩陣_CapOppMap!$D$4:$CO$4,0)),"")) -> 4 | I10: =IF($A10="","",IFERROR(INDEX(16_能力商機矩陣_CapOppMap!$D$157:$CO$157,MATCH($A10,16_能力商機矩陣_CapOppMap!$D$4:$CO$4,0)),"")) -> 4.4 | J10: =IF($A10="","",IFERROR(INDEX(16_能力商機矩陣_CapOppMap!$D$158:$CO$158,MATCH($A10,16_能力商機矩陣_CapOppMap!$D$4:$CO$4,0)),"")) -> 2.4 | K10: =IF($A10="","",IFERROR(INDEX(16_能力商機矩陣_CapOppMap!$D$159:$CO$159,MATCH($A10,16_能力商機矩陣_CapOppMap!$D$4:$CO$4,0)),"")) -> 0 | L10: =IF($A10="","",IF($H10=0,"★白地商機：目前無對應能力，需新增能力或找新夥伴",IF($K10>0,"有缺口："&$K10&"項可對外招募","已有能力可承接"))) -> 已有能力可承接 | M10: G2 | N10: 醫院業主資本支出(CAPEX) | O10: 顧問服務 | P10: 500K-2M USD | Q10: 是 | R10: Healthcare Architect | S10: 須符合 QCVN 01:2021/BXD、TCVN 5687:2024（手術室>36㎡、淨高>3.1m）與消防審查流程 | T10: =IF($A10="","",COUNTIF(14_商機清單_Pipeline!$A$5:$A$34,$U10)) -> 0 | U10: =IF($B10="","",$A10&" "&$B10) -> OPP-06 醫院建築與院區總體規劃設計 | V10: 國際醫療建築事務所＋越南在地設計院 | W10: 醫療機能規劃與感控動線的臨床輸入（台灣參考醫院背書） | X10: =IF($A10="","",IFERROR(INDEX(16_能力商機矩陣_CapOppMap!$D$162:$CO$162,MATCH($A10,16_能力商機矩陣_CapOppMap!$D$4:$CO$4,0)),"")) -> 0 | Y10: =IF(OR($A10="",$H10=""),"",IF($H10=0,"",ROUND(0.45*$I10+0.35*$J10+0.2*IF(LEFT($F10,1)="③",5,IF(LEFT($F10,1)="②",3,1))-IF($K10>0,0.3,0),2)+ROW()/100000)) -> 3.4201 | Z10: =IF($Y10="","",RANK($Y10,$Y$5:$Y$94)) -> 51 | AA10: L1 實體基礎層 | AB10: （本項無專屬發現——見同列右方的家族／領域趨勢，或 19／20 分頁） | AC10: B | AD10: 白梅二院/越德二院已投運：2025-12-19落成，白梅二院2026-06-26收治（首期325床）、越德二院2026-07-09開幕（首期300床），設計各1,000床、各約5,000億越盾。政府監察（2025-04）指兩大標案4,389.9億越盾全流程違規。TCVN 5687:2024（通風空調）更新；Decree 96/2023第40-41條為手術室執照錨點；醫療廢水強制QCVN 28:2010。Decree 58/2025確立屋頂光電自發自用制，已由Nghị định 243/2026（2026-06-26生效）修訂：餘電可售上限由20%提高至50%（2030-12-31前電網條件允許可再協議）、通報門檻改依逆變器容量（<1kW免通報、≥1kW須提前10工作日通報）。
A11: OPP-07 | B11: 千床級醫院統包工程(EPC) | C11: Turnkey Hospital EPC | D11: B 建築工程與設施 | E11: 從設計、土建、機電到醫療設備整合，一次交付一整家醫院；省／中央資本預算或ODA付錢 | F11: ① 已成熟：在地已有供應商 | G11: =IF($A11="","",IF($H11=0,"（尚無對應能力）",IFERROR(INDEX(16_能力商機矩陣_CapOppMap!$D$160:$CO$160,MATCH($A11,16_能力商機矩陣_CapOppMap!$D$4:$CO$4,0)),""))) -> D03 | H11: =IF($A11="","",IFERROR(INDEX(16_能力商機矩陣_CapOppMap!$D$156:$CO$156,MATCH($A11,16_能力商機矩陣_CapOppMap!$D$4:$CO$4,0)),"")) -> 5 | I11: =IF($A11="","",IFERROR(INDEX(16_能力商機矩陣_CapOppMap!$D$157:$CO$157,MATCH($A11,16_能力商機矩陣_CapOppMap!$D$4:$CO$4,0)),"")) -> 4.3 | J11: =IF($A11="","",IFERROR(INDEX(16_能力商機矩陣_CapOppMap!$D$158:$CO$158,MATCH($A11,16_能力商機矩陣_CapOppMap!$D$4:$CO$4,0)),"")) -> 2.5 | K11: =IF($A11="","",IFERROR(INDEX(16_能力商機矩陣_CapOppMap!$D$159:$CO$159,MATCH($A11,16_能力商機矩陣_CapOppMap!$D$4:$CO$4,0)),"")) -> 0 | L11: =IF($A11="","",IF($H11=0,"★白地商機：目前無對應能力，需新增能力或找新夥伴",IF($K11>0,"有缺口："&$K11&"項可對外招募","已有能力可承接"))) -> 已有能力可承接 | M11: G4 | N11: 醫院業主資本支出(CAPEX) | O11: 統包工程(EPC) | P11: >10M USD | Q11: 是 | R11: MEP Lead | S11: 胡志明市三家1000床門戶醫院每家約US$72-75m（≒US$73k/床，2025年開幕）可作為報價基準 | T11: =IF($A11="","",COUNTIF(14_商機清單_Pipeline!$A$5:$A$34,$U11)) -> 0 | U11: =IF($B11="","",$A11&" "&$B11) -> OPP-07 千床級醫院統包工程(EPC) | V11: （待調查） | X11: =IF($A11="","",IFERROR(INDEX(16_能力商機矩陣_CapOppMap!$D$162:$CO$162,MATCH($A11,16_能力商機矩陣_CapOppMap!$D$4:$CO$4,0)),"")) -> 1 | Y11: =IF(OR($A11="",$H11=""),"",IF($H11=0,"",ROUND(0.45*$I11+0.35*$J11+0.2*IF(LEFT($F11,1)="③",5,IF(LEFT($F11,1)="②",3,1))-IF($K11>0,0.3,0),2)+ROW()/100000)) -> 3.01011 | Z11: =IF($Y11="","",RANK($Y11,$Y$5:$Y$94)) -> 72 | AA11: L1 實體基礎層 | AB11: 警示案例：白梅/越德二院停擺6-7年後於2026年終於投運，惟政府監察結論指兩大標案（4,389.9億越盾、占10標案76.6%）從招標文件編製到履約全環節違規，樁基變更浪費約207億越盾、一項設備合約價132億越盾而實際進口價僅40億——公立EPC的付款與治理風險必須在合約層處理。 | AC11: A | AD11: 白梅二院/越德二院已投運：2025-12-19落成，白梅二院2026-06-26收治（首期325床）、越德二院2026-07-09開幕（首期300床），設計各1,000床、各約5,000億越盾。政府監察（2025-04）指兩大標案4,389.9億越盾全流程違規。TCVN 5687:2024（通風空調）更新；Decree 96/2023第40-41條為手術室執照錨點；醫療廢水強制QCVN 28:2010。Decree 58/2025確立屋頂光電自發自用制，已由Nghị định 243/2026（2026-06-26生效）修訂：餘電可售上限由20%提高至50%（2030-12-31前電網條件允許可再協議）、通報門檻改依逆變器容量（<1kW免通報、≥1kW須提前10工作日通報）。
A12: OPP-08 | B12: 手術室與加護病房潔淨空調（模組化OR） | C12: OR/ICU Cleanroom HVAC & Modular OR | D12: B 建築工程與設施 | E12: 層流手術室、負壓隔離病房、模組化手術室隔間板；EPC統包商或醫院付錢 | F12: ② 起步中：剛開始有人做 | G12: =IF($A12="","",IF($H12=0,"（尚無對應能力）",IFERROR(INDEX(16_能力商機矩陣_CapOppMap!$D$160:$CO$160,MATCH($A12,16_能力商機矩陣_CapOppMap!$D$4:$CO$4,0)),""))) -> D03; D05 | H12: =IF($A12="","",IFERROR(INDEX(16_能力商機矩陣_CapOppMap!$D$156:$CO$156,MATCH($A12,16_能力商機矩陣_CapOppMap!$D$4:$CO$4,0)),"")) -> 3 | I12: =IF($A12="","",IFERROR(INDEX(16_能力商機矩陣_CapOppMap!$D$157:$CO$157,MATCH($A12,16_能力商機矩陣_CapOppMap!$D$4:$CO$4,0)),"")) -> 4.6 | J12: =IF($A12="","",IFERROR(INDEX(16_能力商機矩陣_CapOppMap!$D$158:$CO$158,MATCH($A12,16_能力商機矩陣_CapOppMap!$D$4:$CO$4,0)),"")) -> 2.4 | K12: =IF($A12="","",IFERROR(INDEX(16_能力商機矩陣_CapOppMap!$D$159:$CO$159,MATCH($A12,16_能力商機矩陣_CapOppMap!$D$4:$CO$4,0)),"")) -> 1 | L12: =IF($A12="","",IF($H12=0,"★白地商機：目前無對應能力，需新增能力或找新夥伴",IF($K12>0,"有缺口："&$K12&"項可對外招募","已有能力可承接"))) -> 有缺口：1項可對外招募 | M12: G4 | N12: 醫院業主資本支出(CAPEX) | O12: 統包工程(EPC) | P12: 2M-10M USD | Q12: 是 | R12: MEP Lead | S12: 台灣無塵室技術可直接轉用，是本聯盟在工程端最有辨識度的切入點 | T12: =IF($A12="","",COUNTIF(14_商機清單_Pipeline!$A$5:$A$34,$U12)) -> 0 | U12: =IF($B12="","",$A12&" "&$B12) -> OPP-08 手術室與加護病房潔淨空調（模組化OR） | V12: 在地淨化工程商多、品質參差 | W12: 台灣無塵室工藝＋竣工驗收確效文件 | X12: =IF($A12="","",IFERROR(INDEX(16_能力商機矩陣_CapOppMap!$D$162:$CO$162,MATCH($A12,16_能力商機矩陣_CapOppMap!$D$4:$CO$4,0)),"")) -> 0 | Y12: =IF(OR($A12="",$H12=""),"",IF($H12=0,"",ROUND(0.45*$I12+0.35*$J12+0.2*IF(LEFT($F12,1)="③",5,IF(LEFT($F12,1)="②",3,1))-IF($K12>0,0.3,0),2)+ROW()/100000)) -> 3.21012 | Z12: =IF($Y12="","",RANK($Y12,$Y$5:$Y$94)) -> 68 | AA12: L1 實體基礎層 | AB12: 越南無專屬強制醫院潔淨室QCVN，實務援引ISO 14644＋TCVN 5687:2024；Decree 96/2023第40-41條為OR執照法律錨點。 | AC12: A | AD12: 白梅二院/越德二院已投運：2025-12-19落成，白梅二院2026-06-26收治（首期325床）、越德二院2026-07-09開幕（首期300床），設計各1,000床、各約5,000億越盾。政府監察（2025-04）指兩大標案4,389.9億越盾全流程違規。TCVN 5687:2024（通風空調）更新；Decree 96/2023第40-41條為手術室執照錨點；醫療廢水強制QCVN 28:2010。Decree 58/2025確立屋頂光電自發自用制，已由Nghị định 243/2026（2026-06-26生效）修訂：餘電可售上限由20%提高至50%（2030-12-31前電網條件允許可再協議）、通報門檻改依逆變器容量（<1kW免通報、≥1kW須提前10工作日通報）。
A13: OPP-09 | B13: 醫用氣體與真空系統（含竣工確效） | C13: Medical Gas & Vacuum System with Validation | D13: B 建築工程與設施 | E13: 中央氣體機房、分歧管、警報與末端出口，加上在地廠商常省略的竣工驗證與確效 | F13: ② 起步中：剛開始有人做 | G13: =IF($A13="","",IF($H13=0,"（尚無對應能力）",IFERROR(INDEX(16_能力商機矩陣_CapOppMap!$D$160:$CO$160,MATCH($A13,16_能力商機矩陣_CapOppMap!$D$4:$CO$4,0)),""))) -> D03 | H13: =IF($A13="","",IFERROR(INDEX(16_能力商機矩陣_CapOppMap!$D$156:$CO$156,MATCH($A13,16_能力商機矩陣_CapOppMap!$D$4:$CO$4,0)),"")) -> 1 | I13: =IF($A13="","",IFERROR(INDEX(16_能力商機矩陣_CapOppMap!$D$157:$CO$157,MATCH($A13,16_能力商機矩陣_CapOppMap!$D$4:$CO$4,0)),"")) -> 4.4 | J13: =IF($A13="","",IFERROR(INDEX(16_能力商機矩陣_CapOppMap!$D$158:$CO$158,MATCH($A13,16_能力商機矩陣_CapOppMap!$D$4:$CO$4,0)),"")) -> 2.4 | K13: =IF($A13="","",IFERROR(INDEX(16_能力商機矩陣_CapOppMap!$D$159:$CO$159,MATCH($A13,16_能力商機矩陣_CapOppMap!$D$4:$CO$4,0)),"")) -> 0 | L13: =IF($A13="","",IF($H13=0,"★白地商機：目前無對應能力，需新增能力或找新夥伴",IF($K13>0,"有缺口："&$K13&"項可對外招募","已有能力可承接"))) -> 已有能力可承接 | M13: G4 | N13: 醫院業主資本支出(CAPEX) | O13: 統包工程(EPC) | P13: 500K-2M USD | Q13: 是 | R13: MEP Lead | S13: 在地供應商有，但 ISO 7396-1/-2、TCVN 8022 的驗證確效是空白——賣「證明它安全」比賣管路值錢 | T13: =IF($A13="","",COUNTIF(14_商機清單_Pipeline!$A$5:$A$34,$U13)) -> 0 | U13: =IF($B13="","",$A13&" "&$B13) -> OPP-09 醫用氣體與真空系統（含竣工確效） | V13: （待調查） | X13: =IF($A13="","",IFERROR(INDEX(16_能力商機矩陣_CapOppMap!$D$162:$CO$162,MATCH($A13,16_能力商機矩陣_CapOppMap!$D$4:$CO$4,0)),"")) -> 0 | Y13: =IF(OR($A13="",$H13=""),"",IF($H13=0,"",ROUND(0.45*$I13+0.35*$J13+0.2*IF(LEFT($F13,1)="③",5,IF(LEFT($F13,1)="②",3,1))-IF($K13>0,0.3,0),2)+ROW()/100000)) -> 3.42013 | Z13: =IF($Y13="","",RANK($Y13,$Y$5:$Y$94)) -> 50 | AA13: L1 實體基礎層 | AB13: TCVN 8022-1/2:2009等同ISO 7396，國際技術可直接對接。 | AC13: A | AD13: 白梅二院/越德二院已投運：2025-12-19落成，白梅二院2026-06-26收治（首期325床）、越德二院2026-07-09開幕（首期300床），設計各1,000床、各約5,000億越盾。政府監察（2025-04）指兩大標案4,389.9億越盾全流程違規。TCVN 5687:2024（通風空調）更新；Decree 96/2023第40-41條為手術室執照錨點；醫療廢水強制QCVN 28:2010。Decree 58/2025確立屋頂光電自發自用制，已由Nghị định 243/2026（2026-06-26生效）修訂：餘電可售上限由20%提高至50%（2030-12-31前電網條件允許可再協議）、通報門檻改依逆變器容量（<1kW免通報、≥1kW須提前10工作日通報）。
A14: OPP-10 | B14: 醫院供電韌性與隔離電源系統 | C14: Hospital Power Resilience & IT Isolated Power | D14: B 建築工程與設施 | E14: 第2類醫療場所隔離電源盤、UPS、發電機、自動切換與醫療接地；生命安全電力包 | F14: ② 起步中：剛開始有人做 | G14: =IF($A14="","",IF($H14=0,"（尚無對應能力）",IFERROR(INDEX(16_能力商機矩陣_CapOppMap!$D$160:$CO$160,MATCH($A14,16_能力商機矩陣_CapOppMap!$D$4:$CO$4,0)),""))) -> D03 | H14: =IF($A14="","",IFERROR(INDEX(16_能力商機矩陣_CapOppMap!$D$156:$CO$156,MATCH($A14,16_能力商機矩陣_CapOppMap!$D$4:$CO$4,0)),"")) -> 1 | I14: =IF($A14="","",IFERROR(INDEX(16_能力商機矩陣_CapOppMap!$D$157:$CO$157,MATCH($A14,16_能力商機矩陣_CapOppMap!$D$4:$CO$4,0)),"")) -> 4.4 | J14: =IF($A14="","",IFERROR(INDEX(16_能力商機矩陣_CapOppMap!$D$158:$CO$158,MATCH($A14,16_能力商機矩陣_CapOppMap!$D$4:$CO$4,0)),"")) -> 2.7 | K14: =IF($A14="","",IFERROR(INDEX(16_能力商機矩陣_CapOppMap!$D$159:$CO$159,MATCH($A14,16_能力商機矩陣_CapOppMap!$D$4:$CO$4,0)),"")) -> 0 | L14: =IF($A14="","",IF($H14=0,"★白地商機：目前無對應能力，需新增能力或找新夥伴",IF($K14>0,"有缺口："&$K14&"項可對外招募","已有能力可承接"))) -> 已有能力可承接 | M14: G4 | N14: 醫院業主資本支出(CAPEX) | O14: 統包工程(EPC) | P14: 500K-2M USD | Q14: 是 | R14: MEP Lead | S14: IEC 60364-7-710 等級的隔離電源在越南很少被正確規範；電網不穩＋24小時影像/ICU負載使它非做不可 | T14: =IF($A14="","",COUNTIF(14_商機清單_Pipeline!$A$5:$A$34,$U14)) -> 0 | U14: =IF($B14="","",$A14&" "&$B14) -> OPP-10 醫院供電韌性與隔離電源系統 | V14: （待調查） | X14: =IF($A14="","",IFERROR(INDEX(16_能力商機矩陣_CapOppMap!$D$162:$CO$162,MATCH($A14,16_能力商機矩陣_CapOppMap!$D$4:$CO$4,0)),"")) -> 1 | Y14: =IF(OR($A14="",$H14=""),"",IF($H14=0,"",ROUND(0.45*$I14+0.35*$J14+0.2*IF(LEFT($F14,1)="③",5,IF(LEFT($F14,1)="②",3,1))-IF($K14>0,0.3,0),2)+ROW()/100000)) -> 3.53014 | Z14: =IF($Y14="","",RANK($Y14,$Y$5:$Y$94)) -> 45 | AA14: L1 實體基礎層 | AB14: 越南對醫療場所隔離電源（IEC 60364-7-710）專屬強制標準未查得——標準空窗，可用國際標準做差異化。EN建議改：Isolated Power Supply (IPS)，「IT」易誤讀為資訊科技。 | AC14: C | AD14: 白梅二院/越德二院已投運：2025-12-19落成，白梅二院2026-06-26收治（首期325床）、越德二院2026-07-09開幕（首期300床），設計各1,000床、各約5,000億越盾。政府監察（2025-04）指兩大標案4,389.9億越盾全流程違規。TCVN 5687:2024（通風空調）更新；Decree 96/2023第40-41條為手術室執照錨點；醫療廢水強制QCVN 28:2010。Decree 58/2025確立屋頂光電自發自用制，已由Nghị định 243/2026（2026-06-26生效）修訂：餘電可售上限由20%提高至50%（2030-12-31前電網條件允許可再協議）、通報門檻改依逆變器容量（<1kW免通報、≥1kW須提前10工作日通報）。
A15: OPP-11 | B15: 醫療廢水與廢棄物處理廠 | C15: Medical Wastewater & Waste Treatment Plant | D15: B 建築工程與設施 | E15: 院內污水處理廠或高溫滅菌／破碎處理設備，也可做區域處理特許經營 | F15: ② 起步中：剛開始有人做 | G15: =IF($A15="","",IF($H15=0,"（尚無對應能力）",IFERROR(INDEX(16_能力商機矩陣_CapOppMap!$D$160:$CO$160,MATCH($A15,16_能力商機矩陣_CapOppMap!$D$4:$CO$4,0)),""))) -> D03 | H15: =IF($A15="","",IFERROR(INDEX(16_能力商機矩陣_CapOppMap!$D$156:$CO$156,MATCH($A15,16_能力商機矩陣_CapOppMap!$D$4:$CO$4,0)),"")) -> 1 | I15: =IF($A15="","",IFERROR(INDEX(16_能力商機矩陣_CapOppMap!$D$157:$CO$157,MATCH($A15,16_能力商機矩陣_CapOppMap!$D$4:$CO$4,0)),"")) -> 4.1 | J15: =IF($A15="","",IFERROR(INDEX(16_能力商機矩陣_CapOppMap!$D$158:$CO$158,MATCH($A15,16_能力商機矩陣_CapOppMap!$D$4:$CO$4,0)),"")) -> 2.4 | K15: =IF($A15="","",IFERROR(INDEX(16_能力商機矩陣_CapOppMap!$D$159:$CO$159,MATCH($A15,16_能力商機矩陣_CapOppMap!$D$4:$CO$4,0)),"")) -> 0 | L15: =IF($A15="","",IF($H15=0,"★白地商機：目前無對應能力，需新增能力或找新夥伴",IF($K15>0,"有缺口："&$K15&"項可對外招募","已有能力可承接"))) -> 已有能力可承接 | M15: G4 | N15: 醫院營運預算(OPEX) | O15: 管理服務 | P15: 500K-2M USD | Q15: 是 | R15: ESG/Facility Lead | S15: 約70%醫療廢水處理未達標，衛生部正在收緊稽查——是被法規逼出來的大量潛在需求 | T15: =IF($A15="","",COUNTIF(14_商機清單_Pipeline!$A$5:$A$34,$U15)) -> 0 | U15: =IF($B15="","",$A15&" "&$B15) -> OPP-11 醫療廢水與廢棄物處理廠 | V15: 在地環工公司多，但約70%醫療廢水處理未達標 | W15: 達標保證＋代操作年約（衛生部稽查收緊的法規紅利） | X15: =IF($A15="","",IFERROR(INDEX(16_能力商機矩陣_CapOppMap!$D$162:$CO$162,MATCH($A15,16_能力商機矩陣_CapOppMap!$D$4:$CO$4,0)),"")) -> 0 | Y15: =IF(OR($A15="",$H15=""),"",IF($H15=0,"",ROUND(0.45*$I15+0.35*$J15+0.2*IF(LEFT($F15,1)="③",5,IF(LEFT($F15,1)="②",3,1))-IF($K15>0,0.3,0),2)+ROW()/100000)) -> 3.29015 | Z15: =IF($Y15="","",RANK($Y15,$Y$5:$Y$94)) -> 57 | AA15: L1 實體基礎層 | AB15: 強制規範QCVN 28:2010/BTNMT；市場出現0.5-300m³/日模組化產品線；工業廢水已更新QCVN 40:2025＝環境規範翻新訊號。 | AC15: A | AD15: 白梅二院/越德二院已投運：2025-12-19落成，白梅二院2026-06-26收治（首期325床）、越德二院2026-07-09開幕（首期300床），設計各1,000床、各約5,000億越盾。政府監察（2025-04）指兩大標案4,389.9億越盾全流程違規。TCVN 5687:2024（通風空調）更新；Decree 96/2023第40-41條為手術室執照錨點；醫療廢水強制QCVN 28:2010。Decree 58/2025確立屋頂光電自發自用制，已由Nghị định 243/2026（2026-06-26生效）修訂：餘電可售上限由20%提高至50%（2030-12-31前電網條件允許可再協議）、通報門檻改依逆變器容量（<1kW免通報、≥1kW須提前10工作日通報）。
A16: OPP-12 | B16: 綠色醫院能源績效合約與屋頂光電 | C16: Green Hospital ESCO & Rooftop Solar | D16: B 建築工程與設施 | E16: 用節省下來的電費付款，醫院零資本支出；屋頂光電也可用購電合約(PPA)模式 | F16: ③ 尚未出現：幾乎空白 | G16: =IF($A16="","",IF($H16=0,"（尚無對應能力）",IFERROR(INDEX(16_能力商機矩陣_CapOppMap!$D$160:$CO$160,MATCH($A16,16_能力商機矩陣_CapOppMap!$D$4:$CO$4,0)),""))) -> D03 | H16: =IF($A16="","",IFERROR(INDEX(16_能力商機矩陣_CapOppMap!$D$156:$CO$156,MATCH($A16,16_能力商機矩陣_CapOppMap!$D$4:$CO$4,0)),"")) -> 2 | I16: =IF($A16="","",IFERROR(INDEX(16_能力商機矩陣_CapOppMap!$D$157:$CO$157,MATCH($A16,16_能力商機矩陣_CapOppMap!$D$4:$CO$4,0)),"")) -> 4.3 | J16: =IF($A16="","",IFERROR(INDEX(16_能力商機矩陣_CapOppMap!$D$158:$CO$158,MATCH($A16,16_能力商機矩陣_CapOppMap!$D$4:$CO$4,0)),"")) -> 2.6 | K16: =IF($A16="","",IFERROR(INDEX(16_能力商機矩陣_CapOppMap!$D$159:$CO$159,MATCH($A16,16_能力商機矩陣_CapOppMap!$D$4:$CO$4,0)),"")) -> 0 | L16: =IF($A16="","",IF($H16=0,"★白地商機：目前無對應能力，需新增能力或找新夥伴",IF($K16>0,"有缺口："&$K16&"項可對外招募","已有能力可承接"))) -> 已有能力可承接 | M16: G5 | N16: 醫院營運預算(OPEX) | O16: 分潤／服務分成 | P16: 500K-2M USD | Q16: 需組合 | R16: ESG Lead | S16: 越南目標2030年50%公共建築屋頂裝光電；醫院端幾乎沒人做，是政策順風的空白 | T16: =IF($A16="","",COUNTIF(14_商機清單_Pipeline!$A$5:$A$34,$U16)) -> 0 | U16: =IF($B16="","",$A16&" "&$B16) -> OPP-12 綠色醫院能源績效合約與屋頂光電 | V16: （待調查） | X16: =IF($A16="","",IFERROR(INDEX(16_能力商機矩陣_CapOppMap!$D$162:$CO$162,MATCH($A16,16_能力商機矩陣_CapOppMap!$D$4:$CO$4,0)),"")) -> 1 | Y16: =IF(OR($A16="",$H16=""),"",IF($H16=0,"",ROUND(0.45*$I16+0.35*$J16+0.2*IF(LEFT($F16,1)="③",5,IF(LEFT($F16,1)="②",3,1))-IF($K16>0,0.3,0),2)+ROW()/100000)) -> 3.85016 | Z16: =IF($Y16="","",RANK($Y16,$Y$5:$Y$94)) -> 17 | AA16: L1 實體基礎層 | AB16: Decree 58/2025（2025-03-03生效）已由Nghị định 243/2026（2026-06-26生效）修訂：餘電可售上限20%→50%、2030-12-31前電網條件允許可協議更高、未併網之山區離島不限售電量；通報門檻改依逆變器容量（<1kW免通報、≥1kW提前10工作日通報），分級改依併網電壓等級——醫院大屋頂＋日間高負載是典型受益者，額度放寬後自用外售的回收年限明顯改善。ESCO市場「有潛力未成形」，融資與M&V是瓶頸。 | AC16: A | AD16: 白梅二院/越德二院已投運：2025-12-19落成，白梅二院2026-06-26收治（首期325床）、越德二院2026-07-09開幕（首期300床），設計各1,000床、各約5,000億越盾。政府監察（2025-04）指兩大標案4,389.9億越盾全流程違規。TCVN 5687:2024（通風空調）更新；Decree 96/2023第40-41條為手術室執照錨點；醫療廢水強制QCVN 28:2010。Decree 58/2025確立屋頂光電自發自用制，已由Nghị định 243/2026（2026-06-26生效）修訂：餘電可售上限由20%提高至50%（2030-12-31前電網條件允許可再協議）、通報門檻改依逆變器容量（<1kW免通報、≥1kW須提前10工作日通報）。
A17: OPP-13 | B17: 消毒供應中心(CSSD)設備整廠 | C17: Central Sterile Supply Department Turnkey | D17: B 建築工程與設施 | E17: 清洗消毒機、蒸氣／過氧化氫滅菌鍋、器械追溯軟體與符合標準的動線設計 | F17: ② 起步中：剛開始有人做 | G17: =IF($A17="","",IF($H17=0,"（尚無對應能力）",IFERROR(INDEX(16_能力商機矩陣_CapOppMap!$D$160:$CO$160,MATCH($A17,16_能力商機矩陣_CapOppMap!$D$4:$CO$4,0)),""))) -> D03; D05 | H17: =IF($A17="","",IFERROR(INDEX(16_能力商機矩陣_CapOppMap!$D$156:$CO$156,MATCH($A17,16_能力商機矩陣_CapOppMap!$D$4:$CO$4,0)),"")) -> 2 | I17: =IF($A17="","",IFERROR(INDEX(16_能力商機矩陣_CapOppMap!$D$157:$CO$157,MATCH($A17,16_能力商機矩陣_CapOppMap!$D$4:$CO$4,0)),"")) -> 4.7 | J17: =IF($A17="","",IFERROR(INDEX(16_能力商機矩陣_CapOppMap!$D$158:$CO$158,MATCH($A17,16_能力商機矩陣_CapOppMap!$D$4:$CO$4,0)),"")) -> 2.4 | K17: =IF($A17="","",IFERROR(INDEX(16_能力商機矩陣_CapOppMap!$D$159:$CO$159,MATCH($A17,16_能力商機矩陣_CapOppMap!$D$4:$CO$4,0)),"")) -> 0 | L17: =IF($A17="","",IF($H17=0,"★白地商機：目前無對應能力，需新增能力或找新夥伴",IF($K17>0,"有缺口："&$K17&"項可對外招募","已有能力可承接"))) -> 已有能力可承接 | M17: G4 | N17: 醫院業主資本支出(CAPEX) | O17: 設備銷售＋耗材 | P17: 500K-2M USD | Q17: 是 | R17: Clinical Engineering Lead | S17: 省級醫院多半還在用單槽高壓釜，清洗消毒與器械追溯鏈幾乎空白 | T17: =IF($A17="","",COUNTIF(14_商機清單_Pipeline!$A$5:$A$34,$U17)) -> 0 | U17: =IF($B17="","",$A17&" "&$B17) -> OPP-13 消毒供應中心(CSSD)設備整廠 | V17: （待調查） | X17: =IF($A17="","",IFERROR(INDEX(16_能力商機矩陣_CapOppMap!$D$162:$CO$162,MATCH($A17,16_能力商機矩陣_CapOppMap!$D$4:$CO$4,0)),"")) -> 0 | Y17: =IF(OR($A17="",$H17=""),"",IF($H17=0,"",ROUND(0.45*$I17+0.35*$J17+0.2*IF(LEFT($F17,1)="③",5,IF(LEFT($F17,1)="②",3,1))-IF($K17>0,0.3,0),2)+ROW()/100000)) -> 3.56017 | Z17: =IF($Y17="","",RANK($Y17,$Y$5:$Y$94)) -> 43 | AA17: L1 實體基礎層 | AB17: （本項無專屬發現——見同列右方的家族／領域趨勢，或 19／20 分頁） | AC17: B | AD17: 白梅二院/越德二院已投運：2025-12-19落成，白梅二院2026-06-26收治（首期325床）、越德二院2026-07-09開幕（首期300床），設計各1,000床、各約5,000億越盾。政府監察（2025-04）指兩大標案4,389.9億越盾全流程違規。TCVN 5687:2024（通風空調）更新；Decree 96/2023第40-41條為手術室執照錨點；醫療廢水強制QCVN 28:2010。Decree 58/2025確立屋頂光電自發自用制，已由Nghị định 243/2026（2026-06-26生效）修訂：餘電可售上限由20%提高至50%（2030-12-31前電網條件允許可再協議）、通報門檻改依逆變器容量（<1kW免通報、≥1kW須提前10工作日通報）。
A18: OPP-14 | B18: 影像設備整批交鑰匙（CT/MRI/DSA＋機房） | C18: Imaging Fleet Turnkey | D18: C 醫材與臨床設備 | E18: 影像設備＋機房屏蔽＋PACS＋維運一起賣；醫院發展基金、省預算或設備租賃付錢 | F18: ① 已成熟：在地已有供應商 | G18: =IF($A18="","",IF($H18=0,"（尚無對應能力）",IFERROR(INDEX(16_能力商機矩陣_CapOppMap!$D$160:$CO$160,MATCH($A18,16_能力商機矩陣_CapOppMap!$D$4:$CO$4,0)),""))) -> D05 | H18: =IF($A18="","",IFERROR(INDEX(16_能力商機矩陣_CapOppMap!$D$156:$CO$156,MATCH($A18,16_能力商機矩陣_CapOppMap!$D$4:$CO$4,0)),"")) -> 2 | I18: =IF($A18="","",IFERROR(INDEX(16_能力商機矩陣_CapOppMap!$D$157:$CO$157,MATCH($A18,16_能力商機矩陣_CapOppMap!$D$4:$CO$4,0)),"")) -> 4.7 | J18: =IF($A18="","",IFERROR(INDEX(16_能力商機矩陣_CapOppMap!$D$158:$CO$158,MATCH($A18,16_能力商機矩陣_CapOppMap!$D$4:$CO$4,0)),"")) -> 2.4 | K18: =IF($A18="","",IFERROR(INDEX(16_能力商機矩陣_CapOppMap!$D$159:$CO$159,MATCH($A18,16_能力商機矩陣_CapOppMap!$D$4:$CO$4,0)),"")) -> 1 | L18: =IF($A18="","",IF($H18=0,"★白地商機：目前無對應能力，需新增能力或找新夥伴",IF($K18>0,"有缺口："&$K18&"項可對外招募","已有能力可承接"))) -> 有缺口：1項可對外招募 | M18: G3 | N18: 醫院業主資本支出(CAPEX) | O18: 設施/設備PPP | P18: 2M-10M USD | Q18: 是 | R18: Imaging Lead | S18: GE／西門子／飛利浦／中國廠競爭激烈——台灣的切點在機房建置＋PACS整合＋維運包，不是球管本身 | T18: =IF($A18="","",COUNTIF(14_商機清單_Pipeline!$A$5:$A$34,$U18)) -> 1 | U18: =IF($B18="","",$A18&" "&$B18) -> OPP-14 影像設備整批交鑰匙（CT/MRI/DSA＋機房） | V18: GE/西門子/飛利浦＋中國聯影等，設備端價格戰激烈 | W18: 賣機房建置＋PACS整合＋維運SLA，不與原廠拚設備價 | X18: =IF($A18="","",IFERROR(INDEX(16_能力商機矩陣_CapOppMap!$D$162:$CO$162,MATCH($A18,16_能力商機矩陣_CapOppMap!$D$4:$CO$4,0)),"")) -> 0 | Y18: =IF(OR($A18="",$H18=""),"",IF($H18=0,"",ROUND(0.45*$I18+0.35*$J18+0.2*IF(LEFT($F18,1)="③",5,IF(LEFT($F18,1)="②",3,1))-IF($K18>0,0.3,0),2)+ROW()/100000)) -> 2.86018 | Z18: =IF($Y18="","",RANK($Y18,$Y$5:$Y$94)) -> 75 | AA18: L3 臨床設備層 | AB18: 診斷影像列美商務部最大商機類別之一；河內/胡志明吸納全國60%病人＝省級影像缺口。 | AC18: A | AD18: 醫材市場（三家口徑）：TechSci 2024年15.5億美元→2030年25.3億（CAGR 8.45%）、Statista 2025年17.7億→2029年24.7億（CAGR 8.62%）、越南藥管局2024年約17億——CAGR一致約8.1-8.6%。2025-07-01起過渡措施全面終止：須在地MAH、ISO 13485、C/D類CSDT申報。Bidding Law 2023承認設備寄放／按次計費／委外檢驗等模式；⚠承包商選擇方式已於2025-07-01（Luật 90/2025/QH15）由6種增為10種（新增đặt hàng），另有線上詢價與線上採購兩種方式。硬缺口：直線加速器85台、分布近100家中心，放療量能僅滿足約60%需求（越南原子能主管機關2025-08）；透析實際僅4.5-5萬人接受治療、成人CKD達1,000-1,050萬人；PET/CT僅12台。2026-02 Tâm Anh採購全國首套質子治療系統（Mevion S250-FIT，近2兆越盾）。
A19: OPP-15 | B19: 放射腫瘤與核醫中心整廠 | C19: Radiotherapy & Nuclear Medicine Centre Turnkey | D19: C 醫材與臨床設備 | E19: 直線加速器、近接治療、治療計畫系統、防護機房土建、PET/CT；省預算或腫瘤合資公司付錢 | F19: ③ 尚未出現：幾乎空白 | G19: =IF($A19="","",IF($H19=0,"（尚無對應能力）",IFERROR(INDEX(16_能力商機矩陣_CapOppMap!$D$160:$CO$160,MATCH($A19,16_能力商機矩陣_CapOppMap!$D$4:$CO$4,0)),""))) -> D05 | H19: =IF($A19="","",IFERROR(INDEX(16_能力商機矩陣_CapOppMap!$D$156:$CO$156,MATCH($A19,16_能力商機矩陣_CapOppMap!$D$4:$CO$4,0)),"")) -> 3 | I19: =IF($A19="","",IFERROR(INDEX(16_能力商機矩陣_CapOppMap!$D$157:$CO$157,MATCH($A19,16_能力商機矩陣_CapOppMap!$D$4:$CO$4,0)),"")) -> 4.7 | J19: =IF($A19="","",IFERROR(INDEX(16_能力商機矩陣_CapOppMap!$D$158:$CO$158,MATCH($A19,16_能力商機矩陣_CapOppMap!$D$4:$CO$4,0)),"")) -> 2.4 | K19: =IF($A19="","",IFERROR(INDEX(16_能力商機矩陣_CapOppMap!$D$159:$CO$159,MATCH($A19,16_能力商機矩陣_CapOppMap!$D$4:$CO$4,0)),"")) -> 1 | L19: =IF($A19="","",IF($H19=0,"★白地商機：目前無對應能力，需新增能力或找新夥伴",IF($K19>0,"有缺口："&$K19&"項可對外招募","已有能力可承接"))) -> 有缺口：1項可對外招募 | M19: G4 | N19: 省級衛生局預算 | O19: 政府採購 | P19: >10M USD | Q19: 是 | R19: Clinical Engineering Lead | S19: ★放療與核醫設備嚴重不足且集中在河內／胡志明市，腫瘤醫院長期超載，是最大的臨床量能缺口 | T19: =IF($A19="","",COUNTIF(14_商機清單_Pipeline!$A$5:$A$34,$U19)) -> 0 | U19: =IF($B19="","",$A19&" "&$B19) -> OPP-15 放射腫瘤與核醫中心整廠 | V19: Varian/Elekta 原廠直營；量能集中河內/胡志明兩大城 | W19: 整廠輸出（防護土建＋TPS＋物理師訓練）＋ODA組案能力 | X19: =IF($A19="","",IFERROR(INDEX(16_能力商機矩陣_CapOppMap!$D$162:$CO$162,MATCH($A19,16_能力商機矩陣_CapOppMap!$D$4:$CO$4,0)),"")) -> 0 | Y19: =IF(OR($A19="",$H19=""),"",IF($H19=0,"",ROUND(0.45*$I19+0.35*$J19+0.2*IF(LEFT($F19,1)="③",5,IF(LEFT($F19,1)="②",3,1))-IF($K19>0,0.3,0),2)+ROW()/100000)) -> 3.66019 | Z19: =IF($Y19="","",RANK($Y19,$Y$5:$Y$94)) -> 35 | AA19: L3 臨床設備層 | AB19: 全國85台體外放療加速器、分布近100家中心，量能僅滿足約60%需求（越南原子能主管機關2025-08）；約0.84台/百萬人 vs 標準4-8台、43%老舊；PET/CT僅12台、迴旋加速器3台；放療等待2-6週。質子治療：K醫院籌建北越首座質子中心（4.2兆越盾）；Tâm Anh已於2026-02採購全國首套質子系統（Mevion S250-FIT，近2兆越盾）。達低標需增至約400台。 | AC19: A | AD19: 醫材市場（三家口徑）：TechSci 2024年15.5億美元→2030年25.3億（CAGR 8.45%）、Statista 2025年17.7億→2029年24.7億（CAGR 8.62%）、越南藥管局2024年約17億——CAGR一致約8.1-8.6%。2025-07-01起過渡措施全面終止：須在地MAH、ISO 13485、C/D類CSDT申報。Bidding Law 2023承認設備寄放／按次計費／委外檢驗等模式；⚠承包商選擇方式已於2025-07-01（Luật 90/2025/QH15）由6種增為10種（新增đặt hàng），另有線上詢價與線上採購兩種方式。硬缺口：直線加速器85台、分布近100家中心，放療量能僅滿足約60%需求（越南原子能主管機關2025-08）；透析實際僅4.5-5萬人接受治療、成人CKD達1,000-1,050萬人；PET/CT僅12台。2026-02 Tâm Anh採購全國首套質子治療系統（Mevion S250-FIT，近2兆越盾）。
A20: OPP-16 | B20: 心導管室與複合式手術室 | C20: Cath Lab & Hybrid OR | D20: C 醫材與臨床設備 | E20: 心導管室、DSA、血液動力學監測與複合式手術室；醫院資本支出 | F20: ② 起步中：剛開始有人做 | G20: =IF($A20="","",IF($H20=0,"（尚無對應能力）",IFERROR(INDEX(16_能力商機矩陣_CapOppMap!$D$160:$CO$160,MATCH($A20,16_能力商機矩陣_CapOppMap!$D$4:$CO$4,0)),""))) -> D05 | H20: =IF($A20="","",IFERROR(INDEX(16_能力商機矩陣_CapOppMap!$D$156:$CO$156,MATCH($A20,16_能力商機矩陣_CapOppMap!$D$4:$CO$4,0)),"")) -> 1 | I20: =IF($A20="","",IFERROR(INDEX(16_能力商機矩陣_CapOppMap!$D$157:$CO$157,MATCH($A20,16_能力商機矩陣_CapOppMap!$D$4:$CO$4,0)),"")) -> 4.7 | J20: =IF($A20="","",IFERROR(INDEX(16_能力商機矩陣_CapOppMap!$D$158:$CO$158,MATCH($A20,16_能力商機矩陣_CapOppMap!$D$4:$CO$4,0)),"")) -> 2.4 | K20: =IF($A20="","",IFERROR(INDEX(16_能力商機矩陣_CapOppMap!$D$159:$CO$159,MATCH($A20,16_能力商機矩陣_CapOppMap!$D$4:$CO$4,0)),"")) -> 1 | L20: =IF($A20="","",IF($H20=0,"★白地商機：目前無對應能力，需新增能力或找新夥伴",IF($K20>0,"有缺口："&$K20&"項可對外招募","已有能力可承接"))) -> 有缺口：1項可對外招募 | M20: G4 | N20: 醫院業主資本支出(CAPEX) | O20: 設備銷售＋耗材 | P20: 2M-10M USD | Q20: 是 | R20: Clinical Engineering Lead | S20: 心血管是最大的醫材次領域（約US$293m），中央醫院已有、省級還很薄 | T20: =IF($A20="","",COUNTIF(14_商機清單_Pipeline!$A$5:$A$34,$U20)) -> 0 | U20: =IF($B20="","",$A20&" "&$B20) -> OPP-16 心導管室與複合式手術室 | V20: （待調查） | X20: =IF($A20="","",IFERROR(INDEX(16_能力商機矩陣_CapOppMap!$D$162:$CO$162,MATCH($A20,16_能力商機矩陣_CapOppMap!$D$4:$CO$4,0)),"")) -> 0 | Y20: =IF(OR($A20="",$H20=""),"",IF($H20=0,"",ROUND(0.45*$I20+0.35*$J20+0.2*IF(LEFT($F20,1)="③",5,IF(LEFT($F20,1)="②",3,1))-IF($K20>0,0.3,0),2)+ROW()/100000)) -> 3.2602 | Z20: =IF($Y20="","",RANK($Y20,$Y$5:$Y$94)) -> 62 | AA20: L3 臨床設備層 | AB20: 介入心臟市場：Data Bridge估2024年5,849萬美元→2032年9,901萬（CAGR 6.8%）；Expert Market Research估2025年8.6億美元（CAGR 7.45%）——兩者相差約15倍，涵蓋範圍不同（器材 vs 含手術服務）。⚠「越南占東南亞36.4%」僅見Data Bridge自家頁面、其東南亞母報告已404，反推東南亞總額僅約1.6億美元與各國PCI手術量常識不符，不可採信為事實。複合手術室專屬數據未查得。 | AC20: A | AD20: 醫材市場（三家口徑）：TechSci 2024年15.5億美元→2030年25.3億（CAGR 8.45%）、Statista 2025年17.7億→2029年24.7億（CAGR 8.62%）、越南藥管局2024年約17億——CAGR一致約8.1-8.6%。2025-07-01起過渡措施全面終止：須在地MAH、ISO 13485、C/D類CSDT申報。Bidding Law 2023承認設備寄放／按次計費／委外檢驗等模式；⚠承包商選擇方式已於2025-07-01（Luật 90/2025/QH15）由6種增為10種（新增đặt hàng），另有線上詢價與線上採購兩種方式。硬缺口：直線加速器85台、分布近100家中心，放療量能僅滿足約60%需求（越南原子能主管機關2025-08）；透析實際僅4.5-5萬人接受治療、成人CKD達1,000-1,050萬人；PET/CT僅12台。2026-02 Tâm Anh採購全國首套質子治療系統（Mevion S250-FIT，近2兆越盾）。
A21: OPP-17 | B21: 洗腎設備與水處理系統 | C21: Dialysis Plant & RO Water Treatment | D21: C 醫材與臨床設備 | E21: 洗腎機、逆滲透水處理、濃縮液供應；設備一次收入加上耗材長期續收 | F21: ② 起步中：剛開始有人做 | G21: =IF($A21="","",IF($H21=0,"（尚無對應能力）",IFERROR(INDEX(16_能力商機矩陣_CapOppMap!$D$160:$CO$160,MATCH($A21,16_能力商機矩陣_CapOppMap!$D$4:$CO$4,0)),""))) -> D05 | H21: =IF($A21="","",IFERROR(INDEX(16_能力商機矩陣_CapOppMap!$D$156:$CO$156,MATCH($A21,16_能力商機矩陣_CapOppMap!$D$4:$CO$4,0)),"")) -> 2 | I21: =IF($A21="","",IFERROR(INDEX(16_能力商機矩陣_CapOppMap!$D$157:$CO$157,MATCH($A21,16_能力商機矩陣_CapOppMap!$D$4:$CO$4,0)),"")) -> 4.7 | J21: =IF($A21="","",IFERROR(INDEX(16_能力商機矩陣_CapOppMap!$D$158:$CO$158,MATCH($A21,16_能力商機矩陣_CapOppMap!$D$4:$CO$4,0)),"")) -> 2.4 | K21: =IF($A21="","",IFERROR(INDEX(16_能力商機矩陣_CapOppMap!$D$159:$CO$159,MATCH($A21,16_能力商機矩陣_CapOppMap!$D$4:$CO$4,0)),"")) -> 0 | L21: =IF($A21="","",IF($H21=0,"★白地商機：目前無對應能力，需新增能力或找新夥伴",IF($K21>0,"有缺口："&$K21&"項可對外招募","已有能力可承接"))) -> 已有能力可承接 | M21: G4 | N21: 醫院業主資本支出(CAPEX) | O21: 設備銷售＋耗材 | P21: 500K-2M USD | Q21: 是 | R21: Clinical Engineering Lead | S21: 約1300萬慢性腎病人口，但80%洗腎中心集中在都市；健保給付洗腎，付費來源最明確 | T21: =IF($A21="","",COUNTIF(14_商機清單_Pipeline!$A$5:$A$34,$U21)) -> 0 | U21: =IF($B21="","",$A21&" "&$B21) -> OPP-17 洗腎設備與水處理系統 | V21: Fresenius/B.Braun 設備商；在地私人洗腎中心約50家在展開 | W21: 設備＋水處理＋耗材長約＋衛星中心營運知識整包 | X21: =IF($A21="","",IFERROR(INDEX(16_能力商機矩陣_CapOppMap!$D$162:$CO$162,MATCH($A21,16_能力商機矩陣_CapOppMap!$D$4:$CO$4,0)),"")) -> 0 | Y21: =IF(OR($A21="",$H21=""),"",IF($H21=0,"",ROUND(0.45*$I21+0.35*$J21+0.2*IF(LEFT($F21,1)="③",5,IF(LEFT($F21,1)="②",3,1))-IF($K21>0,0.3,0),2)+ROW()/100000)) -> 3.56021 | Z21: =IF($Y21="","",RANK($Y21,$Y$5:$Y$94)) -> 42 | AA21: L3 臨床設備層 | AB21: 透析市場2025年5.04億美元→2034年7.18億；需求>10萬人、實際3.6萬（覆蓋~1/3）；健保給付約25美元/次；全國僅約400透析單位。 | AC21: A | AD21: 醫材市場（三家口徑）：TechSci 2024年15.5億美元→2030年25.3億（CAGR 8.45%）、Statista 2025年17.7億→2029年24.7億（CAGR 8.62%）、越南藥管局2024年約17億——CAGR一致約8.1-8.6%。2025-07-01起過渡措施全面終止：須在地MAH、ISO 13485、C/D類CSDT申報。Bidding Law 2023承認設備寄放／按次計費／委外檢驗等模式；⚠承包商選擇方式已於2025-07-01（Luật 90/2025/QH15）由6種增為10種（新增đặt hàng），另有線上詢價與線上採購兩種方式。硬缺口：直線加速器85台、分布近100家中心，放療量能僅滿足約60%需求（越南原子能主管機關2025-08）；透析實際僅4.5-5萬人接受治療、成人CKD達1,000-1,050萬人；PET/CT僅12台。2026-02 Tâm Anh採購全國首套質子治療系統（Mevion S250-FIT，近2兆越盾）。
A22: OPP-18 | B22: 內視鏡與自動清洗消毒追溯 | C22: Endoscopy Suite & Automated Reprocessing | D22: C 醫材與臨床設備 | E22: 內視鏡主機加上越南醫院普遍買不足的清洗消毒(AER)、乾燥櫃與追溯系統 | F22: ③ 尚未出現：幾乎空白 | G22: =IF($A22="","",IF($H22=0,"（尚無對應能力）",IFERROR(INDEX(16_能力商機矩陣_CapOppMap!$D$160:$CO$160,MATCH($A22,16_能力商機矩陣_CapOppMap!$D$4:$CO$4,0)),""))) -> D05 | H22: =IF($A22="","",IFERROR(INDEX(16_能力商機矩陣_CapOppMap!$D$156:$CO$156,MATCH($A22,16_能力商機矩陣_CapOppMap!$D$4:$CO$4,0)),"")) -> 1 | I22: =IF($A22="","",IFERROR(INDEX(16_能力商機矩陣_CapOppMap!$D$157:$CO$157,MATCH($A22,16_能力商機矩陣_CapOppMap!$D$4:$CO$4,0)),"")) -> 4.7 | J22: =IF($A22="","",IFERROR(INDEX(16_能力商機矩陣_CapOppMap!$D$158:$CO$158,MATCH($A22,16_能力商機矩陣_CapOppMap!$D$4:$CO$4,0)),"")) -> 2.4 | K22: =IF($A22="","",IFERROR(INDEX(16_能力商機矩陣_CapOppMap!$D$159:$CO$159,MATCH($A22,16_能力商機矩陣_CapOppMap!$D$4:$CO$4,0)),"")) -> 0 | L22: =IF($A22="","",IF($H22=0,"★白地商機：目前無對應能力，需新增能力或找新夥伴",IF($K22>0,"有缺口："&$K22&"項可對外招募","已有能力可承接"))) -> 已有能力可承接 | M22: G4 | N22: 醫院業主資本支出(CAPEX) | O22: 設備銷售＋耗材 | P22: 500K-2M USD | Q22: 是 | R22: Clinical Engineering Lead | S22: 內視鏡主機有人賣，但清洗消毒與追溯這一段幾乎沒人做，是感染管制稽查的下一個焦點 | T22: =IF($A22="","",COUNTIF(14_商機清單_Pipeline!$A$5:$A$34,$U22)) -> 0 | U22: =IF($B22="","",$A22&" "&$B22) -> OPP-18 內視鏡與自動清洗消毒追溯 | V22: （待調查） | X22: =IF($A22="","",IFERROR(INDEX(16_能力商機矩陣_CapOppMap!$D$162:$CO$162,MATCH($A22,16_能力商機矩陣_CapOppMap!$D$4:$CO$4,0)),"")) -> 0 | Y22: =IF(OR($A22="",$H22=""),"",IF($H22=0,"",ROUND(0.45*$I22+0.35*$J22+0.2*IF(LEFT($F22,1)="③",5,IF(LEFT($F22,1)="②",3,1))-IF($K22>0,0.3,0),2)+ROW()/100000)) -> 3.96022 | Z22: =IF($Y22="","",RANK($Y22,$Y$5:$Y$94)) -> 11 | AA22: L3 臨床設備層 | AB22: 越南專屬市場數據與法規未查得；Olympus已在Cho Ray/108醫院驗證內視鏡AI（2022-23）可作切入參照。 | AC22: C | AD22: 醫材市場（三家口徑）：TechSci 2024年15.5億美元→2030年25.3億（CAGR 8.45%）、Statista 2025年17.7億→2029年24.7億（CAGR 8.62%）、越南藥管局2024年約17億——CAGR一致約8.1-8.6%。2025-07-01起過渡措施全面終止：須在地MAH、ISO 13485、C/D類CSDT申報。Bidding Law 2023承認設備寄放／按次計費／委外檢驗等模式；⚠承包商選擇方式已於2025-07-01（Luật 90/2025/QH15）由6種增為10種（新增đặt hàng），另有線上詢價與線上採購兩種方式。硬缺口：直線加速器85台、分布近100家中心，放療量能僅滿足約60%需求（越南原子能主管機關2025-08）；透析實際僅4.5-5萬人接受治療、成人CKD達1,000-1,050萬人；PET/CT僅12台。2026-02 Tâm Anh採購全國首套質子治療系統（Mevion S250-FIT，近2兆越盾）。
A23: OPP-19 | B23: 加護病房與整合手術室設備包 | C23: ICU & Integrated OR Equipment Package | D23: C 醫材與臨床設備 | E23: 吊塔、影像整合、呼吸器、ECMO、麻醉機、監視系統與中央站的整區交付 | F23: ② 起步中：剛開始有人做 | G23: =IF($A23="","",IF($H23=0,"（尚無對應能力）",IFERROR(INDEX(16_能力商機矩陣_CapOppMap!$D$160:$CO$160,MATCH($A23,16_能力商機矩陣_CapOppMap!$D$4:$CO$4,0)),""))) -> D05 | H23: =IF($A23="","",IFERROR(INDEX(16_能力商機矩陣_CapOppMap!$D$156:$CO$156,MATCH($A23,16_能力商機矩陣_CapOppMap!$D$4:$CO$4,0)),"")) -> 2 | I23: =IF($A23="","",IFERROR(INDEX(16_能力商機矩陣_CapOppMap!$D$157:$CO$157,MATCH($A23,16_能力商機矩陣_CapOppMap!$D$4:$CO$4,0)),"")) -> 4.5 | J23: =IF($A23="","",IFERROR(INDEX(16_能力商機矩陣_CapOppMap!$D$158:$CO$158,MATCH($A23,16_能力商機矩陣_CapOppMap!$D$4:$CO$4,0)),"")) -> 2.4 | K23: =IF($A23="","",IFERROR(INDEX(16_能力商機矩陣_CapOppMap!$D$159:$CO$159,MATCH($A23,16_能力商機矩陣_CapOppMap!$D$4:$CO$4,0)),"")) -> 1 | L23: =IF($A23="","",IF($H23=0,"★白地商機：目前無對應能力，需新增能力或找新夥伴",IF($K23>0,"有缺口："&$K23&"項可對外招募","已有能力可承接"))) -> 有缺口：1項可對外招募 | M23: G4 | N23: 醫院業主資本支出(CAPEX) | O23: 設備銷售＋耗材 | P23: 2M-10M USD | Q23: 是 | R23: Clinical Engineering Lead | S23: 衛生部指出90%中央醫院在急救、ICU、心血管與外科設備上有短缺 | T23: =IF($A23="","",COUNTIF(14_商機清單_Pipeline!$A$5:$A$34,$U23)) -> 0 | U23: =IF($B23="","",$A23&" "&$B23) -> OPP-19 加護病房與整合手術室設備包 | V23: （待調查） | X23: =IF($A23="","",IFERROR(INDEX(16_能力商機矩陣_CapOppMap!$D$162:$CO$162,MATCH($A23,16_能力商機矩陣_CapOppMap!$D$4:$CO$4,0)),"")) -> 0 | Y23: =IF(OR($A23="",$H23=""),"",IF($H23=0,"",ROUND(0.45*$I23+0.35*$J23+0.2*IF(LEFT($F23,1)="③",5,IF(LEFT($F23,1)="②",3,1))-IF($K23>0,0.3,0),2)+ROW()/100000)) -> 3.17023 | Z23: =IF($Y23="","",RANK($Y23,$Y$5:$Y$94)) -> 69 | AA23: L3 臨床設備層 | AB23: （本項無專屬發現——見同列右方的家族／領域趨勢，或 19／20 分頁） | AC23: B | AD23: 醫材市場（三家口徑）：TechSci 2024年15.5億美元→2030年25.3億（CAGR 8.45%）、Statista 2025年17.7億→2029年24.7億（CAGR 8.62%）、越南藥管局2024年約17億——CAGR一致約8.1-8.6%。2025-07-01起過渡措施全面終止：須在地MAH、ISO 13485、C/D類CSDT申報。Bidding Law 2023承認設備寄放／按次計費／委外檢驗等模式；⚠承包商選擇方式已於2025-07-01（Luật 90/2025/QH15）由6種增為10種（新增đặt hàng），另有線上詢價與線上採購兩種方式。硬缺口：直線加速器85台、分布近100家中心，放療量能僅滿足約60%需求（越南原子能主管機關2025-08）；透析實際僅4.5-5萬人接受治療、成人CKD達1,000-1,050萬人；PET/CT僅12台。2026-02 Tâm Anh採購全國首套質子治療系統（Mevion S250-FIT，近2兆越盾）。
A24: OPP-20 | B24: 生殖醫學(IVF)實驗室整廠 | C24: IVF Laboratory Turnkey | D24: C 醫材與臨床設備 | E24: 培養箱、顯微操作、縮時攝影、冷凍保存與潔淨等級空調，加上訓練與流程建置 | F24: ② 起步中：剛開始有人做 | G24: =IF($A24="","",IF($H24=0,"（尚無對應能力）",IFERROR(INDEX(16_能力商機矩陣_CapOppMap!$D$160:$CO$160,MATCH($A24,16_能力商機矩陣_CapOppMap!$D$4:$CO$4,0)),""))) -> D05 | H24: =IF($A24="","",IFERROR(INDEX(16_能力商機矩陣_CapOppMap!$D$156:$CO$156,MATCH($A24,16_能力商機矩陣_CapOppMap!$D$4:$CO$4,0)),"")) -> 2 | I24: =IF($A24="","",IFERROR(INDEX(16_能力商機矩陣_CapOppMap!$D$157:$CO$157,MATCH($A24,16_能力商機矩陣_CapOppMap!$D$4:$CO$4,0)),"")) -> 4.7 | J24: =IF($A24="","",IFERROR(INDEX(16_能力商機矩陣_CapOppMap!$D$158:$CO$158,MATCH($A24,16_能力商機矩陣_CapOppMap!$D$4:$CO$4,0)),"")) -> 2.4 | K24: =IF($A24="","",IFERROR(INDEX(16_能力商機矩陣_CapOppMap!$D$159:$CO$159,MATCH($A24,16_能力商機矩陣_CapOppMap!$D$4:$CO$4,0)),"")) -> 0 | L24: =IF($A24="","",IF($H24=0,"★白地商機：目前無對應能力，需新增能力或找新夥伴",IF($K24>0,"有缺口："&$K24&"項可對外招募","已有能力可承接"))) -> 已有能力可承接 | M24: G4 | N24: 病人自費 | O24: 設備銷售＋耗材 | P24: 500K-2M USD | Q24: 是 | R24: Clinical Engineering Lead | S24: 全自費、不涉健保，台灣／日本臨床品牌有明顯溢價 | T24: =IF($A24="","",COUNTIF(14_商機清單_Pipeline!$A$5:$A$34,$U24)) -> 0 | U24: =IF($B24="","",$A24&" "&$B24) -> OPP-20 生殖醫學(IVF)實驗室整廠 | V24: （待調查） | X24: =IF($A24="","",IFERROR(INDEX(16_能力商機矩陣_CapOppMap!$D$162:$CO$162,MATCH($A24,16_能力商機矩陣_CapOppMap!$D$4:$CO$4,0)),"")) -> 0 | Y24: =IF(OR($A24="",$H24=""),"",IF($H24=0,"",ROUND(0.45*$I24+0.35*$J24+0.2*IF(LEFT($F24,1)="③",5,IF(LEFT($F24,1)="②",3,1))-IF($K24>0,0.3,0),2)+ROW()/100000)) -> 3.56024 | Z24: =IF($Y24="","",RANK($Y24,$Y$5:$Y$94)) -> 41 | AA24: L3 臨床設備層 | AB24: 全國65家持照生殖中心、年5萬+週期、成功率40-50%、單週期約3,000-4,600美元（已開發國家1/5）；1998年來累計20萬IVF嬰兒。 | AC24: A | AD24: 醫材市場（三家口徑）：TechSci 2024年15.5億美元→2030年25.3億（CAGR 8.45%）、Statista 2025年17.7億→2029年24.7億（CAGR 8.62%）、越南藥管局2024年約17億——CAGR一致約8.1-8.6%。2025-07-01起過渡措施全面終止：須在地MAH、ISO 13485、C/D類CSDT申報。Bidding Law 2023承認設備寄放／按次計費／委外檢驗等模式；⚠承包商選擇方式已於2025-07-01（Luật 90/2025/QH15）由6種增為10種（新增đặt hàng），另有線上詢價與線上採購兩種方式。硬缺口：直線加速器85台、分布近100家中心，放療量能僅滿足約60%需求（越南原子能主管機關2025-08）；透析實際僅4.5-5萬人接受治療、成人CKD達1,000-1,050萬人；PET/CT僅12台。2026-02 Tâm Anh採購全國首套質子治療系統（Mevion S250-FIT，近2兆越盾）。
