Workbook

Sheet 00_使用說明_Howto
A1: VMH-EcoMap-2 專案商模試算器 v1.0｜Project Business Case Calculator
A2: 搭配主工具「VMH-EcoMap-1_主工具_越南醫院生態盤點」使用。主工具回答「做不做、誰做、何時做」；本檔回答「這一個子專案划不划算」。本檔的六個設計重點：投資類別框架（不同類別用不同評估尺規）、三幣別一鍵切換、BOQ 級成本明細、折舊攤提與越南稅務優惠、WACC 推算與 FCFF 現金流、使能型投資專用評估。
A4: 一、本檔最重要的一個觀念：不同類型的投資，要用不同的尺
B5: 把「機房」「網路」「資料平台」這類基礎建設，拿去跟「CT 影像中心」用同一套 NPV 標準比較，結論一定是基礎建設不值得投——但那是尺用錯了，不是案子不好。 MIT Sloan（Weill & Aral）的實證指出：基礎建設是企業 IT 支出中佔比最高的一類（平均 46%），也是「事前最難做成本正當化（most difficult to cost-justify in advance）」的一類——因為效益歸屬於建在它上面的其他專案，成本卻留在自己身上。同一份研究還顯示：★ 績效前段班公司把 55% 的 IT 支出放在基礎建設，後段班只有 37%。 因此本檔在 01 分頁要求先選「投資類別」，10 決策摘要會依類別套用不同的判讀規則，使能型投資另有 09 分頁專用的「自建 vs 外租 TCO」評估。
A10: 二、六種投資類別與各自該用的評估指標
B11: 類別 | C11: 定義 | D11: 通過條件 | E11: 主要指標 | F11: 典型案例
B12: A 營收型投資 Revenue-generating | C12: 本身直接向外部付款者收費，自己就能產生現金流。對應 Weill 四分類的 Transactional／Strategic。 | D12: NPV ＞ 0、IRR ≥ WACC、折現回收期在合約年限內 | E12: NPV／IRR／PI | F12: 例：CT 影像中心、檢驗中心、健檢中心——有給付碼或自費市場，「做一件收一件」。
B13: B 使能型投資 Enabling / Infrastructure | C13: 本身不直接收費，而是讓其他專案得以成立、或降低整體營運成本。Weill 四分類佔比最高（46%）、也是 MIT Sloan 明指「事前最難做成本正當化」的一類。 | D13: ΔTCO（不做 vs 做）現值 ＞ 0；服務單位成本低於外購市價；承載專案數 ≥ 2 | E13: ΔTCO 現值／單位服務成本／選擇權價值 | F13: 例：院內 IDC 機房、院區網路、資料平台、整合中介層。★ 用單獨 NPV 評估必然為負——那是尺用錯了，不是案子不好。
B14: C 法規強制型 Mandatory / Compliance | C14: 法規或評鑑要求，不做就不能營業。CFA 資本預算明列此類「通常不產生營收、繞過傳統成本效益分析」。 | D14: 在合規前提下的最低總成本；並列出「不做的代價」（罰則、停業、失去投標資格） | E14: 最低合規成本／不做的代價 | F14: 例：電子病歷分級驗收、個資法 PDPL 91/2025 合規、資安等級保護、輻射安全許可。
B15: D 降本型投資 Cost-reduction | C15: 不增加收入，但減少既有支出。效益＝被避免掉的成本。 | D15: 成本節省現值 ＞ 投資額；回收期 ≤ 設備壽命的一半 | E15: 成本節省 NPV／回收期 | F15: 例：無片化（省底片）、能源優化、流程自動化、以租代購取代自購。
B16: E 汰換維持型 Replacement / Maintenance | C16: 維持既有營運不中斷。CFA 分類指出此類「通常不做詳細分析」，因為不做就停擺。 | D16: 與「不汰換的停機風險成本」比較；同規格中取最低生命週期成本 | E16: 生命週期成本／停機風險 | F16: 例：UPS 電池更換、伺服器汰換、球管更換、到期授權續約。
B17: F 策略布局型 Strategic / Option | C17: 為了取得未來機會、參考案例或市場位置。現金流高度不確定，CFA 指出需「超越傳統資本預算」的方法。 | D17: 分階段關卡（stage-gate）：每階段設可量測的續投條件，而非一次核定全額 | E17: 選擇權價值／階段關卡達成率 | F17: 例：第一家旗艦醫院（取得 reference site）、新國家市場試點、AI 產品共同開發。
A19: 三、分頁導覽（黃底＝要填，藍字＝公式自動算）
B20: 順序 | C20: 分頁 | D20: 性質 | E20: 內容
B21: ① | C21: 01 專案設定 | D21: 填 | E21: 專案識別、★投資類別、幣別與匯率（預設新台幣，可一鍵切換 USD／VND）、稅務優惠、營運資金、終值假設。
B22: ①B | C22: 01B 類別判斷精靈 | D22: 填 | E22: ★ 不確定該選哪一種投資類別時用。回答四題 → 推薦一類＋說明理由＋列出下一步，並與 01 分頁目前的選擇比對。
B23: ② | C23: 02 投資成本 CAPEX | D23: 填 | E23: BOQ 級明細：分項工程名稱、單位、數量、單價、進口／在地、關稅與 VAT、折舊類別與年限、置換年、殘值率。
B24: ③ | C24: 03 營運成本 OPEX | D24: 填 | E24: 人力、維保、耗材、電力、授權、保險；可設年成長率，並標示「隨服務量變動」或「固定」。
B25: ④ | C25: 04 收入與產能 | D25: 填 | E25: 服務量、健保價與自費價、自費比例、成長率、開辦爬坡。使能型投資可留白（收入為 0）。
B26: ⑤ | C26: 05 折舊攤提 | D26: 算 | E26: 依 02 每一列的折舊類別與年限，逐年計算折舊；置換資產於置換年重新起算。依越南 Circular 45/2013/TT-BTC。
B27: ⑥ | C27: 06 現金流 | D27: 算 | E27: 營收→EBITDA→折舊→EBIT→所得稅（含免稅期與虧損扣抵）→NOPAT→＋折舊−資本支出−營運資金＝自由現金流 FCFF。
B28: ⑦ | C28: 07 折現率 WACC | D28: 填/算 | E28: CAPM：無風險利率＋β×成熟市場風險溢酬＋越南國家風險溢酬，再與債務成本加權。可切換為手動輸入。
B29: ⑧ | C29: 08 敏感度 | D29: 算 | E29: 三情境（保守／基準／樂觀）、量價 ±30% 矩陣、龍捲風圖（哪個變數最致命）、損益兩平點。
B30: ⑨ | C30: 09 使能型評估 | D30: 填/算 | E30: ★ 僅使能型投資需要：自建 vs 外租十年 TCO 比較、承載專案成本分攤、單位服務成本、選擇權價值。
B31: ⑩ | C31: 10 決策摘要 | D31: 算 | E31: 一頁結論。★ 判讀規則依 01 選定的投資類別自動切換。
B32: ⑪ | C32: 11 假設來源 | D32: 填 | E32: 每一筆金額與比率的出處、狀態（實績／報價／法規／推測）、日期、負責人。
A34: 四、本檔的六個設計重點
B35: ▍三幣別一鍵切換 | C35: 01 分頁選「輸入幣別」與「顯示幣別」，全檔金額自動換算。預設輸入新台幣。另可切換顯示單位（元／千元／百萬元），避免越南盾位數過長。
B36: ▍BOQ 級成本明細 | C36: 02、03 用工程界正式的分項名稱與「數量×單價」結構，並區分進口／在地。★ 越南醫療服務免 VAT，代表進項 VAT 不可扣抵、必須計入成本——本檔已內建此欄位，這是越南醫院財務模型最常見的重大低估。
B37: ▍折舊與越南稅務優惠 | C37: 折舊依 Circular 45/2013/TT-BTC 的法定年限區間。稅率不再寫死：社會化醫療領域適用 10% 優惠稅率（PwC：整個專案期），並內建免稅 4 年＋減半期，且免稅起算採「首次獲利年 vs 營收第 4 年孰早」的法定規則。虧損可扣抵 5 年。
B38: ▍營運資金 | C38: 越南健保給付延遲是真實風險——2025 年胡志明市各醫院被懸置的健保結算近 2,500 十億越盾。本檔把健保應收天數與自費應收天數分開設定，並計入現金流。
B39: ▍WACC 與 FCFF | C39: 折現率不再是隨手填的數字：07 分頁用 CAPM 推算（越南 10 年期公債殖利率＋β×成熟市場 ERP＋越南國家風險溢酬）。現金流改用業界標準的無槓桿自由現金流 FCFF。
B40: ▍MIRR、PI、ROIC、龍捲風 | C40: IRR 對「中途有大額置換投資」的現金流可能出現多重解，且隱含以 IRR 本身再投資的不合理假設——本檔改以 MIRR 為主要報酬指標。另加 PI（資本受限時的排序指標）、ROIC（與 WACC 比較）、龍捲風圖（找出最致命的變數）。
B42: 重要聲明：本檔內建的金額為「規劃用示意值」，用來讓模型立即跑出結果與示範用法，不是越南市場報價。正式評估前，每一筆金額都必須以廠商報價、越南在地工程估算或合約條件取代，並在 11 分頁登錄出處。稅務優惠的實際適用（特別是社會化醫療 10% 稅率的資格認定）須由越南在地稅務顧問就個案出具確認。

Sheet 01_專案設定_Setup
A1: 01 專案設定｜Project Setup
A2: 黃底＝請填寫或用下拉選擇；藍字＝公式自動算，請勿覆蓋。本頁的設定會驅動後面所有分頁。
J3: （類別查表區，可隱藏）
A4: A. 專案識別 | J4: A 營收型投資 Revenue-generating | K4: 本身直接向外部付款者收費，自己就能產生現金流。對應 Weill 四分類的 Transactional／Strategic。 | L4: NPV ＞ 0、IRR ≥ WACC、折現回收期在合約年限內 | M4: NPV／IRR／PI | N4: 例：CT 影像中心、檢驗中心、健檢中心——有給付碼或自費市場，「做一件收一件」。 | O4: NPV
A5: 專案名稱 Project name | B5: B醫院 500床 HIS／EMR 以租代購 一期（模擬案） | D5: 建議格式：醫院＋標的＋期別，例「A醫院 128排CT影像中心 一期」 | J5: B 使能型投資 Enabling / Infrastructure | K5: 本身不直接收費，而是讓其他專案得以成立、或降低整體營運成本。Weill 四分類佔比最高（46%）、也是 MIT Sloan 明指「事前最難做成本正當化」的一類。 | L5: ΔTCO（不做 vs 做）現值 ＞ 0；服務單位成本低於外購市價；承載專案數 ≥ 2 | M5: ΔTCO 現值／單位服務成本／選擇權價值 | N5: 例：院內 IDC 機房、院區網路、資料平台、整合中介層。★ 用單獨 NPV 評估必然為負——那是尺用錯了，不是案子不好。 | O5: DTCO
A6: 對應能力 CAP ID | B6: CAP-033 HIS／EMR核心平台 | D6: 對應主工具 03 能力總表的編號，讓本案接得回盤點結果 | J6: C 法規強制型 Mandatory / Compliance | K6: 法規或評鑑要求，不做就不能營業。CFA 資本預算明列此類「通常不產生營收、繞過傳統成本效益分析」。 | L6: 在合規前提下的最低總成本；並列出「不做的代價」（罰則、停業、失去投標資格） | M6: 最低合規成本／不做的代價 | N6: 例：電子病歷分級驗收、個資法 PDPL 91/2025 合規、資安等級保護、輻射安全許可。 | O6: MINCOST
A7: 主責夥伴 Lead partner | B7: P-007 醫療資訊整合商（＋群晶科技：承載環境） | D7: 對應主工具 04 夥伴拼圖 | J7: D 降本型投資 Cost-reduction | K7: 不增加收入，但減少既有支出。效益＝被避免掉的成本。 | L7: 成本節省現值 ＞ 投資額；回收期 ≤ 設備壽命的一半 | M7: 成本節省 NPV／回收期 | N7: 例：無片化（省底片）、能源優化、流程自動化、以租代購取代自購。 | O7: SAVING
A8: 情境範本 Template | B8: HIS 醫療資訊系統 | D8: CT 影像設備／IDC 機房／HIS 醫療資訊系統／自訂 | J8: E 汰換維持型 Replacement / Maintenance | K8: 維持既有營運不中斷。CFA 分類指出此類「通常不做詳細分析」，因為不做就停擺。 | L8: 與「不汰換的停機風險成本」比較；同規格中取最低生命週期成本 | M8: 生命週期成本／停機風險 | N8: 例：UPS 電池更換、伺服器汰換、球管更換、到期授權續約。 | O8: LCC
A9: ★ 投資類別 Investment category | B9: F 策略布局型 Strategic / Option | D9: ★ 最重要的一格。不同類別在 10 決策摘要會套用不同的判讀規則——用錯尺就會做出錯的決定。 | J9: F 策略布局型 Strategic / Option | K9: 為了取得未來機會、參考案例或市場位置。現金流高度不確定，CFA 指出需「超越傳統資本預算」的方法。 | L9: 分階段關卡（stage-gate）：每階段設可量測的續投條件，而非一次核定全額 | M9: 選擇權價值／階段關卡達成率 | N9: 例：第一家旗艦醫院（取得 reference site）、新國家市場試點、AI 產品共同開發。 | O9: OPTION
A10: └ 類別定義 | B10: =IFERROR(INDEX(_CatDef,MATCH($B$9,_CatName,0)),"") -> 為了取得未來機會、參考案例或市場位置。現金流高度不確定，CFA 指出需「超越傳統資本預算」的方法。
A11: └ 通過條件 | B11: =IFERROR(INDEX(_CatCond,MATCH($B$9,_CatName,0)),"") -> 分階段關卡（stage-gate）：每階段設可量測的續投條件，而非一次核定全額
A12: └ 主要評估指標 | B12: =IFERROR(INDEX(_CatMetric,MATCH($B$9,_CatName,0)),"") -> 選擇權價值／階段關卡達成率
A13: └ 判斷精靈比對 | B13: =IF(LEFT('01B_類別判斷_Wizard'!$C$22,1)="▶","▶ 不確定要選哪一類？請到 01B 判斷精靈分頁回答四題，它會推薦一類並說明理由。",IF('01B_類別判斷_Wizard'!$C$22=$B$9,"✓ 與 01B 判斷精靈的建議一致。","⚠ 與 01B 判斷精靈的建議不一致——精靈建議：「"&'01B_類別判斷_Wizard'!$C$22&"」。若你有充分理由維持目前的選擇，請在 11 假設來源分頁記錄原因。")) -> ✓ 與 01B 判斷精靈的建議一致。
A15: B. 幣別與匯率（預設輸入新台幣；顯示幣別可一鍵切換）
A16: 輸入幣別 Input currency | B16: TWD 新台幣 | D16: ★ 02、03、04 分頁「單價」欄位是用這個幣別填寫的。改這一格不會換算既有數字，只改變你打算用什麼幣別填。
A17: 顯示幣別 Display currency | B17: TWD 新台幣 | D17: ★ 一鍵切換：改這一格，全檔的金額顯示會自動換算。輸入的數字不動。
A18: 顯示單位 Display unit | B18: 千元 Thousand | D18: 越南盾位數很長，建議切到「百萬 Million」；新台幣建議「千元」。
A20: 匯率表（以越南盾為基準） | D20: ★ 財務模型慣例：3–10 年的長期預測不應直接用即期匯率。Damodaran 明述「Never use the current spot rate for long-term projections」，正確作法是用兩國通膨差（購買力平價）推算逐年匯率，或全程用單一幣別建模、最後才換算。本檔採後者（較穩健），並在 11 分頁登錄匯率假設與日期。
A21: 幣別 | B21: 1 單位 ＝ ? 越南盾 | C21: 代碼
A22: TWD 新台幣 | B22: 810 | C22: TWD
A23: USD 美元 | B23: 26082 | C23: USD
A24: VND 越南盾 | B24: 1 | C24: VND
A26: 輸入幣別對 VND 匯率 | B26: =INDEX($B$22:$B$24,MATCH($B$16,$A$22:$A$24,0)) -> 810 | D26: 自動由上表帶出
A27: 顯示幣別對 VND 匯率 | B27: =INDEX($B$22:$B$24,MATCH($B$17,$A$22:$A$24,0)) -> 810 | D27: 自動由上表帶出
A28: 幣別換算倍率 FX multiplier | B28: =$B$26/$B$27 -> 1 | D28: ＝輸入幣別匯率 ÷ 顯示幣別匯率。輸入幣別的金額 × 這個倍率 ＝ 顯示幣別的金額。
A29: 顯示單位除數 | B29: =IF($B$18="元 Unit",1,IF($B$18="千元 Thousand",1000,1000000)) -> 1000 | D29: 自動由「顯示單位」帶出
A30: ★ 顯示係數 Display factor | B30: =$B$28/$B$29 -> 0.001 | D30: 全檔所有「顯示幣別」欄位都乘這個係數。
A31: 金額標示 Money label | B31: =LEFT($B$17,3)&" "&IF($B$29=1,"元",IF($B$29=1000,"千",""&"百萬")) -> TWD 千 | D31: 出現在各分頁的欄位標題，例「TWD 千」
A33: C. 時間與稅務（越南）
A34: 模型年數 Model years | B34: 10 | C34: 年 | D34: 建議 8–12 年，須涵蓋主要設備壽命。本檔欄位配置上限為 10 年。
A35: 建置期 Build months | B35: 12 | C35: 月 | D35: 第 0 年＝建置期，不產生收入
A36: 起始年 Start year | B36: 2027 | C36: 年 | D36: 第 1 個營運年的西元年
A37: 標準企業所得稅率 | B37: 0.2 | D37: 越南標準 CIT 稅率 20%（Law 67/2025/QH15 自 2025/10/1 生效）
A38: 適用優惠稅率 | B38: 0.1 | D38: ★ PwC 越南 Pocket Tax Book 明載：教育、醫療等社會化領域享有「整個專案存續期間」的 10% 稅率。若本案不符資格請改回 20%。資格認定須由越南稅務顧問確認。
A39: 免稅年數 Tax holiday | B39: 4 | C39: 年 | D39: 社會化專案：位於社經困難地區者免稅 4 年＋減半 9 年；一般地區免稅 4 年＋減半 5 年。
A40: 減半年數 50% reduction | B40: 5 | C40: 年 | D40: 接續免稅期之後，稅率減半（10%→5%）
A41: 免稅起算規則：營收後最多遞延 | B41: 3 | C41: 年 | D41: ★ 法定規則（PwC）：免稅期自「首次從受優惠活動獲利」起算；但若產生營收後 3 年內仍未獲利，則自營運第 4 年起強制起算。本檔已內建此邏輯。
A42: 虧損可扣抵年限 | B42: 5 | C42: 年 | D42: 越南：虧損可全額連續向後扣抵最長 5 年，不得向前扣抵。逾期未用即永久失效。
A43: ★ 進項 VAT 可否扣抵 | B43: 否 — 醫療服務免 VAT | D43: ★ 越南醫療檢查治療服務屬 VAT「免稅（exempt）」而非零稅率（VAT Law 48/2024/QH15 第 5 條第 10 款）。免稅代表進項 VAT 不可扣抵、必須計入成本。這是越南醫院財務模型最常見的重大低估（CAPEX 會少估 5–10%）。
A45: D. 折現率
...

Sheet 01B_類別判斷_Wizard
A1: 01B 投資類別判斷精靈｜Which yardstick should this project be measured with?
A2: 不確定 01 分頁該選哪一種投資類別時，回答下面四題（不適用的題目留白即可），本頁會推薦一類並說明理由。★ 這是輔助工具，不是替你決定——推薦出來之後請自己確認合理，再回到 01 分頁 B 欄選擇。
A4: ★ 回答之前先確認一件事：本試算器一律站在「群晶／聯盟」的投資角度，不是醫院的角度。 同一個案子，對醫院可能是「法規強制型」（不做不能營業），對群晶卻是「營收型」或「策略布局型」。搞錯立場，後面四題都會答錯。
A7: A. 依序回答（不適用的題留白）
A8: 題號 | B8: 問題 | C8: 你的回答（下拉選擇） | D8: 怎麼想這一題
A9: Q1 | B9: 這個案子有沒有錢從「聯盟外部」進來？ | C9: 有，但金額還算不準（要等市場成熟，或要等第 2、3 個客戶） | D9: ★ 關鍵在「外部」兩個字。外部＝聯盟以外的付款者（醫院、健保 BHYT、病人自費、保險公司）。院內或聯盟內的「內部轉付服務費」不算——那是左手換右手，不是新的錢進來。「算得準」的意思是：有公告給付碼、有正式報價，或有可比的市場行情。
A12: Q2 | B12: 不做這個案子，會發生什麼？（Q1 選「沒有」才需要答） | D12: 這一題在問「效益的形式」。它不產生收入，那它到底幫你避免了什麼？是別的專案做不成、是被罰、是某筆支出繼續花、還是營運中斷——四種答案對應四種不同的評估方法。
A15: Q3 | B15: 這個案子承載（服務）幾個其他專案？ | D15: ★ 使能型投資的硬門檻：必須 ≥ 2。只服務單一專案的「平台」，本質上是那個專案的成本，不是平台，應該把成本併進那個專案一起評估。填之前可以先去 09 分頁 F 區塊把承載清單列出來數一數。
A18: Q4 | B18: 不做的話，現有營運會不會停擺？（Q2 選「某一筆既有支出」才需要答） | D18: 用來分辨 D 降本型與 E 汰換維持型。判準是「你有沒有真的選擇」：不做就停擺 ⇒ E（沒得選，不必細算，同規格取最低生命週期成本即可）；還能撐一段時間 ⇒ D（有得選，要細算，因為你可以選擇不做）。
A21: B. 判斷結果
A22: ★ 建議投資類別 | C22: =IF($C$9="","▶ 請先回答 Q1",IF(ISNUMBER(SEARCH("算得準",$C$9)),"A 營收型投資 Revenue-generating",IF(ISNUMBER(SEARCH("算不準",$C$9)),"F 策略布局型 Strategic / Option",IF($C$12="","▶ 請回答 Q2",IF(ISNUMBER(SEARCH("別的專案",$C$12)),IF($C$15="","▶ 請回答 Q3",IF($C$15>=2,"B 使能型投資 Enabling / Infrastructure","⚠ 不應獨立立案（承載專案數不足 2）")),IF(ISNUMBER(SEARCH("罰",$C$12)),"C 法規強制型 Mandatory / Compliance",IF(ISNUMBER(SEARCH("既有支出",$C$12)),IF($C$18="","▶ 請回答 Q4",IF(ISNUMBER(SEARCH("會停擺",$C$18)),"E 汰換維持型 Replacement / Maintenance","D 降本型投資 Cost-reduction")),IF(ISNUMBER(SEARCH("營運會中斷",$C$12)),"E 汰換維持型 Replacement / Maintenance","▶ 請回答 Q2")))))))) -> F 策略布局型 Strategic / Option
A23: 判斷理由 | C23: =IF(LEFT($C$22,1)="▶","",IF(LEFT($C$22,1)="A","效益是外部客戶付進來的錢，而且金額算得準 ⇒ 用 NPV／MIRR／PI 這把尺，本案適合走標準資本預算流程。",IF(LEFT($C$22,1)="B","它不對外收費，但別的專案要靠它才能做，且承載 "&$C$15&" 個專案（≥2）⇒ 用 ΔTCO 差異法（做 vs 不做），不是絕對 NPV。",IF(LEFT($C$22,1)="C","不做就不能營業，屬強制投資 ⇒ 比的是「合規前提下的最低總成本」與「不做的代價」。NPV 為負屬正常，不構成否決理由。",IF(LEFT($C$22,1)="D","收入不變，但某筆既有支出會消失，而且你還有得選 ⇒ 效益＝被避免掉的成本，要細算。",IF(LEFT($C$22,1)="E","不做就停擺，沒得選 ⇒ 不必用 NPV 論斷，同規格中取最低生命週期成本、並確認停機風險成本即可。",IF(LEFT($C$22,1)="F","錢會進來，但現在算不準（要等市場成熟或第 2、3 個客戶）⇒ 不要一次核定全額，改用分階段關卡。","承載專案數不足 2 ⇒ 這不是平台，是它所服務的那一個專案的成本。建議把本案的建置成本併入該專案一起評估，不要獨立立案。"))))))) -> 錢會進來，但現在算不準（要等市場成熟或第 2、3 個客戶）⇒ 不要一次核定全額，改用分階段關卡。
A24: 建議下一步 | C24: =IF(LEFT($C$22,1)="▶","",IF(LEFT($C$22,1)="B","▶ 到 09 使能型評估分頁：F 區塊填承載專案清單、C 區塊填外租比較報價，ΔTCO 才算得出來。",IF(LEFT($C$22,1)="F","▶ 把 02 分頁的 CAPEX 拆成 2–3 期，每期在 11 假設來源分頁寫下可量測的續投條件（不要一次核定全額）。",IF(LEFT($C$22,1)="C","▶ 到 11 假設來源分頁登錄：法源、期限、不做的罰則或停業風險，並附至少三家供應商的比價。",IF(LEFT($C$22,1)="E","▶ 到 11 假設來源分頁登錄：現有資產的剩餘壽命、故障率，以及不汰換的停機風險成本。",IF(LEFT($C$22,1)="⚠","▶ 不要獨立立案。把本案成本併入它所服務的那個專案，或先確認第 2 個承載專案再回來。","▶ 把 02 分頁的示意值換成廠商正式報價，並確認 07 分頁的折現率已與投資方書面談定。")))))) -> ▶ 把 02 分頁的 CAPEX 拆成 2–3 期，每期在 11 假設來源分頁寫下可量測的續投條件（不要一次核定全額）。
A25: 與 01 分頁比對 | C25: =IF(LEFT($C$22,1)="▶","",IF($C$22='01_專案設定_Setup'!$B$9,"✓ 與 01 分頁目前的選擇一致，可以繼續。","⚠ 01 分頁目前選的是「"&'01_專案設定_Setup'!$B$9&"」，與本頁建議不同。若要採用建議，請到 01 分頁 B9 改選；若你有充分理由維持原選擇（例如本案同時具備兩種屬性），請在 11 假設來源分頁記錄理由。")) -> ✓ 與 01 分頁目前的選擇一致，可以繼續。
A28: C. 四個最常卡住的地方
A29: ① 立場沒講清楚 | C29: 同一個案子，對醫院是「法規強制型」（2025 年 10 月前必須完成電子病歷），對群晶卻是「策略布局型」。本表一律站在群晶／聯盟的投資角度。填之前先確認你在算誰的帳。
A30: ② 內部轉付被當成營收 | C30: 機房向院內其他專案收「內部服務費」，看起來像收入，但那是左手換右手。判準：這筆錢有沒有從聯盟外部進來？沒有就是 B 使能型，不是 A 營收型。
A31: ③ D 和 E 分不開 | C31: 汰換舊伺服器同時也省電費，算哪一種？看你有沒有真的選擇：不換就停擺 ⇒ E（不必細算）；還能撐但換了更省 ⇒ D（要細算）。這就是 Q4 在問的事。
A32: ④ 一個案子同時符合兩三類 | C32: 很常見。IDC 案其實同時是 B（承載別的專案）和 D（比外租省錢）。規則：選效益佔比最大的那一類，其餘寫進 11 假設來源分頁備註，不要為了數字好看挑一個。
A34: 如果四題怎麼答都答不出來，通常不是分類法不夠用，而是「專案範圍畫錯了」——把兩件性質不同的事綁在同一個案子裡。這時候該做的是拆案，不是硬選一個類別。（本工具的 IDC 個案刻意把院區網路排除在機房案之外，就是這個理由。）

Sheet 02_投資成本_CAPEX
A1: 02 投資成本 CAPEX｜工程分項明細（BOQ）
A2: 黃底＝要填。每一列請用工程界正式的分項名稱，並以「數量 × 單價」結構表達，這樣才能拿去跟廠商報價逐項核對。★ 關稅與 VAT：越南醫療服務屬 VAT 免稅，代表進項 VAT 不可扣抵、必須計入成本並資本化——K 欄已內建此計算。★ 折舊年限依 Circular 45/2013/TT-BTC：建物 25–50 年、醫療設備 6–15 年、電腦設備 3–8 年、軟體 3–8 年。
A4: ★ 進口項目會被課關稅與進口 VAT，且關稅計價基礎是 CIF（含運費保險）；在地施工項目只有 VAT。CT 主機 HS 9022.12.00 的 MFN 稅率為 0%、FTA 亦為 0%（須附有效 C/O），但 UPS／發電機／空調類非 ITA 涵蓋，稅率明顯較高。
A5: 項次 | B5: 分類 | C5: 分項工程名稱 Work item（工程界正式名稱） | D5: 單位 | E5: 數量 | F5: 單價 （輸入幣別） | G5: 未稅小計 （輸入幣別） | H5: 進口／在地 | I5: 關稅率 | J5: VAT率 | K5: 不可扣抵稅費 （輸入幣別） | L5: 含稅總額 （輸入幣別） | M5: 折舊類別 | N5: 折舊 年限 | O5: 置換年 | P5: 殘值率 | Q5: =CONCATENATE("含稅總額",CHAR(10),"（",'01_專案設定_Setup'!$B$31,"）") -> 含稅總額 （TWD 千） | R5: 出處／備註
A6: 1 | B6: 軟體 | C6: HIS／EMR 核心平台授權（500 床規模，含門診、住院、批價、病歷） | D6: 套 | E6: 1 | F6: 9205500 | G6: =IF($C6="",0,$E6*$F6) -> 9205500 | H6: 進口 | I6: 0 | J6: 0.1 | K6: =IF($C6="",0,$G6*$I6+$G6*(1+$I6)*$J6*IF(LEFT('01_專案設定_Setup'!$B$43,1)="否",1,0)) -> 920550 | L6: =IF($C6="",0,$G6+$K6) -> 10126050 | M6: 軟體與無形 Software | N6: 5 | O6: 0 | P6: 0 | Q6: =IF($C6="",0,$L6*'01_專案設定_Setup'!$B$30) -> 10126.05 | R6: tuoitre.vn：越南一級醫院 IT 投資 10.5–40bn VND、占營收 0.57–2.1%。★ 越南無公開每床授權價，廠商不公布價目（ykhoanet.com）
A7: 2 | B7: 軟體 | C7: LIS 檢驗資訊模組與儀器雙向介接 | D7: 套 | E7: 1 | F7: 1453500 | G7: =IF($C7="",0,$E7*$F7) -> 1453500 | H7: 進口 | I7: 0 | J7: 0.1 | K7: =IF($C7="",0,$G7*$I7+$G7*(1+$I7)*$J7*IF(LEFT('01_專案設定_Setup'!$B$43,1)="否",1,0)) -> 145350 | L7: =IF($C7="",0,$G7+$K7) -> 1598850 | M7: 軟體與無形 Software | N7: 5 | O7: 0 | P7: 0 | Q7: =IF($C7="",0,$L7*'01_專案設定_Setup'!$B$30) -> 1598.85 | R7: 電子病歷分級驗收要求檢驗檢查閉環
A8: 3 | B8: 軟體 | C8: RIS／PACS 介接與院內影像調閱 | D8: 套 | E8: 1 | F8: 1065900 | G8: =IF($C8="",0,$E8*$F8) -> 1065900 | H8: 進口 | I8: 0 | J8: 0.1 | K8: =IF($C8="",0,$G8*$I8+$G8*(1+$I8)*$J8*IF(LEFT('01_專案設定_Setup'!$B$43,1)="否",1,0)) -> 106590 | L8: =IF($C8="",0,$G8+$K8) -> 1172490 | M8: 軟體與無形 Software | N8: 5 | O8: 0 | P8: 0 | Q8: =IF($C8="",0,$L8*'01_專案設定_Setup'!$B$30) -> 1172.49 | R8: 與 A 醫院 CT 案的 PACS 採同一套標準，利於日後複製
A9: 4 | B9: 軟體 | C9: 藥事管理與閉環給藥 CPOE／BCMA 模組 | D9: 套 | E9: 1 | F9: 1227400 | G9: =IF($C9="",0,$E9*$F9) -> 1227400 | H9: 進口 | I9: 0 | J9: 0.1 | K9: =IF($C9="",0,$G9*$I9+$G9*(1+$I9)*$J9*IF(LEFT('01_專案設定_Setup'!$B$43,1)="否",1,0)) -> 122740 | L9: =IF($C9="",0,$G9+$K9) -> 1350140 | M9: 軟體與無形 Software | N9: 5 | O9: 0 | P9: 0 | Q9: =IF($C9="",0,$L9*'01_專案設定_Setup'!$B$30) -> 1350.14 | R9: 給藥安全是 EMR 分級驗收的重點項目
A10: 5 | B10: 軟體 | C10: 護理紀錄與電子表單（含行動護理車終端授權） | D10: 套 | E10: 1 | F10: 839800 | G10: =IF($C10="",0,$E10*$F10) -> 839800 | H10: 進口 | I10: 0 | J10: 0.1 | K10: =IF($C10="",0,$G10*$I10+$G10*(1+$I10)*$J10*IF(LEFT('01_專案設定_Setup'!$B$43,1)="否",1,0)) -> 83980 | L10: =IF($C10="",0,$G10+$K10) -> 923780 | M10: 軟體與無形 Software | N10: 5 | O10: 0 | P10: 0 | Q10: =IF($C10="",0,$L10*'01_專案設定_Setup'!$B$30) -> 923.78 | R10: 護理紀錄電子化是無紙化的最大工作量
A11: 6 | B11: 軟體 | C11: FHIR 介接引擎（HL7 FHIR R4＋DICOM） | D11: 套 | E11: 1 | F11: 1550400 | G11: =IF($C11="",0,$E11*$F11) -> 1550400 | H11: 進口 | I11: 0 | J11: 0.1 | K11: =IF($C11="",0,$G11*$I11+$G11*(1+$I11)*$J11*IF(LEFT('01_專案設定_Setup'!$B$43,1)="否",1,0)) -> 155040 | L11: =IF($C11="",0,$G11+$K11) -> 1705440 | M11: 軟體與無形 Software | N11: 5 | O11: 0 | P11: 0 | Q11: =IF($C11="",0,$L11*'01_專案設定_Setup'!$B$30) -> 1705.44 | R11: Decision 2146/QĐ-BYT 指定 HL7 FHIR R4＋DICOM 為國家標準；★ 越南本地 IG 仍為試用版，規格會變
A12: 7 | B12: 軟體 | C12: VNeID／VSS 健保申報與身分核驗介接 | D12: 套 | E12: 1 | F12: 1421200 | G12: =IF($C12="",0,$E12*$F12) -> 1421200 | H12: 進口 | I12: 0 | J12: 0.1 | K12: =IF($C12="",0,$G12*$I12+$G12*(1+$I12)*$J12*IF(LEFT('01_專案設定_Setup'!$B$43,1)="否",1,0)) -> 142120 | L12: =IF($C12="",0,$G12+$K12) -> 1563320 | M12: 軟體與無形 Software | N12: 5 | O12: 0 | P12: 0 | Q12: =IF($C12="",0,$L12*'01_專案設定_Setup'!$B$30) -> 1563.32 | R12: ★ 越南社保正在修訂申報資料閘道規則，介接規格變更風險高，OPEX 已編列維護費
A13: 8 | B13: 服務 | C13: 越南在地化：病歷範本、衛生部報表格式、越文介面與術語對應 | D13: 式 | E13: 1 | F13: 3714500 | G13: =IF($C13="",0,$E13*$F13) -> 3714500 | H13: 在地 | I13: 0 | J13: 0.08 | K13: =IF($C13="",0,$G13*$I13+$G13*(1+$I13)*$J13*IF(LEFT('01_專案設定_Setup'!$B$43,1)="否",1,0)) -> 297160 | L13: =IF($C13="",0,$G13+$K13) -> 4011660 | M13: 軟體與無形 Software | N13: 5 | O13: 0 | P13: 0 | Q13: =IF($C13="",0,$L13*'01_專案設定_Setup'!$B$30) -> 4011.66 | R13: ★ 一次性投入。複製到第 2、3 家醫院時可攤薄六成以上——這是本案的核心商業論點
A14: 9 | B14: 服務 | C14: 資料移轉與病人主檔 MPI 清理去重（與 CCCD／VNeID 比對） | D14: 式 | E14: 1 | F14: 2196400 | G14: =IF($C14="",0,$E14*$F14) -> 2196400 | H14: 在地 | I14: 0 | J14: 0.08 | K14: =IF($C14="",0,$G14*$I14+$G14*(1+$I14)*$J14*IF(LEFT('01_專案設定_Setup'!$B$43,1)="否",1,0)) -> 175712 | L14: =IF($C14="",0,$G14+$K14) -> 2372112 | M14: 費用化 Expensed | N14: 0 | O14: 0 | P14: 0 | Q14: =IF($C14="",0,$L14*'01_專案設定_Setup'!$B$30) -> 2372.112 | R14: pacscribe.com：資料移轉 US$0.05–0.50/study。★ 一次性投入
A15: 10 | B15: 服務 | C15: 導入服務：流程重整、平行測試、12 個月上線輔導 | D15: 式 | E15: 1 | F15: 4360500 | G15: =IF($C15="",0,$E15*$F15) -> 4360500 | H15: 在地 | I15: 0 | J15: 0.08 | K15: =IF($C15="",0,$G15*$I15+$G15*(1+$I15)*$J15*IF(LEFT('01_專案設定_Setup'!$B$43,1)="否",1,0)) -> 348840 | L15: =IF($C15="",0,$G15+$K15) -> 4709340 | M15: 費用化 Expensed | N15: 0 | O15: 0 | P15: 0 | Q15: =IF($C15="",0,$L15*'01_專案設定_Setup'!$B$30) -> 4709.34 | R15: bvdkthaibinh.vn：越南 EMR 租賃 RFQ 多為 36 個月、按季付款無預付。★ 一次性投入
A16: 11 | B16: 服務 | C16: 醫師與護理教育訓練（含種子講師制度） | D16: 人 | E16: 600 | F16: 2261 | G16: =IF($C16="",0,$E16*$F16) -> 1356600 | H16: 在地 | I16: 0 | J16: 0.08 | K16: =IF($C16="",0,$G16*$I16+$G16*(1+$I16)*$J16*IF(LEFT('01_專案設定_Setup'!$B$43,1)="否",1,0)) -> 108528 | L16: =IF($C16="",0,$G16+$K16) -> 1465128 | M16: 費用化 Expensed | N16: 0 | O16: 0 | P16: 0 | Q16: =IF($C16="",0,$L16*'01_專案設定_Setup'!$B$30) -> 1465.128 | R16: pacscribe.com：訓練 US$200–700/人。500 床醫院約 600 名需訓人員。★ 一次性投入
A17: 12 | B17: 設備 | C17: 承載環境：伺服器、儲存、備份（可承載於 A醫院 IDC，或商用雲） | D17: 式 | E17: 1 | F17: 2842400 | G17: =IF($C17="",0,$E17*$F17) -> 2842400 | H17: 進口 | I17: 0 | J17: 0.1 | K17: =IF($C17="",0,$G17*$I17+$G17*(1+$I17)*$J17*IF(LEFT('01_專案設定_Setup'!$B$43,1)="否",1,0)) -> 284240 | L17: =IF($C17="",0,$G17+$K17) -> 3126640 | M17: 電腦與網通 IT | N17: 5 | O17: 6 | P17: 0.05 | Q17: =IF($C17="",0,$L17*'01_專案設定_Setup'!$B$30) -> 3126.64 | R17: ★ 若承載於 A醫院 IDC，本項即為聯盟內部轉付，並構成該機房「承載專案數 ≥2」的證據
... A21: 16 | B21: 預備 | C21: 不可預見費 Contingency | D21: 式 | E21: 1 | F21: 2100000 | G21: =IF($C21="",0,$E21*$F21) -> 2100000 | H21: 在地 | I21: 0 | J21: 0.08 | K21: =IF($C21="",0,$G21*$I21+$G21*(1+$I21)*$J21*IF(LEFT('01_專案設定_Setup'!$B$43,1)="否",1,0)) -> 168000 | L21: =IF($C21="",0,$G21+$K21) -> 2268000 | M21: 費用化 Expensed | N21: 0 | O21: 0 | P21: 0 | Q21: =IF($C21="",0,$L21*'01_專案設定_Setup'!$B$30) -> 2268 | R21: 約未稅總額 6%。醫院流程重整的變更風險高
A22: 17 | G22: =IF($C22="",0,$E22*$F22) -> 0 | K22: =IF($C22="",0,$G22*$I22+$G22*(1+$I22)*$J22*IF(LEFT('01_專案設定_Setup'!$B$43,1)="否",1,0)) -> 0 | L22: =IF($C22="",0,$G22+$K22) -> 0 | Q22: =IF($C22="",0,$L22*'01_專案設定_Setup'!$B$30) -> 0
A23: 18 | G23: =IF($C23="",0,$E23*$F23) -> 0 | K23: =IF($C23="",0,$G23*$I23+$G23*(1+$I23)*$J23*IF(LEFT('01_專案設定_Setup'!$B$43,1)="否",1,0)) -> 0 | L23: =IF($C23="",0,$G23+$K23) -> 0 | Q23: =IF($C23="",0,$L23*'01_專案設定_Setup'!$B$30) -> 0
A24: 19 | G24: =IF($C24="",0,$E24*$F24) -> 0 | K24: =IF($C24="",0,$G24*$I24+$G24*(1+$I24)*$J24*IF(LEFT('01_專案設定_Setup'!$B$43,1)="否",1,0)) -> 0 | L24: =IF($C24="",0,$G24+$K24) -> 0 | Q24: =IF($C24="",0,$L24*'01_專案設定_Setup'!$B$30) -> 0
A25: 20 | G25: =IF($C25="",0,$E25*$F25) -> 0 | K25: =IF($C25="",0,$G25*$I25+$G25*(1+$I25)*$J25*IF(LEFT('01_專案設定_Setup'!$B$43,1)="否",1,0)) -> 0 | L25: =IF($C25="",0,$G25+$K25) -> 0 | Q25: =IF($C25="",0,$L25*'01_專案設定_Setup'!$B$30) -> 0
A26: 21 | G26: =IF($C26="",0,$E26*$F26) -> 0 | K26: =IF($C26="",0,$G26*$I26+$G26*(1+$I26)*$J26*IF(LEFT('01_專案設定_Setup'!$B$43,1)="否",1,0)) -> 0 | L26: =IF($C26="",0,$G26+$K26) -> 0 | Q26: =IF($C26="",0,$L26*'01_專案設定_Setup'!$B$30) -> 0
A27: 22 | G27: =IF($C27="",0,$E27*$F27) -> 0 | K27: =IF($C27="",0,$G27*$I27+$G27*(1+$I27)*$J27*IF(LEFT('01_專案設定_Setup'!$B$43,1)="否",1,0)) -> 0 | L27: =IF($C27="",0,$G27+$K27) -> 0 | Q27: =IF($C27="",0,$L27*'01_專案設定_Setup'!$B$30) -> 0
A28: 23 | G28: =IF($C28="",0,$E28*$F28) -> 0 | K28: =IF($C28="",0,$G28*$I28+$G28*(1+$I28)*$J28*IF(LEFT('01_專案設定_Setup'!$B$43,1)="否",1,0)) -> 0 | L28: =IF($C28="",0,$G28+$K28) -> 0 | Q28: =IF($C28="",0,$L28*'01_專案設定_Setup'!$B$30) -> 0
A29: 24 | G29: =IF($C29="",0,$E29*$F29) -> 0 | K29: =IF($C29="",0,$G29*$I29+$G29*(1+$I29)*$J29*IF(LEFT('01_專案設定_Setup'!$B$43,1)="否",1,0)) -> 0 | L29: =IF($C29="",0,$G29+$K29) -> 0 | Q29: =IF($C29="",0,$L29*'01_專案設定_Setup'!$B$30) -> 0
A30: 25 | G30: =IF($C30="",0,$E30*$F30) -> 0 | K30: =IF($C30="",0,$G30*$I30+$G30*(1+$I30)*$J30*IF(LEFT('01_專案設定_Setup'!$B$43,1)="否",1,0)) -> 0 | L30: =IF($C30="",0,$G30+$K30) -> 0 | Q30: =IF($C30="",0,$L30*'01_專案設定_Setup'!$B$30) -> 0
A31: 26 | G31: =IF($C31="",0,$E31*$F31) -> 0 | K31: =IF($C31="",0,$G31*$I31+$G31*(1+$I31)*$J31*IF(LEFT('01_專案設定_Setup'!$B$43,1)="否",1,0)) -> 0 | L31: =IF($C31="",0,$G31+$K31) -> 0 | Q31: =IF($C31="",0,$L31*'01_專案設定_Setup'!$B$30) -> 0
A32: 27 | G32: =IF($C32="",0,$E32*$F32) -> 0 | K32: =IF($C32="",0,$G32*$I32+$G32*(1+$I32)*$J32*IF(LEFT('01_專案設定_Setup'!$B$43,1)="否",1,0)) -> 0 | L32: =IF($C32="",0,$G32+$K32) -> 0 | Q32: =IF($C32="",0,$L32*'01_專案設定_Setup'!$B$30) -> 0
A33: 28 | G33: =IF($C33="",0,$E33*$F33) -> 0 | K33: =IF($C33="",0,$G33*$I33+$G33*(1+$I33)*$J33*IF(LEFT('01_專案設定_Setup'!$B$43,1)="否",1,0)) -> 0 | L33: =IF($C33="",0,$G33+$K33) -> 0 | Q33: =IF($C33="",0,$L33*'01_專案設定_Setup'!$B$30) -> 0
... A63: 58 | G63: =IF($C63="",0,$E63*$F63) -> 0 | K63: =IF($C63="",0,$G63*$I63+$G63*(1+$I63)*$J63*IF(LEFT('01_專案設定_Setup'!$B$43,1)="否",1,0)) -> 0 | L63: =IF($C63="",0,$G63+$K63) -> 0 | Q63: =IF($C63="",0,$L63*'01_專案設定_Setup'!$B$30) -> 0
C64: 合計 Total CAPEX（含不可扣抵稅費） | G64: =SUM($G$6:$G$63) -> 37597700 | K64: =SUM($K$6:$K$63) -> 3421902 | L64: =SUM($L$6:$L$63) -> 41019602 | Q64: =SUM($Q$6:$Q$63) -> 41019.602
A66: 分類小計與結構檢查
A67: 分類 | B67: 未稅金額 | C67: 佔比 | E67: 折舊類別 | F67: 含稅金額 | G67: 折舊年限（加權） | I67: 進口／在地 | J67: 含稅金額 | K67: 佔比
A68: 設備 | B68: =SUMIF($B$6:$B$63,$A68,$G$6:$G$63) -> 2842400 | C68: =IFERROR($B68/$G$64,0) -> 0.075600369 | E68: 建物與裝修 Building | F68: =SUMIF($M$6:$M$63,$E68,$L$6:$L$63) -> 0 | G68: =IFERROR(SUMPRODUCT(($M$6:$M$63=$E68)*$L$6:$L$63*$N$6:$N$63)/$F68,0) -> 0 | I68: 進口 | J68: =SUMIF($H$6:$H$63,$I68,$L$6:$L$63) -> 22774730 | K68: =IFERROR($J68/$L$64,0) -> 0.55521577
A69: 工程 | B69: =SUMIF($B$6:$B$63,$A69,$G$6:$G$63) -> 0 | C69: =IFERROR($B69/$G$64,0) -> 0 | E69: 醫療設備 Medical equip | F69: =SUMIF($M$6:$M$63,$E69,$L$6:$L$63) -> 0 | G69: =IFERROR(SUMPRODUCT(($M$6:$M$63=$E69)*$L$6:$L$63*$N$6:$N$63)/$F69,0) -> 0 | I69: 在地 | J69: =SUMIF($H$6:$H$63,$I69,$L$6:$L$63) -> 18244872 | K69: =IFERROR($J69/$L$64,0) -> 0.44478423
A70: 軟體 | B70: =SUMIF($B$6:$B$63,$A70,$G$6:$G$63) -> 17861900 | C70: =IFERROR($B70/$G$64,0) -> 0.47507959 | E70: 機電設備 M&E | F70: =SUMIF($M$6:$M$63,$E70,$L$6:$L$63) -> 0 | G70: =IFERROR(SUMPRODUCT(($M$6:$M$63=$E70)*$L$6:$L$63*$N$6:$N$63)/$F70,0) -> 0 | I70: 混合 | J70: =SUMIF($H$6:$H$63,$I70,$L$6:$L$63) -> 0 | K70: =IFERROR($J70/$L$64,0) -> 0
A71: 服務 | B71: =SUMIF($B$6:$B$63,$A71,$G$6:$G$63) -> 14793400 | C71: =IFERROR($B71/$G$64,0) -> 0.39346556 | E71: 電腦與網通 IT | F71: =SUMIF($M$6:$M$63,$E71,$L$6:$L$63) -> 3126640 | G71: =IFERROR(SUMPRODUCT(($M$6:$M$63=$E71)*$L$6:$L$63*$N$6:$N$63)/$F71,0) -> 5
A72: 預備 | B72: =SUMIF($B$6:$B$63,$A72,$G$6:$G$63) -> 2100000 | C72: =IFERROR($B72/$G$64,0) -> 0.05585448 | E72: 軟體與無形 Software | F72: =SUMIF($M$6:$M$63,$E72,$L$6:$L$63) -> 23659750 | G72: =IFERROR(SUMPRODUCT(($M$6:$M$63=$E72)*$L$6:$L$63*$N$6:$N$63)/$F72,0) -> 5
E73: 費用化 Expensed | F73: =SUMIF($M$6:$M$63,$E73,$L$6:$L$63) -> 14233212 | G73: =IFERROR(SUMPRODUCT(($M$6:$M$63=$E73)*$L$6:$L$63*$N$6:$N$63)/$F73,0) -> 0
A75: ★ 檢查點：不可扣抵稅費佔未稅金額的比例 | D75: =IFERROR($K$64/$G$64,0) -> 0.091013599 | F75: 若這個數字低於 4%，表示你可能把進項 VAT 當成可退稅處理了。越南醫療服務免 VAT ⇒ 進項不可扣抵 ⇒ 這一筆是實實在在的成本。

Sheet 03_營運成本_OPEX
A1: 03 營運成本 OPEX｜年度營運成本明細
A2: 黃底＝要填。「成本性質」欄很重要：標為「變動」的項目會隨 04 分頁的服務量爬坡而等比例縮放（例如顯影劑、耗材）；標為「固定」的項目不隨量變動（例如維保合約、人力、保險）。這一欄填錯，開辦頭幾年的現金流會嚴重失真。
A4: 項次 | B4: 分類 | C4: 成本項目 Cost item | D4: 單位 | E4: 數量 | F4: 單價／年費 （輸入幣別） | G4: 首年金額 （輸入幣別） | H4: 年成長率 | I4: 成本性質 | J4: =CONCATENATE("首年金額",CHAR(10),"（",'01_專案設定_Setup'!$B$31,"）") -> 首年金額 （TWD 千） | K4: 負責角色 | L4: 出處／備註
A5: 1 | B5: 人力 | C5: 產品維護與版本升級團隊（3 人） | D5: 人 | E5: 3 | F5: 468000 | G5: =IF($C5="",0,$E5*$F5) -> 1404000 | H5: 0.08 | I5: 固定 | J5: =IF($C5="",0,$G5*'01_專案設定_Setup'!$B$30) -> 1404 | K5: 醫療資訊 | L5: manpower.com.vn：越南資深開發／DevOps 37–75m VND/月。★ 成長率 8% 反映越南 IT 薪資漲幅
A6: 2 | B6: 人力 | C6: 現場駐點支援工程師（2 人） | D6: 人 | E6: 2 | F6: 316500 | G6: =IF($C6="",0,$E6*$F6) -> 633000 | H6: 0.08 | I6: 固定 | J6: =IF($C6="",0,$G6*'01_專案設定_Setup'!$B$30) -> 633 | K6: 醫療資訊 | L6: ykhoanet.com：越南醫院 IT 10–20m VND/月，駐點取高段
A7: 3 | B7: 公用 | C7: 承載環境代管費（機房／雲端） | D7: 年 | E7: 1 | F7: 1033600 | G7: =IF($C7="",0,$E7*$F7) -> 1033600 | H7: 0.03 | I7: 固定 | J7: =IF($C7="",0,$G7*'01_專案設定_Setup'!$B$30) -> 1033.6 | K7: 數位基建 | L7: ★ 若承載於 A醫院 IDC 即為聯盟內部轉付；市價見 IDC 案 09 分頁的外租單價
A8: 4 | B8: 軟體 | C8: 第三方軟體授權（資料庫、中介軟體、報表引擎） | D8: 年 | E8: 1 | F8: 904400 | G8: =IF($C8="",0,$E8*$F8) -> 904400 | H8: 0.05 | I8: 固定 | J8: =IF($C8="",0,$G8*'01_專案設定_Setup'!$B$30) -> 904.4 | K8: 醫療資訊 | L8: 原廠年費
A9: 5 | B9: 維保 | C9: 資安維運與弱點修補（SOC 訂閱） | D9: 年 | E9: 1 | F9: 678300 | G9: =IF($C9="",0,$E9*$F9) -> 678300 | H9: 0.06 | I9: 固定 | J9: =IF($C9="",0,$G9*'01_專案設定_Setup'!$B$30) -> 678.3 | K9: CISO | L9: PDPL 91/2025 的 72 小時通報義務需有偵測與應變量能
A10: 6 | B10: 服務 | C10: FHIR／VSS 介接規格變更維護 | D10: 年 | E10: 1 | F10: 516800 | G10: =IF($C10="",0,$E10*$F10) -> 516800 | H10: 0.05 | I10: 固定 | J10: =IF($C10="",0,$G10*'01_專案設定_Setup'!$B$30) -> 516.8 | K10: 醫療資訊 | L10: ★ 越南社保正在修訂申報資料閘道規則，介接規格會變。這是越南醫療 IT 特有的持續性成本
A11: 7 | B11: 法規 | C11: 年度稽核與合規（EMR 分級年度覆核、個資稽核） | D11: 年 | E11: 1 | F11: 387600 | G11: =IF($C11="",0,$E11*$F11) -> 387600 | H11: 0.04 | I11: 固定 | J11: =IF($C11="",0,$G11*'01_專案設定_Setup'!$B$30) -> 387.6 | K11: 法務 | L11: 含衛生部電子病歷分級年度覆核
A12: 8 | B12: 公用 | C12: 機房電力與對外頻寬分攤 | D12: 年 | E12: 1 | F12: 258400 | G12: =IF($C12="",0,$E12*$F12) -> 258400 | H12: 0.05 | I12: 固定 | J12: =IF($C12="",0,$G12*'01_專案設定_Setup'!$B$30) -> 258.4 | K12: 數位基建 | L12: 承載環境的水電與頻寬
A13: 9 | B13: 服務 | C13: 客服專線與持續教育訓練支援 | D13: 年 | E13: 1 | F13: 323000 | G13: =IF($C13="",0,$E13*$F13) -> 323000 | H13: 0.05 | I13: 變動 | J13: =IF($C13="",0,$G13*'01_專案設定_Setup'!$B$30) -> 323 | K13: 營運 | L13: 人員異動後的補訓需求持續存在
A14: 10 | B14: 管理 | C14: 間接管理費分攤 Overhead | D14: 年 | E14: 1 | F14: 581400 | G14: =IF($C14="",0,$E14*$F14) -> 581400 | H14: 0.05 | I14: 固定 | J14: =IF($C14="",0,$G14*'01_專案設定_Setup'!$B$30) -> 581.4 | K14: 財務 | L14: 分攤聯盟管理成本
A15: 11 | G15: =IF($C15="",0,$E15*$F15) -> 0 | J15: =IF($C15="",0,$G15*'01_專案設定_Setup'!$B$30) -> 0
A16: 12 | G16: =IF($C16="",0,$E16*$F16) -> 0 | J16: =IF($C16="",0,$G16*'01_專案設定_Setup'!$B$30) -> 0
A17: 13 | G17: =IF($C17="",0,$E17*$F17) -> 0 | J17: =IF($C17="",0,$G17*'01_專案設定_Setup'!$B$30) -> 0
A18: 14 | G18: =IF($C18="",0,$E18*$F18) -> 0 | J18: =IF($C18="",0,$G18*'01_專案設定_Setup'!$B$30) -> 0
A19: 15 | G19: =IF($C19="",0,$E19*$F19) -> 0 | J19: =IF($C19="",0,$G19*'01_專案設定_Setup'!$B$30) -> 0
A20: 16 | G20: =IF($C20="",0,$E20*$F20) -> 0 | J20: =IF($C20="",0,$G20*'01_專案設定_Setup'!$B$30) -> 0
A21: 17 | G21: =IF($C21="",0,$E21*$F21) -> 0 | J21: =IF($C21="",0,$G21*'01_專案設定_Setup'!$B$30) -> 0
A22: 18 | G22: =IF($C22="",0,$E22*$F22) -> 0 | J22: =IF($C22="",0,$G22*'01_專案設定_Setup'!$B$30) -> 0
A23: 19 | G23: =IF($C23="",0,$E23*$F23) -> 0 | J23: =IF($C23="",0,$G23*'01_專案設定_Setup'!$B$30) -> 0
A24: 20 | G24: =IF($C24="",0,$E24*$F24) -> 0 | J24: =IF($C24="",0,$G24*'01_專案設定_Setup'!$B$30) -> 0
A25: 21 | G25: =IF($C25="",0,$E25*$F25) -> 0 | J25: =IF($C25="",0,$G25*'01_專案設定_Setup'!$B$30) -> 0
A26: 22 | G26: =IF($C26="",0,$E26*$F26) -> 0 | J26: =IF($C26="",0,$G26*'01_專案設定_Setup'!$B$30) -> 0
... A34: 30 | G34: =IF($C34="",0,$E34*$F34) -> 0 | J34: =IF($C34="",0,$G34*'01_專案設定_Setup'!$B$30) -> 0
C35: 合計 首年 OPEX | G35: =SUM($G$5:$G$34) -> 6720500 | J35: =SUM($J$5:$J$34) -> 6720.5
C36: 其中：變動成本 Variable | G36: =SUMIF($I$5:$I$34,"變動",$G$5:$G$34) -> 323000 | J36: =$G36*'01_專案設定_Setup'!$B$30 -> 323
C37: 其中：固定成本 Fixed | G37: =SUMIF($I$5:$I$34,"固定",$G$5:$G$34) -> 6397500 | J37: =$G37*'01_專案設定_Setup'!$B$30 -> 6397.5
C38: 加權平均年成長率（依金額加權） | G38: =IFERROR(SUMPRODUCT($G$5:$G$34,$H$5:$H$34)/$G$35,0) -> 0.056449669
A40: ★ 越南在地成本的三個常見低估：①「原廠維保」影像設備的業界行情是設備價的 8–15%／年，十年就是另一台機器的錢；② 薪資年成長率不要填 0——越南薪資漲幅明顯高於服務單價漲幅，這個剪刀差是長期模型裡最容易被忽略的殺手；③ 進口耗材要計入不可扣抵的進項 VAT。

Sheet 04_收入產能_Revenue
A1: 04 收入與產能｜Revenue & Capacity
A2: 黃底＝要填。收入 ＝ 服務量 × 計費期數 × 加權單價 × 爬坡率。健保與自費分開設定，因為兩者的「單價」與「收現速度」完全不同——收現速度會在 06 分頁的營運資金計算中用到。★ 使能型投資（如機房）若不直接對外收費，本頁服務量可填 0，改到 09 分頁做評估。
A4: A. 產能與服務量
A5: 服務床數 Beds | B5: 500 | C5: 床 | D5: B 醫院核定床數。★ 若實際規模為 700–800 床，請直接改這一格重算——床數是本案最直接的槓桿。
A6: 計費期數 Billing periods | B6: 12 | C6: 月／年 | D6: 以租代購年費按月計，一年 12 期
A7: 設計產能利用率 Capacity utilisation | B7: 0.85 | D7: 滿載服務量相對於設備設計最大產能的比例，用來檢查「量」的假設是否物理上可行
A9: B. 單價（健保 vs 自費）
A10: 基本服務費 Base fee | B10: 1680 | C10: TWD／床／月 | D10: 含 HIS／EMR／LIS／RIS、承載環境與維運。500 床 × 1,680 × 12 ＝ 1,008 萬 TWD／年 ≒ 8.2bn VND／年；五年約 41bn VND，已落在越南一級醫院 IT 投資區間（10.5–40bn VND）的上緣。
A11: 加值模組費 Add-on fee | B11: 2420 | C11: TWD／床／月 | D11: AI 判讀介接、病人 App、BI 營運指揮、行動護理等加值模組
A12: 加值模組採用比例 | B12: 0.2 | D12: 初期僅部分科別導入加值模組
A13: 加權平均單價 Weighted price | B13: =$B$10*(1-$B$12)+$B$11*$B$12 -> 1828 | C13: TWD／床／月 | D13: 自動計算
A15: C. 成長率
A16: 服務量年成長率 | B16: 0.02 | D16: 床數成長有限，主要來自服務範圍擴大
A17: 單價年成長率 | B17: 0.03 | D17: 合約每 3 年檢討一次。★ 越南尚無醫院軟體的公開定價基準（ykhoanet.com），廠商不公布價目
A19: D. 開辦爬坡 Ramp-up（第 1–10 年，滿載＝100%）
A20: 年度 | B20: 第 1 年 | C20: 第 2 年 | D20: 第 3 年 | E20: 第 4 年 | F20: 第 5 年 | G20: 第 6 年 | H20: 第 7 年 | I20: 第 8 年 | J20: 第 9 年 | K20: 第 10 年
A21: 爬坡率 Ramp | B21: 0.4 | C21: 0.75 | D21: 1 | E21: 1 | F21: 1 | G21: 1 | H21: 1 | I21: 1 | J21: 1 | K21: 1
A23: E. 逐年營收（自動計算，顯示幣別）
A24: 項目 | B24: =CONCATENATE("第 1 年",CHAR(10),"(",'01_專案設定_Setup'!$B$36+0,")") -> 第 1 年 (2027) | C24: =CONCATENATE("第 2 年",CHAR(10),"(",'01_專案設定_Setup'!$B$36+1,")") -> 第 2 年 (2028) | D24: =CONCATENATE("第 3 年",CHAR(10),"(",'01_專案設定_Setup'!$B$36+2,")") -> 第 3 年 (2029) | E24: =CONCATENATE("第 4 年",CHAR(10),"(",'01_專案設定_Setup'!$B$36+3,")") -> 第 4 年 (2030) | F24: =CONCATENATE("第 5 年",CHAR(10),"(",'01_專案設定_Setup'!$B$36+4,")") -> 第 5 年 (2031) | G24: =CONCATENATE("第 6 年",CHAR(10),"(",'01_專案設定_Setup'!$B$36+5,")") -> 第 6 年 (2032) | H24: =CONCATENATE("第 7 年",CHAR(10),"(",'01_專案設定_Setup'!$B$36+6,")") -> 第 7 年 (2033) | I24: =CONCATENATE("第 8 年",CHAR(10),"(",'01_專案設定_Setup'!$B$36+7,")") -> 第 8 年 (2034) | J24: =CONCATENATE("第 9 年",CHAR(10),"(",'01_專案設定_Setup'!$B$36+8,")") -> 第 9 年 (2035) | K24: =CONCATENATE("第 10 年",CHAR(10),"(",'01_專案設定_Setup'!$B$36+9,")") -> 第 10 年 (2036)
A25: 服務量（爬坡後） | B25: =$B$5*$B$6*(1+$B$16)^0*B$21 -> 2400 | C25: =$B$5*$B$6*(1+$B$16)^1*C$21 -> 4590 | D25: =$B$5*$B$6*(1+$B$16)^2*D$21 -> 6242.4 | E25: =$B$5*$B$6*(1+$B$16)^3*E$21 -> 6367.248 | F25: =$B$5*$B$6*(1+$B$16)^4*F$21 -> 6494.593 | G25: =$B$5*$B$6*(1+$B$16)^5*G$21 -> 6624.4848 | H25: =$B$5*$B$6*(1+$B$16)^6*H$21 -> 6756.9745 | I25: =$B$5*$B$6*(1+$B$16)^7*I$21 -> 6892.114 | J25: =$B$5*$B$6*(1+$B$16)^8*J$21 -> 7029.9563 | K25: =$B$5*$B$6*(1+$B$16)^9*K$21 -> 7170.5554
A26: 加權單價（成長後・輸入幣別） | B26: =$B$13*(1+$B$17)^0 -> 1828 | C26: =$B$13*(1+$B$17)^1 -> 1882.84 | D26: =$B$13*(1+$B$17)^2 -> 1939.3252 | E26: =$B$13*(1+$B$17)^3 -> 1997.505 | F26: =$B$13*(1+$B$17)^4 -> 2057.4301 | G26: =$B$13*(1+$B$17)^5 -> 2119.153 | H26: =$B$13*(1+$B$17)^6 -> 2182.7276 | I26: =$B$13*(1+$B$17)^7 -> 2248.2094 | J26: =$B$13*(1+$B$17)^8 -> 2315.6557 | K26: =$B$13*(1+$B$17)^9 -> 2385.1254
A27: 健保營收 BHYT（顯示幣別） | B27: =IF($B$5=0,0,B$25*(1-$B$12)*$B$10*(1+$B$17)^0*'01_專案設定_Setup'!$B$30) -> 3225.6 | C27: =IF($B$5=0,0,C$25*(1-$B$12)*$B$10*(1+$B$17)^1*'01_專案設定_Setup'!$B$30) -> 6354.0288 | D27: =IF($B$5=0,0,D$25*(1-$B$12)*$B$10*(1+$B$17)^2*'01_專案設定_Setup'!$B$30) -> 8900.7235 | E27: =IF($B$5=0,0,E$25*(1-$B$12)*$B$10*(1+$B$17)^3*'01_專案設定_Setup'!$B$30) -> 9351.1002 | F27: =IF($B$5=0,0,F$25*(1-$B$12)*$B$10*(1+$B$17)^4*'01_專案設定_Setup'!$B$30) -> 9824.2658 | G27: =IF($B$5=0,0,G$25*(1-$B$12)*$B$10*(1+$B$17)^5*'01_專案設定_Setup'!$B$30) -> 10321.374 | H27: =IF($B$5=0,0,H$25*(1-$B$12)*$B$10*(1+$B$17)^6*'01_專案設定_Setup'!$B$30) -> 10843.635 | I27: =IF($B$5=0,0,I$25*(1-$B$12)*$B$10*(1+$B$17)^7*'01_專案設定_Setup'!$B$30) -> 11392.323 | J27: =IF($B$5=0,0,J$25*(1-$B$12)*$B$10*(1+$B$17)^8*'01_專案設定_Setup'!$B$30) -> 11968.775 | K27: =IF($B$5=0,0,K$25*(1-$B$12)*$B$10*(1+$B$17)^9*'01_專案設定_Setup'!$B$30) -> 12574.395
A28: 自費營收 Self-pay（顯示幣別） | B28: =IF($B$5=0,0,B$25*$B$12*$B$11*(1+$B$17)^0*'01_專案設定_Setup'!$B$30) -> 1161.6 | C28: =IF($B$5=0,0,C$25*$B$12*$B$11*(1+$B$17)^1*'01_專案設定_Setup'!$B$30) -> 2288.2068 | D28: =IF($B$5=0,0,D$25*$B$12*$B$11*(1+$B$17)^2*'01_專案設定_Setup'!$B$30) -> 3205.3201 | E28: =IF($B$5=0,0,E$25*$B$12*$B$11*(1+$B$17)^3*'01_專案設定_Setup'!$B$30) -> 3367.5093 | F28: =IF($B$5=0,0,F$25*$B$12*$B$11*(1+$B$17)^4*'01_專案設定_Setup'!$B$30) -> 3537.9053 | G28: =IF($B$5=0,0,G$25*$B$12*$B$11*(1+$B$17)^5*'01_專案設定_Setup'!$B$30) -> 3716.9233 | H28: =IF($B$5=0,0,H$25*$B$12*$B$11*(1+$B$17)^6*'01_專案設定_Setup'!$B$30) -> 3904.9996 | I28: =IF($B$5=0,0,I$25*$B$12*$B$11*(1+$B$17)^7*'01_專案設定_Setup'!$B$30) -> 4102.5926 | J28: =IF($B$5=0,0,J$25*$B$12*$B$11*(1+$B$17)^8*'01_專案設定_Setup'!$B$30) -> 4310.1837 | K28: =IF($B$5=0,0,K$25*$B$12*$B$11*(1+$B$17)^9*'01_專案設定_Setup'!$B$30) -> 4528.279
A29: 營收合計 Total revenue（顯示幣別） | B29: =B$27+B$28 -> 4387.2 | C29: =C$27+C$28 -> 8642.2356 | D29: =D$27+D$28 -> 12106.044 | E29: =E$27+E$28 -> 12718.609 | F29: =F$27+F$28 -> 13362.171 | G29: =G$27+G$28 -> 14038.297 | H29: =H$27+H$28 -> 14748.635 | I29: =I$27+I$28 -> 15494.916 | ... K29: =K$27+K$28 -> 17102.674
A31: 滿載年營收 Full-capacity revenue（顯示幣別） | B31: =$B$5*$B$6*$B$13*'01_專案設定_Setup'!$B$30 -> 10968 | D31: ＝服務量 × 計費期數 × 加權單價，不含爬坡與成長。用來檢查量級是否合理。
A33: 收入＝床數 × 月數 × 服務費（以租代購年費）。爬坡代表分階段上線：第 1 年 40%（門診）、第 2 年 75%（住院＋檢驗）、第 3 年起 100%（全院無紙化）。★ 本案投資類別選「F 策略布局型」而非「A 營收型」，原因見 10 分頁的解讀。

Sheet 05_折舊攤提_Depreciation
A1: 05 折舊攤提｜Depreciation & Amortisation Schedule
A2: 全公式，不需編輯。逐列對應 02 分頁的每一個 CAPEX 分項，依其折舊類別與年限採直線法計提；設有「置換年」的資產（如 UPS 電池、球管、伺服器）會在置換年重新起算一段折舊。★ 折舊年限依越南 Circular 45/2013/TT-BTC 附錄一的法定區間：建物 25–50 年、醫療設備 6–15 年、電腦設備 3–8 年、軟體 3–8 年。★ 稅務提醒：本案若適用長期免稅或 10% 優惠稅率，加速折舊反而會浪費稅盾——折舊年限宜取法定區間的上限。
A4: 項次 | B4: 分項名稱 | C4: 折舊類別 | D4: 年限 | E4: 置換年 | F4: 折舊基數 | G4: 第 1 年 | H4: 第 2 年 | I4: 第 3 年 | J4: 第 4 年 | K4: 第 5 年 | L4: 第 6 年 | M4: 第 7 年 | N4: 第 8 年 | O4: 第 9 年 | P4: 第 10 年
A5: =IF('02_投資成本_CAPEX'!$C6="","",'02_投資成本_CAPEX'!$A6) -> 1 | B5: =IF('02_投資成本_CAPEX'!$C6="","",'02_投資成本_CAPEX'!$C6) -> HIS／EMR 核心平台授權（500 床規模，含門診、住院、批價、病歷） | C5: =IF('02_投資成本_CAPEX'!$C6="","",'02_投資成本_CAPEX'!$M6) -> 軟體與無形 Software | D5: =IF('02_投資成本_CAPEX'!$C6="","",'02_投資成本_CAPEX'!$N6) -> 5 | E5: =IF('02_投資成本_CAPEX'!$C6="","",'02_投資成本_CAPEX'!$O6) -> 0 | F5: =IF('02_投資成本_CAPEX'!$C6="",0,'02_投資成本_CAPEX'!$L6*(1-'02_投資成本_CAPEX'!$P6)*'01_專案設定_Setup'!$B$30) -> 10126.05 | G5: =IF(OR('02_投資成本_CAPEX'!$C6="",'02_投資成本_CAPEX'!$N6=0),0,IF(AND(1>=1,1<='02_投資成本_CAPEX'!$N6),$F5/'02_投資成本_CAPEX'!$N6,0)+IF(AND('02_投資成本_CAPEX'!$O6>0,1>='02_投資成本_CAPEX'!$O6,1<='02_投資成本_CAPEX'!$O6+'02_投資成本_CAPEX'!$N6-1),$F5/'02_投資成本_CAPEX'!$N6,0)) -> 2025.21 | H5: =IF(OR('02_投資成本_CAPEX'!$C6="",'02_投資成本_CAPEX'!$N6=0),0,IF(AND(2>=1,2<='02_投資成本_CAPEX'!$N6),$F5/'02_投資成本_CAPEX'!$N6,0)+IF(AND('02_投資成本_CAPEX'!$O6>0,2>='02_投資成本_CAPEX'!$O6,2<='02_投資成本_CAPEX'!$O6+'02_投資成本_CAPEX'!$N6-1),$F5/'02_投資成本_CAPEX'!$N6,0)) -> 2025.21 | I5: =IF(OR('02_投資成本_CAPEX'!$C6="",'02_投資成本_CAPEX'!$N6=0),0,IF(AND(3>=1,3<='02_投資成本_CAPEX'!$N6),$F5/'02_投資成本_CAPEX'!$N6,0)+IF(AND('02_投資成本_CAPEX'!$O6>0,3>='02_投資成本_CAPEX'!$O6,3<='02_投資成本_CAPEX'!$O6+'02_投資成本_CAPEX'!$N6-1),$F5/'02_投資成本_CAPEX'!$N6,0)) -> 2025.21 | J5: =IF(OR('02_投資成本_CAPEX'!$C6="",'02_投資成本_CAPEX'!$N6=0),0,IF(AND(4>=1,4<='02_投資成本_CAPEX'!$N6),$F5/'02_投資成本_CAPEX'!$N6,0)+IF(AND('02_投資成本_CAPEX'!$O6>0,4>='02_投資成本_CAPEX'!$O6,4<='02_投資成本_CAPEX'!$O6+'02_投資成本_CAPEX'!$N6-1),$F5/'02_投資成本_CAPEX'!$N6,0)) -> 2025.21 | K5: =IF(OR('02_投資成本_CAPEX'!$C6="",'02_投資成本_CAPEX'!$N6=0),0,IF(AND(5>=1,5<='02_投資成本_CAPEX'!$N6),$F5/'02_投資成本_CAPEX'!$N6,0)+IF(AND('02_投資成本_CAPEX'!$O6>0,5>='02_投資成本_CAPEX'!$O6,5<='02_投資成本_CAPEX'!$O6+'02_投資成本_CAPEX'!$N6-1),$F5/'02_投資成本_CAPEX'!$N6,0)) -> 2025.21 | L5: =IF(OR('02_投資成本_CAPEX'!$C6="",'02_投資成本_CAPEX'!$N6=0),0,IF(AND(6>=1,6<='02_投資成本_CAPEX'!$N6),$F5/'02_投資成本_CAPEX'!$N6,0)+IF(AND('02_投資成本_CAPEX'!$O6>0,6>='02_投資成本_CAPEX'!$O6,6<='02_投資成本_CAPEX'!$O6+'02_投資成本_CAPEX'!$N6-1),$F5/'02_投資成本_CAPEX'!$N6,0)) -> 0 | M5: =IF(OR('02_投資成本_CAPEX'!$C6="",'02_投資成本_CAPEX'!$N6=0),0,IF(AND(7>=1,7<='02_投資成本_CAPEX'!$N6),$F5/'02_投資成本_CAPEX'!$N6,0)+IF(AND('02_投資成本_CAPEX'!$O6>0,7>='02_投資成本_CAPEX'!$O6,7<='02_投資成本_CAPEX'!$O6+'02_投資成本_CAPEX'!$N6-1),$F5/'02_投資成本_CAPEX'!$N6,0)) -> 0 | N5: =IF(OR('02_投資成本_CAPEX'!$C6="",'02_投資成本_CAPEX'!$N6=0),0,IF(AND(8>=1,8<='02_投資成本_CAPEX'!$N6),$F5/'02_投資成本_CAPEX'!$N6,0)+IF(AND('02_投資成本_CAPEX'!$O6>0,8>='02_投資成本_CAPEX'!$O6,8<='02_投資成本_CAPEX'!$O6+'02_投資成本_CAPEX'!$N6-1),$F5/'02_投資成本_CAPEX'!$N6,0)) -> 0 | O5: =IF(OR('02_投資成本_CAPEX'!$C6="",'02_投資成本_CAPEX'!$N6=0),0,IF(AND(9>=1,9<='02_投資成本_CAPEX'!$N6),$F5/'02_投資成本_CAPEX'!$N6,0)+IF(AND('02_投資成本_CAPEX'!$O6>0,9>='02_投資成本_CAPEX'!$O6,9<='02_投資成本_CAPEX'!$O6+'02_投資成本_CAPEX'!$N6-1),$F5/'02_投資成本_CAPEX'!$N6,0)) -> 0 | P5: =IF(OR('02_投資成本_CAPEX'!$C6="",'02_投資成本_CAPEX'!$N6=0),0,IF(AND(10>=1,10<='02_投資成本_CAPEX'!$N6),$F5/'02_投資成本_CAPEX'!$N6,0)+IF(AND('02_投資成本_CAPEX'!$O6>0,10>='02_投資成本_CAPEX'!$O6,10<='02_投資成本_CAPEX'!$O6+'02_投資成本_CAPEX'!$N6-1),$F5/'02_投資成本_CAPEX'!$N6,0)) -> 0
A6: =IF('02_投資成本_CAPEX'!$C7="","",'02_投資成本_CAPEX'!$A7) -> 2 | B6: =IF('02_投資成本_CAPEX'!$C7="","",'02_投資成本_CAPEX'!$C7) -> LIS 檢驗資訊模組與儀器雙向介接 | C6: =IF('02_投資成本_CAPEX'!$C7="","",'02_投資成本_CAPEX'!$M7) -> 軟體與無形 Software | D6: =IF('02_投資成本_CAPEX'!$C7="","",'02_投資成本_CAPEX'!$N7) -> 5 | E6: =IF('02_投資成本_CAPEX'!$C7="","",'02_投資成本_CAPEX'!$O7) -> 0 | F6: =IF('02_投資成本_CAPEX'!$C7="",0,'02_投資成本_CAPEX'!$L7*(1-'02_投資成本_CAPEX'!$P7)*'01_專案設定_Setup'!$B$30) -> 1598.85 | G6: =IF(OR('02_投資成本_CAPEX'!$C7="",'02_投資成本_CAPEX'!$N7=0),0,IF(AND(1>=1,1<='02_投資成本_CAPEX'!$N7),$F6/'02_投資成本_CAPEX'!$N7,0)+IF(AND('02_投資成本_CAPEX'!$O7>0,1>='02_投資成本_CAPEX'!$O7,1<='02_投資成本_CAPEX'!$O7+'02_投資成本_CAPEX'!$N7-1),$F6/'02_投資成本_CAPEX'!$N7,0)) -> 319.77 | H6: =IF(OR('02_投資成本_CAPEX'!$C7="",'02_投資成本_CAPEX'!$N7=0),0,IF(AND(2>=1,2<='02_投資成本_CAPEX'!$N7),$F6/'02_投資成本_CAPEX'!$N7,0)+IF(AND('02_投資成本_CAPEX'!$O7>0,2>='02_投資成本_CAPEX'!$O7,2<='02_投資成本_CAPEX'!$O7+'02_投資成本_CAPEX'!$N7-1),$F6/'02_投資成本_CAPEX'!$N7,0)) -> 319.77 | I6: =IF(OR('02_投資成本_CAPEX'!$C7="",'02_投資成本_CAPEX'!$N7=0),0,IF(AND(3>=1,3<='02_投資成本_CAPEX'!$N7),$F6/'02_投資成本_CAPEX'!$N7,0)+IF(AND('02_投資成本_CAPEX'!$O7>0,3>='02_投資成本_CAPEX'!$O7,3<='02_投資成本_CAPEX'!$O7+'02_投資成本_CAPEX'!$N7-1),$F6/'02_投資成本_CAPEX'!$N7,0)) -> 319.77 | J6: =IF(OR('02_投資成本_CAPEX'!$C7="",'02_投資成本_CAPEX'!$N7=0),0,IF(AND(4>=1,4<='02_投資成本_CAPEX'!$N7),$F6/'02_投資成本_CAPEX'!$N7,0)+IF(AND('02_投資成本_CAPEX'!$O7>0,4>='02_投資成本_CAPEX'!$O7,4<='02_投資成本_CAPEX'!$O7+'02_投資成本_CAPEX'!$N7-1),$F6/'02_投資成本_CAPEX'!$N7,0)) -> 319.77 | K6: =IF(OR('02_投資成本_CAPEX'!$C7="",'02_投資成本_CAPEX'!$N7=0),0,IF(AND(5>=1,5<='02_投資成本_CAPEX'!$N7),$F6/'02_投資成本_CAPEX'!$N7,0)+IF(AND('02_投資成本_CAPEX'!$O7>0,5>='02_投資成本_CAPEX'!$O7,5<='02_投資成本_CAPEX'!$O7+'02_投資成本_CAPEX'!$N7-1),$F6/'02_投資成本_CAPEX'!$N7,0)) -> 319.77 | L6: =IF(OR('02_投資成本_CAPEX'!$C7="",'02_投資成本_CAPEX'!$N7=0),0,IF(AND(6>=1,6<='02_投資成本_CAPEX'!$N7),$F6/'02_投資成本_CAPEX'!$N7,0)+IF(AND('02_投資成本_CAPEX'!$O7>0,6>='02_投資成本_CAPEX'!$O7,6<='02_投資成本_CAPEX'!$O7+'02_投資成本_CAPEX'!$N7-1),$F6/'02_投資成本_CAPEX'!$N7,0)) -> 0 | M6: =IF(OR('02_投資成本_CAPEX'!$C7="",'02_投資成本_CAPEX'!$N7=0),0,IF(AND(7>=1,7<='02_投資成本_CAPEX'!$N7),$F6/'02_投資成本_CAPEX'!$N7,0)+IF(AND('02_投資成本_CAPEX'!$O7>0,7>='02_投資成本_CAPEX'!$O7,7<='02_投資成本_CAPEX'!$O7+'02_投資成本_CAPEX'!$N7-1),$F6/'02_投資成本_CAPEX'!$N7,0)) -> 0 | N6: =IF(OR('02_投資成本_CAPEX'!$C7="",'02_投資成本_CAPEX'!$N7=0),0,IF(AND(8>=1,8<='02_投資成本_CAPEX'!$N7),$F6/'02_投資成本_CAPEX'!$N7,0)+IF(AND('02_投資成本_CAPEX'!$O7>0,8>='02_投資成本_CAPEX'!$O7,8<='02_投資成本_CAPEX'!$O7+'02_投資成本_CAPEX'!$N7-1),$F6/'02_投資成本_CAPEX'!$N7,0)) -> 0 | O6: =IF(OR('02_投資成本_CAPEX'!$C7="",'02_投資成本_CAPEX'!$N7=0),0,IF(AND(9>=1,9<='02_投資成本_CAPEX'!$N7),$F6/'02_投資成本_CAPEX'!$N7,0)+IF(AND('02_投資成本_CAPEX'!$O7>0,9>='02_投資成本_CAPEX'!$O7,9<='02_投資成本_CAPEX'!$O7+'02_投資成本_CAPEX'!$N7-1),$F6/'02_投資成本_CAPEX'!$N7,0)) -> 0 | P6: =IF(OR('02_投資成本_CAPEX'!$C7="",'02_投資成本_CAPEX'!$N7=0),0,IF(AND(10>=1,10<='02_投資成本_CAPEX'!$N7),$F6/'02_投資成本_CAPEX'!$N7,0)+IF(AND('02_投資成本_CAPEX'!$O7>0,10>='02_投資成本_CAPEX'!$O7,10<='02_投資成本_CAPEX'!$O7+'02_投資成本_CAPEX'!$N7-1),$F6/'02_投資成本_CAPEX'!$N7,0)) -> 0
A7: =IF('02_投資成本_CAPEX'!$C8="","",'02_投資成本_CAPEX'!$A8) -> 3 | B7: =IF('02_投資成本_CAPEX'!$C8="","",'02_投資成本_CAPEX'!$C8) -> RIS／PACS 介接與院內影像調閱 | C7: =IF('02_投資成本_CAPEX'!$C8="","",'02_投資成本_CAPEX'!$M8) -> 軟體與無形 Software | D7: =IF('02_投資成本_CAPEX'!$C8="","",'02_投資成本_CAPEX'!$N8) -> 5 | E7: =IF('02_投資成本_CAPEX'!$C8="","",'02_投資成本_CAPEX'!$O8) -> 0 | F7: =IF('02_投資成本_CAPEX'!$C8="",0,'02_投資成本_CAPEX'!$L8*(1-'02_投資成本_CAPEX'!$P8)*'01_專案設定_Setup'!$B$30) -> 1172.49 | G7: =IF(OR('02_投資成本_CAPEX'!$C8="",'02_投資成本_CAPEX'!$N8=0),0,IF(AND(1>=1,1<='02_投資成本_CAPEX'!$N8),$F7/'02_投資成本_CAPEX'!$N8,0)+IF(AND('02_投資成本_CAPEX'!$O8>0,1>='02_投資成本_CAPEX'!$O8,1<='02_投資成本_CAPEX'!$O8+'02_投資成本_CAPEX'!$N8-1),$F7/'02_投資成本_CAPEX'!$N8,0)) -> 234.498 | H7: =IF(OR('02_投資成本_CAPEX'!$C8="",'02_投資成本_CAPEX'!$N8=0),0,IF(AND(2>=1,2<='02_投資成本_CAPEX'!$N8),$F7/'02_投資成本_CAPEX'!$N8,0)+IF(AND('02_投資成本_CAPEX'!$O8>0,2>='02_投資成本_CAPEX'!$O8,2<='02_投資成本_CAPEX'!$O8+'02_投資成本_CAPEX'!$N8-1),$F7/'02_投資成本_CAPEX'!$N8,0)) -> 234.498 | I7: =IF(OR('02_投資成本_CAPEX'!$C8="",'02_投資成本_CAPEX'!$N8=0),0,IF(AND(3>=1,3<='02_投資成本_CAPEX'!$N8),$F7/'02_投資成本_CAPEX'!$N8,0)+IF(AND('02_投資成本_CAPEX'!$O8>0,3>='02_投資成本_CAPEX'!$O8,3<='02_投資成本_CAPEX'!$O8+'02_投資成本_CAPEX'!$N8-1),$F7/'02_投資成本_CAPEX'!$N8,0)) -> 234.498 | J7: =IF(OR('02_投資成本_CAPEX'!$C8="",'02_投資成本_CAPEX'!$N8=0),0,IF(AND(4>=1,4<='02_投資成本_CAPEX'!$N8),$F7/'02_投資成本_CAPEX'!$N8,0)+IF(AND('02_投資成本_CAPEX'!$O8>0,4>='02_投資成本_CAPEX'!$O8,4<='02_投資成本_CAPEX'!$O8+'02_投資成本_CAPEX'!$N8-1),$F7/'02_投資成本_CAPEX'!$N8,0)) -> 234.498 | K7: =IF(OR('02_投資成本_CAPEX'!$C8="",'02_投資成本_CAPEX'!$N8=0),0,IF(AND(5>=1,5<='02_投資成本_CAPEX'!$N8),$F7/'02_投資成本_CAPEX'!$N8,0)+IF(AND('02_投資成本_CAPEX'!$O8>0,5>='02_投資成本_CAPEX'!$O8,5<='02_投資成本_CAPEX'!$O8+'02_投資成本_CAPEX'!$N8-1),$F7/'02_投資成本_CAPEX'!$N8,0)) -> 234.498 | L7: =IF(OR('02_投資成本_CAPEX'!$C8="",'02_投資成本_CAPEX'!$N8=0),0,IF(AND(6>=1,6<='02_投資成本_CAPEX'!$N8),$F7/'02_投資成本_CAPEX'!$N8,0)+IF(AND('02_投資成本_CAPEX'!$O8>0,6>='02_投資成本_CAPEX'!$O8,6<='02_投資成本_CAPEX'!$O8+'02_投資成本_CAPEX'!$N8-1),$F7/'02_投資成本_CAPEX'!$N8,0)) -> 0 | M7: =IF(OR('02_投資成本_CAPEX'!$C8="",'02_投資成本_CAPEX'!$N8=0),0,IF(AND(7>=1,7<='02_投資成本_CAPEX'!$N8),$F7/'02_投資成本_CAPEX'!$N8,0)+IF(AND('02_投資成本_CAPEX'!$O8>0,7>='02_投資成本_CAPEX'!$O8,7<='02_投資成本_CAPEX'!$O8+'02_投資成本_CAPEX'!$N8-1),$F7/'02_投資成本_CAPEX'!$N8,0)) -> 0 | N7: =IF(OR('02_投資成本_CAPEX'!$C8="",'02_投資成本_CAPEX'!$N8=0),0,IF(AND(8>=1,8<='02_投資成本_CAPEX'!$N8),$F7/'02_投資成本_CAPEX'!$N8,0)+IF(AND('02_投資成本_CAPEX'!$O8>0,8>='02_投資成本_CAPEX'!$O8,8<='02_投資成本_CAPEX'!$O8+'02_投資成本_CAPEX'!$N8-1),$F7/'02_投資成本_CAPEX'!$N8,0)) -> 0 | O7: =IF(OR('02_投資成本_CAPEX'!$C8="",'02_投資成本_CAPEX'!$N8=0),0,IF(AND(9>=1,9<='02_投資成本_CAPEX'!$N8),$F7/'02_投資成本_CAPEX'!$N8,0)+IF(AND('02_投資成本_CAPEX'!$O8>0,9>='02_投資成本_CAPEX'!$O8,9<='02_投資成本_CAPEX'!$O8+'02_投資成本_CAPEX'!$N8-1),$F7/'02_投資成本_CAPEX'!$N8,0)) -> 0 | P7: =IF(OR('02_投資成本_CAPEX'!$C8="",'02_投資成本_CAPEX'!$N8=0),0,IF(AND(10>=1,10<='02_投資成本_CAPEX'!$N8),$F7/'02_投資成本_CAPEX'!$N8,0)+IF(AND('02_投資成本_CAPEX'!$O8>0,10>='02_投資成本_CAPEX'!$O8,10<='02_投資成本_CAPEX'!$O8+'02_投資成本_CAPEX'!$N8-1),$F7/'02_投資成本_CAPEX'!$N8,0)) -> 0
A8: =IF('02_投資成本_CAPEX'!$C9="","",'02_投資成本_CAPEX'!$A9) -> 4 | B8: =IF('02_投資成本_CAPEX'!$C9="","",'02_投資成本_CAPEX'!$C9) -> 藥事管理與閉環給藥 CPOE／BCMA 模組 | C8: =IF('02_投資成本_CAPEX'!$C9="","",'02_投資成本_CAPEX'!$M9) -> 軟體與無形 Software | D8: =IF('02_投資成本_CAPEX'!$C9="","",'02_投資成本_CAPEX'!$N9) -> 5 | E8: =IF('02_投資成本_CAPEX'!$C9="","",'02_投資成本_CAPEX'!$O9) -> 0 | F8: =IF('02_投資成本_CAPEX'!$C9="",0,'02_投資成本_CAPEX'!$L9*(1-'02_投資成本_CAPEX'!$P9)*'01_專案設定_Setup'!$B$30) -> 1350.14 | G8: =IF(OR('02_投資成本_CAPEX'!$C9="",'02_投資成本_CAPEX'!$N9=0),0,IF(AND(1>=1,1<='02_投資成本_CAPEX'!$N9),$F8/'02_投資成本_CAPEX'!$N9,0)+IF(AND('02_投資成本_CAPEX'!$O9>0,1>='02_投資成本_CAPEX'!$O9,1<='02_投資成本_CAPEX'!$O9+'02_投資成本_CAPEX'!$N9-1),$F8/'02_投資成本_CAPEX'!$N9,0)) -> 270.028 | H8: =IF(OR('02_投資成本_CAPEX'!$C9="",'02_投資成本_CAPEX'!$N9=0),0,IF(AND(2>=1,2<='02_投資成本_CAPEX'!$N9),$F8/'02_投資成本_CAPEX'!$N9,0)+IF(AND('02_投資成本_CAPEX'!$O9>0,2>='02_投資成本_CAPEX'!$O9,2<='02_投資成本_CAPEX'!$O9+'02_投資成本_CAPEX'!$N9-1),$F8/'02_投資成本_CAPEX'!$N9,0)) -> 270.028 | I8: =IF(OR('02_投資成本_CAPEX'!$C9="",'02_投資成本_CAPEX'!$N9=0),0,IF(AND(3>=1,3<='02_投資成本_CAPEX'!$N9),$F8/'02_投資成本_CAPEX'!$N9,0)+IF(AND('02_投資成本_CAPEX'!$O9>0,3>='02_投資成本_CAPEX'!$O9,3<='02_投資成本_CAPEX'!$O9+'02_投資成本_CAPEX'!$N9-1),$F8/'02_投資成本_CAPEX'!$N9,0)) -> 270.028 | J8: =IF(OR('02_投資成本_CAPEX'!$C9="",'02_投資成本_CAPEX'!$N9=0),0,IF(AND(4>=1,4<='02_投資成本_CAPEX'!$N9),$F8/'02_投資成本_CAPEX'!$N9,0)+IF(AND('02_投資成本_CAPEX'!$O9>0,4>='02_投資成本_CAPEX'!$O9,4<='02_投資成本_CAPEX'!$O9+'02_投資成本_CAPEX'!$N9-1),$F8/'02_投資成本_CAPEX'!$N9,0)) -> 270.028 | K8: =IF(OR('02_投資成本_CAPEX'!$C9="",'02_投資成本_CAPEX'!$N9=0),0,IF(AND(5>=1,5<='02_投資成本_CAPEX'!$N9),$F8/'02_投資成本_CAPEX'!$N9,0)+IF(AND('02_投資成本_CAPEX'!$O9>0,5>='02_投資成本_CAPEX'!$O9,5<='02_投資成本_CAPEX'!$O9+'02_投資成本_CAPEX'!$N9-1),$F8/'02_投資成本_CAPEX'!$N9,0)) -> 270.028 | L8: =IF(OR('02_投資成本_CAPEX'!$C9="",'02_投資成本_CAPEX'!$N9=0),0,IF(AND(6>=1,6<='02_投資成本_CAPEX'!$N9),$F8/'02_投資成本_CAPEX'!$N9,0)+IF(AND('02_投資成本_CAPEX'!$O9>0,6>='02_投資成本_CAPEX'!$O9,6<='02_投資成本_CAPEX'!$O9+'02_投資成本_CAPEX'!$N9-1),$F8/'02_投資成本_CAPEX'!$N9,0)) -> 0 | M8: =IF(OR('02_投資成本_CAPEX'!$C9="",'02_投資成本_CAPEX'!$N9=0),0,IF(AND(7>=1,7<='02_投資成本_CAPEX'!$N9),$F8/'02_投資成本_CAPEX'!$N9,0)+IF(AND('02_投資成本_CAPEX'!$O9>0,7>='02_投資成本_CAPEX'!$O9,7<='02_投資成本_CAPEX'!$O9+'02_投資成本_CAPEX'!$N9-1),$F8/'02_投資成本_CAPEX'!$N9,0)) -> 0 | N8: =IF(OR('02_投資成本_CAPEX'!$C9="",'02_投資成本_CAPEX'!$N9=0),0,IF(AND(8>=1,8<='02_投資成本_CAPEX'!$N9),$F8/'02_投資成本_CAPEX'!$N9,0)+IF(AND('02_投資成本_CAPEX'!$O9>0,8>='02_投資成本_CAPEX'!$O9,8<='02_投資成本_CAPEX'!$O9+'02_投資成本_CAPEX'!$N9-1),$F8/'02_投資成本_CAPEX'!$N9,0)) -> 0 | O8: =IF(OR('02_投資成本_CAPEX'!$C9="",'02_投資成本_CAPEX'!$N9=0),0,IF(AND(9>=1,9<='02_投資成本_CAPEX'!$N9),$F8/'02_投資成本_CAPEX'!$N9,0)+IF(AND('02_投資成本_CAPEX'!$O9>0,9>='02_投資成本_CAPEX'!$O9,9<='02_投資成本_CAPEX'!$O9+'02_投資成本_CAPEX'!$N9-1),$F8/'02_投資成本_CAPEX'!$N9,0)) -> 0 | P8: =IF(OR('02_投資成本_CAPEX'!$C9="",'02_投資成本_CAPEX'!$N9=0),0,IF(AND(10>=1,10<='02_投資成本_CAPEX'!$N9),$F8/'02_投資成本_CAPEX'!$N9,0)+IF(AND('02_投資成本_CAPEX'!$O9>0,10>='02_投資成本_CAPEX'!$O9,10<='02_投資成本_CAPEX'!$O9+'02_投資成本_CAPEX'!$N9-1),$F8/'02_投資成本_CAPEX'!$N9,0)) -> 0
A9: =IF('02_投資成本_CAPEX'!$C10="","",'02_投資成本_CAPEX'!$A10) -> 5 | B9: =IF('02_投資成本_CAPEX'!$C10="","",'02_投資成本_CAPEX'!$C10) -> 護理紀錄與電子表單（含行動護理車終端授權） | C9: =IF('02_投資成本_CAPEX'!$C10="","",'02_投資成本_CAPEX'!$M10) -> 軟體與無形 Software | D9: =IF('02_投資成本_CAPEX'!$C10="","",'02_投資成本_CAPEX'!$N10) -> 5 | E9: =IF('02_投資成本_CAPEX'!$C10="","",'02_投資成本_CAPEX'!$O10) -> 0 | F9: =IF('02_投資成本_CAPEX'!$C10="",0,'02_投資成本_CAPEX'!$L10*(1-'02_投資成本_CAPEX'!$P10)*'01_專案設定_Setup'!$B$30) -> 923.78 | G9: =IF(OR('02_投資成本_CAPEX'!$C10="",'02_投資成本_CAPEX'!$N10=0),0,IF(AND(1>=1,1<='02_投資成本_CAPEX'!$N10),$F9/'02_投資成本_CAPEX'!$N10,0)+IF(AND('02_投資成本_CAPEX'!$O10>0,1>='02_投資成本_CAPEX'!$O10,1<='02_投資成本_CAPEX'!$O10+'02_投資成本_CAPEX'!$N10-1),$F9/'02_投資成本_CAPEX'!$N10,0)) -> 184.756 | H9: =IF(OR('02_投資成本_CAPEX'!$C10="",'02_投資成本_CAPEX'!$N10=0),0,IF(AND(2>=1,2<='02_投資成本_CAPEX'!$N10),$F9/'02_投資成本_CAPEX'!$N10,0)+IF(AND('02_投資成本_CAPEX'!$O10>0,2>='02_投資成本_CAPEX'!$O10,2<='02_投資成本_CAPEX'!$O10+'02_投資成本_CAPEX'!$N10-1),$F9/'02_投資成本_CAPEX'!$N10,0)) -> 184.756 | I9: =IF(OR('02_投資成本_CAPEX'!$C10="",'02_投資成本_CAPEX'!$N10=0),0,IF(AND(3>=1,3<='02_投資成本_CAPEX'!$N10),$F9/'02_投資成本_CAPEX'!$N10,0)+IF(AND('02_投資成本_CAPEX'!$O10>0,3>='02_投資成本_CAPEX'!$O10,3<='02_投資成本_CAPEX'!$O10+'02_投資成本_CAPEX'!$N10-1),$F9/'02_投資成本_CAPEX'!$N10,0)) -> 184.756 | J9: =IF(OR('02_投資成本_CAPEX'!$C10="",'02_投資成本_CAPEX'!$N10=0),0,IF(AND(4>=1,4<='02_投資成本_CAPEX'!$N10),$F9/'02_投資成本_CAPEX'!$N10,0)+IF(AND('02_投資成本_CAPEX'!$O10>0,4>='02_投資成本_CAPEX'!$O10,4<='02_投資成本_CAPEX'!$O10+'02_投資成本_CAPEX'!$N10-1),$F9/'02_投資成本_CAPEX'!$N10,0)) -> 184.756 | K9: =IF(OR('02_投資成本_CAPEX'!$C10="",'02_投資成本_CAPEX'!$N10=0),0,IF(AND(5>=1,5<='02_投資成本_CAPEX'!$N10),$F9/'02_投資成本_CAPEX'!$N10,0)+IF(AND('02_投資成本_CAPEX'!$O10>0,5>='02_投資成本_CAPEX'!$O10,5<='02_投資成本_CAPEX'!$O10+'02_投資成本_CAPEX'!$N10-1),$F9/'02_投資成本_CAPEX'!$N10,0)) -> 184.756 | L9: =IF(OR('02_投資成本_CAPEX'!$C10="",'02_投資成本_CAPEX'!$N10=0),0,IF(AND(6>=1,6<='02_投資成本_CAPEX'!$N10),$F9/'02_投資成本_CAPEX'!$N10,0)+IF(AND('02_投資成本_CAPEX'!$O10>0,6>='02_投資成本_CAPEX'!$O10,6<='02_投資成本_CAPEX'!$O10+'02_投資成本_CAPEX'!$N10-1),$F9/'02_投資成本_CAPEX'!$N10,0)) -> 0 | M9: =IF(OR('02_投資成本_CAPEX'!$C10="",'02_投資成本_CAPEX'!$N10=0),0,IF(AND(7>=1,7<='02_投資成本_CAPEX'!$N10),$F9/'02_投資成本_CAPEX'!$N10,0)+IF(AND('02_投資成本_CAPEX'!$O10>0,7>='02_投資成本_CAPEX'!$O10,7<='02_投資成本_CAPEX'!$O10+'02_投資成本_CAPEX'!$N10-1),$F9/'02_投資成本_CAPEX'!$N10,0)) -> 0 | N9: =IF(OR('02_投資成本_CAPEX'!$C10="",'02_投資成本_CAPEX'!$N10=0),0,IF(AND(8>=1,8<='02_投資成本_CAPEX'!$N10),$F9/'02_投資成本_CAPEX'!$N10,0)+IF(AND('02_投資成本_CAPEX'!$O10>0,8>='02_投資成本_CAPEX'!$O10,8<='02_投資成本_CAPEX'!$O10+'02_投資成本_CAPEX'!$N10-1),$F9/'02_投資成本_CAPEX'!$N10,0)) -> 0 | O9: =IF(OR('02_投資成本_CAPEX'!$C10="",'02_投資成本_CAPEX'!$N10=0),0,IF(AND(9>=1,9<='02_投資成本_CAPEX'!$N10),$F9/'02_投資成本_CAPEX'!$N10,0)+IF(AND('02_投資成本_CAPEX'!$O10>0,9>='02_投資成本_CAPEX'!$O10,9<='02_投資成本_CAPEX'!$O10+'02_投資成本_CAPEX'!$N10-1),$F9/'02_投資成本_CAPEX'!$N10,0)) -> 0 | P9: =IF(OR('02_投資成本_CAPEX'!$C10="",'02_投資成本_CAPEX'!$N10=0),0,IF(AND(10>=1,10<='02_投資成本_CAPEX'!$N10),$F9/'02_投資成本_CAPEX'!$N10,0)+IF(AND('02_投資成本_CAPEX'!$O10>0,10>='02_投資成本_CAPEX'!$O10,10<='02_投資成本_CAPEX'!$O10+'02_投資成本_CAPEX'!$N10-1),$F9/'02_投資成本_CAPEX'!$N10,0)) -> 0
A10: =IF('02_投資成本_CAPEX'!$C11="","",'02_投資成本_CAPEX'!$A11) -> 6 | B10: =IF('02_投資成本_CAPEX'!$C11="","",'02_投資成本_CAPEX'!$C11) -> FHIR 介接引擎（HL7 FHIR R4＋DICOM） | C10: =IF('02_投資成本_CAPEX'!$C11="","",'02_投資成本_CAPEX'!$M11) -> 軟體與無形 Software | D10: =IF('02_投資成本_CAPEX'!$C11="","",'02_投資成本_CAPEX'!$N11) -> 5 | E10: =IF('02_投資成本_CAPEX'!$C11="","",'02_投資成本_CAPEX'!$O11) -> 0 | F10: =IF('02_投資成本_CAPEX'!$C11="",0,'02_投資成本_CAPEX'!$L11*(1-'02_投資成本_CAPEX'!$P11)*'01_專案設定_Setup'!$B$30) -> 1705.44 | G10: =IF(OR('02_投資成本_CAPEX'!$C11="",'02_投資成本_CAPEX'!$N11=0),0,IF(AND(1>=1,1<='02_投資成本_CAPEX'!$N11),$F10/'02_投資成本_CAPEX'!$N11,0)+IF(AND('02_投資成本_CAPEX'!$O11>0,1>='02_投資成本_CAPEX'!$O11,1<='02_投資成本_CAPEX'!$O11+'02_投資成本_CAPEX'!$N11-1),$F10/'02_投資成本_CAPEX'!$N11,0)) -> 341.088 | H10: =IF(OR('02_投資成本_CAPEX'!$C11="",'02_投資成本_CAPEX'!$N11=0),0,IF(AND(2>=1,2<='02_投資成本_CAPEX'!$N11),$F10/'02_投資成本_CAPEX'!$N11,0)+IF(AND('02_投資成本_CAPEX'!$O11>0,2>='02_投資成本_CAPEX'!$O11,2<='02_投資成本_CAPEX'!$O11+'02_投資成本_CAPEX'!$N11-1),$F10/'02_投資成本_CAPEX'!$N11,0)) -> 341.088 | I10: =IF(OR('02_投資成本_CAPEX'!$C11="",'02_投資成本_CAPEX'!$N11=0),0,IF(AND(3>=1,3<='02_投資成本_CAPEX'!$N11),$F10/'02_投資成本_CAPEX'!$N11,0)+IF(AND('02_投資成本_CAPEX'!$O11>0,3>='02_投資成本_CAPEX'!$O11,3<='02_投資成本_CAPEX'!$O11+'02_投資成本_CAPEX'!$N11-1),$F10/'02_投資成本_CAPEX'!$N11,0)) -> 341.088 | J10: =IF(OR('02_投資成本_CAPEX'!$C11="",'02_投資成本_CAPEX'!$N11=0),0,IF(AND(4>=1,4<='02_投資成本_CAPEX'!$N11),$F10/'02_投資成本_CAPEX'!$N11,0)+IF(AND('02_投資成本_CAPEX'!$O11>0,4>='02_投資成本_CAPEX'!$O11,4<='02_投資成本_CAPEX'!$O11+'02_投資成本_CAPEX'!$N11-1),$F10/'02_投資成本_CAPEX'!$N11,0)) -> 341.088 | K10: =IF(OR('02_投資成本_CAPEX'!$C11="",'02_投資成本_CAPEX'!$N11=0),0,IF(AND(5>=1,5<='02_投資成本_CAPEX'!$N11),$F10/'02_投資成本_CAPEX'!$N11,0)+IF(AND('02_投資成本_CAPEX'!$O11>0,5>='02_投資成本_CAPEX'!$O11,5<='02_投資成本_CAPEX'!$O11+'02_投資成本_CAPEX'!$N11-1),$F10/'02_投資成本_CAPEX'!$N11,0)) -> 341.088 | L10: =IF(OR('02_投資成本_CAPEX'!$C11="",'02_投資成本_CAPEX'!$N11=0),0,IF(AND(6>=1,6<='02_投資成本_CAPEX'!$N11),$F10/'02_投資成本_CAPEX'!$N11,0)+IF(AND('02_投資成本_CAPEX'!$O11>0,6>='02_投資成本_CAPEX'!$O11,6<='02_投資成本_CAPEX'!$O11+'02_投資成本_CAPEX'!$N11-1),$F10/'02_投資成本_CAPEX'!$N11,0)) -> 0 | M10: =IF(OR('02_投資成本_CAPEX'!$C11="",'02_投資成本_CAPEX'!$N11=0),0,IF(AND(7>=1,7<='02_投資成本_CAPEX'!$N11),$F10/'02_投資成本_CAPEX'!$N11,0)+IF(AND('02_投資成本_CAPEX'!$O11>0,7>='02_投資成本_CAPEX'!$O11,7<='02_投資成本_CAPEX'!$O11+'02_投資成本_CAPEX'!$N11-1),$F10/'02_投資成本_CAPEX'!$N11,0)) -> 0 | N10: =IF(OR('02_投資成本_CAPEX'!$C11="",'02_投資成本_CAPEX'!$N11=0),0,IF(AND(8>=1,8<='02_投資成本_CAPEX'!$N11),$F10/'02_投資成本_CAPEX'!$N11,0)+IF(AND('02_投資成本_CAPEX'!$O11>0,8>='02_投資成本_CAPEX'!$O11,8<='02_投資成本_CAPEX'!$O11+'02_投資成本_CAPEX'!$N11-1),$F10/'02_投資成本_CAPEX'!$N11,0)) -> 0 | O10: =IF(OR('02_投資成本_CAPEX'!$C11="",'02_投資成本_CAPEX'!$N11=0),0,IF(AND(9>=1,9<='02_投資成本_CAPEX'!$N11),$F10/'02_投資成本_CAPEX'!$N11,0)+IF(AND('02_投資成本_CAPEX'!$O11>0,9>='02_投資成本_CAPEX'!$O11,9<='02_投資成本_CAPEX'!$O11+'02_投資成本_CAPEX'!$N11-1),$F10/'02_投資成本_CAPEX'!$N11,0)) -> 0 | P10: =IF(OR('02_投資成本_CAPEX'!$C11="",'02_投資成本_CAPEX'!$N11=0),0,IF(AND(10>=1,10<='02_投資成本_CAPEX'!$N11),$F10/'02_投資成本_CAPEX'!$N11,0)+IF(AND('02_投資成本_CAPEX'!$O11>0,10>='02_投資成本_CAPEX'!$O11,10<='02_投資成本_CAPEX'!$O11+'02_投資成本_CAPEX'!$N11-1),$F10/'02_投資成本_CAPEX'!$N11,0)) -> 0
A11: =IF('02_投資成本_CAPEX'!$C12="","",'02_投資成本_CAPEX'!$A12) -> 7 | B11: =IF('02_投資成本_CAPEX'!$C12="","",'02_投資成本_CAPEX'!$C12) -> VNeID／VSS 健保申報與身分核驗介接 | C11: =IF('02_投資成本_CAPEX'!$C12="","",'02_投資成本_CAPEX'!$M12) -> 軟體與無形 Software | D11: =IF('02_投資成本_CAPEX'!$C12="","",'02_投資成本_CAPEX'!$N12) -> 5 | E11: =IF('02_投資成本_CAPEX'!$C12="","",'02_投資成本_CAPEX'!$O12) -> 0 | F11: =IF('02_投資成本_CAPEX'!$C12="",0,'02_投資成本_CAPEX'!$L12*(1-'02_投資成本_CAPEX'!$P12)*'01_專案設定_Setup'!$B$30) -> 1563.32 | G11: =IF(OR('02_投資成本_CAPEX'!$C12="",'02_投資成本_CAPEX'!$N12=0),0,IF(AND(1>=1,1<='02_投資成本_CAPEX'!$N12),$F11/'02_投資成本_CAPEX'!$N12,0)+IF(AND('02_投資成本_CAPEX'!$O12>0,1>='02_投資成本_CAPEX'!$O12,1<='02_投資成本_CAPEX'!$O12+'02_投資成本_CAPEX'!$N12-1),$F11/'02_投資成本_CAPEX'!$N12,0)) -> 312.664 | H11: =IF(OR('02_投資成本_CAPEX'!$C12="",'02_投資成本_CAPEX'!$N12=0),0,IF(AND(2>=1,2<='02_投資成本_CAPEX'!$N12),$F11/'02_投資成本_CAPEX'!$N12,0)+IF(AND('02_投資成本_CAPEX'!$O12>0,2>='02_投資成本_CAPEX'!$O12,2<='02_投資成本_CAPEX'!$O12+'02_投資成本_CAPEX'!$N12-1),$F11/'02_投資成本_CAPEX'!$N12,0)) -> 312.664 | I11: =IF(OR('02_投資成本_CAPEX'!$C12="",'02_投資成本_CAPEX'!$N12=0),0,IF(AND(3>=1,3<='02_投資成本_CAPEX'!$N12),$F11/'02_投資成本_CAPEX'!$N12,0)+IF(AND('02_投資成本_CAPEX'!$O12>0,3>='02_投資成本_CAPEX'!$O12,3<='02_投資成本_CAPEX'!$O12+'02_投資成本_CAPEX'!$N12-1),$F11/'02_投資成本_CAPEX'!$N12,0)) -> 312.664 | J11: =IF(OR('02_投資成本_CAPEX'!$C12="",'02_投資成本_CAPEX'!$N12=0),0,IF(AND(4>=1,4<='02_投資成本_CAPEX'!$N12),$F11/'02_投資成本_CAPEX'!$N12,0)+IF(AND('02_投資成本_CAPEX'!$O12>0,4>='02_投資成本_CAPEX'!$O12,4<='02_投資成本_CAPEX'!$O12+'02_投資成本_CAPEX'!$N12-1),$F11/'02_投資成本_CAPEX'!$N12,0)) -> 312.664 | K11: =IF(OR('02_投資成本_CAPEX'!$C12="",'02_投資成本_CAPEX'!$N12=0),0,IF(AND(5>=1,5<='02_投資成本_CAPEX'!$N12),$F11/'02_投資成本_CAPEX'!$N12,0)+IF(AND('02_投資成本_CAPEX'!$O12>0,5>='02_投資成本_CAPEX'!$O12,5<='02_投資成本_CAPEX'!$O12+'02_投資成本_CAPEX'!$N12-1),$F11/'02_投資成本_CAPEX'!$N12,0)) -> 312.664 | L11: =IF(OR('02_投資成本_CAPEX'!$C12="",'02_投資成本_CAPEX'!$N12=0),0,IF(AND(6>=1,6<='02_投資成本_CAPEX'!$N12),$F11/'02_投資成本_CAPEX'!$N12,0)+IF(AND('02_投資成本_CAPEX'!$O12>0,6>='02_投資成本_CAPEX'!$O12,6<='02_投資成本_CAPEX'!$O12+'02_投資成本_CAPEX'!$N12-1),$F11/'02_投資成本_CAPEX'!$N12,0)) -> 0 | M11: =IF(OR('02_投資成本_CAPEX'!$C12="",'02_投資成本_CAPEX'!$N12=0),0,IF(AND(7>=1,7<='02_投資成本_CAPEX'!$N12),$F11/'02_投資成本_CAPEX'!$N12,0)+IF(AND('02_投資成本_CAPEX'!$O12>0,7>='02_投資成本_CAPEX'!$O12,7<='02_投資成本_CAPEX'!$O12+'02_投資成本_CAPEX'!$N12-1),$F11/'02_投資成本_CAPEX'!$N12,0)) -> 0 | N11: =IF(OR('02_投資成本_CAPEX'!$C12="",'02_投資成本_CAPEX'!$N12=0),0,IF(AND(8>=1,8<='02_投資成本_CAPEX'!$N12),$F11/'02_投資成本_CAPEX'!$N12,0)+IF(AND('02_投資成本_CAPEX'!$O12>0,8>='02_投資成本_CAPEX'!$O12,8<='02_投資成本_CAPEX'!$O12+'02_投資成本_CAPEX'!$N12-1),$F11/'02_投資成本_CAPEX'!$N12,0)) -> 0 | O11: =IF(OR('02_投資成本_CAPEX'!$C12="",'02_投資成本_CAPEX'!$N12=0),0,IF(AND(9>=1,9<='02_投資成本_CAPEX'!$N12),$F11/'02_投資成本_CAPEX'!$N12,0)+IF(AND('02_投資成本_CAPEX'!$O12>0,9>='02_投資成本_CAPEX'!$O12,9<='02_投資成本_CAPEX'!$O12+'02_投資成本_CAPEX'!$N12-1),$F11/'02_投資成本_CAPEX'!$N12,0)) -> 0 | P11: =IF(OR('02_投資成本_CAPEX'!$C12="",'02_投資成本_CAPEX'!$N12=0),0,IF(AND(10>=1,10<='02_投資成本_CAPEX'!$N12),$F11/'02_投資成本_CAPEX'!$N12,0)+IF(AND('02_投資成本_CAPEX'!$O12>0,10>='02_投資成本_CAPEX'!$O12,10<='02_投資成本_CAPEX'!$O12+'02_投資成本_CAPEX'!$N12-1),$F11/'02_投資成本_CAPEX'!$N12,0)) -> 0
A12: =IF('02_投資成本_CAPEX'!$C13="","",'02_投資成本_CAPEX'!$A13) -> 8 | B12: =IF('02_投資成本_CAPEX'!$C13="","",'02_投資成本_CAPEX'!$C13) -> 越南在地化：病歷範本、衛生部報表格式、越文介面與術語對應 | C12: =IF('02_投資成本_CAPEX'!$C13="","",'02_投資成本_CAPEX'!$M13) -> 軟體與無形 Software | D12: =IF('02_投資成本_CAPEX'!$C13="","",'02_投資成本_CAPEX'!$N13) -> 5 | E12: =IF('02_投資成本_CAPEX'!$C13="","",'02_投資成本_CAPEX'!$O13) -> 0 | F12: =IF('02_投資成本_CAPEX'!$C13="",0,'02_投資成本_CAPEX'!$L13*(1-'02_投資成本_CAPEX'!$P13)*'01_專案設定_Setup'!$B$30) -> 4011.66 | G12: =IF(OR('02_投資成本_CAPEX'!$C13="",'02_投資成本_CAPEX'!$N13=0),0,IF(AND(1>=1,1<='02_投資成本_CAPEX'!$N13),$F12/'02_投資成本_CAPEX'!$N13,0)+IF(AND('02_投資成本_CAPEX'!$O13>0,1>='02_投資成本_CAPEX'!$O13,1<='02_投資成本_CAPEX'!$O13+'02_投資成本_CAPEX'!$N13-1),$F12/'02_投資成本_CAPEX'!$N13,0)) -> 802.332 | H12: =IF(OR('02_投資成本_CAPEX'!$C13="",'02_投資成本_CAPEX'!$N13=0),0,IF(AND(2>=1,2<='02_投資成本_CAPEX'!$N13),$F12/'02_投資成本_CAPEX'!$N13,0)+IF(AND('02_投資成本_CAPEX'!$O13>0,2>='02_投資成本_CAPEX'!$O13,2<='02_投資成本_CAPEX'!$O13+'02_投資成本_CAPEX'!$N13-1),$F12/'02_投資成本_CAPEX'!$N13,0)) -> 802.332 | I12: =IF(OR('02_投資成本_CAPEX'!$C13="",'02_投資成本_CAPEX'!$N13=0),0,IF(AND(3>=1,3<='02_投資成本_CAPEX'!$N13),$F12/'02_投資成本_CAPEX'!$N13,0)+IF(AND('02_投資成本_CAPEX'!$O13>0,3>='02_投資成本_CAPEX'!$O13,3<='02_投資成本_CAPEX'!$O13+'02_投資成本_CAPEX'!$N13-1),$F12/'02_投資成本_CAPEX'!$N13,0)) -> 802.332 | J12: =IF(OR('02_投資成本_CAPEX'!$C13="",'02_投資成本_CAPEX'!$N13=0),0,IF(AND(4>=1,4<='02_投資成本_CAPEX'!$N13),$F12/'02_投資成本_CAPEX'!$N13,0)+IF(AND('02_投資成本_CAPEX'!$O13>0,4>='02_投資成本_CAPEX'!$O13,4<='02_投資成本_CAPEX'!$O13+'02_投資成本_CAPEX'!$N13-1),$F12/'02_投資成本_CAPEX'!$N13,0)) -> 802.332 | K12: =IF(OR('02_投資成本_CAPEX'!$C13="",'02_投資成本_CAPEX'!$N13=0),0,IF(AND(5>=1,5<='02_投資成本_CAPEX'!$N13),$F12/'02_投資成本_CAPEX'!$N13,0)+IF(AND('02_投資成本_CAPEX'!$O13>0,5>='02_投資成本_CAPEX'!$O13,5<='02_投資成本_CAPEX'!$O13+'02_投資成本_CAPEX'!$N13-1),$F12/'02_投資成本_CAPEX'!$N13,0)) -> 802.332 | L12: =IF(OR('02_投資成本_CAPEX'!$C13="",'02_投資成本_CAPEX'!$N13=0),0,IF(AND(6>=1,6<='02_投資成本_CAPEX'!$N13),$F12/'02_投資成本_CAPEX'!$N13,0)+IF(AND('02_投資成本_CAPEX'!$O13>0,6>='02_投資成本_CAPEX'!$O13,6<='02_投資成本_CAPEX'!$O13+'02_投資成本_CAPEX'!$N13-1),$F12/'02_投資成本_CAPEX'!$N13,0)) -> 0 | M12: =IF(OR('02_投資成本_CAPEX'!$C13="",'02_投資成本_CAPEX'!$N13=0),0,IF(AND(7>=1,7<='02_投資成本_CAPEX'!$N13),$F12/'02_投資成本_CAPEX'!$N13,0)+IF(AND('02_投資成本_CAPEX'!$O13>0,7>='02_投資成本_CAPEX'!$O13,7<='02_投資成本_CAPEX'!$O13+'02_投資成本_CAPEX'!$N13-1),$F12/'02_投資成本_CAPEX'!$N13,0)) -> 0 | N12: =IF(OR('02_投資成本_CAPEX'!$C13="",'02_投資成本_CAPEX'!$N13=0),0,IF(AND(8>=1,8<='02_投資成本_CAPEX'!$N13),$F12/'02_投資成本_CAPEX'!$N13,0)+IF(AND('02_投資成本_CAPEX'!$O13>0,8>='02_投資成本_CAPEX'!$O13,8<='02_投資成本_CAPEX'!$O13+'02_投資成本_CAPEX'!$N13-1),$F12/'02_投資成本_CAPEX'!$N13,0)) -> 0 | O12: =IF(OR('02_投資成本_CAPEX'!$C13="",'02_投資成本_CAPEX'!$N13=0),0,IF(AND(9>=1,9<='02_投資成本_CAPEX'!$N13),$F12/'02_投資成本_CAPEX'!$N13,0)+IF(AND('02_投資成本_CAPEX'!$O13>0,9>='02_投資成本_CAPEX'!$O13,9<='02_投資成本_CAPEX'!$O13+'02_投資成本_CAPEX'!$N13-1),$F12/'02_投資成本_CAPEX'!$N13,0)) -> 0 | P12: =IF(OR('02_投資成本_CAPEX'!$C13="",'02_投資成本_CAPEX'!$N13=0),0,IF(AND(10>=1,10<='02_投資成本_CAPEX'!$N13),$F12/'02_投資成本_CAPEX'!$N13,0)+IF(AND('02_投資成本_CAPEX'!$O13>0,10>='02_投資成本_CAPEX'!$O13,10<='02_投資成本_CAPEX'!$O13+'02_投資成本_CAPEX'!$N13-1),$F12/'02_投資成本_CAPEX'!$N13,0)) -> 0
